<?xml version="1.0" ?>
<!-- =================================================================================== -->
<!-- |    This document was autogenerated by xacro from /ws/fanuc_m710_description/robot/m710ic_50.urdf.xacro | -->
<!-- |    EDITING THIS FILE BY HAND IS NOT RECOMMENDED                                 | -->
<!-- =================================================================================== -->
<robot name="m710ic_50">
  <link name="world"/>
  <link name="ee_link"/>
  <!-- links -->
  <link name="base_link">
    <visual>
      <origin rpy="0 0 0" xyz="0 0 0"/>
      <geometry>
        <mesh filename="package://fanuc_m710_description/meshes/m710ic_50/visual/base.dae"/>
      </geometry>
    </visual>
    <collision>
      <origin rpy="0 0 0" xyz="0 0 0"/>
      <geometry>
        <mesh filename="package://fanuc_m710_description/meshes/m710ic_50/collision/base.stl"/>
      </geometry>
    </collision>
    <inertial>
      <mass value=" 130"/>
      <origin xyz="-.0493 -.000226  .119"/>
      <inertia ixx=" 3.45" ixy=" .0092" ixz=" .0522" iyy=" 3.53" iyz="-.00428" izz=" 5.62"/>
    </inertial>
  </link>
  <link name="J1_link">
    <visual>
      <origin rpy="0 0 0" xyz="0 0 0"/>
      <geometry>
        <mesh filename="package://fanuc_m710_description/meshes/m710ic_50/visual/j1.dae"/>
      </geometry>
    </visual>
    <collision>
      <origin rpy="0 0 0" xyz="0 0 0"/>
      <geometry>
        <mesh filename="package://fanuc_m710_description/meshes/m710ic_50/collision/j1.stl"/>
      </geometry>
    </collision>
    <inertial>
      <mass value=" 201"/>
      <origin xyz=" .0515 -.00696 -.105"/>
      <inertia ixx=" 7.51" ixy="-.334" ixz="-.508" iyy=" 6.41" iyz=" .219" izz=" 8.04"/>
    </inertial>
  </link>
  <link name="J2_link">
    <visual>
      <origin rpy="0 0 0" xyz="0 0 0"/>
      <geometry>
        <mesh filename="package://fanuc_m710_description/meshes/m710ic_50/visual/j2.dae"/>
      </geometry>
    </visual>
    <collision>
      <origin rpy="0 0 0" xyz="0 0 0"/>
      <geometry>
        <mesh filename="package://fanuc_m710_description/meshes/m710ic_50/collision/j2.stl"/>
      </geometry>
    </collision>
    <inertial>
      <mass value=" 90.9"/>
      <origin xyz=" .00284  .154  .344"/>
      <inertia ixx=" 7.86" ixy=" .0228" ixz=" .0016" iyy=" 8.13" iyz="-.305" izz=" .756"/>
    </inertial>
  </link>
  <link name="J3_link">
    <visual>
      <origin rpy="0 0 0" xyz="0 0 0"/>
      <geometry>
        <mesh filename="package://fanuc_m710_description/meshes/m710ic_50/visual/j3.dae"/>
      </geometry>
    </visual>
    <collision>
      <origin rpy="0 0 0" xyz="0 0 0"/>
      <geometry>
        <mesh filename="package://fanuc_m710_description/meshes/m710ic_50/collision/j3.stl"/>
      </geometry>
    </collision>
    <inertial>
      <mass value=" 95.4"/>
      <origin xyz=" .0214 -.0311  .087"/>
      <inertia ixx=" 1.84" ixy="-.183" ixz="-.245" iyy=" 2.4" iyz="-.0978" izz=" 2.17"/>
    </inertial>
  </link>
  <link name="J4_link">
    <visual>
      <origin rpy="0 0 0" xyz="0 0 0"/>
      <geometry>
        <mesh filename="package://fanuc_m710_description/meshes/m710ic_50/visual/j4.dae"/>
      </geometry>
    </visual>
    <collision>
      <origin rpy="0 0 0" xyz="0 0 0"/>
      <geometry>
        <mesh filename="package://fanuc_m710_description/meshes/m710ic_50/collision/j4.stl"/>
      </geometry>
    </collision>
    <inertial>
      <mass value=" 33"/>
      <origin xyz=" .682 -.022  .000466"/>
      <inertia ixx=" .121" ixy=" .1" ixz="-.000784" iyy=" 1.7" iyz="-.00052" izz=" 1.71"/>
    </inertial>
  </link>
  <link name="J5_link">
    <visual>
      <origin rpy="0 0 0" xyz="0 0 0"/>
      <geometry>
        <mesh filename="package://fanuc_m710_description/meshes/m710ic_50/visual/j5.dae"/>
      </geometry>
    </visual>
    <collision>
      <origin rpy="0 0 0" xyz="0 0 0"/>
      <geometry>
        <mesh filename="package://fanuc_m710_description/meshes/m710ic_50/collision/j5.stl"/>
      </geometry>
    </collision>
    <inertial>
      <mass value=" 9.23"/>
      <origin xyz=" .0411  .00198 -.000000000648"/>
      <inertia ixx=" .0336" ixy="-.00263" ixz=" .0000000000294" iyy=" .0498" iyz=" .000000000344" izz=" .0512"/>
    </inertial>
  </link>
  <link name="J6_link">
    <visual>
      <origin rpy="0 0 0" xyz="0 0 0"/>
      <geometry>
        <mesh filename="package://fanuc_m710_description/meshes/m710ic_50/visual/j6.dae"/>
      </geometry>
    </visual>
    <collision>
      <origin rpy="0 0 0" xyz="0 0 0"/>
      <geometry>
        <mesh filename="package://fanuc_m710_description/meshes/m710ic_50/collision/j6.stl"/>
      </geometry>
    </collision>
    <inertial>
      <mass value=" .483"/>
      <origin xyz=" .165 -4.6E-18 -1.29E-18"/>
      <inertia ixx=" .000937" ixy="-1.3E-18" ixz="-1.5E-19" iyy=" .000485" iyz=" .0000000000691" izz=" .000485"/>
    </inertial>
  </link>
  <!-- joints -->
  <joint name="J1" type="revolute">
    <origin rpy="0 0 0" xyz=" 0  0  .565"/>
    <parent link="base_link"/>
    <child link="J1_link"/>
    <axis xyz=" 0  0  1"/>
    <limit effort="5000" lower="-3.141592653589793" upper="3.141592653589793" velocity="3.0543261909900767"/>
  </joint>
  <joint name="J2" type="revolute">
    <origin rpy="0 0 0" xyz=" .15  0  0"/>
    <parent link="J1_link"/>
    <child link="J2_link"/>
    <axis xyz=" 0  1  0"/>
    <limit effort="7000" lower="-1.5707963267948966" upper="2.356194490192345" velocity="3.0543261909900767"/>
  </joint>
  <joint name="J3" type="revolute">
    <origin rpy="0 0 0" xyz=" 0  0  .87"/>
    <parent link="J2_link"/>
    <child link="J3_link"/>
    <axis xyz=" 0 -1  0"/>
    <limit effort="6000" lower="-1.4049900478554354" upper="3.5779249665883754" velocity="3.0543261909900767"/>
  </joint>
  <joint name="J4" type="revolute">
    <origin rpy="0 0 0" xyz=" 0  0  .17"/>
    <parent link="J3_link"/>
    <child link="J4_link"/>
    <axis xyz="-1  0  0"/>
    <limit effort="800" lower="-6.283185307179586" upper="6.283185307179586" velocity="4.363323129985824"/>
  </joint>
  <joint name="J5" type="revolute">
    <origin rpy="0 0 0" xyz=" 1.016  0  0"/>
    <parent link="J4_link"/>
    <child link="J5_link"/>
    <axis xyz=" 0 -1  0"/>
    <limit effort="900" lower="-2.181661564992912" upper="2.181661564992912" velocity="4.363323129985824"/>
  </joint>
  <joint name="J6" type="revolute">
    <origin rpy="0 0 0" xyz=" 0  0  0"/>
    <parent link="J5_link"/>
    <child link="J6_link"/>
    <axis xyz="-1  0  0"/>
    <limit effort="700" lower="-6.283185307179586" upper="6.283185307179586" velocity="6.19591884457987"/>
  </joint>
  <!-- world coords -->
  <link name="wbase"/>
  <joint name="base_link-wbase" type="fixed">
    <origin rpy="0 0 0" xyz=" 0  0  .565"/>
    <parent link="base_link"/>
    <child link="wbase"/>
  </joint>
  <!-- flange coords -->
  <link name="flange"/>
  <joint name="J6-flange" type="fixed">
    <origin rpy="0 0 0" xyz=" .175  0  0"/>
    <parent link="J6_link"/>
    <child link="flange"/>
  </joint>
  <!-- FANUC flange coords -->
  <link name="fanuc_flange"/>
  <joint name="flange-fanuc_flange" type="fixed">
    <origin rpy="3.141592653589793 -1.5707963267948966 0.0" xyz="0 0 0"/>
    <parent link="flange"/>
    <child link="fanuc_flange"/>
  </joint>
  <!-- Attach to parent -->
  <joint name="base_joint" type="fixed">
    <origin rpy="0 0 0" xyz="0 0 0"/>
    <parent link="world"/>
    <child link="base_link"/>
  </joint>
  <!-- Attach child -->
  <joint name="child_joint" type="fixed">
    <origin rpy="0 0 0" xyz="0 0 0"/>
    <parent link="flange"/>
    <child link="ee_link"/>
  </joint>
</robot>

