<?xml version="1.0" ?>
<!-- =================================================================================== -->
<!-- |    This document was autogenerated by xacro from /repos/fanuc_description/fanuc_m710_description/robot/m710id_70.urdf.xacro | -->
<!-- |    EDITING THIS FILE BY HAND IS NOT RECOMMENDED                                 | -->
<!-- =================================================================================== -->
<robot name="m710id_70">
  <link name="world"/>
  <link name="ee_link"/>
  <!-- links -->
  <link name="base_link">
    <visual>
      <origin rpy="0 0 0" xyz="0 0 0"/>
      <geometry>
        <mesh filename="package://fanuc_m710_description/meshes/m710id_70/visual/base.dae"/>
      </geometry>
    </visual>
    <collision>
      <origin rpy="0 0 0" xyz="0 0 0"/>
      <geometry>
        <mesh filename="package://fanuc_m710_description/meshes/m710id_70/collision/base.stl"/>
      </geometry>
    </collision>
    <inertial>
      <mass value=" 115"/>
      <origin xyz="-.0562 -.000509  .109"/>
      <inertia ixx=" 2.95" ixy="-.0346" ixz=" .0263" iyy=" 3.15" iyz=" .00171" izz=" 5.12"/>
    </inertial>
  </link>
  <link name="J1_link">
    <visual>
      <origin rpy="0 0 0" xyz="0 0 0"/>
      <geometry>
        <mesh filename="package://fanuc_m710_description/meshes/m710id_70/visual/j1.dae"/>
      </geometry>
    </visual>
    <collision>
      <origin rpy="0 0 0" xyz="0 0 0"/>
      <geometry>
        <mesh filename="package://fanuc_m710_description/meshes/m710id_70/collision/j1.stl"/>
      </geometry>
    </collision>
    <inertial>
      <mass value=" 189"/>
      <origin xyz=" .0361 -.00394 -.0874"/>
      <inertia ixx=" 7.22" ixy=" .238" ixz="-.646" iyy=" 5.83" iyz=" .444" izz=" 7.43"/>
    </inertial>
  </link>
  <link name="J2_link">
    <visual>
      <origin rpy="0 0 0" xyz="0 0 0"/>
      <geometry>
        <mesh filename="package://fanuc_m710_description/meshes/m710id_70/visual/j2.dae"/>
      </geometry>
    </visual>
    <collision>
      <origin rpy="0 0 0" xyz="0 0 0"/>
      <geometry>
        <mesh filename="package://fanuc_m710_description/meshes/m710id_70/collision/j2.stl"/>
      </geometry>
    </collision>
    <inertial>
      <mass value=" 137"/>
      <origin xyz="-.0291  .17  .4"/>
      <inertia ixx=" 13.3" ixy=" .0925" ixz="-.0231" iyy=" 14.2" iyz="-1.14" izz=" 1.9"/>
    </inertial>
  </link>
  <link name="J3_link">
    <visual>
      <origin rpy="0 0 0" xyz="0 0 0"/>
      <geometry>
        <mesh filename="package://fanuc_m710_description/meshes/m710id_70/visual/j3.dae"/>
      </geometry>
    </visual>
    <collision>
      <origin rpy="0 0 0" xyz="0 0 0"/>
      <geometry>
        <mesh filename="package://fanuc_m710_description/meshes/m710id_70/collision/j3.stl"/>
      </geometry>
    </collision>
    <inertial>
      <mass value=" 93.9"/>
      <origin xyz=" .0255 -.005  .0679"/>
      <inertia ixx=" 2" ixy="-.0815" ixz="-.327" iyy=" 2.53" iyz="-.0631" izz=" 2.02"/>
    </inertial>
  </link>
  <link name="J4_link">
    <visual>
      <origin rpy="0 0 0" xyz="0 0 0"/>
      <geometry>
        <mesh filename="package://fanuc_m710_description/meshes/m710id_70/visual/j4.dae"/>
      </geometry>
    </visual>
    <collision>
      <origin rpy="0 0 0" xyz="0 0 0"/>
      <geometry>
        <mesh filename="package://fanuc_m710_description/meshes/m710id_70/collision/j4.stl"/>
      </geometry>
    </collision>
    <inertial>
      <mass value=" 34.8"/>
      <origin xyz=" .612 -.00489  .000279"/>
      <inertia ixx=" .14" ixy=" .012" ixz="-.000192" iyy=" 1.83" iyz="-.000335" izz=" 1.83"/>
    </inertial>
  </link>
  <link name="J5_link">
    <visual>
      <origin rpy="0 0 0" xyz="0 0 0"/>
      <geometry>
        <mesh filename="package://fanuc_m710_description/meshes/m710id_70/visual/j5.dae"/>
      </geometry>
    </visual>
    <collision>
      <origin rpy="0 0 0" xyz="0 0 0"/>
      <geometry>
        <mesh filename="package://fanuc_m710_description/meshes/m710id_70/collision/j5.stl"/>
      </geometry>
    </collision>
    <inertial>
      <mass value=" 10.2"/>
      <origin xyz=" .0344 -.0134  .0000000923"/>
      <inertia ixx=" .0448" ixy="-.00501" ixz="-.000000106" iyy=" .0525" iyz="-.00000028" izz=" .0678"/>
    </inertial>
  </link>
  <link name="J6_link">
    <visual>
      <origin rpy="0 0 0" xyz="0 0 0"/>
      <geometry>
        <mesh filename="package://fanuc_m710_description/meshes/m710id_70/visual/j6.dae"/>
      </geometry>
    </visual>
    <collision>
      <origin rpy="0 0 0" xyz="0 0 0"/>
      <geometry>
        <mesh filename="package://fanuc_m710_description/meshes/m710id_70/collision/j6.stl"/>
      </geometry>
    </collision>
    <inertial>
      <mass value=" .447"/>
      <origin xyz=" .165 -7.3E-19  3.24E-19"/>
      <inertia ixx=" .000872" ixy="-1.22E-19" ixz="-4.86E-20" iyy=" .000451" iyz="-1.66E-21" izz=" .000451"/>
    </inertial>
  </link>
  <!-- joints -->
  <joint name="J1" type="revolute">
    <origin rpy="0 0 0" xyz=" 0  0  .565"/>
    <parent link="base_link"/>
    <child link="J1_link"/>
    <axis xyz=" 0  0  1"/>
    <limit effort="8000" lower="-3.2288591161895095" upper="3.2288591161895095" velocity="3.141592653589793"/>
  </joint>
  <joint name="J2" type="revolute">
    <origin rpy="0 0 0" xyz=" .15  0  0"/>
    <parent link="J1_link"/>
    <child link="J2_link"/>
    <axis xyz=" 0  1  0"/>
    <limit effort="10000" lower="-1.3089969389957472" upper="2.6179938779914944" velocity="3.141592653589793"/>
  </joint>
  <joint name="J3" type="revolute">
    <origin rpy="0 0 0" xyz=" 0  0  .895"/>
    <parent link="J2_link"/>
    <child link="J3_link"/>
    <axis xyz=" 0 -1  0"/>
    <limit effort="5000" lower="-1.4049900478554354" upper="3.5779249665883754" velocity="3.141592653589793"/>
  </joint>
  <joint name="J4" type="revolute">
    <origin rpy="0 0 0" xyz=" 0  0  .17"/>
    <parent link="J3_link"/>
    <child link="J4_link"/>
    <axis xyz="-1  0  0"/>
    <limit effort="2000" lower="-6.981317007977318" upper="6.981317007977318" velocity="4.537856055185257"/>
  </joint>
  <joint name="J5" type="revolute">
    <origin rpy="0 0 0" xyz=" 1.045  0  0"/>
    <parent link="J4_link"/>
    <child link="J5_link"/>
    <axis xyz=" 0 -1  0"/>
    <limit effort="1000" lower="-2.181661564992912" upper="2.181661564992912" velocity="4.537856055185257"/>
  </joint>
  <joint name="J6" type="revolute">
    <origin rpy="0 0 0" xyz=" 0  0  0"/>
    <parent link="J5_link"/>
    <child link="J6_link"/>
    <axis xyz="-1  0  0"/>
    <limit effort="900" lower="-6.981317007977318" upper="6.981317007977318" velocity="6.457718232379019"/>
  </joint>
  <!-- world coords -->
  <link name="wbase"/>
  <joint name="base_link-wbase" type="fixed">
    <origin rpy="0 0 0" xyz=" 0  0  .565"/>
    <parent link="base_link"/>
    <child link="wbase"/>
  </joint>
  <!-- flange coords -->
  <link name="flange"/>
  <joint name="J6-flange" type="fixed">
    <origin rpy="0 0 0" xyz=" .175  0  0"/>
    <parent link="J6_link"/>
    <child link="flange"/>
  </joint>
  <!-- FANUC flange coords -->
  <link name="fanuc_flange"/>
  <joint name="flange-fanuc_flange" type="fixed">
    <origin rpy="3.141592653589793 -1.5707963267948966 0.0" xyz="0 0 0"/>
    <parent link="flange"/>
    <child link="fanuc_flange"/>
  </joint>
  <!-- Attach to parent -->
  <joint name="base_joint" type="fixed">
    <origin rpy="0 0 0" xyz="0 0 0"/>
    <parent link="world"/>
    <child link="base_link"/>
  </joint>
  <!-- Attach child -->
  <joint name="child_joint" type="fixed">
    <origin rpy="0 0 0" xyz="0 0 0"/>
    <parent link="flange"/>
    <child link="ee_link"/>
  </joint>
</robot>

