<?xml version="1.0" ?>
<!-- =================================================================================== -->
<!-- |    This document was autogenerated by xacro from /repos/fanuc_description/fanuc_r2000_description/robot/r2000ic_190s.urdf.xacro | -->
<!-- |    EDITING THIS FILE BY HAND IS NOT RECOMMENDED                                 | -->
<!-- =================================================================================== -->
<robot name="r2000ic_190s">
  <link name="world"/>
  <link name="ee_link"/>
  <!-- links -->
  <link name="base_link">
    <visual>
      <origin rpy="0 0 0" xyz="0 0 0"/>
      <geometry>
        <mesh filename="package://fanuc_r2000_description/meshes/r2000ic_190s/visual/base.dae"/>
      </geometry>
    </visual>
    <collision>
      <origin rpy="0 0 0" xyz="0 0 0"/>
      <geometry>
        <mesh filename="package://fanuc_r2000_description/meshes/r2000ic_190s/collision/base.stl"/>
      </geometry>
    </collision>
    <inertial>
      <mass value=" 247"/>
      <origin xyz="-.137 -.00069  .142"/>
      <inertia ixx=" 8.48" ixy=" .227" ixz="-.36" iyy=" 17.7" iyz=" .0176" izz=" 22.4"/>
    </inertial>
  </link>
  <link name="J1_link">
    <visual>
      <origin rpy="0 0 0" xyz="0 0 0"/>
      <geometry>
        <mesh filename="package://fanuc_r2000_description/meshes/r2000ic_190s/visual/j1.dae"/>
      </geometry>
    </visual>
    <collision>
      <origin rpy="0 0 0" xyz="0 0 0"/>
      <geometry>
        <mesh filename="package://fanuc_r2000_description/meshes/r2000ic_190s/collision/j1.stl"/>
      </geometry>
    </collision>
    <inertial>
      <mass value=" 337"/>
      <origin xyz=" .098  .032 -.138"/>
      <inertia ixx=" 18.3" ixy=" .135" ixz="-3.37" iyy=" 18.8" iyz=" .0169" izz=" 22.8"/>
    </inertial>
  </link>
  <link name="J2_link">
    <visual>
      <origin rpy="0 0 0" xyz="0 0 0"/>
      <geometry>
        <mesh filename="package://fanuc_r2000_description/meshes/r2000ic_190s/visual/j2.dae"/>
      </geometry>
    </visual>
    <collision>
      <origin rpy="0 0 0" xyz="0 0 0"/>
      <geometry>
        <mesh filename="package://fanuc_r2000_description/meshes/r2000ic_190s/collision/j2.stl"/>
      </geometry>
    </collision>
    <inertial>
      <mass value=" 228"/>
      <origin xyz=" .0121  .262  .372"/>
      <inertia ixx=" 23.2" ixy="-.0236" ixz="-.415" iyy=" 23.3" iyz="-1.85" izz=" 4.89"/>
    </inertial>
  </link>
  <link name="J3_link">
    <visual>
      <origin rpy="0 0 0" xyz="0 0 0"/>
      <geometry>
        <mesh filename="package://fanuc_r2000_description/meshes/r2000ic_190s/visual/j3.dae"/>
      </geometry>
    </visual>
    <collision>
      <origin rpy="0 0 0" xyz="0 0 0"/>
      <geometry>
        <mesh filename="package://fanuc_r2000_description/meshes/r2000ic_190s/collision/j3.stl"/>
      </geometry>
    </collision>
    <inertial>
      <mass value=" 264"/>
      <origin xyz=" .108  .0589  .151"/>
      <inertia ixx=" 9.38" ixy="-.363" ixz="-.895" iyy=" 16.9" iyz="-.00649" izz=" 17.6"/>
    </inertial>
  </link>
  <link name="J4_link">
    <visual>
      <origin rpy="0 0 0" xyz="0 0 0"/>
      <geometry>
        <mesh filename="package://fanuc_r2000_description/meshes/r2000ic_190s/visual/j4.dae"/>
      </geometry>
    </visual>
    <collision>
      <origin rpy="0 0 0" xyz="0 0 0"/>
      <geometry>
        <mesh filename="package://fanuc_r2000_description/meshes/r2000ic_190s/collision/j4.stl"/>
      </geometry>
    </collision>
    <inertial>
      <mass value=" 15.6"/>
      <origin xyz=" .783 -.00981  .00000000152"/>
      <inertia ixx=" .0763" ixy=" .011" ixz=" .00000000318" iyy=" .181" iyz=" .00000000175" izz=" .176"/>
    </inertial>
  </link>
  <link name="J5_link">
    <visual>
      <origin rpy="0 0 0" xyz="0 0 0"/>
      <geometry>
        <mesh filename="package://fanuc_r2000_description/meshes/r2000ic_190s/visual/j5.dae"/>
      </geometry>
    </visual>
    <collision>
      <origin rpy="0 0 0" xyz="0 0 0"/>
      <geometry>
        <mesh filename="package://fanuc_r2000_description/meshes/r2000ic_190s/collision/j5.stl"/>
      </geometry>
    </collision>
    <inertial>
      <mass value=" 27.2"/>
      <origin xyz=" .0522 -.024 -.0000000449"/>
      <inertia ixx=" .259" ixy="-.0393" ixz=" .000000125" iyy=" .283" iyz="-.000000137" izz=" .366"/>
    </inertial>
  </link>
  <link name="J6_link">
    <visual>
      <origin rpy="0 0 0" xyz="0 0 0"/>
      <geometry>
        <mesh filename="package://fanuc_r2000_description/meshes/r2000ic_190s/visual/j6.dae"/>
      </geometry>
    </visual>
    <collision>
      <origin rpy="0 0 0" xyz="0 0 0"/>
      <geometry>
        <mesh filename="package://fanuc_r2000_description/meshes/r2000ic_190s/collision/j6.stl"/>
      </geometry>
    </collision>
    <inertial>
      <mass value=" 1.93"/>
      <origin xyz=" .221  .000000432  .0000159"/>
      <inertia ixx=" .00901" ixy="-.00000000543" ixz=" .00000024" iyy=" .00475" iyz=" .000000475" izz=" .00476"/>
    </inertial>
  </link>
  <!-- joints -->
  <joint name="J1" type="revolute">
    <origin rpy="0 0 0" xyz=" 0  0  .67"/>
    <parent link="base_link"/>
    <child link="J1_link"/>
    <axis xyz=" 0  0  1"/>
    <limit effort="10000" lower="-3.2288591161895095" upper="3.2288591161895095" velocity="1.8325957145940461"/>
  </joint>
  <joint name="J2" type="revolute">
    <origin rpy="0 0 0" xyz=" .312  0  0"/>
    <parent link="J1_link"/>
    <child link="J2_link"/>
    <axis xyz=" 0  1  0"/>
    <limit effort="30000" lower="-1.3962634015954636" upper="2.2689280275926285" velocity="1.5707963267948966"/>
  </joint>
  <joint name="J3" type="revolute">
    <origin rpy="0 0 0" xyz=" 0  0  .8"/>
    <parent link="J2_link"/>
    <child link="J3_link"/>
    <axis xyz=" 0 -1  0"/>
    <limit effort="20000" lower="-1.3439035240356338" upper="3.141592653589793" velocity="2.530727415391778"/>
  </joint>
  <joint name="J4" type="revolute">
    <origin rpy="0 0 0" xyz=" 0  0  .225"/>
    <parent link="J3_link"/>
    <child link="J4_link"/>
    <axis xyz="-1  0  0"/>
    <limit effort="5000" lower="-6.283185307179586" upper="6.283185307179586" velocity="2.0943951023931953"/>
  </joint>
  <joint name="J5" type="revolute">
    <origin rpy="0 0 0" xyz=" .9  0  0"/>
    <parent link="J4_link"/>
    <child link="J5_link"/>
    <axis xyz=" 0 -1  0"/>
    <limit effort="5000" lower="-2.181661564992912" upper="2.181661564992912" velocity="2.0943951023931953"/>
  </joint>
  <joint name="J6" type="revolute">
    <origin rpy="0 0 0" xyz=" 0  0  0"/>
    <parent link="J5_link"/>
    <child link="J6_link"/>
    <axis xyz="-1  0  0"/>
    <limit effort="3000" lower="-6.283185307179586" upper="6.283185307179586" velocity="3.490658503988659"/>
  </joint>
  <!-- world coords -->
  <link name="wbase"/>
  <joint name="base_link-wbase" type="fixed">
    <origin rpy="0 0 0" xyz=" 0  0  .67"/>
    <parent link="base_link"/>
    <child link="wbase"/>
  </joint>
  <!-- flange coords -->
  <link name="flange"/>
  <joint name="J6-flange" type="fixed">
    <origin rpy="0 0 0" xyz=" .24  0  0"/>
    <parent link="J6_link"/>
    <child link="flange"/>
  </joint>
  <!-- FANUC flange coords -->
  <link name="fanuc_flange"/>
  <joint name="flange-fanuc_flange" type="fixed">
    <origin rpy="3.141592653589793 -1.5707963267948966 0.0" xyz="0 0 0"/>
    <parent link="flange"/>
    <child link="fanuc_flange"/>
  </joint>
  <!-- Attach to parent -->
  <joint name="base_joint" type="fixed">
    <origin rpy="0 0 0" xyz="0 0 0"/>
    <parent link="world"/>
    <child link="base_link"/>
  </joint>
  <!-- Attach child -->
  <joint name="child_joint" type="fixed">
    <origin rpy="0 0 0" xyz="0 0 0"/>
    <parent link="flange"/>
    <child link="ee_link"/>
  </joint>
</robot>

