<?xml version="1.0" ?>
<!-- =================================================================================== -->
<!-- |    This document was autogenerated by xacro from /repos/fanuc_description/fanuc_m710_description/robot/m710ic_20l.urdf.xacro | -->
<!-- |    EDITING THIS FILE BY HAND IS NOT RECOMMENDED                                 | -->
<!-- =================================================================================== -->
<robot name="m710ic_20l">
  <link name="world"/>
  <link name="ee_link"/>
  <!-- links -->
  <link name="base_link">
    <visual>
      <origin rpy="0 0 0" xyz="0 0 0"/>
      <geometry>
        <mesh filename="package://fanuc_m710_description/meshes/m710ic_20l/visual/base.dae"/>
      </geometry>
    </visual>
    <collision>
      <origin rpy="0 0 0" xyz="0 0 0"/>
      <geometry>
        <mesh filename="package://fanuc_m710_description/meshes/m710ic_20l/collision/base.stl"/>
      </geometry>
    </collision>
    <inertial>
      <mass value=" 121"/>
      <origin xyz="-.0566 -.000891  .119"/>
      <inertia ixx=" 3.2" ixy="-.0136" ixz=" .0398" iyy=" 3.45" iyz="-.0063" izz=" 5.39"/>
    </inertial>
  </link>
  <link name="J1_link">
    <visual>
      <origin rpy="0 0 0" xyz="0 0 0"/>
      <geometry>
        <mesh filename="package://fanuc_m710_description/meshes/m710ic_20l/visual/j1.dae"/>
      </geometry>
    </visual>
    <collision>
      <origin rpy="0 0 0" xyz="0 0 0"/>
      <geometry>
        <mesh filename="package://fanuc_m710_description/meshes/m710ic_20l/collision/j1.stl"/>
      </geometry>
    </collision>
    <inertial>
      <mass value=" 183"/>
      <origin xyz=" .0515 -.00696 -.105"/>
      <inertia ixx=" 6.83" ixy="-.304" ixz="-.462" iyy=" 5.83" iyz=" .199" izz=" 7.31"/>
    </inertial>
  </link>
  <link name="J2_link">
    <visual>
      <origin rpy="0 0 0" xyz="0 0 0"/>
      <geometry>
        <mesh filename="package://fanuc_m710_description/meshes/m710ic_20l/visual/j2.dae"/>
      </geometry>
    </visual>
    <collision>
      <origin rpy="0 0 0" xyz="0 0 0"/>
      <geometry>
        <mesh filename="package://fanuc_m710_description/meshes/m710ic_20l/collision/j2.stl"/>
      </geometry>
    </collision>
    <inertial>
      <mass value=" 103"/>
      <origin xyz=" .00255  .155  .462"/>
      <inertia ixx=" 14.2" ixy=" .0237" ixz=" .016" iyy=" 14.5" iyz="-.459" izz=" .855"/>
    </inertial>
  </link>
  <link name="J3_link">
    <visual>
      <origin rpy="0 0 0" xyz="0 0 0"/>
      <geometry>
        <mesh filename="package://fanuc_m710_description/meshes/m710ic_20l/visual/j3.dae"/>
      </geometry>
    </visual>
    <collision>
      <origin rpy="0 0 0" xyz="0 0 0"/>
      <geometry>
        <mesh filename="package://fanuc_m710_description/meshes/m710ic_20l/collision/j3.stl"/>
      </geometry>
    </collision>
    <inertial>
      <mass value=" 82.7"/>
      <origin xyz=" .0731 -.0312  .113"/>
      <inertia ixx=" 1.63" ixy="-.0732" ixz="-.223" iyy=" 2" iyz=" .0871" izz=" 1.77"/>
    </inertial>
  </link>
  <link name="J4_link">
    <visual>
      <origin rpy="0 0 0" xyz="0 0 0"/>
      <geometry>
        <mesh filename="package://fanuc_m710_description/meshes/m710ic_20l/visual/j4.dae"/>
      </geometry>
    </visual>
    <collision>
      <origin rpy="0 0 0" xyz="0 0 0"/>
      <geometry>
        <mesh filename="package://fanuc_m710_description/meshes/m710ic_20l/collision/j4.stl"/>
      </geometry>
    </collision>
    <inertial>
      <mass value=" 47.1"/>
      <origin xyz=" 1.12 -.00605  .000000367"/>
      <inertia ixx=" .141" ixy=" .0701" ixz="-.00000499" iyy=" 8.67" iyz=" .0000000236" izz=" 8.7"/>
    </inertial>
  </link>
  <link name="J5_link">
    <visual>
      <origin rpy="0 0 0" xyz="0 0 0"/>
      <geometry>
        <mesh filename="package://fanuc_m710_description/meshes/m710ic_20l/visual/j5.dae"/>
      </geometry>
    </visual>
    <collision>
      <origin rpy="0 0 0" xyz="0 0 0"/>
      <geometry>
        <mesh filename="package://fanuc_m710_description/meshes/m710ic_20l/collision/j5.stl"/>
      </geometry>
    </collision>
    <inertial>
      <mass value=" 2.84"/>
      <origin xyz="-.00319  .00468 -.00437"/>
      <inertia ixx=" .00408" ixy=" .0000884" ixz="-.000101" iyy=" .00953" iyz="-.00000838" izz=" .00945"/>
    </inertial>
  </link>
  <link name="J6_link">
    <visual>
      <origin rpy="0 0 0" xyz="0 0 0"/>
      <geometry>
        <mesh filename="package://fanuc_m710_description/meshes/m710ic_20l/visual/j6.dae"/>
      </geometry>
    </visual>
    <collision>
      <origin rpy="0 0 0" xyz="0 0 0"/>
      <geometry>
        <mesh filename="package://fanuc_m710_description/meshes/m710ic_20l/collision/j6.stl"/>
      </geometry>
    </collision>
    <inertial>
      <mass value=" .0206"/>
      <origin xyz=" .097  3.42E-20  2.82E-19"/>
      <inertia ixx=" .00000642" ixy=" 8.81E-21" ixz="-3.45E-22" iyy=" .00000327" iyz="-1.42E-23" izz=" .00000327"/>
    </inertial>
  </link>
  <!-- joints -->
  <joint name="J1" type="revolute">
    <origin rpy="0 0 0" xyz=" 0  0  .565"/>
    <parent link="base_link"/>
    <child link="J1_link"/>
    <axis xyz=" 0  0  1"/>
    <limit effort="5000" lower="-3.141592653589793" upper="3.141592653589793" velocity="3.0543261909900767"/>
  </joint>
  <joint name="J2" type="revolute">
    <origin rpy="0 0 0" xyz=" .15  0  0"/>
    <parent link="J1_link"/>
    <child link="J2_link"/>
    <axis xyz=" 0  1  0"/>
    <limit effort="10000" lower="-1.5707963267948966" upper="2.356194490192345" velocity="2.8797932657906435"/>
  </joint>
  <joint name="J3" type="revolute">
    <origin rpy="0 0 0" xyz=" 0  0  1.15"/>
    <parent link="J2_link"/>
    <child link="J3_link"/>
    <axis xyz=" 0 -1  0"/>
    <limit effort="4000" lower="-1.4049900478554354" upper="3.5779249665883754" velocity="3.141592653589793"/>
  </joint>
  <joint name="J4" type="revolute">
    <origin rpy="0 0 0" xyz=" 0  0  .19"/>
    <parent link="J3_link"/>
    <child link="J4_link"/>
    <axis xyz="-1  0  0"/>
    <limit effort="200" lower="-3.490658503988659" upper="3.490658503988659" velocity="6.1086523819801535"/>
  </joint>
  <joint name="J5" type="revolute">
    <origin rpy="0 0 0" xyz=" 1.8  0  0"/>
    <parent link="J4_link"/>
    <child link="J5_link"/>
    <axis xyz=" 0 -1  0"/>
    <limit effort="200" lower="-2.443460952792061" upper="2.443460952792061" velocity="6.283185307179586"/>
  </joint>
  <joint name="J6" type="revolute">
    <origin rpy="0 0 0" xyz=" 0  0  0"/>
    <parent link="J5_link"/>
    <child link="J6_link"/>
    <axis xyz="-1  0  0"/>
    <limit effort="100" lower="-7.853981633974483" upper="7.853981633974483" velocity="10.471975511965978"/>
  </joint>
  <!-- world coords -->
  <link name="wbase"/>
  <joint name="base_link-wbase" type="fixed">
    <origin rpy="0 0 0" xyz=" 0  0  .565"/>
    <parent link="base_link"/>
    <child link="wbase"/>
  </joint>
  <!-- flange coords -->
  <link name="flange"/>
  <joint name="J6-flange" type="fixed">
    <origin rpy="0 0 0" xyz=" .1  0  0"/>
    <parent link="J6_link"/>
    <child link="flange"/>
  </joint>
  <!-- FANUC flange coords -->
  <link name="fanuc_flange"/>
  <joint name="flange-fanuc_flange" type="fixed">
    <origin rpy="3.141592653589793 -1.5707963267948966 0.0" xyz="0 0 0"/>
    <parent link="flange"/>
    <child link="fanuc_flange"/>
  </joint>
  <!-- Attach to parent -->
  <joint name="base_joint" type="fixed">
    <origin rpy="0 0 0" xyz="0 0 0"/>
    <parent link="world"/>
    <child link="base_link"/>
  </joint>
  <!-- Attach child -->
  <joint name="child_joint" type="fixed">
    <origin rpy="0 0 0" xyz="0 0 0"/>
    <parent link="flange"/>
    <child link="ee_link"/>
  </joint>
</robot>

