<?xml version="1.0" ?>
<!-- =================================================================================== -->
<!-- |    This document was autogenerated by xacro from /ws/fanuc_crx_description/robot/crx10ia_lp.urdf.xacro | -->
<!-- |    EDITING THIS FILE BY HAND IS NOT RECOMMENDED                                 | -->
<!-- =================================================================================== -->
<robot name="crx10ia_lp">
  <link name="world"/>
  <link name="ee_link"/>
  <!-- links -->
  <link name="base_link">
    <visual>
      <origin rpy="0 0 0" xyz="0 0 0"/>
      <geometry>
        <mesh filename="package://fanuc_crx_description/meshes/crx10ia_lp/visual/base.dae"/>
      </geometry>
    </visual>
    <collision>
      <origin rpy="0 0 0" xyz="0 0 0"/>
      <geometry>
        <mesh filename="package://fanuc_crx_description/meshes/crx10ia_lp/collision/base.stl"/>
      </geometry>
    </collision>
    <inertial>
      <mass value=" 14.6"/>
      <origin xyz="-.0126 -.000000186  .12"/>
      <inertia ixx=" .17" ixy="-.000000352" ixz=" .00497" iyy=" .17" iyz="-.000000286" izz=" .149"/>
    </inertial>
  </link>
  <link name="J1_link">
    <visual>
      <origin rpy="0 0 0" xyz="0 0 0"/>
      <geometry>
        <mesh filename="package://fanuc_crx_description/meshes/crx10ia_lp/visual/j1.dae"/>
      </geometry>
    </visual>
    <collision>
      <origin rpy="0 0 0" xyz="0 0 0"/>
      <geometry>
        <mesh filename="package://fanuc_crx_description/meshes/crx10ia_lp/collision/j1.stl"/>
      </geometry>
    </collision>
    <inertial>
      <mass value=" 5.2"/>
      <origin xyz="-.0000000152 -.0217 -.0384"/>
      <inertia ixx=" .0348" ixy="-.0000000133" ixz=" .0000000233" iyy=" .03" iyz=" .00228" izz=" .0226"/>
    </inertial>
  </link>
  <link name="J2_link">
    <visual>
      <origin rpy="0 0 0" xyz="0 0 0"/>
      <geometry>
        <mesh filename="package://fanuc_crx_description/meshes/crx10ia_lp/visual/j2.dae"/>
      </geometry>
    </visual>
    <collision>
      <origin rpy="0 0 0" xyz="0 0 0"/>
      <geometry>
        <mesh filename="package://fanuc_crx_description/meshes/crx10ia_lp/collision/j2.stl"/>
      </geometry>
    </collision>
    <inertial>
      <mass value=" 18.9"/>
      <origin xyz=" .0000000891 -.186  .352"/>
      <inertia ixx=" 1.11" ixy="-.000000259" ixz="-.000000118" iyy=" 1.08" iyz="-.0361" izz=" .085"/>
    </inertial>
  </link>
  <link name="J3_link">
    <visual>
      <origin rpy="0 0 0" xyz="0 0 0"/>
      <geometry>
        <mesh filename="package://fanuc_crx_description/meshes/crx10ia_lp/visual/j3.dae"/>
      </geometry>
    </visual>
    <collision>
      <origin rpy="0 0 0" xyz="0 0 0"/>
      <geometry>
        <mesh filename="package://fanuc_crx_description/meshes/crx10ia_lp/collision/j3.stl"/>
      </geometry>
    </collision>
    <inertial>
      <mass value=" 2.66"/>
      <origin xyz=" .0385 -.00854  .00000105"/>
      <inertia ixx=" .00634" ixy="-.000437" ixz="-.000000195" iyy=" .0118" iyz="-.000000107" izz=" .0121"/>
    </inertial>
  </link>
  <link name="J4_link">
    <visual>
      <origin rpy="0 0 0" xyz="0 0 0"/>
      <geometry>
        <mesh filename="package://fanuc_crx_description/meshes/crx10ia_lp/visual/j4.dae"/>
      </geometry>
    </visual>
    <collision>
      <origin rpy="0 0 0" xyz="0 0 0"/>
      <geometry>
        <mesh filename="package://fanuc_crx_description/meshes/crx10ia_lp/collision/j4.stl"/>
      </geometry>
    </collision>
    <inertial>
      <mass value=" 3.88"/>
      <origin xyz=" .378 -.00456 -.000000088"/>
      <inertia ixx=" .00653" ixy=" .00105" ixz="-.0000000212" iyy=" .0604" iyz=" .00000000854" izz=" .0609"/>
    </inertial>
  </link>
  <link name="J5_link">
    <visual>
      <origin rpy="0 0 0" xyz="0 0 0"/>
      <geometry>
        <mesh filename="package://fanuc_crx_description/meshes/crx10ia_lp/visual/j5.dae"/>
      </geometry>
    </visual>
    <collision>
      <origin rpy="0 0 0" xyz="0 0 0"/>
      <geometry>
        <mesh filename="package://fanuc_crx_description/meshes/crx10ia_lp/collision/j5.stl"/>
      </geometry>
    </collision>
    <inertial>
      <mass value=" 1.43"/>
      <origin xyz=" .0227 -.135 -.000000151"/>
      <inertia ixx=" .00278" ixy=" .000258" ixz="-.00000000906" iyy=" .00316" iyz="-.00000000128" izz=" .00395"/>
    </inertial>
  </link>
  <link name="J6_link">
    <visual>
      <origin rpy="0 0 0" xyz="0 0 0"/>
      <geometry>
        <mesh filename="package://fanuc_crx_description/meshes/crx10ia_lp/visual/j6.dae"/>
      </geometry>
    </visual>
    <collision>
      <origin rpy="0 0 0" xyz="0 0 0"/>
      <geometry>
        <mesh filename="package://fanuc_crx_description/meshes/crx10ia_lp/collision/j6.stl"/>
      </geometry>
    </collision>
    <inertial>
      <mass value=" .33"/>
      <origin xyz=" .129  4.81E-19 -4.86E-19"/>
      <inertia ixx=" .000339" ixy=" 2.48E-19" ixz="-4.5E-20" iyy=" .00026" iyz=" 1.38E-20" izz=" .00026"/>
    </inertial>
  </link>
  <!-- joints -->
  <joint name="J1" type="revolute">
    <origin rpy="0 0 0" xyz=" 0  0  .465"/>
    <parent link="base_link"/>
    <child link="J1_link"/>
    <axis xyz=" 0  0  1"/>
    <limit effort="700" lower="-3.141592653589793" upper="3.141592653589793" velocity="2.0943951023931953"/>
  </joint>
  <joint name="J2" type="revolute">
    <origin rpy="0 0 0" xyz=" 0  0  0"/>
    <parent link="J1_link"/>
    <child link="J2_link"/>
    <axis xyz=" 0  1  0"/>
    <limit effort="700" lower="-3.141592653589793" upper="3.141592653589793" velocity="2.0943951023931953"/>
  </joint>
  <joint name="J3" type="revolute">
    <origin rpy="0 0 0" xyz=" 0  0  .71"/>
    <parent link="J2_link"/>
    <child link="J3_link"/>
    <axis xyz=" 0 -1  0"/>
    <limit effort="400" lower="-4.71238898038469" upper="4.71238898038469" velocity="3.141592653589793"/>
  </joint>
  <joint name="J4" type="revolute">
    <origin rpy="0 0 0" xyz=" 0  0  0"/>
    <parent link="J3_link"/>
    <child link="J4_link"/>
    <axis xyz="-1  0  0"/>
    <limit effort="80" lower="-3.3161255787892263" upper="3.3161255787892263" velocity="3.141592653589793"/>
  </joint>
  <joint name="J5" type="revolute">
    <origin rpy="0 0 0" xyz=" .54  0  0"/>
    <parent link="J4_link"/>
    <child link="J5_link"/>
    <axis xyz=" 0 -1  0"/>
    <limit effort="70" lower="-3.141592653589793" upper="3.141592653589793" velocity="3.141592653589793"/>
  </joint>
  <joint name="J6" type="revolute">
    <origin rpy="0 0 0" xyz=" 0 -.15  0"/>
    <parent link="J5_link"/>
    <child link="J6_link"/>
    <axis xyz="-1  0  0"/>
    <limit effort="70" lower="-3.9269908169872414" upper="3.9269908169872414" velocity="3.141592653589793"/>
  </joint>
  <!-- world coords -->
  <link name="wbase"/>
  <joint name="base_link-wbase" type="fixed">
    <origin rpy="0 0 0" xyz=" 0  0  .465"/>
    <parent link="base_link"/>
    <child link="wbase"/>
  </joint>
  <!-- flange coords -->
  <link name="flange"/>
  <joint name="J6-flange" type="fixed">
    <origin rpy="0 0 0" xyz=" .16  0  0"/>
    <parent link="J6_link"/>
    <child link="flange"/>
  </joint>
  <!-- FANUC flange coords -->
  <link name="fanuc_flange"/>
  <joint name="flange-fanuc_flange" type="fixed">
    <origin rpy="3.141592653589793 -1.5707963267948966 0.0" xyz="0 0 0"/>
    <parent link="flange"/>
    <child link="fanuc_flange"/>
  </joint>
  <!-- Attach to parent -->
  <joint name="base_joint" type="fixed">
    <origin rpy="0 0 0" xyz="0 0 0"/>
    <parent link="world"/>
    <child link="base_link"/>
  </joint>
  <!-- Attach child -->
  <joint name="child_joint" type="fixed">
    <origin rpy="0 0 0" xyz="0 0 0"/>
    <parent link="flange"/>
    <child link="ee_link"/>
  </joint>
</robot>

