<?xml version="1.0" ?>
<!-- =================================================================================== -->
<!-- |    This document was autogenerated by xacro from /repos/fanuc_description/fanuc_lrmate_description/robot/lrmate200id7c.urdf.xacro | -->
<!-- |    EDITING THIS FILE BY HAND IS NOT RECOMMENDED                                 | -->
<!-- =================================================================================== -->
<robot name="lrmate200id7c">
  <link name="world"/>
  <link name="ee_link"/>
  <!-- links -->
  <link name="base_link">
    <visual>
      <origin rpy="0 0 0" xyz="0 0 0"/>
      <geometry>
        <mesh filename="package://fanuc_lrmate_description/meshes/lrmate200id7c/visual/base.dae"/>
      </geometry>
    </visual>
    <collision>
      <origin rpy="0 0 0" xyz="0 0 0"/>
      <geometry>
        <mesh filename="package://fanuc_lrmate_description/meshes/lrmate200id7c/collision/base.stl"/>
      </geometry>
    </collision>
    <inertial>
      <mass value=" 5.28"/>
      <origin xyz="-.0146 -.000342  .0796"/>
      <inertia ixx=" .025" ixy="-.000573" ixz=" .000296" iyy=" .0305" iyz="-.000121" izz=" .0321"/>
    </inertial>
  </link>
  <link name="J1_link">
    <visual>
      <origin rpy="0 0 0" xyz="0 0 0"/>
      <geometry>
        <mesh filename="package://fanuc_lrmate_description/meshes/lrmate200id7c/visual/j1.dae"/>
      </geometry>
    </visual>
    <collision>
      <origin rpy="0 0 0" xyz="0 0 0"/>
      <geometry>
        <mesh filename="package://fanuc_lrmate_description/meshes/lrmate200id7c/collision/j1.stl"/>
      </geometry>
    </collision>
    <inertial>
      <mass value=" 5.61"/>
      <origin xyz=" .0287  .000102 -.0547"/>
      <inertia ixx=" .0416" ixy=" .0000238" ixz="-.0055" iyy=" .0302" iyz=" .000121" izz=" .0321"/>
    </inertial>
  </link>
  <link name="J2_link">
    <visual>
      <origin rpy="0 0 0" xyz="0 0 0"/>
      <geometry>
        <mesh filename="package://fanuc_lrmate_description/meshes/lrmate200id7c/visual/j2.dae"/>
      </geometry>
    </visual>
    <collision>
      <origin rpy="0 0 0" xyz="0 0 0"/>
      <geometry>
        <mesh filename="package://fanuc_lrmate_description/meshes/lrmate200id7c/collision/j2.stl"/>
      </geometry>
    </collision>
    <inertial>
      <mass value=" 9.02"/>
      <origin xyz="-.00271 -.000976  .159"/>
      <inertia ixx=" .158" ixy=" .0000334" ixz=" .000153" iyy=" .136" iyz="-.00108" izz=" .0428"/>
    </inertial>
  </link>
  <link name="J3_link">
    <visual>
      <origin rpy="0 0 0" xyz="0 0 0"/>
      <geometry>
        <mesh filename="package://fanuc_lrmate_description/meshes/lrmate200id7c/visual/j3.dae"/>
      </geometry>
    </visual>
    <collision>
      <origin rpy="0 0 0" xyz="0 0 0"/>
      <geometry>
        <mesh filename="package://fanuc_lrmate_description/meshes/lrmate200id7c/collision/j3.stl"/>
      </geometry>
    </collision>
    <inertial>
      <mass value=" 2.15"/>
      <origin xyz=" .00887 -.0000626  .0171"/>
      <inertia ixx=" .00583" ixy="-.0000458" ixz="-.00062" iyy=" .00664" iyz="-.0000459" izz=" .00667"/>
    </inertial>
  </link>
  <link name="J4_link">
    <visual>
      <origin rpy="0 0 0" xyz="0 0 0"/>
      <geometry>
        <mesh filename="package://fanuc_lrmate_description/meshes/lrmate200id7c/visual/j4.dae"/>
      </geometry>
    </visual>
    <collision>
      <origin rpy="0 0 0" xyz="0 0 0"/>
      <geometry>
        <mesh filename="package://fanuc_lrmate_description/meshes/lrmate200id7c/collision/j4.stl"/>
      </geometry>
    </collision>
    <inertial>
      <mass value=" 2.41"/>
      <origin xyz=" .223  .00356  .00215"/>
      <inertia ixx=" .00394" ixy=" .00000026" ixz=" .0000723" iyy=" .017" iyz="-.00000945" izz=" .017"/>
    </inertial>
  </link>
  <link name="J5_link">
    <visual>
      <origin rpy="0 0 0" xyz="0 0 0"/>
      <geometry>
        <mesh filename="package://fanuc_lrmate_description/meshes/lrmate200id7c/visual/j5.dae"/>
      </geometry>
    </visual>
    <collision>
      <origin rpy="0 0 0" xyz="0 0 0"/>
      <geometry>
        <mesh filename="package://fanuc_lrmate_description/meshes/lrmate200id7c/collision/j5.stl"/>
      </geometry>
    </collision>
    <inertial>
      <mass value=" .501"/>
      <origin xyz=" .0236  .00233 -.00000699"/>
      <inertia ixx=" .000391" ixy=" .0000229" ixz="-.0000000238" iyy=" .000782" iyz="-.0000000285" izz=" .000741"/>
    </inertial>
  </link>
  <link name="J6_link">
    <visual>
      <origin rpy="0 0 0" xyz="0 0 0"/>
      <geometry>
        <mesh filename="package://fanuc_lrmate_description/meshes/lrmate200id7c/visual/j6.dae"/>
      </geometry>
    </visual>
    <collision>
      <origin rpy="0 0 0" xyz="0 0 0"/>
      <geometry>
        <mesh filename="package://fanuc_lrmate_description/meshes/lrmate200id7c/collision/j6.stl"/>
      </geometry>
    </collision>
    <inertial>
      <mass value=" .021"/>
      <origin xyz=" .0836 -3.24E-19 -1.22E-18"/>
      <inertia ixx=" .00000504" ixy=" 1.85E-21" ixz="-4.72E-21" iyy=" .00000296" iyz=" 4.98E-22" izz=" .00000296"/>
    </inertial>
  </link>
  <!-- joints -->
  <joint name="J1" type="revolute">
    <origin rpy="0 0 0" xyz=" 0  0  .33"/>
    <parent link="base_link"/>
    <child link="J1_link"/>
    <axis xyz=" 0  0  1"/>
    <limit effort="500" lower="-3.141592653589793" upper="3.141592653589793" velocity="7.853981633974483"/>
  </joint>
  <joint name="J2" type="revolute">
    <origin rpy="0 0 0" xyz=" .05  0  0"/>
    <parent link="J1_link"/>
    <child link="J2_link"/>
    <axis xyz=" 0  1  0"/>
    <limit effort="500" lower="-1.7453292519943295" upper="2.530727415391778" velocity="6.632251157578453"/>
  </joint>
  <joint name="J3" type="revolute">
    <origin rpy="0 0 0" xyz=" 0  0  .33"/>
    <parent link="J2_link"/>
    <child link="J3_link"/>
    <axis xyz=" 0 -1  0"/>
    <limit effort="200" lower="-1.2217304763960306" upper="3.5779249665883754" velocity="9.075712110370514"/>
  </joint>
  <joint name="J4" type="revolute">
    <origin rpy="0 0 0" xyz=" 0  0  .035"/>
    <parent link="J3_link"/>
    <child link="J4_link"/>
    <axis xyz="-1  0  0"/>
    <limit effort="70" lower="-3.3161255787892263" upper="3.3161255787892263" velocity="9.599310885968812"/>
  </joint>
  <joint name="J5" type="revolute">
    <origin rpy="0 0 0" xyz=" .335  0  0"/>
    <parent link="J4_link"/>
    <child link="J5_link"/>
    <axis xyz=" 0 -1  0"/>
    <limit effort="40" lower="-2.181661564992912" upper="2.181661564992912" velocity="9.512044423369096"/>
  </joint>
  <joint name="J6" type="revolute">
    <origin rpy="0 0 0" xyz=" 0  0  0"/>
    <parent link="J5_link"/>
    <child link="J6_link"/>
    <axis xyz="-1  0  0"/>
    <limit effort="20" lower="-6.283185307179586" upper="6.283185307179586" velocity="17.453292519943297"/>
  </joint>
  <!-- world coords -->
  <link name="wbase"/>
  <joint name="base_link-wbase" type="fixed">
    <origin rpy="0 0 0" xyz=" 0  0  .33"/>
    <parent link="base_link"/>
    <child link="wbase"/>
  </joint>
  <!-- flange coords -->
  <link name="flange"/>
  <joint name="J6-flange" type="fixed">
    <origin rpy="0 0 0" xyz=" .09  0  0"/>
    <parent link="J6_link"/>
    <child link="flange"/>
  </joint>
  <!-- FANUC flange coords -->
  <link name="fanuc_flange"/>
  <joint name="flange-fanuc_flange" type="fixed">
    <origin rpy="3.141592653589793 -1.5707963267948966 0.0" xyz="0 0 0"/>
    <parent link="flange"/>
    <child link="fanuc_flange"/>
  </joint>
  <!-- Attach to parent -->
  <joint name="base_joint" type="fixed">
    <origin rpy="0 0 0" xyz="0 0 0"/>
    <parent link="world"/>
    <child link="base_link"/>
  </joint>
  <!-- Attach child -->
  <joint name="child_joint" type="fixed">
    <origin rpy="0 0 0" xyz="0 0 0"/>
    <parent link="flange"/>
    <child link="ee_link"/>
  </joint>
</robot>

