<?xml version="1.0" ?>
<!-- =================================================================================== -->
<!-- |    This document was autogenerated by xacro from /repos/fanuc_description/fanuc_m20_description/robot/m20_25-18d.urdf.xacro | -->
<!-- |    EDITING THIS FILE BY HAND IS NOT RECOMMENDED                                 | -->
<!-- =================================================================================== -->
<robot name="m20_25-18d">
  <link name="world"/>
  <link name="ee_link"/>
  <!-- links -->
  <link name="base_link">
    <visual>
      <origin rpy="0 0 0" xyz="0 0 0"/>
      <geometry>
        <mesh filename="package://fanuc_m20_description/meshes/m20_25-18d/visual/base.dae"/>
      </geometry>
    </visual>
    <collision>
      <origin rpy="0 0 0" xyz="0 0 0"/>
      <geometry>
        <mesh filename="package://fanuc_m20_description/meshes/m20_25-18d/collision/base.stl"/>
      </geometry>
    </collision>
    <inertial>
      <mass value=" 45.8"/>
      <origin xyz="-.0767  .00288  .109"/>
      <inertia ixx=" .497" ixy=" .029" ixz=" .0137" iyy=" 1.1" iyz=" .0000537" izz=" 1.16"/>
    </inertial>
  </link>
  <link name="J1_link">
    <visual>
      <origin rpy="0 0 0" xyz="0 0 0"/>
      <geometry>
        <mesh filename="package://fanuc_m20_description/meshes/m20_25-18d/visual/j1.dae"/>
      </geometry>
    </visual>
    <collision>
      <origin rpy="0 0 0" xyz="0 0 0"/>
      <geometry>
        <mesh filename="package://fanuc_m20_description/meshes/m20_25-18d/collision/j1.stl"/>
      </geometry>
    </collision>
    <inertial>
      <mass value=" 62.8"/>
      <origin xyz=" .0158 -.0106 -.0831"/>
      <inertia ixx=" 1.35" ixy=" .133" ixz="-.0417" iyy=" 1.11" iyz="-.108" izz=" 1.3"/>
    </inertial>
  </link>
  <link name="J2_link">
    <visual>
      <origin rpy="0 0 0" xyz="0 0 0"/>
      <geometry>
        <mesh filename="package://fanuc_m20_description/meshes/m20_25-18d/visual/j2.dae"/>
      </geometry>
    </visual>
    <collision>
      <origin rpy="0 0 0" xyz="0 0 0"/>
      <geometry>
        <mesh filename="package://fanuc_m20_description/meshes/m20_25-18d/collision/j2.stl"/>
      </geometry>
    </collision>
    <inertial>
      <mass value=" 65.8"/>
      <origin xyz="-.0343 -.172  .38"/>
      <inertia ixx=" 4.86" ixy="-.0809" ixz=" .0453" iyy=" 4.98" iyz="-.118" izz=" .536"/>
    </inertial>
  </link>
  <link name="J3_link">
    <visual>
      <origin rpy="0 0 0" xyz="0 0 0"/>
      <geometry>
        <mesh filename="package://fanuc_m20_description/meshes/m20_25-18d/visual/j3.dae"/>
      </geometry>
    </visual>
    <collision>
      <origin rpy="0 0 0" xyz="0 0 0"/>
      <geometry>
        <mesh filename="package://fanuc_m20_description/meshes/m20_25-18d/collision/j3.stl"/>
      </geometry>
    </collision>
    <inertial>
      <mass value=" 52.9"/>
      <origin xyz=" .134  .00796  .103"/>
      <inertia ixx=" .901" ixy="-.0784" ixz="-.294" iyy=" 1.13" iyz="-.0385" izz=" 1.06"/>
    </inertial>
  </link>
  <link name="J4_link">
    <visual>
      <origin rpy="0 0 0" xyz="0 0 0"/>
      <geometry>
        <mesh filename="package://fanuc_m20_description/meshes/m20_25-18d/visual/j4.dae"/>
      </geometry>
    </visual>
    <collision>
      <origin rpy="0 0 0" xyz="0 0 0"/>
      <geometry>
        <mesh filename="package://fanuc_m20_description/meshes/m20_25-18d/collision/j4.stl"/>
      </geometry>
    </collision>
    <inertial>
      <mass value=" 20.2"/>
      <origin xyz=" .586 -.0481 -.000358"/>
      <inertia ixx=" .0769" ixy=" .053" ixz="-.00106" iyy=" .647" iyz="-.0000313" izz=" .656"/>
    </inertial>
  </link>
  <link name="J5_link">
    <visual>
      <origin rpy="0 0 0" xyz="0 0 0"/>
      <geometry>
        <mesh filename="package://fanuc_m20_description/meshes/m20_25-18d/visual/j5.dae"/>
      </geometry>
    </visual>
    <collision>
      <origin rpy="0 0 0" xyz="0 0 0"/>
      <geometry>
        <mesh filename="package://fanuc_m20_description/meshes/m20_25-18d/collision/j5.stl"/>
      </geometry>
    </collision>
    <inertial>
      <mass value=" 1.98"/>
      <origin xyz=" .0276 -.0121  .000000522"/>
      <inertia ixx=" .00394" ixy="-.000785" ixz=" .0000000339" iyy=" .00462" iyz=" .00000000332" izz=" .0041"/>
    </inertial>
  </link>
  <link name="J6_link">
    <visual>
      <origin rpy="0 0 0" xyz="0 0 0"/>
      <geometry>
        <mesh filename="package://fanuc_m20_description/meshes/m20_25-18d/visual/j6.dae"/>
      </geometry>
    </visual>
    <collision>
      <origin rpy="0 0 0" xyz="0 0 0"/>
      <geometry>
        <mesh filename="package://fanuc_m20_description/meshes/m20_25-18d/collision/j6.stl"/>
      </geometry>
    </collision>
    <inertial>
      <mass value=" .558"/>
      <origin xyz=" .0581 -.000000509  .000000147"/>
      <inertia ixx=" .000585" ixy="-.00000000703" ixz=" .0000000019" iyy=" .000433" iyz=" .0000000227" izz=" .000433"/>
    </inertial>
  </link>
  <!-- joints -->
  <joint name="J1" type="revolute">
    <origin rpy="0 0 0" xyz=" 0  0  .425"/>
    <parent link="base_link"/>
    <child link="J1_link"/>
    <axis xyz=" 0  0  1"/>
    <limit effort="7000" lower="-3.2288591161895095" upper="3.2288591161895095" velocity="3.6651914291880923"/>
  </joint>
  <joint name="J2" type="revolute">
    <origin rpy="0 0 0" xyz=" .075  0  0"/>
    <parent link="J1_link"/>
    <child link="J2_link"/>
    <axis xyz=" 0  1  0"/>
    <limit effort="8000" lower="-1.7453292519943295" upper="2.792526803190927" velocity="3.6651914291880923"/>
  </joint>
  <joint name="J3" type="revolute">
    <origin rpy="0 0 0" xyz=" 0  0  .84"/>
    <parent link="J2_link"/>
    <child link="J3_link"/>
    <axis xyz=" 0 -1  0"/>
    <limit effort="4000" lower="-1.5707963267948966" upper="3.839724354387525" velocity="4.625122517784973"/>
  </joint>
  <joint name="J4" type="revolute">
    <origin rpy="0 0 0" xyz=" 0  0  .215"/>
    <parent link="J3_link"/>
    <child link="J4_link"/>
    <axis xyz="-1  0  0"/>
    <limit effort="300" lower="-3.490658503988659" upper="3.490658503988659" velocity="7.3303828583761845"/>
  </joint>
  <joint name="J5" type="revolute">
    <origin rpy="0 0 0" xyz=" .89  0  0"/>
    <parent link="J4_link"/>
    <child link="J5_link"/>
    <axis xyz=" 0 -1  0"/>
    <limit effort="300" lower="-3.141575200297273" upper="3.141575200297273" velocity="7.3303828583761845"/>
  </joint>
  <joint name="J6" type="revolute">
    <origin rpy="0 0 0" xyz=" 0  0  0"/>
    <parent link="J5_link"/>
    <child link="J6_link"/>
    <axis xyz="-1  0  0"/>
    <limit effort="200" lower="-7.853981633974483" upper="7.853981633974483" velocity="12.566370614359172"/>
  </joint>
  <!-- world coords -->
  <link name="wbase"/>
  <joint name="base_link-wbase" type="fixed">
    <origin rpy="0 0 0" xyz=" 0  0  .425"/>
    <parent link="base_link"/>
    <child link="wbase"/>
  </joint>
  <!-- flange coords -->
  <link name="flange"/>
  <joint name="J6-flange" type="fixed">
    <origin rpy="0 0 0" xyz=" .09  0  0"/>
    <parent link="J6_link"/>
    <child link="flange"/>
  </joint>
  <!-- FANUC flange coords -->
  <link name="fanuc_flange"/>
  <joint name="flange-fanuc_flange" type="fixed">
    <origin rpy="3.141592653589793 -1.5707963267948966 0.0" xyz="0 0 0"/>
    <parent link="flange"/>
    <child link="fanuc_flange"/>
  </joint>
  <!-- Attach to parent -->
  <joint name="base_joint" type="fixed">
    <origin rpy="0 0 0" xyz="0 0 0"/>
    <parent link="world"/>
    <child link="base_link"/>
  </joint>
  <!-- Attach child -->
  <joint name="child_joint" type="fixed">
    <origin rpy="0 0 0" xyz="0 0 0"/>
    <parent link="flange"/>
    <child link="ee_link"/>
  </joint>
</robot>

