<?xml version="1.0" ?>
<!-- =================================================================================== -->
<!-- |    This document was autogenerated by xacro from /ws/fanuc_r1000ia_description/robot/r1000ia_80f.urdf.xacro | -->
<!-- |    EDITING THIS FILE BY HAND IS NOT RECOMMENDED                                 | -->
<!-- =================================================================================== -->
<robot name="r1000ia_80f">
  <link name="world"/>
  <link name="ee_link"/>
  <!-- links -->
  <link name="base_link">
    <visual>
      <origin rpy="0 0 0" xyz="0 0 0"/>
      <geometry>
        <mesh filename="package://fanuc_r1000ia_description/meshes/r1000ia_80f/visual/base.dae"/>
      </geometry>
    </visual>
    <collision>
      <origin rpy="0 0 0" xyz="0 0 0"/>
      <geometry>
        <mesh filename="package://fanuc_r1000ia_description/meshes/r1000ia_80f/collision/base.stl"/>
      </geometry>
    </collision>
    <inertial>
      <mass value=" 127"/>
      <origin xyz="-.129  .0048  .117"/>
      <inertia ixx=" 2.52" ixy=" .225" ixz="-.147" iyy=" 5.67" iyz=" .014" izz=" 6.98"/>
    </inertial>
  </link>
  <link name="J1_link">
    <visual>
      <origin rpy="0 0 0" xyz="0 0 0"/>
      <geometry>
        <mesh filename="package://fanuc_r1000ia_description/meshes/r1000ia_80f/visual/j1.dae"/>
      </geometry>
    </visual>
    <collision>
      <origin rpy="0 0 0" xyz="0 0 0"/>
      <geometry>
        <mesh filename="package://fanuc_r1000ia_description/meshes/r1000ia_80f/collision/j1.stl"/>
      </geometry>
    </collision>
    <inertial>
      <mass value=" 172"/>
      <origin xyz=" .133 -.00239 -.0395"/>
      <inertia ixx=" 4.59" ixy="-.244" ixz="-.202" iyy=" 6.84" iyz=" .395" izz=" 7.08"/>
    </inertial>
  </link>
  <link name="J2_link">
    <visual>
      <origin rpy="0 0 0" xyz="0 0 0"/>
      <geometry>
        <mesh filename="package://fanuc_r1000ia_description/meshes/r1000ia_80f/visual/j2.dae"/>
      </geometry>
    </visual>
    <collision>
      <origin rpy="0 0 0" xyz="0 0 0"/>
      <geometry>
        <mesh filename="package://fanuc_r1000ia_description/meshes/r1000ia_80f/collision/j2.stl"/>
      </geometry>
    </collision>
    <inertial>
      <mass value=" 104"/>
      <origin xyz=" .00598  .148  .394"/>
      <inertia ixx=" 9.79" ixy="-.00239" ixz=" .00593" iyy=" 10.2" iyz="-.158" izz=" .974"/>
    </inertial>
  </link>
  <link name="J3_link">
    <visual>
      <origin rpy="0 0 0" xyz="0 0 0"/>
      <geometry>
        <mesh filename="package://fanuc_r1000ia_description/meshes/r1000ia_80f/visual/j3.dae"/>
      </geometry>
    </visual>
    <collision>
      <origin rpy="0 0 0" xyz="0 0 0"/>
      <geometry>
        <mesh filename="package://fanuc_r1000ia_description/meshes/r1000ia_80f/collision/j3.stl"/>
      </geometry>
    </collision>
    <inertial>
      <mass value=" 194"/>
      <origin xyz=" .238  .011  .139"/>
      <inertia ixx=" 4.9" ixy="-.0545" ixz="-1.79" iyy=" 12.5" iyz="-.195" izz=" 11.8"/>
    </inertial>
  </link>
  <link name="J4_link">
    <visual>
      <origin rpy="0 0 0" xyz="0 0 0"/>
      <geometry>
        <mesh filename="package://fanuc_r1000ia_description/meshes/r1000ia_80f/visual/j4.dae"/>
      </geometry>
    </visual>
    <collision>
      <origin rpy="0 0 0" xyz="0 0 0"/>
      <geometry>
        <mesh filename="package://fanuc_r1000ia_description/meshes/r1000ia_80f/collision/j4.stl"/>
      </geometry>
    </collision>
    <inertial>
      <mass value=" 7.43"/>
      <origin xyz=" .929 -.00482  1.99E-16"/>
      <inertia ixx=" .0217" ixy=" .00203" ixz=" 2.82E-15" iyy=" .0477" iyz=" .00000000000431" izz=" .0454"/>
    </inertial>
  </link>
  <link name="J5_link">
    <visual>
      <origin rpy="0 0 0" xyz="0 0 0"/>
      <geometry>
        <mesh filename="package://fanuc_r1000ia_description/meshes/r1000ia_80f/visual/j5.dae"/>
      </geometry>
    </visual>
    <collision>
      <origin rpy="0 0 0" xyz="0 0 0"/>
      <geometry>
        <mesh filename="package://fanuc_r1000ia_description/meshes/r1000ia_80f/collision/j5.stl"/>
      </geometry>
    </collision>
    <inertial>
      <mass value=" 14.5"/>
      <origin xyz=" .0473 -.0132 -.00000000107"/>
      <inertia ixx=" .0807" ixy="-.0112" ixz="-.000000000352" iyy=" .0994" iyz="-.000000000904" izz=" .121"/>
    </inertial>
  </link>
  <link name="J6_link">
    <visual>
      <origin rpy="0 0 0" xyz="0 0 0"/>
      <geometry>
        <mesh filename="package://fanuc_r1000ia_description/meshes/r1000ia_80f/visual/j6.dae"/>
      </geometry>
    </visual>
    <collision>
      <origin rpy="0 0 0" xyz="0 0 0"/>
      <geometry>
        <mesh filename="package://fanuc_r1000ia_description/meshes/r1000ia_80f/collision/j6.stl"/>
      </geometry>
    </collision>
    <inertial>
      <mass value=" .402"/>
      <origin xyz=" .181  .000127  .000171"/>
      <inertia ixx=" .0008" ixy="-.00000000000204" ixz="-.000000436" iyy=" .000409" iyz=" .0000000000617" izz=" .000413"/>
    </inertial>
  </link>
  <!-- joints -->
  <joint name="J1" type="revolute">
    <origin rpy="0 0 0" xyz=" 0  0  .45"/>
    <parent link="base_link"/>
    <child link="J1_link"/>
    <axis xyz=" 0  0  1"/>
    <limit effort="9000" lower="-3.141592653589793" upper="3.141592653589793" velocity="2.9670597283903604"/>
  </joint>
  <joint name="J2" type="revolute">
    <origin rpy="0 0 0" xyz=" .32  0  0"/>
    <parent link="J1_link"/>
    <child link="J2_link"/>
    <axis xyz=" 0  1  0"/>
    <limit effort="10000" lower="-1.5707963267948966" upper="2.705260340591211" velocity="2.443460952792061"/>
  </joint>
  <joint name="J3" type="revolute">
    <origin rpy="0 0 0" xyz=" 0  0  .87"/>
    <parent link="J2_link"/>
    <child link="J3_link"/>
    <axis xyz=" 0 -1  0"/>
    <limit effort="8000" lower="-1.4311699866353502" upper="2.443460952792061" velocity="2.792526803190927"/>
  </joint>
  <joint name="J4" type="revolute">
    <origin rpy="0 0 0" xyz=" 0  0  .225"/>
    <parent link="J3_link"/>
    <child link="J4_link"/>
    <axis xyz="-1  0  0"/>
    <limit effort="2000" lower="-6.283185307179586" upper="6.283185307179586" velocity="4.014257279586958"/>
  </joint>
  <joint name="J5" type="revolute">
    <origin rpy="0 0 0" xyz=" 1.015  0  0"/>
    <parent link="J4_link"/>
    <child link="J5_link"/>
    <axis xyz=" 0 -1  0"/>
    <limit effort="2000" lower="-2.181661564992912" upper="2.181661564992912" velocity="4.014257279586958"/>
  </joint>
  <joint name="J6" type="revolute">
    <origin rpy="0 0 0" xyz=" 0  0  0"/>
    <parent link="J5_link"/>
    <child link="J6_link"/>
    <axis xyz="-1  0  0"/>
    <limit effort="2000" lower="-6.283185307179586" upper="6.283185307179586" velocity="6.1086523819801535"/>
  </joint>
  <!-- world coords -->
  <link name="wbase"/>
  <joint name="base_link-wbase" type="fixed">
    <origin rpy="0 0 0" xyz=" 0  0  .45"/>
    <parent link="base_link"/>
    <child link="wbase"/>
  </joint>
  <!-- flange coords -->
  <link name="flange"/>
  <joint name="J6-flange" type="fixed">
    <origin rpy="0 0 0" xyz=" .175  0  0"/>
    <parent link="J6_link"/>
    <child link="flange"/>
  </joint>
  <!-- FANUC flange coords -->
  <link name="fanuc_flange"/>
  <joint name="flange-fanuc_flange" type="fixed">
    <origin rpy="3.141592653589793 -1.5707963267948966 0.0" xyz="0 0 0"/>
    <parent link="flange"/>
    <child link="fanuc_flange"/>
  </joint>
  <!-- Attach to parent -->
  <joint name="base_joint" type="fixed">
    <origin rpy="0 0 0" xyz="0 0 0"/>
    <parent link="world"/>
    <child link="base_link"/>
  </joint>
  <!-- Attach child -->
  <joint name="child_joint" type="fixed">
    <origin rpy="0 0 0" xyz="0 0 0"/>
    <parent link="flange"/>
    <child link="ee_link"/>
  </joint>
</robot>

