<?xml version="1.0" ?>
<!-- =================================================================================== -->
<!-- |    This document was autogenerated by xacro from /repos/fanuc_description/fanuc_m10_description/robot/m10_8-20d.urdf.xacro | -->
<!-- |    EDITING THIS FILE BY HAND IS NOT RECOMMENDED                                 | -->
<!-- =================================================================================== -->
<robot name="m10_8-20d">
  <link name="world"/>
  <link name="ee_link"/>
  <!-- links -->
  <link name="base_link">
    <visual>
      <origin rpy="0 0 0" xyz="0 0 0"/>
      <geometry>
        <mesh filename="package://fanuc_m10_description/meshes/m10_8-20d/visual/base.dae"/>
      </geometry>
    </visual>
    <collision>
      <origin rpy="0 0 0" xyz="0 0 0"/>
      <geometry>
        <mesh filename="package://fanuc_m10_description/meshes/m10_8-20d/collision/base.stl"/>
      </geometry>
    </collision>
    <inertial>
      <mass value=" 48"/>
      <origin xyz=" .00757 -.0212  .138"/>
      <inertia ixx=" .791" ixy=" .0324" ixz="-.0279" iyy=" .79" iyz=" .0527" izz=" .952"/>
    </inertial>
  </link>
  <link name="J1_link">
    <visual>
      <origin rpy="0 0 0" xyz="0 0 0"/>
      <geometry>
        <mesh filename="package://fanuc_m10_description/meshes/m10_8-20d/visual/j1.dae"/>
      </geometry>
    </visual>
    <collision>
      <origin rpy="0 0 0" xyz="0 0 0"/>
      <geometry>
        <mesh filename="package://fanuc_m10_description/meshes/m10_8-20d/collision/j1.stl"/>
      </geometry>
    </collision>
    <inertial>
      <mass value=" 25.1"/>
      <origin xyz=" .0385 -.0176 -.0359"/>
      <inertia ixx=" .285" ixy="-.0106" ixz="-.0157" iyy=" .242" iyz="-.00898" izz=" .336"/>
    </inertial>
  </link>
  <link name="J2_link">
    <visual>
      <origin rpy="0 0 0" xyz="0 0 0"/>
      <geometry>
        <mesh filename="package://fanuc_m10_description/meshes/m10_8-20d/visual/j2.dae"/>
      </geometry>
    </visual>
    <collision>
      <origin rpy="0 0 0" xyz="0 0 0"/>
      <geometry>
        <mesh filename="package://fanuc_m10_description/meshes/m10_8-20d/collision/j2.stl"/>
      </geometry>
    </collision>
    <inertial>
      <mass value=" 33.5"/>
      <origin xyz="-.0227 -.151  .402"/>
      <inertia ixx=" 2.3" ixy="-.0223" ixz=" .0191" iyy=" 2.33" iyz="-.0412" izz=" .152"/>
    </inertial>
  </link>
  <link name="J3_link">
    <visual>
      <origin rpy="0 0 0" xyz="0 0 0"/>
      <geometry>
        <mesh filename="package://fanuc_m10_description/meshes/m10_8-20d/visual/j3.dae"/>
      </geometry>
    </visual>
    <collision>
      <origin rpy="0 0 0" xyz="0 0 0"/>
      <geometry>
        <mesh filename="package://fanuc_m10_description/meshes/m10_8-20d/collision/j3.stl"/>
      </geometry>
    </collision>
    <inertial>
      <mass value=" 54.5"/>
      <origin xyz=" .242  .0064  .116"/>
      <inertia ixx=" .693" ixy="-.0249" ixz="-.368" iyy=" 2.13" iyz="-.035" izz=" 2.1"/>
    </inertial>
  </link>
  <link name="J4_link">
    <visual>
      <origin rpy="0 0 0" xyz="0 0 0"/>
      <geometry>
        <mesh filename="package://fanuc_m10_description/meshes/m10_8-20d/visual/j4.dae"/>
      </geometry>
    </visual>
    <collision>
      <origin rpy="0 0 0" xyz="0 0 0"/>
      <geometry>
        <mesh filename="package://fanuc_m10_description/meshes/m10_8-20d/collision/j4.stl"/>
      </geometry>
    </collision>
    <inertial>
      <mass value=" 17.5"/>
      <origin xyz=" .678 -.0311 -.000832"/>
      <inertia ixx=" .0509" ixy=" .0696" ixz=" .000437" iyy=" .9" iyz="-.000433" izz=" .915"/>
    </inertial>
  </link>
  <link name="J5_link">
    <visual>
      <origin rpy="0 0 0" xyz="0 0 0"/>
      <geometry>
        <mesh filename="package://fanuc_m10_description/meshes/m10_8-20d/visual/j5.dae"/>
      </geometry>
    </visual>
    <collision>
      <origin rpy="0 0 0" xyz="0 0 0"/>
      <geometry>
        <mesh filename="package://fanuc_m10_description/meshes/m10_8-20d/collision/j5.stl"/>
      </geometry>
    </collision>
    <inertial>
      <mass value=" 1.16"/>
      <origin xyz=" .0214 -.015  .0000000000494"/>
      <inertia ixx=" .00173" ixy="-.000392" ixz=" .00000000000155" iyy=" .00191" iyz=" .00000000000141" izz=" .00189"/>
    </inertial>
  </link>
  <link name="J6_link">
    <visual>
      <origin rpy="0 0 0" xyz="0 0 0"/>
      <geometry>
        <mesh filename="package://fanuc_m10_description/meshes/m10_8-20d/visual/j6.dae"/>
      </geometry>
    </visual>
    <collision>
      <origin rpy="0 0 0" xyz="0 0 0"/>
      <geometry>
        <mesh filename="package://fanuc_m10_description/meshes/m10_8-20d/collision/j6.stl"/>
      </geometry>
    </collision>
    <inertial>
      <mass value=" .224"/>
      <origin xyz=" .0537  .000000457  .00000541"/>
      <inertia ixx=" .000131" ixy="-.000000000116" ixz="-.00000000799" iyy=" .000102" iyz="-.00000000000398" izz=" .000102"/>
    </inertial>
  </link>
  <!-- joints -->
  <joint name="J1" type="revolute">
    <origin rpy="0 0 0" xyz=" 0  0  .45"/>
    <parent link="base_link"/>
    <child link="J1_link"/>
    <axis xyz=" 0  0  1"/>
    <limit effort="2000" lower="-3.2288591161895095" upper="3.2288591161895095" velocity="3.6651914291880923"/>
  </joint>
  <joint name="J2" type="revolute">
    <origin rpy="0 0 0" xyz=" .075  0  0"/>
    <parent link="J1_link"/>
    <child link="J2_link"/>
    <axis xyz=" 0  1  0"/>
    <limit effort="3000" lower="-1.5707963267948966" upper="2.530727415391778" velocity="3.6651914291880923"/>
  </joint>
  <joint name="J3" type="revolute">
    <origin rpy="0 0 0" xyz=" 0  0  .84"/>
    <parent link="J2_link"/>
    <child link="J3_link"/>
    <axis xyz=" 0 -1  0"/>
    <limit effort="1000" lower="-1.5707963267948966" upper="3.8746309394274117" velocity="3.839724354387525"/>
  </joint>
  <joint name="J4" type="revolute">
    <origin rpy="0 0 0" xyz=" 0  0  .195"/>
    <parent link="J3_link"/>
    <child link="J4_link"/>
    <axis xyz="-1  0  0"/>
    <limit effort="100" lower="-3.3161255787892263" upper="3.3161255787892263" velocity="7.504915783575617"/>
  </joint>
  <joint name="J5" type="revolute">
    <origin rpy="0 0 0" xyz=" 1.1  0  0"/>
    <parent link="J4_link"/>
    <child link="J5_link"/>
    <axis xyz=" 0 -1  0"/>
    <limit effort="100" lower="-3.141575200297273" upper="3.141575200297273" velocity="7.853981633974483"/>
  </joint>
  <joint name="J6" type="revolute">
    <origin rpy="0 0 0" xyz=" 0  0  0"/>
    <parent link="J5_link"/>
    <child link="J6_link"/>
    <axis xyz="-1  0  0"/>
    <limit effort="50" lower="-7.853981633974483" upper="7.853981633974483" velocity="12.566370614359172"/>
  </joint>
  <!-- world coords -->
  <link name="wbase"/>
  <joint name="base_link-wbase" type="fixed">
    <origin rpy="0 0 0" xyz=" 0  0  .45"/>
    <parent link="base_link"/>
    <child link="wbase"/>
  </joint>
  <!-- flange coords -->
  <link name="flange"/>
  <joint name="J6-flange" type="fixed">
    <origin rpy="0 0 0" xyz=" .075  0  0"/>
    <parent link="J6_link"/>
    <child link="flange"/>
  </joint>
  <!-- FANUC flange coords -->
  <link name="fanuc_flange"/>
  <joint name="flange-fanuc_flange" type="fixed">
    <origin rpy="3.141592653589793 -1.5707963267948966 0.0" xyz="0 0 0"/>
    <parent link="flange"/>
    <child link="fanuc_flange"/>
  </joint>
  <!-- Attach to parent -->
  <joint name="base_joint" type="fixed">
    <origin rpy="0 0 0" xyz="0 0 0"/>
    <parent link="world"/>
    <child link="base_link"/>
  </joint>
  <!-- Attach child -->
  <joint name="child_joint" type="fixed">
    <origin rpy="0 0 0" xyz="0 0 0"/>
    <parent link="flange"/>
    <child link="ee_link"/>
  </joint>
</robot>

