<?xml version="1.0" ?>
<!-- =================================================================================== -->
<!-- |    This document was autogenerated by xacro from /ws/fanuc_paint_description/robot/p350ia_45_rh.urdf.xacro | -->
<!-- |    EDITING THIS FILE BY HAND IS NOT RECOMMENDED                                 | -->
<!-- =================================================================================== -->
<robot name="p350ia_45_rh">
  <link name="world"/>
  <link name="ee_link"/>
  <!-- links -->
  <link name="base_link">
    <visual>
      <origin rpy="0 0 0" xyz="0 0 0"/>
      <geometry>
        <mesh filename="package://fanuc_paint_description/meshes/p350ia_45_rh/visual/base.dae"/>
      </geometry>
    </visual>
    <collision>
      <origin rpy="0 0 0" xyz="0 0 0"/>
      <geometry>
        <mesh filename="package://fanuc_paint_description/meshes/p350ia_45_rh/collision/base.stl"/>
      </geometry>
    </collision>
    <inertial>
      <mass value=" 188"/>
      <origin xyz="-.188  .000477  .119"/>
      <inertia ixx=" 5.87" ixy="-.0225" ixz="-.0132" iyy=" 10.4" iyz=" .00925" izz=" 14.6"/>
    </inertial>
  </link>
  <link name="J1_link">
    <visual>
      <origin rpy="0 0 0" xyz="0 0 0"/>
      <geometry>
        <mesh filename="package://fanuc_paint_description/meshes/p350ia_45_rh/visual/j1.dae"/>
      </geometry>
    </visual>
    <collision>
      <origin rpy="0 0 0" xyz="0 0 0"/>
      <geometry>
        <mesh filename="package://fanuc_paint_description/meshes/p350ia_45_rh/collision/j1.stl"/>
      </geometry>
    </collision>
    <inertial>
      <mass value=" 167"/>
      <origin xyz=" .0439 -.00829 -.0906"/>
      <inertia ixx=" 6.08" ixy="-.281" ixz="-.654" iyy=" 4.94" iyz=" .172" izz=" 6.77"/>
    </inertial>
  </link>
  <link name="J2_link">
    <visual>
      <origin rpy="0 0 0" xyz="0 0 0"/>
      <geometry>
        <mesh filename="package://fanuc_paint_description/meshes/p350ia_45_rh/visual/j2.dae"/>
      </geometry>
    </visual>
    <collision>
      <origin rpy="0 0 0" xyz="0 0 0"/>
      <geometry>
        <mesh filename="package://fanuc_paint_description/meshes/p350ia_45_rh/collision/j2.stl"/>
      </geometry>
    </collision>
    <inertial>
      <mass value=" 102"/>
      <origin xyz=" .00255  .155  .462"/>
      <inertia ixx=" 14" ixy=" .0235" ixz=" .0158" iyy=" 14.3" iyz="-.453" izz=" .845"/>
    </inertial>
  </link>
  <link name="J3_link">
    <visual>
      <origin rpy="0 0 0" xyz="0 0 0"/>
      <geometry>
        <mesh filename="package://fanuc_paint_description/meshes/p350ia_45_rh/visual/j3.dae"/>
      </geometry>
    </visual>
    <collision>
      <origin rpy="0 0 0" xyz="0 0 0"/>
      <geometry>
        <mesh filename="package://fanuc_paint_description/meshes/p350ia_45_rh/collision/j3.stl"/>
      </geometry>
    </collision>
    <inertial>
      <mass value=" 82.1"/>
      <origin xyz=" .0118 -.0319  .085"/>
      <inertia ixx=" 1.61" ixy="-.148" ixz="-.179" iyy=" 1.94" iyz="-.0821" izz=" 1.74"/>
    </inertial>
  </link>
  <link name="J4_link">
    <visual>
      <origin rpy="0 0 0" xyz="0 0 0"/>
      <geometry>
        <mesh filename="package://fanuc_paint_description/meshes/p350ia_45_rh/visual/j4.dae"/>
      </geometry>
    </visual>
    <collision>
      <origin rpy="0 0 0" xyz="0 0 0"/>
      <geometry>
        <mesh filename="package://fanuc_paint_description/meshes/p350ia_45_rh/collision/j4.stl"/>
      </geometry>
    </collision>
    <inertial>
      <mass value=" 41.9"/>
      <origin xyz=" .806 -.0208  .000409"/>
      <inertia ixx=" .155" ixy=" .17" ixz="-.00156" iyy=" 4.17" iyz="-.000541" izz=" 4.18"/>
    </inertial>
  </link>
  <link name="J5_link">
    <visual>
      <origin rpy="0 0 0" xyz="0 0 0"/>
      <geometry>
        <mesh filename="package://fanuc_paint_description/meshes/p350ia_45_rh/visual/j5.dae"/>
      </geometry>
    </visual>
    <collision>
      <origin rpy="0 0 0" xyz="0 0 0"/>
      <geometry>
        <mesh filename="package://fanuc_paint_description/meshes/p350ia_45_rh/collision/j5.stl"/>
      </geometry>
    </collision>
    <inertial>
      <mass value=" 8.4"/>
      <origin xyz=" .0404  .00391 -.00000114"/>
      <inertia ixx=" .0311" ixy="-.00241" ixz=" .000000354" iyy=" .0447" iyz="-.000000318" izz=" .0473"/>
    </inertial>
  </link>
  <link name="J6_link">
    <visual>
      <origin rpy="0 0 0" xyz="0 0 0"/>
      <geometry>
        <mesh filename="package://fanuc_paint_description/meshes/p350ia_45_rh/visual/j6.dae"/>
      </geometry>
    </visual>
    <collision>
      <origin rpy="0 0 0" xyz="0 0 0"/>
      <geometry>
        <mesh filename="package://fanuc_paint_description/meshes/p350ia_45_rh/collision/j6.stl"/>
      </geometry>
    </collision>
    <inertial>
      <mass value=" .434"/>
      <origin xyz=" .165 -4.6E-18 -1.29E-18"/>
      <inertia ixx=" .000842" ixy="-1.16E-18" ixz="-1.35E-19" iyy=" .000436" iyz=" .000000000062" izz=" .000436"/>
    </inertial>
  </link>
  <!-- joints -->
  <joint name="J1" type="revolute">
    <origin rpy="0 0 0" xyz=" 0  0  .565"/>
    <parent link="base_link"/>
    <child link="J1_link"/>
    <axis xyz=" 0  0  1"/>
    <limit effort="9000" lower="-3.141592653589793" upper="3.141592653589793" velocity="3.141592653589793"/>
  </joint>
  <joint name="J2" type="revolute">
    <origin rpy="0 0 0" xyz=" .15  0  0"/>
    <parent link="J1_link"/>
    <child link="J2_link"/>
    <axis xyz=" 0  1  0"/>
    <limit effort="9000" lower="-1.5707963267948966" upper="2.356194490192345" velocity="3.141592653589793"/>
  </joint>
  <joint name="J3" type="revolute">
    <origin rpy="0 0 0" xyz=" 0  0  1.15"/>
    <parent link="J2_link"/>
    <child link="J3_link"/>
    <axis xyz=" 0 -1  0"/>
    <limit effort="4000" lower="-1.4049900478554354" upper="3.5779249665883754" velocity="3.141592653589793"/>
  </joint>
  <joint name="J4" type="revolute">
    <origin rpy="0 0 0" xyz=" 0  0  .17"/>
    <parent link="J3_link"/>
    <child link="J4_link"/>
    <axis xyz="-1  0  0"/>
    <limit effort="800" lower="-6.981317007977318" upper="6.981317007977318" velocity="4.363323129985824"/>
  </joint>
  <joint name="J5" type="revolute">
    <origin rpy="0 0 0" xyz=" 1.295  0  0"/>
    <parent link="J4_link"/>
    <child link="J5_link"/>
    <axis xyz=" 0 -1  0"/>
    <limit effort="900" lower="-2.181661564992912" upper="2.181661564992912" velocity="4.363323129985824"/>
  </joint>
  <joint name="J6" type="revolute">
    <origin rpy="0 0 0" xyz=" 0  0  0"/>
    <parent link="J5_link"/>
    <child link="J6_link"/>
    <axis xyz="-1  0  0"/>
    <limit effort="700" lower="-6.981317007977318" upper="6.981317007977318" velocity="6.283185307179586"/>
  </joint>
  <!-- world coords -->
  <link name="wbase"/>
  <joint name="base_link-wbase" type="fixed">
    <origin rpy="0 0 0" xyz=" 0  0  .565"/>
    <parent link="base_link"/>
    <child link="wbase"/>
  </joint>
  <!-- flange coords -->
  <link name="flange"/>
  <joint name="J6-flange" type="fixed">
    <origin rpy="0 0 0" xyz=" .175  0  0"/>
    <parent link="J6_link"/>
    <child link="flange"/>
  </joint>
  <!-- FANUC flange coords -->
  <link name="fanuc_flange"/>
  <joint name="flange-fanuc_flange" type="fixed">
    <origin rpy="3.141592653589793 -1.5707963267948966 0.0" xyz="0 0 0"/>
    <parent link="flange"/>
    <child link="fanuc_flange"/>
  </joint>
  <!-- Attach to parent -->
  <joint name="base_joint" type="fixed">
    <origin rpy="0 0 0" xyz="0 0 0"/>
    <parent link="world"/>
    <child link="base_link"/>
  </joint>
  <!-- Attach child -->
  <joint name="child_joint" type="fixed">
    <origin rpy="0 0 0" xyz="0 0 0"/>
    <parent link="flange"/>
    <child link="ee_link"/>
  </joint>
</robot>

