<?xml version="1.0" ?>
<!-- =================================================================================== -->
<!-- |    This document was autogenerated by xacro from /ws/fanuc_r2000_description/robot/r2000ic_210r.urdf.xacro | -->
<!-- |    EDITING THIS FILE BY HAND IS NOT RECOMMENDED                                 | -->
<!-- =================================================================================== -->
<robot name="r2000ic_210r">
  <link name="world"/>
  <link name="ee_link"/>
  <!-- links -->
  <link name="base_link">
    <visual>
      <origin rpy="0 0 0" xyz="0 0 0"/>
      <geometry>
        <mesh filename="package://fanuc_r2000_description/meshes/r2000ic_210r/visual/base.dae"/>
      </geometry>
    </visual>
    <collision>
      <origin rpy="0 0 0" xyz="0 0 0"/>
      <geometry>
        <mesh filename="package://fanuc_r2000_description/meshes/r2000ic_210r/collision/base.stl"/>
      </geometry>
    </collision>
    <inertial>
      <mass value=" 189"/>
      <origin xyz="-.104 -.00417  .135"/>
      <inertia ixx=" 5.95" ixy=" .0712" ixz="-.13" iyy=" 11.6" iyz=" .00636" izz=" 14.8"/>
    </inertial>
  </link>
  <link name="J1_link">
    <visual>
      <origin rpy="0 0 0" xyz="0 0 0"/>
      <geometry>
        <mesh filename="package://fanuc_r2000_description/meshes/r2000ic_210r/visual/j1.dae"/>
      </geometry>
    </visual>
    <collision>
      <origin rpy="0 0 0" xyz="0 0 0"/>
      <geometry>
        <mesh filename="package://fanuc_r2000_description/meshes/r2000ic_210r/collision/j1.stl"/>
      </geometry>
    </collision>
    <inertial>
      <mass value=" 682"/>
      <origin xyz=" .202  .145 -.0127"/>
      <inertia ixx=" 48.9" ixy=" 7.01" ixz="-2.91" iyy=" 85.6" iyz="-4.57" izz=" 100"/>
    </inertial>
  </link>
  <link name="J2_link">
    <visual>
      <origin rpy="0 0 0" xyz="0 0 0"/>
      <geometry>
        <mesh filename="package://fanuc_r2000_description/meshes/r2000ic_210r/visual/j2.dae"/>
      </geometry>
    </visual>
    <collision>
      <origin rpy="0 0 0" xyz="0 0 0"/>
      <geometry>
        <mesh filename="package://fanuc_r2000_description/meshes/r2000ic_210r/collision/j2.stl"/>
      </geometry>
    </collision>
    <inertial>
      <mass value=" 221"/>
      <origin xyz=" .434  .246  .00114"/>
      <inertia ixx=" 4.59" ixy="-1.48" ixz=" .7" iyy=" 28.3" iyz="-.198" izz=" 28"/>
    </inertial>
  </link>
  <link name="J3_link">
    <visual>
      <origin rpy="0 0 0" xyz="0 0 0"/>
      <geometry>
        <mesh filename="package://fanuc_r2000_description/meshes/r2000ic_210r/visual/j3.dae"/>
      </geometry>
    </visual>
    <collision>
      <origin rpy="0 0 0" xyz="0 0 0"/>
      <geometry>
        <mesh filename="package://fanuc_r2000_description/meshes/r2000ic_210r/collision/j3.stl"/>
      </geometry>
    </collision>
    <inertial>
      <mass value=" 250"/>
      <origin xyz=" .127  .055 -.324"/>
      <inertia ixx=" 24.8" ixy=" .409" ixz=" 3.13" iyy=" 24.3" iyz="-1.15" izz=" 7.83"/>
    </inertial>
  </link>
  <link name="J4_link">
    <visual>
      <origin rpy="0 0 0" xyz="0 0 0"/>
      <geometry>
        <mesh filename="package://fanuc_r2000_description/meshes/r2000ic_210r/visual/j4.dae"/>
      </geometry>
    </visual>
    <collision>
      <origin rpy="0 0 0" xyz="0 0 0"/>
      <geometry>
        <mesh filename="package://fanuc_r2000_description/meshes/r2000ic_210r/collision/j4.stl"/>
      </geometry>
    </collision>
    <inertial>
      <mass value=" 9.89"/>
      <origin xyz="-.0000000108 -.00867 -1.18"/>
      <inertia ixx=" .0868" ixy="-.000000000103" ixz=" .00000000763" iyy=" .0888" iyz="-.00519" izz=" .0386"/>
    </inertial>
  </link>
  <link name="J5_link">
    <visual>
      <origin rpy="0 0 0" xyz="0 0 0"/>
      <geometry>
        <mesh filename="package://fanuc_r2000_description/meshes/r2000ic_210r/visual/j5.dae"/>
      </geometry>
    </visual>
    <collision>
      <origin rpy="0 0 0" xyz="0 0 0"/>
      <geometry>
        <mesh filename="package://fanuc_r2000_description/meshes/r2000ic_210r/collision/j5.stl"/>
      </geometry>
    </collision>
    <inertial>
      <mass value=" 18"/>
      <origin xyz="-.00000000195 -.0214 -.0485"/>
      <inertia ixx=" .196" ixy=" .0000000000649" ixz=" .00000000371" iyy=" .158" iyz=" .0204" izz=" .134"/>
    </inertial>
  </link>
  <link name="J6_link">
    <visual>
      <origin rpy="0 0 0" xyz="0 0 0"/>
      <geometry>
        <mesh filename="package://fanuc_r2000_description/meshes/r2000ic_210r/visual/j6.dae"/>
      </geometry>
    </visual>
    <collision>
      <origin rpy="0 0 0" xyz="0 0 0"/>
      <geometry>
        <mesh filename="package://fanuc_r2000_description/meshes/r2000ic_210r/collision/j6.stl"/>
      </geometry>
    </collision>
    <inertial>
      <mass value=" .921"/>
      <origin xyz=" .0000957 -.0000000101 -.198"/>
      <inertia ixx=" .00139" ixy=" .0000000000755" ixz=" .000000658" iyy=" .00139" iyz="-.0000000000115" izz=" .00258"/>
    </inertial>
  </link>
  <!-- joints -->
  <joint name="J1" type="revolute">
    <origin rpy="0 0 0" xyz=" 0  0  .6"/>
    <parent link="base_link"/>
    <child link="J1_link"/>
    <axis xyz=" 0  0  1"/>
    <limit effort="10000" lower="-3.2288591161895095" upper="3.2288591161895095" velocity="1.8325957145940461"/>
  </joint>
  <joint name="J2" type="revolute">
    <origin rpy="0 0 0" xyz=" .72  0  0"/>
    <parent link="J1_link"/>
    <child link="J2_link"/>
    <axis xyz=" 0  1  0"/>
    <limit effort="20000" lower="-2.0943951023931953" upper="1.3962634015954636" velocity="1.7453292519943295"/>
  </joint>
  <joint name="J3" type="revolute">
    <origin rpy="0 0 0" xyz=" 1.075  0  0"/>
    <parent link="J2_link"/>
    <child link="J3_link"/>
    <axis xyz=" 0 -1  0"/>
    <limit effort="20000" lower="-1.3788101090755203" upper="3.141592653589793" velocity="1.9198621771937625"/>
  </joint>
  <joint name="J4" type="revolute">
    <origin rpy="0 0 0" xyz=" .225  0  0"/>
    <parent link="J3_link"/>
    <child link="J4_link"/>
    <axis xyz=" 0  0  1"/>
    <limit effort="5000" lower="-6.283185307179586" upper="6.283185307179586" velocity="2.443460952792061"/>
  </joint>
  <joint name="J5" type="revolute">
    <origin rpy="0 0 0" xyz=" 0  0 -1.28"/>
    <parent link="J4_link"/>
    <child link="J5_link"/>
    <axis xyz=" 0 -1  0"/>
    <limit effort="5000" lower="-2.181661564992912" upper="2.181661564992912" velocity="2.443460952792061"/>
  </joint>
  <joint name="J6" type="revolute">
    <origin rpy="0 0 0" xyz=" 0  0  0"/>
    <parent link="J5_link"/>
    <child link="J6_link"/>
    <axis xyz=" 0  0  1"/>
    <limit effort="3000" lower="-6.283185307179586" upper="6.283185307179586" velocity="3.839724354387525"/>
  </joint>
  <!-- world coords -->
  <link name="wbase"/>
  <joint name="base_link-wbase" type="fixed">
    <origin rpy="0 0 0" xyz=" 0  0  .6"/>
    <parent link="base_link"/>
    <child link="wbase"/>
  </joint>
  <!-- flange coords -->
  <link name="flange"/>
  <joint name="J6-flange" type="fixed">
    <origin rpy="0 0 0" xyz=" 0  0 -.215"/>
    <parent link="J6_link"/>
    <child link="flange"/>
  </joint>
  <!-- FANUC flange coords -->
  <link name="fanuc_flange"/>
  <joint name="flange-fanuc_flange" type="fixed">
    <origin rpy="3.141592653589793 0.0 0.0" xyz="0 0 0"/>
    <parent link="flange"/>
    <child link="fanuc_flange"/>
  </joint>
  <!-- Attach to parent -->
  <joint name="base_joint" type="fixed">
    <origin rpy="0 0 0" xyz="0 0 0"/>
    <parent link="world"/>
    <child link="base_link"/>
  </joint>
  <!-- Attach child -->
  <joint name="child_joint" type="fixed">
    <origin rpy="0 0 0" xyz="0 0 0"/>
    <parent link="flange"/>
    <child link="ee_link"/>
  </joint>
</robot>

