<?xml version="1.0" ?>
<!-- =================================================================================== -->
<!-- |    This document was autogenerated by xacro from /ws/fanuc_m710_description/robot/m710ic_50s.urdf.xacro | -->
<!-- |    EDITING THIS FILE BY HAND IS NOT RECOMMENDED                                 | -->
<!-- =================================================================================== -->
<robot name="m710ic_50s">
  <link name="world"/>
  <link name="ee_link"/>
  <!-- links -->
  <link name="base_link">
    <visual>
      <origin rpy="0 0 0" xyz="0 0 0"/>
      <geometry>
        <mesh filename="package://fanuc_m710_description/meshes/m710ic_50s/visual/base.dae"/>
      </geometry>
    </visual>
    <collision>
      <origin rpy="0 0 0" xyz="0 0 0"/>
      <geometry>
        <mesh filename="package://fanuc_m710_description/meshes/m710ic_50s/collision/base.stl"/>
      </geometry>
    </collision>
    <inertial>
      <mass value=" 135"/>
      <origin xyz="-.0493 -.000226  .119"/>
      <inertia ixx=" 3.6" ixy=" .00959" ixz=" .0544" iyy=" 3.68" iyz="-.00446" izz=" 5.85"/>
    </inertial>
  </link>
  <link name="J1_link">
    <visual>
      <origin rpy="0 0 0" xyz="0 0 0"/>
      <geometry>
        <mesh filename="package://fanuc_m710_description/meshes/m710ic_50s/visual/j1.dae"/>
      </geometry>
    </visual>
    <collision>
      <origin rpy="0 0 0" xyz="0 0 0"/>
      <geometry>
        <mesh filename="package://fanuc_m710_description/meshes/m710ic_50s/collision/j1.stl"/>
      </geometry>
    </collision>
    <inertial>
      <mass value=" 210"/>
      <origin xyz=" .0518 -.00682 -.105"/>
      <inertia ixx=" 7.83" ixy="-.355" ixz="-.526" iyy=" 6.7" iyz=" .229" izz=" 8.39"/>
    </inertial>
  </link>
  <link name="J2_link">
    <visual>
      <origin rpy="0 0 0" xyz="0 0 0"/>
      <geometry>
        <mesh filename="package://fanuc_m710_description/meshes/m710ic_50s/visual/j2.dae"/>
      </geometry>
    </visual>
    <collision>
      <origin rpy="0 0 0" xyz="0 0 0"/>
      <geometry>
        <mesh filename="package://fanuc_m710_description/meshes/m710ic_50s/collision/j2.stl"/>
      </geometry>
    </collision>
    <inertial>
      <mass value=" 77.5"/>
      <origin xyz=" .0035  .149  .236"/>
      <inertia ixx=" 3.67" ixy=" .0139" ixz=" .00907" iyy=" 3.94" iyz="-.164" izz=" .703"/>
    </inertial>
  </link>
  <link name="J3_link">
    <visual>
      <origin rpy="0 0 0" xyz="0 0 0"/>
      <geometry>
        <mesh filename="package://fanuc_m710_description/meshes/m710ic_50s/visual/j3.dae"/>
      </geometry>
    </visual>
    <collision>
      <origin rpy="0 0 0" xyz="0 0 0"/>
      <geometry>
        <mesh filename="package://fanuc_m710_description/meshes/m710ic_50s/collision/j3.stl"/>
      </geometry>
    </collision>
    <inertial>
      <mass value=" 95.4"/>
      <origin xyz=" .0151 -.032 -.0842"/>
      <inertia ixx=" 1.85" ixy="-.173" ixz=" .226" iyy=" 2.27" iyz=" .0972" izz=" 2.05"/>
    </inertial>
  </link>
  <link name="J4_link">
    <visual>
      <origin rpy="0 0 0" xyz="0 0 0"/>
      <geometry>
        <mesh filename="package://fanuc_m710_description/meshes/m710ic_50s/visual/j4.dae"/>
      </geometry>
    </visual>
    <collision>
      <origin rpy="0 0 0" xyz="0 0 0"/>
      <geometry>
        <mesh filename="package://fanuc_m710_description/meshes/m710ic_50s/collision/j4.stl"/>
      </geometry>
    </collision>
    <inertial>
      <mass value=" 16.8"/>
      <origin xyz=" .448 -.0248  .000134"/>
      <inertia ixx=" .062" ixy=" .0291" ixz="-.000149" iyy=" .233" iyz="-.0000411" izz=" .239"/>
    </inertial>
  </link>
  <link name="J5_link">
    <visual>
      <origin rpy="0 0 0" xyz="0 0 0"/>
      <geometry>
        <mesh filename="package://fanuc_m710_description/meshes/m710ic_50s/visual/j5.dae"/>
      </geometry>
    </visual>
    <collision>
      <origin rpy="0 0 0" xyz="0 0 0"/>
      <geometry>
        <mesh filename="package://fanuc_m710_description/meshes/m710ic_50s/collision/j5.stl"/>
      </geometry>
    </collision>
    <inertial>
      <mass value=" 9.62"/>
      <origin xyz=" .0411  .00198 -.000000000648"/>
      <inertia ixx=" .035" ixy="-.00274" ixz=" .0000000000306" iyy=" .0519" iyz=" .000000000358" izz=" .0534"/>
    </inertial>
  </link>
  <link name="J6_link">
    <visual>
      <origin rpy="0 0 0" xyz="0 0 0"/>
      <geometry>
        <mesh filename="package://fanuc_m710_description/meshes/m710ic_50s/visual/j6.dae"/>
      </geometry>
    </visual>
    <collision>
      <origin rpy="0 0 0" xyz="0 0 0"/>
      <geometry>
        <mesh filename="package://fanuc_m710_description/meshes/m710ic_50s/collision/j6.stl"/>
      </geometry>
    </collision>
    <inertial>
      <mass value=" .504"/>
      <origin xyz=" .165 -4.6E-18 -1.29E-18"/>
      <inertia ixx=" .000976" ixy="-1.35E-18" ixz="-1.57E-19" iyy=" .000506" iyz=" .000000000072" izz=" .000506"/>
    </inertial>
  </link>
  <!-- joints -->
  <joint name="J1" type="revolute">
    <origin rpy="0 0 0" xyz=" 0  0  .565"/>
    <parent link="base_link"/>
    <child link="J1_link"/>
    <axis xyz=" 0  0  1"/>
    <limit effort="5000" lower="-3.141592653589793" upper="3.141592653589793" velocity="3.0543261909900767"/>
  </joint>
  <joint name="J2" type="revolute">
    <origin rpy="0 0 0" xyz=" .15  0  0"/>
    <parent link="J1_link"/>
    <child link="J2_link"/>
    <axis xyz=" 0  1  0"/>
    <limit effort="7000" lower="-0.9948376736367679" upper="1.9547687622336491" velocity="3.0543261909900767"/>
  </joint>
  <joint name="J3" type="revolute">
    <origin rpy="0 0 0" xyz=" 0  0  .6"/>
    <parent link="J2_link"/>
    <child link="J3_link"/>
    <axis xyz=" 0 -1  0"/>
    <limit effort="5000" lower="-0.7330382858376184" upper="4.223696789826278" velocity="3.0543261909900767"/>
  </joint>
  <joint name="J4" type="revolute">
    <origin rpy="0 0 0" xyz=" 0  0 -.17"/>
    <parent link="J3_link"/>
    <child link="J4_link"/>
    <axis xyz="-1  0  0"/>
    <limit effort="800" lower="-6.283185307179586" upper="6.283185307179586" velocity="4.363323129985824"/>
  </joint>
  <joint name="J5" type="revolute">
    <origin rpy="0 0 0" xyz=" .585  0  0"/>
    <parent link="J4_link"/>
    <child link="J5_link"/>
    <axis xyz=" 0 -1  0"/>
    <limit effort="900" lower="-2.181661564992912" upper="2.181661564992912" velocity="4.363323129985824"/>
  </joint>
  <joint name="J6" type="revolute">
    <origin rpy="0 0 0" xyz=" 0  0  0"/>
    <parent link="J5_link"/>
    <child link="J6_link"/>
    <axis xyz="-1  0  0"/>
    <limit effort="700" lower="-6.283185307179586" upper="6.283185307179586" velocity="6.19591884457987"/>
  </joint>
  <!-- world coords -->
  <link name="wbase"/>
  <joint name="base_link-wbase" type="fixed">
    <origin rpy="0 0 0" xyz=" 0  0  .565"/>
    <parent link="base_link"/>
    <child link="wbase"/>
  </joint>
  <!-- flange coords -->
  <link name="flange"/>
  <joint name="J6-flange" type="fixed">
    <origin rpy="0 0 0" xyz=" .175  0  0"/>
    <parent link="J6_link"/>
    <child link="flange"/>
  </joint>
  <!-- FANUC flange coords -->
  <link name="fanuc_flange"/>
  <joint name="flange-fanuc_flange" type="fixed">
    <origin rpy="3.141592653589793 -1.5707963267948966 0.0" xyz="0 0 0"/>
    <parent link="flange"/>
    <child link="fanuc_flange"/>
  </joint>
  <!-- Attach to parent -->
  <joint name="base_joint" type="fixed">
    <origin rpy="0 0 0" xyz="0 0 0"/>
    <parent link="world"/>
    <child link="base_link"/>
  </joint>
  <!-- Attach child -->
  <joint name="child_joint" type="fixed">
    <origin rpy="0 0 0" xyz="0 0 0"/>
    <parent link="flange"/>
    <child link="ee_link"/>
  </joint>
</robot>

