<?xml version="1.0" ?>
<!-- =================================================================================== -->
<!-- |    This document was autogenerated by xacro from /ws/fanuc_lrmate_description/robot/lrmate200id7lc.urdf.xacro | -->
<!-- |    EDITING THIS FILE BY HAND IS NOT RECOMMENDED                                 | -->
<!-- =================================================================================== -->
<robot name="lrmate200id7lc">
  <link name="world"/>
  <link name="ee_link"/>
  <!-- links -->
  <link name="base_link">
    <visual>
      <origin rpy="0 0 0" xyz="0 0 0"/>
      <geometry>
        <mesh filename="package://fanuc_lrmate_description/meshes/lrmate200id7lc/visual/base.dae"/>
      </geometry>
    </visual>
    <collision>
      <origin rpy="0 0 0" xyz="0 0 0"/>
      <geometry>
        <mesh filename="package://fanuc_lrmate_description/meshes/lrmate200id7lc/collision/base.stl"/>
      </geometry>
    </collision>
    <inertial>
      <mass value=" 5.08"/>
      <origin xyz="-.0146 -.000342  .0796"/>
      <inertia ixx=" .024" ixy="-.000551" ixz=" .000284" iyy=" .0293" iyz="-.000117" izz=" .0309"/>
    </inertial>
  </link>
  <link name="J1_link">
    <visual>
      <origin rpy="0 0 0" xyz="0 0 0"/>
      <geometry>
        <mesh filename="package://fanuc_lrmate_description/meshes/lrmate200id7lc/visual/j1.dae"/>
      </geometry>
    </visual>
    <collision>
      <origin rpy="0 0 0" xyz="0 0 0"/>
      <geometry>
        <mesh filename="package://fanuc_lrmate_description/meshes/lrmate200id7lc/collision/j1.stl"/>
      </geometry>
    </collision>
    <inertial>
      <mass value=" 5.4"/>
      <origin xyz=" .0287  .000102 -.0547"/>
      <inertia ixx=" .04" ixy=" .0000229" ixz="-.00529" iyy=" .0291" iyz=" .000117" izz=" .0309"/>
    </inertial>
  </link>
  <link name="J2_link">
    <visual>
      <origin rpy="0 0 0" xyz="0 0 0"/>
      <geometry>
        <mesh filename="package://fanuc_lrmate_description/meshes/lrmate200id7lc/visual/j2.dae"/>
      </geometry>
    </visual>
    <collision>
      <origin rpy="0 0 0" xyz="0 0 0"/>
      <geometry>
        <mesh filename="package://fanuc_lrmate_description/meshes/lrmate200id7lc/collision/j2.stl"/>
      </geometry>
    </collision>
    <inertial>
      <mass value=" 10.9"/>
      <origin xyz="-.00311 -.00124  .217"/>
      <inertia ixx=" .28" ixy=" .0000323" ixz=" .000717" iyy=" .254" iyz="-.00194" izz=" .0509"/>
    </inertial>
  </link>
  <link name="J3_link">
    <visual>
      <origin rpy="0 0 0" xyz="0 0 0"/>
      <geometry>
        <mesh filename="package://fanuc_lrmate_description/meshes/lrmate200id7lc/visual/j3.dae"/>
      </geometry>
    </visual>
    <collision>
      <origin rpy="0 0 0" xyz="0 0 0"/>
      <geometry>
        <mesh filename="package://fanuc_lrmate_description/meshes/lrmate200id7lc/collision/j3.stl"/>
      </geometry>
    </collision>
    <inertial>
      <mass value=" 2.07"/>
      <origin xyz=" .00887 -.0000626  .0171"/>
      <inertia ixx=" .00561" ixy="-.0000441" ixz="-.000596" iyy=" .00638" iyz="-.0000442" izz=" .00642"/>
    </inertial>
  </link>
  <link name="J4_link">
    <visual>
      <origin rpy="0 0 0" xyz="0 0 0"/>
      <geometry>
        <mesh filename="package://fanuc_lrmate_description/meshes/lrmate200id7lc/visual/j4.dae"/>
      </geometry>
    </visual>
    <collision>
      <origin rpy="0 0 0" xyz="0 0 0"/>
      <geometry>
        <mesh filename="package://fanuc_lrmate_description/meshes/lrmate200id7lc/collision/j4.stl"/>
      </geometry>
    </collision>
    <inertial>
      <mass value=" 3.07"/>
      <origin xyz=" .266  .00354  .00226"/>
      <inertia ixx=" .0051" ixy="-.0000092" ixz=" .0000312" iyy=" .0346" iyz="-.00000958" izz=" .0346"/>
    </inertial>
  </link>
  <link name="J5_link">
    <visual>
      <origin rpy="0 0 0" xyz="0 0 0"/>
      <geometry>
        <mesh filename="package://fanuc_lrmate_description/meshes/lrmate200id7lc/visual/j5.dae"/>
      </geometry>
    </visual>
    <collision>
      <origin rpy="0 0 0" xyz="0 0 0"/>
      <geometry>
        <mesh filename="package://fanuc_lrmate_description/meshes/lrmate200id7lc/collision/j5.stl"/>
      </geometry>
    </collision>
    <inertial>
      <mass value=" .482"/>
      <origin xyz=" .0236  .00233 -.00000699"/>
      <inertia ixx=" .000376" ixy=" .000022" ixz="-.0000000229" iyy=" .000753" iyz="-.0000000274" izz=" .000712"/>
    </inertial>
  </link>
  <link name="J6_link">
    <visual>
      <origin rpy="0 0 0" xyz="0 0 0"/>
      <geometry>
        <mesh filename="package://fanuc_lrmate_description/meshes/lrmate200id7lc/visual/j6.dae"/>
      </geometry>
    </visual>
    <collision>
      <origin rpy="0 0 0" xyz="0 0 0"/>
      <geometry>
        <mesh filename="package://fanuc_lrmate_description/meshes/lrmate200id7lc/collision/j6.stl"/>
      </geometry>
    </collision>
    <inertial>
      <mass value=" .0202"/>
      <origin xyz=" .0836 -3.24E-19 -1.22E-18"/>
      <inertia ixx=" .00000485" ixy=" 1.78E-21" ixz="-4.54E-21" iyy=" .00000285" iyz=" 4.79E-22" izz=" .00000285"/>
    </inertial>
  </link>
  <!-- joints -->
  <joint name="J1" type="revolute">
    <origin rpy="0 0 0" xyz=" 0  0  .33"/>
    <parent link="base_link"/>
    <child link="J1_link"/>
    <axis xyz=" 0  0  1"/>
    <limit effort="600" lower="-3.141592653589793" upper="3.141592653589793" velocity="6.457718232379019"/>
  </joint>
  <joint name="J2" type="revolute">
    <origin rpy="0 0 0" xyz=" .05  0  0"/>
    <parent link="J1_link"/>
    <child link="J2_link"/>
    <axis xyz=" 0  1  0"/>
    <limit effort="600" lower="-1.7453292519943295" upper="2.530727415391778" velocity="5.410520681182422"/>
  </joint>
  <joint name="J3" type="revolute">
    <origin rpy="0 0 0" xyz=" 0  0  .44"/>
    <parent link="J2_link"/>
    <child link="J3_link"/>
    <axis xyz=" 0 -1  0"/>
    <limit effort="300" lower="-1.2217304763960306" upper="3.717551306747922" velocity="7.155849933176751"/>
  </joint>
  <joint name="J4" type="revolute">
    <origin rpy="0 0 0" xyz=" 0  0  .035"/>
    <parent link="J3_link"/>
    <child link="J4_link"/>
    <axis xyz="-1  0  0"/>
    <limit effort="70" lower="-3.3161255787892263" upper="3.3161255787892263" velocity="9.599310885968812"/>
  </joint>
  <joint name="J5" type="revolute">
    <origin rpy="0 0 0" xyz=" .42  0  0"/>
    <parent link="J4_link"/>
    <child link="J5_link"/>
    <axis xyz=" 0 -1  0"/>
    <limit effort="40" lower="-2.181661564992912" upper="2.181661564992912" velocity="9.512044423369096"/>
  </joint>
  <joint name="J6" type="revolute">
    <origin rpy="0 0 0" xyz=" 0  0  0"/>
    <parent link="J5_link"/>
    <child link="J6_link"/>
    <axis xyz="-1  0  0"/>
    <limit effort="20" lower="-6.283185307179586" upper="6.283185307179586" velocity="17.453292519943297"/>
  </joint>
  <!-- world coords -->
  <link name="wbase"/>
  <joint name="base_link-wbase" type="fixed">
    <origin rpy="0 0 0" xyz=" 0  0  .33"/>
    <parent link="base_link"/>
    <child link="wbase"/>
  </joint>
  <!-- flange coords -->
  <link name="flange"/>
  <joint name="J6-flange" type="fixed">
    <origin rpy="0 0 0" xyz=" .09  0  0"/>
    <parent link="J6_link"/>
    <child link="flange"/>
  </joint>
  <!-- FANUC flange coords -->
  <link name="fanuc_flange"/>
  <joint name="flange-fanuc_flange" type="fixed">
    <origin rpy="3.141592653589793 -1.5707963267948966 0.0" xyz="0 0 0"/>
    <parent link="flange"/>
    <child link="fanuc_flange"/>
  </joint>
  <!-- Attach to parent -->
  <joint name="base_joint" type="fixed">
    <origin rpy="0 0 0" xyz="0 0 0"/>
    <parent link="world"/>
    <child link="base_link"/>
  </joint>
  <!-- Attach child -->
  <joint name="child_joint" type="fixed">
    <origin rpy="0 0 0" xyz="0 0 0"/>
    <parent link="flange"/>
    <child link="ee_link"/>
  </joint>
</robot>

