<?xml version="1.0" ?>
<!-- =================================================================================== -->
<!-- |    This document was autogenerated by xacro from /repos/fanuc_description/fanuc_m710_description/robot/m710ic_45m.urdf.xacro | -->
<!-- |    EDITING THIS FILE BY HAND IS NOT RECOMMENDED                                 | -->
<!-- =================================================================================== -->
<robot name="m710ic_45m">
  <link name="world"/>
  <link name="ee_link"/>
  <!-- links -->
  <link name="base_link">
    <visual>
      <origin rpy="0 0 0" xyz="0 0 0"/>
      <geometry>
        <mesh filename="package://fanuc_m710_description/meshes/m710ic_45m/visual/base.dae"/>
      </geometry>
    </visual>
    <collision>
      <origin rpy="0 0 0" xyz="0 0 0"/>
      <geometry>
        <mesh filename="package://fanuc_m710_description/meshes/m710ic_45m/collision/base.stl"/>
      </geometry>
    </collision>
    <inertial>
      <mass value=" 128"/>
      <origin xyz="-.0566 -.000891  .119"/>
      <inertia ixx=" 3.37" ixy="-.0143" ixz=" .0419" iyy=" 3.64" iyz="-.00664" izz=" 5.68"/>
    </inertial>
  </link>
  <link name="J1_link">
    <visual>
      <origin rpy="0 0 0" xyz="0 0 0"/>
      <geometry>
        <mesh filename="package://fanuc_m710_description/meshes/m710ic_45m/visual/j1.dae"/>
      </geometry>
    </visual>
    <collision>
      <origin rpy="0 0 0" xyz="0 0 0"/>
      <geometry>
        <mesh filename="package://fanuc_m710_description/meshes/m710ic_45m/collision/j1.stl"/>
      </geometry>
    </collision>
    <inertial>
      <mass value=" 192"/>
      <origin xyz=" .0514 -.00698 -.104"/>
      <inertia ixx=" 7.14" ixy="-.31" ixz="-.501" iyy=" 6.1" iyz=" .208" izz=" 7.66"/>
    </inertial>
  </link>
  <link name="J2_link">
    <visual>
      <origin rpy="0 0 0" xyz="0 0 0"/>
      <geometry>
        <mesh filename="package://fanuc_m710_description/meshes/m710ic_45m/visual/j2.dae"/>
      </geometry>
    </visual>
    <collision>
      <origin rpy="0 0 0" xyz="0 0 0"/>
      <geometry>
        <mesh filename="package://fanuc_m710_description/meshes/m710ic_45m/collision/j2.stl"/>
      </geometry>
    </collision>
    <inertial>
      <mass value=" 109"/>
      <origin xyz=" .00255  .155  .462"/>
      <inertia ixx=" 15" ixy=" .025" ixz=" .0168" iyy=" 15.3" iyz="-.483" izz=" .901"/>
    </inertial>
  </link>
  <link name="J3_link">
    <visual>
      <origin rpy="0 0 0" xyz="0 0 0"/>
      <geometry>
        <mesh filename="package://fanuc_m710_description/meshes/m710ic_45m/visual/j3.dae"/>
      </geometry>
    </visual>
    <collision>
      <origin rpy="0 0 0" xyz="0 0 0"/>
      <geometry>
        <mesh filename="package://fanuc_m710_description/meshes/m710ic_45m/collision/j3.stl"/>
      </geometry>
    </collision>
    <inertial>
      <mass value=" 87.5"/>
      <origin xyz=" .0116 -.0318  .0851"/>
      <inertia ixx=" 1.71" ixy="-.159" ixz="-.191" iyy=" 2.07" iyz="-.0869" izz=" 1.86"/>
    </inertial>
  </link>
  <link name="J4_link">
    <visual>
      <origin rpy="0 0 0" xyz="0 0 0"/>
      <geometry>
        <mesh filename="package://fanuc_m710_description/meshes/m710ic_45m/visual/j4.dae"/>
      </geometry>
    </visual>
    <collision>
      <origin rpy="0 0 0" xyz="0 0 0"/>
      <geometry>
        <mesh filename="package://fanuc_m710_description/meshes/m710ic_45m/collision/j4.stl"/>
      </geometry>
    </collision>
    <inertial>
      <mass value=" 44.7"/>
      <origin xyz=" .806 -.0208  .000409"/>
      <inertia ixx=" .165" ixy=" .181" ixz="-.00166" iyy=" 4.44" iyz="-.000577" izz=" 4.46"/>
    </inertial>
  </link>
  <link name="J5_link">
    <visual>
      <origin rpy="0 0 0" xyz="0 0 0"/>
      <geometry>
        <mesh filename="package://fanuc_m710_description/meshes/m710ic_45m/visual/j5.dae"/>
      </geometry>
    </visual>
    <collision>
      <origin rpy="0 0 0" xyz="0 0 0"/>
      <geometry>
        <mesh filename="package://fanuc_m710_description/meshes/m710ic_45m/collision/j5.stl"/>
      </geometry>
    </collision>
    <inertial>
      <mass value=" 8.95"/>
      <origin xyz=" .0404  .00391 -.00000114"/>
      <inertia ixx=" .0332" ixy="-.00257" ixz=" .000000378" iyy=" .0476" iyz="-.000000339" izz=" .0505"/>
    </inertial>
  </link>
  <link name="J6_link">
    <visual>
      <origin rpy="0 0 0" xyz="0 0 0"/>
      <geometry>
        <mesh filename="package://fanuc_m710_description/meshes/m710ic_45m/visual/j6.dae"/>
      </geometry>
    </visual>
    <collision>
      <origin rpy="0 0 0" xyz="0 0 0"/>
      <geometry>
        <mesh filename="package://fanuc_m710_description/meshes/m710ic_45m/collision/j6.stl"/>
      </geometry>
    </collision>
    <inertial>
      <mass value=" .463"/>
      <origin xyz=" .165 -4.6E-18 -1.29E-18"/>
      <inertia ixx=" .000898" ixy="-1.24E-18" ixz="-1.44E-19" iyy=" .000465" iyz=" .0000000000662" izz=" .000465"/>
    </inertial>
  </link>
  <!-- joints -->
  <joint name="J1" type="revolute">
    <origin rpy="0 0 0" xyz=" 0  0  .565"/>
    <parent link="base_link"/>
    <child link="J1_link"/>
    <axis xyz=" 0  0  1"/>
    <limit effort="9000" lower="-3.141592653589793" upper="3.141592653589793" velocity="3.141592653589793"/>
  </joint>
  <joint name="J2" type="revolute">
    <origin rpy="0 0 0" xyz=" .15  0  0"/>
    <parent link="J1_link"/>
    <child link="J2_link"/>
    <axis xyz=" 0  1  0"/>
    <limit effort="9000" lower="-1.5707963267948966" upper="2.356194490192345" velocity="3.141592653589793"/>
  </joint>
  <joint name="J3" type="revolute">
    <origin rpy="0 0 0" xyz=" 0  0  1.15"/>
    <parent link="J2_link"/>
    <child link="J3_link"/>
    <axis xyz=" 0 -1  0"/>
    <limit effort="4000" lower="-1.4049900478554354" upper="3.5779249665883754" velocity="3.141592653589793"/>
  </joint>
  <joint name="J4" type="revolute">
    <origin rpy="0 0 0" xyz=" 0  0  .17"/>
    <parent link="J3_link"/>
    <child link="J4_link"/>
    <axis xyz="-1  0  0"/>
    <limit effort="800" lower="-6.981317007977318" upper="6.981317007977318" velocity="4.363323129985824"/>
  </joint>
  <joint name="J5" type="revolute">
    <origin rpy="0 0 0" xyz=" 1.295  0  0"/>
    <parent link="J4_link"/>
    <child link="J5_link"/>
    <axis xyz=" 0 -1  0"/>
    <limit effort="900" lower="-2.181661564992912" upper="2.181661564992912" velocity="4.363323129985824"/>
  </joint>
  <joint name="J6" type="revolute">
    <origin rpy="0 0 0" xyz=" 0  0  0"/>
    <parent link="J5_link"/>
    <child link="J6_link"/>
    <axis xyz="-1  0  0"/>
    <limit effort="700" lower="-6.981317007977318" upper="6.981317007977318" velocity="6.283185307179586"/>
  </joint>
  <!-- world coords -->
  <link name="wbase"/>
  <joint name="base_link-wbase" type="fixed">
    <origin rpy="0 0 0" xyz=" 0  0  .565"/>
    <parent link="base_link"/>
    <child link="wbase"/>
  </joint>
  <!-- flange coords -->
  <link name="flange"/>
  <joint name="J6-flange" type="fixed">
    <origin rpy="0 0 0" xyz=" .175  0  0"/>
    <parent link="J6_link"/>
    <child link="flange"/>
  </joint>
  <!-- FANUC flange coords -->
  <link name="fanuc_flange"/>
  <joint name="flange-fanuc_flange" type="fixed">
    <origin rpy="3.141592653589793 -1.5707963267948966 0.0" xyz="0 0 0"/>
    <parent link="flange"/>
    <child link="fanuc_flange"/>
  </joint>
  <!-- Attach to parent -->
  <joint name="base_joint" type="fixed">
    <origin rpy="0 0 0" xyz="0 0 0"/>
    <parent link="world"/>
    <child link="base_link"/>
  </joint>
  <!-- Attach child -->
  <joint name="child_joint" type="fixed">
    <origin rpy="0 0 0" xyz="0 0 0"/>
    <parent link="flange"/>
    <child link="ee_link"/>
  </joint>
</robot>

