<?xml version="1.0" ?>
<!-- =================================================================================== -->
<!-- |    This document was autogenerated by xacro from /repos/fanuc_description/fanuc_r2000_description/robot/r2000ic_270f.urdf.xacro | -->
<!-- |    EDITING THIS FILE BY HAND IS NOT RECOMMENDED                                 | -->
<!-- =================================================================================== -->
<robot name="r2000ic_270f">
  <link name="world"/>
  <link name="ee_link"/>
  <!-- links -->
  <link name="base_link">
    <visual>
      <origin rpy="0 0 0" xyz="0 0 0"/>
      <geometry>
        <mesh filename="package://fanuc_r2000_description/meshes/r2000ic_270f/visual/base.dae"/>
      </geometry>
    </visual>
    <collision>
      <origin rpy="0 0 0" xyz="0 0 0"/>
      <geometry>
        <mesh filename="package://fanuc_r2000_description/meshes/r2000ic_270f/collision/base.stl"/>
      </geometry>
    </collision>
    <inertial>
      <mass value=" 232"/>
      <origin xyz="-.137 -.00069  .142"/>
      <inertia ixx=" 7.96" ixy=" .213" ixz="-.338" iyy=" 16.6" iyz=" .0165" izz=" 21"/>
    </inertial>
  </link>
  <link name="J1_link">
    <visual>
      <origin rpy="0 0 0" xyz="0 0 0"/>
      <geometry>
        <mesh filename="package://fanuc_r2000_description/meshes/r2000ic_270f/visual/j1.dae"/>
      </geometry>
    </visual>
    <collision>
      <origin rpy="0 0 0" xyz="0 0 0"/>
      <geometry>
        <mesh filename="package://fanuc_r2000_description/meshes/r2000ic_270f/collision/j1.stl"/>
      </geometry>
    </collision>
    <inertial>
      <mass value=" 424"/>
      <origin xyz=" .0199  .064 -.114"/>
      <inertia ixx=" 23.5" ixy=" 4.28" ixz="-.762" iyy=" 33.6" iyz="-.954" izz=" 38.4"/>
    </inertial>
  </link>
  <link name="J2_link">
    <visual>
      <origin rpy="0 0 0" xyz="0 0 0"/>
      <geometry>
        <mesh filename="package://fanuc_r2000_description/meshes/r2000ic_270f/visual/j2.dae"/>
      </geometry>
    </visual>
    <collision>
      <origin rpy="0 0 0" xyz="0 0 0"/>
      <geometry>
        <mesh filename="package://fanuc_r2000_description/meshes/r2000ic_270f/collision/j2.stl"/>
      </geometry>
    </collision>
    <inertial>
      <mass value=" 286"/>
      <origin xyz=" .00363  .259  .488"/>
      <inertia ixx=" 43.6" ixy="-.0681" ixz="-1.22" iyy=" 44.5" iyz="-2.81" izz=" 6.77"/>
    </inertial>
  </link>
  <link name="J3_link">
    <visual>
      <origin rpy="0 0 0" xyz="0 0 0"/>
      <geometry>
        <mesh filename="package://fanuc_r2000_description/meshes/r2000ic_270f/visual/j3.dae"/>
      </geometry>
    </visual>
    <collision>
      <origin rpy="0 0 0" xyz="0 0 0"/>
      <geometry>
        <mesh filename="package://fanuc_r2000_description/meshes/r2000ic_270f/collision/j3.stl"/>
      </geometry>
    </collision>
    <inertial>
      <mass value=" 336"/>
      <origin xyz=" .242  .0593  .154"/>
      <inertia ixx=" 11.7" ixy=" .369" ixz="-2.32" iyy=" 38.1" iyz="-.0876" izz=" 39.1"/>
    </inertial>
  </link>
  <link name="J4_link">
    <visual>
      <origin rpy="0 0 0" xyz="0 0 0"/>
      <geometry>
        <mesh filename="package://fanuc_r2000_description/meshes/r2000ic_270f/visual/j4.dae"/>
      </geometry>
    </visual>
    <collision>
      <origin rpy="0 0 0" xyz="0 0 0"/>
      <geometry>
        <mesh filename="package://fanuc_r2000_description/meshes/r2000ic_270f/collision/j4.stl"/>
      </geometry>
    </collision>
    <inertial>
      <mass value=" 14.6"/>
      <origin xyz=" 1.16 -.00981  .00000000149"/>
      <inertia ixx=" .0716" ixy=" .0103" ixz=" .00000000304" iyy=" .17" iyz=" .00000000163" izz=" .165"/>
    </inertial>
  </link>
  <link name="J5_link">
    <visual>
      <origin rpy="0 0 0" xyz="0 0 0"/>
      <geometry>
        <mesh filename="package://fanuc_r2000_description/meshes/r2000ic_270f/visual/j5.dae"/>
      </geometry>
    </visual>
    <collision>
      <origin rpy="0 0 0" xyz="0 0 0"/>
      <geometry>
        <mesh filename="package://fanuc_r2000_description/meshes/r2000ic_270f/collision/j5.stl"/>
      </geometry>
    </collision>
    <inertial>
      <mass value=" 25.5"/>
      <origin xyz=" .0522 -.024 -.0000000449"/>
      <inertia ixx=" .243" ixy="-.0369" ixz=" .000000117" iyy=" .265" iyz="-.000000128" izz=" .344"/>
    </inertial>
  </link>
  <link name="J6_link">
    <visual>
      <origin rpy="0 0 0" xyz="0 0 0"/>
      <geometry>
        <mesh filename="package://fanuc_r2000_description/meshes/r2000ic_270f/visual/j6.dae"/>
      </geometry>
    </visual>
    <collision>
      <origin rpy="0 0 0" xyz="0 0 0"/>
      <geometry>
        <mesh filename="package://fanuc_r2000_description/meshes/r2000ic_270f/collision/j6.stl"/>
      </geometry>
    </collision>
    <inertial>
      <mass value=" 1.81"/>
      <origin xyz=" .221  .000000432  .0000159"/>
      <inertia ixx=" .00845" ixy="-.00000000509" ixz=" .000000225" iyy=" .00446" iyz=" .000000446" izz=" .00446"/>
    </inertial>
  </link>
  <!-- joints -->
  <joint name="J1" type="revolute">
    <origin rpy="0 0 0" xyz=" 0  0  .67"/>
    <parent link="base_link"/>
    <child link="J1_link"/>
    <axis xyz=" 0  0  1"/>
    <limit effort="20000" lower="-3.2288591161895095" upper="3.2288591161895095" velocity="1.8325957145940461"/>
  </joint>
  <joint name="J2" type="revolute">
    <origin rpy="0 0 0" xyz=" .312  0  0"/>
    <parent link="J1_link"/>
    <child link="J2_link"/>
    <axis xyz=" 0  1  0"/>
    <limit effort="30000" lower="-1.0471975511965976" upper="1.3264502315156905" velocity="1.5707963267948966"/>
  </joint>
  <joint name="J3" type="revolute">
    <origin rpy="0 0 0" xyz=" 0  0  1.075"/>
    <parent link="J2_link"/>
    <child link="J3_link"/>
    <axis xyz=" 0 -1  0"/>
    <limit effort="30000" lower="-1.3788101090755203" upper="3.141592653589793" velocity="1.4835298641951802"/>
  </joint>
  <joint name="J4" type="revolute">
    <origin rpy="0 0 0" xyz=" 0  0  .225"/>
    <parent link="J3_link"/>
    <child link="J4_link"/>
    <axis xyz="-1  0  0"/>
    <limit effort="6000" lower="-6.283185307179586" upper="6.283185307179586" velocity="2.0943951023931953"/>
  </joint>
  <joint name="J5" type="revolute">
    <origin rpy="0 0 0" xyz=" 1.28  0  0"/>
    <parent link="J4_link"/>
    <child link="J5_link"/>
    <axis xyz=" 0 -1  0"/>
    <limit effort="6000" lower="-2.181661564992912" upper="2.181661564992912" velocity="2.0943951023931953"/>
  </joint>
  <joint name="J6" type="revolute">
    <origin rpy="0 0 0" xyz=" 0  0  0"/>
    <parent link="J5_link"/>
    <child link="J6_link"/>
    <axis xyz="-1  0  0"/>
    <limit effort="3000" lower="-6.283185307179586" upper="6.283185307179586" velocity="3.490658503988659"/>
  </joint>
  <!-- world coords -->
  <link name="wbase"/>
  <joint name="base_link-wbase" type="fixed">
    <origin rpy="0 0 0" xyz=" 0  0  .67"/>
    <parent link="base_link"/>
    <child link="wbase"/>
  </joint>
  <!-- flange coords -->
  <link name="flange"/>
  <joint name="J6-flange" type="fixed">
    <origin rpy="0 0 0" xyz=" .24  0  0"/>
    <parent link="J6_link"/>
    <child link="flange"/>
  </joint>
  <!-- FANUC flange coords -->
  <link name="fanuc_flange"/>
  <joint name="flange-fanuc_flange" type="fixed">
    <origin rpy="3.141592653589793 -1.5707963267948966 0.0" xyz="0 0 0"/>
    <parent link="flange"/>
    <child link="fanuc_flange"/>
  </joint>
  <!-- Attach to parent -->
  <joint name="base_joint" type="fixed">
    <origin rpy="0 0 0" xyz="0 0 0"/>
    <parent link="world"/>
    <child link="base_link"/>
  </joint>
  <!-- Attach child -->
  <joint name="child_joint" type="fixed">
    <origin rpy="0 0 0" xyz="0 0 0"/>
    <parent link="flange"/>
    <child link="ee_link"/>
  </joint>
</robot>

