<?xml version="1.0" ?>
<!-- =================================================================================== -->
<!-- |    This document was autogenerated by xacro from /ws/fanuc_r2000_description/robot/r2000id_165fh.urdf.xacro | -->
<!-- |    EDITING THIS FILE BY HAND IS NOT RECOMMENDED                                 | -->
<!-- =================================================================================== -->
<robot name="r2000id_165fh">
  <link name="world"/>
  <link name="ee_link"/>
  <!-- links -->
  <link name="base_link">
    <visual>
      <origin rpy="0 0 0" xyz="0 0 0"/>
      <geometry>
        <mesh filename="package://fanuc_r2000_description/meshes/r2000id_165fh/visual/base.dae"/>
      </geometry>
    </visual>
    <collision>
      <origin rpy="0 0 0" xyz="0 0 0"/>
      <geometry>
        <mesh filename="package://fanuc_r2000_description/meshes/r2000id_165fh/collision/base.stl"/>
      </geometry>
    </collision>
    <inertial>
      <mass value=" 186"/>
      <origin xyz="-.12  .00361  .142"/>
      <inertia ixx=" 5.13" ixy=" .218" ixz="-.401" iyy=" 9.3" iyz=" .0347" izz=" 11.6"/>
    </inertial>
  </link>
  <link name="J1_link">
    <visual>
      <origin rpy="0 0 0" xyz="0 0 0"/>
      <geometry>
        <mesh filename="package://fanuc_r2000_description/meshes/r2000id_165fh/visual/j1.dae"/>
      </geometry>
    </visual>
    <collision>
      <origin rpy="0 0 0" xyz="0 0 0"/>
      <geometry>
        <mesh filename="package://fanuc_r2000_description/meshes/r2000id_165fh/collision/j1.stl"/>
      </geometry>
    </collision>
    <inertial>
      <mass value=" 402"/>
      <origin xyz=" .0153  .0583 -.124"/>
      <inertia ixx=" 20.1" ixy=" 4.37" ixz="-1.67" iyy=" 28.2" iyz="-.536" izz=" 32.4"/>
    </inertial>
  </link>
  <link name="J2_link">
    <visual>
      <origin rpy="0 0 0" xyz="0 0 0"/>
      <geometry>
        <mesh filename="package://fanuc_r2000_description/meshes/r2000id_165fh/visual/j2.dae"/>
      </geometry>
    </visual>
    <collision>
      <origin rpy="0 0 0" xyz="0 0 0"/>
      <geometry>
        <mesh filename="package://fanuc_r2000_description/meshes/r2000id_165fh/collision/j2.stl"/>
      </geometry>
    </collision>
    <inertial>
      <mass value=" 230"/>
      <origin xyz="-.00847  .188  .499"/>
      <inertia ixx=" 31.5" ixy=" .0403" ixz="-.675" iyy=" 32.5" iyz=" .0615" izz=" 3.88"/>
    </inertial>
  </link>
  <link name="J3_link">
    <visual>
      <origin rpy="0 0 0" xyz="0 0 0"/>
      <geometry>
        <mesh filename="package://fanuc_r2000_description/meshes/r2000id_165fh/visual/j3.dae"/>
      </geometry>
    </visual>
    <collision>
      <origin rpy="0 0 0" xyz="0 0 0"/>
      <geometry>
        <mesh filename="package://fanuc_r2000_description/meshes/r2000id_165fh/collision/j3.stl"/>
      </geometry>
    </collision>
    <inertial>
      <mass value=" 168"/>
      <origin xyz=" .0574  .0144  .12"/>
      <inertia ixx=" 5.07" ixy="-.0496" ixz="-.851" iyy=" 6.34" iyz="-.0631" izz=" 6.27"/>
    </inertial>
  </link>
  <link name="J4_link">
    <visual>
      <origin rpy="0 0 0" xyz="0 0 0"/>
      <geometry>
        <mesh filename="package://fanuc_r2000_description/meshes/r2000id_165fh/visual/j4.dae"/>
      </geometry>
    </visual>
    <collision>
      <origin rpy="0 0 0" xyz="0 0 0"/>
      <geometry>
        <mesh filename="package://fanuc_r2000_description/meshes/r2000id_165fh/collision/j4.stl"/>
      </geometry>
    </collision>
    <inertial>
      <mass value=" 143"/>
      <origin xyz=" .862 -.000218 -.00234"/>
      <inertia ixx=" 2.27" ixy=" .0165" ixz="-.032" iyy=" 9.85" iyz=" .0000653" izz=" 10.8"/>
    </inertial>
  </link>
  <link name="J5_link">
    <visual>
      <origin rpy="0 0 0" xyz="0 0 0"/>
      <geometry>
        <mesh filename="package://fanuc_r2000_description/meshes/r2000id_165fh/visual/j5.dae"/>
      </geometry>
    </visual>
    <collision>
      <origin rpy="0 0 0" xyz="0 0 0"/>
      <geometry>
        <mesh filename="package://fanuc_r2000_description/meshes/r2000id_165fh/collision/j5.stl"/>
      </geometry>
    </collision>
    <inertial>
      <mass value=" 19.4"/>
      <origin xyz=" .0655 -.000949  .0000007"/>
      <inertia ixx=" .123" ixy="-.00423" ixz=" .00000221" iyy=" .184" iyz=" .000000228" izz=" .187"/>
    </inertial>
  </link>
  <link name="J6_link">
    <visual>
      <origin rpy="0 0 0" xyz="0 0 0"/>
      <geometry>
        <mesh filename="package://fanuc_r2000_description/meshes/r2000id_165fh/visual/j6.dae"/>
      </geometry>
    </visual>
    <collision>
      <origin rpy="0 0 0" xyz="0 0 0"/>
      <geometry>
        <mesh filename="package://fanuc_r2000_description/meshes/r2000id_165fh/collision/j6.stl"/>
      </geometry>
    </collision>
    <inertial>
      <mass value=" .814"/>
      <origin xyz=" .214 -.00000144 -.000000457"/>
      <inertia ixx=" .00293" ixy=" .00000000888" ixz="-.000000024" iyy=" .00149" iyz=" .0000000117" izz=" .00149"/>
    </inertial>
  </link>
  <!-- joints -->
  <joint name="J1" type="revolute">
    <origin rpy="0 0 0" xyz=" 0  0  .67"/>
    <parent link="base_link"/>
    <child link="J1_link"/>
    <axis xyz=" 0  0  1"/>
    <limit effort="10000" lower="-3.2288591161895095" upper="3.2288591161895095" velocity="2.2689280275926285"/>
  </joint>
  <joint name="J2" type="revolute">
    <origin rpy="0 0 0" xyz=" .312  0  0"/>
    <parent link="J1_link"/>
    <child link="J2_link"/>
    <axis xyz=" 0  1  0"/>
    <limit effort="20000" lower="-1.117010721276371" upper="1.3264502315156905" velocity="1.9198621771937625"/>
  </joint>
  <joint name="J3" type="revolute">
    <origin rpy="0 0 0" xyz=" 0  0  1.075"/>
    <parent link="J2_link"/>
    <child link="J3_link"/>
    <axis xyz=" 0 -1  0"/>
    <limit effort="20000" lower="-1.3788101090755203" upper="1.7453292519943295" velocity="2.007128639793479"/>
  </joint>
  <joint name="J4" type="revolute">
    <origin rpy="0 0 0" xyz=" 0  0  .225"/>
    <parent link="J3_link"/>
    <child link="J4_link"/>
    <axis xyz="-1  0  0"/>
    <limit effort="4000" lower="-3.6651914291880923" upper="3.6651914291880923" velocity="3.0543261909900767"/>
  </joint>
  <joint name="J5" type="revolute">
    <origin rpy="0 0 0" xyz=" 1.23  0  0"/>
    <parent link="J4_link"/>
    <child link="J5_link"/>
    <axis xyz=" 0 -1  0"/>
    <limit effort="4000" lower="-2.181661564992912" upper="2.181661564992912" velocity="2.9670597283903604"/>
  </joint>
  <joint name="J6" type="revolute">
    <origin rpy="0 0 0" xyz=" 0  0  0"/>
    <parent link="J5_link"/>
    <child link="J6_link"/>
    <axis xyz="-1  0  0"/>
    <limit effort="3000" lower="-3.6651914291880923" upper="3.6651914291880923" velocity="4.886921905584122"/>
  </joint>
  <!-- world coords -->
  <link name="wbase"/>
  <joint name="base_link-wbase" type="fixed">
    <origin rpy="0 0 0" xyz=" 0  0  .67"/>
    <parent link="base_link"/>
    <child link="wbase"/>
  </joint>
  <!-- flange coords -->
  <link name="flange"/>
  <joint name="J6-flange" type="fixed">
    <origin rpy="0 0 0" xyz=" .225  0  0"/>
    <parent link="J6_link"/>
    <child link="flange"/>
  </joint>
  <!-- FANUC flange coords -->
  <link name="fanuc_flange"/>
  <joint name="flange-fanuc_flange" type="fixed">
    <origin rpy="3.141592653589793 -1.5707963267948966 0.0" xyz="0 0 0"/>
    <parent link="flange"/>
    <child link="fanuc_flange"/>
  </joint>
  <!-- Attach to parent -->
  <joint name="base_joint" type="fixed">
    <origin rpy="0 0 0" xyz="0 0 0"/>
    <parent link="world"/>
    <child link="base_link"/>
  </joint>
  <!-- Attach child -->
  <joint name="child_joint" type="fixed">
    <origin rpy="0 0 0" xyz="0 0 0"/>
    <parent link="flange"/>
    <child link="ee_link"/>
  </joint>
</robot>

