<?xml version="1.0" ?>
<!-- =================================================================================== -->
<!-- |    This document was autogenerated by xacro from /ws/fanuc_m800_description/robot/m800_60_20b.urdf.xacro | -->
<!-- |    EDITING THIS FILE BY HAND IS NOT RECOMMENDED                                 | -->
<!-- =================================================================================== -->
<robot name="m800_60_20b">
  <link name="world"/>
  <link name="ee_link"/>
  <!-- links -->
  <link name="base_link">
    <visual>
      <origin rpy="0 0 0" xyz="0 0 0"/>
      <geometry>
        <mesh filename="package://fanuc_m800_description/meshes/m800_60_20b/visual/base.dae"/>
      </geometry>
    </visual>
    <collision>
      <origin rpy="0 0 0" xyz="0 0 0"/>
      <geometry>
        <mesh filename="package://fanuc_m800_description/meshes/m800_60_20b/collision/base.stl"/>
      </geometry>
    </collision>
    <inertial>
      <mass value=" 211"/>
      <origin xyz="-.135  .00064  .131"/>
      <inertia ixx=" 5.54" ixy=" .148" ixz="-.404" iyy=" 11.2" iyz=" .0289" izz=" 14.2"/>
    </inertial>
  </link>
  <link name="J1_link">
    <visual>
      <origin rpy="0 0 0" xyz="0 0 0"/>
      <geometry>
        <mesh filename="package://fanuc_m800_description/meshes/m800_60_20b/visual/j1.dae"/>
      </geometry>
    </visual>
    <collision>
      <origin rpy="0 0 0" xyz="0 0 0"/>
      <geometry>
        <mesh filename="package://fanuc_m800_description/meshes/m800_60_20b/collision/j1.stl"/>
      </geometry>
    </collision>
    <inertial>
      <mass value=" 251"/>
      <origin xyz=" .124  .0126 -.109"/>
      <inertia ixx=" 9.2" ixy="-.405" ixz="-2.62" iyy=" 11.3" iyz="-.245" izz=" 12.9"/>
    </inertial>
  </link>
  <link name="J2_link">
    <visual>
      <origin rpy="0 0 0" xyz="0 0 0"/>
      <geometry>
        <mesh filename="package://fanuc_m800_description/meshes/m800_60_20b/visual/j2.dae"/>
      </geometry>
    </visual>
    <collision>
      <origin rpy="0 0 0" xyz="0 0 0"/>
      <geometry>
        <mesh filename="package://fanuc_m800_description/meshes/m800_60_20b/collision/j2.stl"/>
      </geometry>
    </collision>
    <inertial>
      <mass value=" 145"/>
      <origin xyz=" .00223  .157  .388"/>
      <inertia ixx=" 13.3" ixy="-.0333" ixz="-.0318" iyy=" 13.8" iyz=" .154" izz=" 1.68"/>
    </inertial>
  </link>
  <link name="J3_link">
    <visual>
      <origin rpy="0 0 0" xyz="0 0 0"/>
      <geometry>
        <mesh filename="package://fanuc_m800_description/meshes/m800_60_20b/visual/j3.dae"/>
      </geometry>
    </visual>
    <collision>
      <origin rpy="0 0 0" xyz="0 0 0"/>
      <geometry>
        <mesh filename="package://fanuc_m800_description/meshes/m800_60_20b/collision/j3.stl"/>
      </geometry>
    </collision>
    <inertial>
      <mass value=" 141"/>
      <origin xyz=" .0772  .0191  .106"/>
      <inertia ixx=" 4.53" ixy="-.0941" ixz="-.912" iyy=" 3.63" iyz="-.113" izz=" 4.23"/>
    </inertial>
  </link>
  <link name="J4_link">
    <visual>
      <origin rpy="0 0 0" xyz="0 0 0"/>
      <geometry>
        <mesh filename="package://fanuc_m800_description/meshes/m800_60_20b/visual/j4.dae"/>
      </geometry>
    </visual>
    <collision>
      <origin rpy="0 0 0" xyz="0 0 0"/>
      <geometry>
        <mesh filename="package://fanuc_m800_description/meshes/m800_60_20b/collision/j4.stl"/>
      </geometry>
    </collision>
    <inertial>
      <mass value=" 59.9"/>
      <origin xyz=" .656 -.000349 -.000145"/>
      <inertia ixx=" .457" ixy="-.00541" ixz="-.000528" iyy=" 2.15" iyz=" .0000124" izz=" 2.3"/>
    </inertial>
  </link>
  <link name="J5_link">
    <visual>
      <origin rpy="0 0 0" xyz="0 0 0"/>
      <geometry>
        <mesh filename="package://fanuc_m800_description/meshes/m800_60_20b/visual/j5.dae"/>
      </geometry>
    </visual>
    <collision>
      <origin rpy="0 0 0" xyz="0 0 0"/>
      <geometry>
        <mesh filename="package://fanuc_m800_description/meshes/m800_60_20b/collision/j5.stl"/>
      </geometry>
    </collision>
    <inertial>
      <mass value=" 11.9"/>
      <origin xyz=" .0553 -.00233 -.00363"/>
      <inertia ixx=" .0435" ixy="-.000653" ixz=" .00233" iyy=" .0858" iyz="-.000142" izz=" .0824"/>
    </inertial>
  </link>
  <link name="J6_link">
    <visual>
      <origin rpy="0 0 0" xyz="0 0 0"/>
      <geometry>
        <mesh filename="package://fanuc_m800_description/meshes/m800_60_20b/visual/j6.dae"/>
      </geometry>
    </visual>
    <collision>
      <origin rpy="0 0 0" xyz="0 0 0"/>
      <geometry>
        <mesh filename="package://fanuc_m800_description/meshes/m800_60_20b/collision/j6.stl"/>
      </geometry>
    </collision>
    <inertial>
      <mass value=" .733"/>
      <origin xyz=" .174  2.29E-18  3.93E-18"/>
      <inertia ixx=" .00125" ixy=" 1.27E-18" ixz=" 8.86E-19" iyy=" .000692" iyz=" .0000000000517" izz=" .000692"/>
    </inertial>
  </link>
  <!-- joints -->
  <joint name="J1" type="revolute">
    <origin rpy="0 0 0" xyz=" 0  0  .6"/>
    <parent link="base_link"/>
    <child link="J1_link"/>
    <axis xyz=" 0  0  1"/>
    <limit effort="10000" lower="-3.2288591161895095" upper="3.2288591161895095" velocity="2.6179938779914944"/>
  </joint>
  <joint name="J2" type="revolute">
    <origin rpy="0 0 0" xyz=" .312  0  0"/>
    <parent link="J1_link"/>
    <child link="J2_link"/>
    <axis xyz=" 0  1  0"/>
    <limit effort="10000" lower="-1.5707963267948966" upper="2.356194490192345" velocity="2.6179938779914944"/>
  </joint>
  <joint name="J3" type="revolute">
    <origin rpy="0 0 0" xyz=" 0  0  .8"/>
    <parent link="J2_link"/>
    <child link="J3_link"/>
    <axis xyz=" 0 -1  0"/>
    <limit effort="7000" lower="-1.3439035240356338" upper="2.443460952792061" velocity="2.6179938779914944"/>
  </joint>
  <joint name="J4" type="revolute">
    <origin rpy="0 0 0" xyz=" 0  0  .225"/>
    <parent link="J3_link"/>
    <child link="J4_link"/>
    <axis xyz="-1  0  0"/>
    <limit effort="2000" lower="-6.283185307179586" upper="6.283185307179586" velocity="4.537856055185257"/>
  </joint>
  <joint name="J5" type="revolute">
    <origin rpy="0 0 0" xyz=" .9  0  0"/>
    <parent link="J4_link"/>
    <child link="J5_link"/>
    <axis xyz=" 0 -1  0"/>
    <limit effort="1000" lower="-2.181661564992912" upper="2.181661564992912" velocity="4.537856055185257"/>
  </joint>
  <joint name="J6" type="revolute">
    <origin rpy="0 0 0" xyz=" 0  0  0"/>
    <parent link="J5_link"/>
    <child link="J6_link"/>
    <axis xyz="-1  0  0"/>
    <limit effort="600" lower="-6.283185307179586" upper="6.283185307179586" velocity="6.981317007977318"/>
  </joint>
  <!-- world coords -->
  <link name="wbase"/>
  <joint name="base_link-wbase" type="fixed">
    <origin rpy="0 0 0" xyz=" 0  0  .6"/>
    <parent link="base_link"/>
    <child link="wbase"/>
  </joint>
  <!-- flange coords -->
  <link name="flange"/>
  <joint name="J6-flange" type="fixed">
    <origin rpy="0 0 0" xyz=" .19  0  0"/>
    <parent link="J6_link"/>
    <child link="flange"/>
  </joint>
  <!-- FANUC flange coords -->
  <link name="fanuc_flange"/>
  <joint name="flange-fanuc_flange" type="fixed">
    <origin rpy="3.141592653589793 -1.5707963267948966 0.0" xyz="0 0 0"/>
    <parent link="flange"/>
    <child link="fanuc_flange"/>
  </joint>
  <!-- Attach to parent -->
  <joint name="base_joint" type="fixed">
    <origin rpy="0 0 0" xyz="0 0 0"/>
    <parent link="world"/>
    <child link="base_link"/>
  </joint>
  <!-- Attach child -->
  <joint name="child_joint" type="fixed">
    <origin rpy="0 0 0" xyz="0 0 0"/>
    <parent link="flange"/>
    <child link="ee_link"/>
  </joint>
</robot>

