<?xml version="1.0" ?>
<!-- =================================================================================== -->
<!-- |    This document was autogenerated by xacro from /ws/fanuc_crx_description/robot/crx3ia.urdf.xacro | -->
<!-- |    EDITING THIS FILE BY HAND IS NOT RECOMMENDED                                 | -->
<!-- =================================================================================== -->
<robot name="crx3ia">
  <link name="world"/>
  <link name="ee_link"/>
  <!-- links -->
  <link name="base_link">
    <visual>
      <origin rpy="0 0 0" xyz="0 0 0"/>
      <geometry>
        <mesh filename="package://fanuc_crx_description/meshes/crx3ia/visual/base.dae"/>
      </geometry>
    </visual>
    <collision>
      <origin rpy="0 0 0" xyz="0 0 0"/>
      <geometry>
        <mesh filename="package://fanuc_crx_description/meshes/crx3ia/collision/base.stl"/>
      </geometry>
    </collision>
    <inertial>
      <mass value=" .798"/>
      <origin xyz="-.0193 -.00000331  .028"/>
      <inertia ixx=" .000864" ixy="-.000000153" ixz=" .0000271" iyy=" .00169" iyz="-.0000000643" izz=" .00211"/>
    </inertial>
  </link>
  <link name="J1_link">
    <visual>
      <origin rpy="0 0 0" xyz="0 0 0"/>
      <geometry>
        <mesh filename="package://fanuc_crx_description/meshes/crx3ia/visual/j1.dae"/>
      </geometry>
    </visual>
    <collision>
      <origin rpy="0 0 0" xyz="0 0 0"/>
      <geometry>
        <mesh filename="package://fanuc_crx_description/meshes/crx3ia/collision/j1.stl"/>
      </geometry>
    </collision>
    <inertial>
      <mass value=" 1.95"/>
      <origin xyz=" .0000000283 -.0201 -.0208"/>
      <inertia ixx=" .0064" ixy="-.00000000462" ixz="-.000000000477" iyy=" .00508" iyz=" .000417" izz=" .00468"/>
    </inertial>
  </link>
  <link name="J2_link">
    <visual>
      <origin rpy="0 0 0" xyz="0 0 0"/>
      <geometry>
        <mesh filename="package://fanuc_crx_description/meshes/crx3ia/visual/j2.dae"/>
      </geometry>
    </visual>
    <collision>
      <origin rpy="0 0 0" xyz="0 0 0"/>
      <geometry>
        <mesh filename="package://fanuc_crx_description/meshes/crx3ia/collision/j2.stl"/>
      </geometry>
    </collision>
    <inertial>
      <mass value=" 4.39"/>
      <origin xyz="-.000000223 -.137  .143"/>
      <inertia ixx=" .0527" ixy="-.0000000435" ixz="-.0000000196" iyy=" .0509" iyz="-.00223" izz=" .0095"/>
    </inertial>
  </link>
  <link name="J3_link">
    <visual>
      <origin rpy="0 0 0" xyz="0 0 0"/>
      <geometry>
        <mesh filename="package://fanuc_crx_description/meshes/crx3ia/visual/j3.dae"/>
      </geometry>
    </visual>
    <collision>
      <origin rpy="0 0 0" xyz="0 0 0"/>
      <geometry>
        <mesh filename="package://fanuc_crx_description/meshes/crx3ia/collision/j3.stl"/>
      </geometry>
    </collision>
    <inertial>
      <mass value=" 1.35"/>
      <origin xyz=" .0256 -.00533 -.0000033"/>
      <inertia ixx=" .00222" ixy="-.0000977" ixz=" .0000000249" iyy=" .00319" iyz="-.0000000162" izz=" .00343"/>
    </inertial>
  </link>
  <link name="J4_link">
    <visual>
      <origin rpy="0 0 0" xyz="0 0 0"/>
      <geometry>
        <mesh filename="package://fanuc_crx_description/meshes/crx3ia/visual/j4.dae"/>
      </geometry>
    </visual>
    <collision>
      <origin rpy="0 0 0" xyz="0 0 0"/>
      <geometry>
        <mesh filename="package://fanuc_crx_description/meshes/crx3ia/collision/j4.stl"/>
      </geometry>
    </collision>
    <inertial>
      <mass value=" 1.49"/>
      <origin xyz=" .207 -.00409  .00000000534"/>
      <inertia ixx=" .0018" ixy=" .000199" ixz="-.000000000721" iyy=" .00643" iyz="-.0000000000442" izz=" .0065"/>
    </inertial>
  </link>
  <link name="J5_link">
    <visual>
      <origin rpy="0 0 0" xyz="0 0 0"/>
      <geometry>
        <mesh filename="package://fanuc_crx_description/meshes/crx3ia/visual/j5.dae"/>
      </geometry>
    </visual>
    <collision>
      <origin rpy="0 0 0" xyz="0 0 0"/>
      <geometry>
        <mesh filename="package://fanuc_crx_description/meshes/crx3ia/collision/j5.stl"/>
      </geometry>
    </collision>
    <inertial>
      <mass value=" .772"/>
      <origin xyz=" .0147 -.101  .000000000642"/>
      <inertia ixx=" .000972" ixy=" .0000686" ixz=" .000000000119" iyy=" .0011" iyz="-.000000000368" izz=" .00128"/>
    </inertial>
  </link>
  <link name="J6_link">
    <visual>
      <origin rpy="0 0 0" xyz="0 0 0"/>
      <geometry>
        <mesh filename="package://fanuc_crx_description/meshes/crx3ia/visual/j6.dae"/>
      </geometry>
    </visual>
    <collision>
      <origin rpy="0 0 0" xyz="0 0 0"/>
      <geometry>
        <mesh filename="package://fanuc_crx_description/meshes/crx3ia/collision/j6.stl"/>
      </geometry>
    </collision>
    <inertial>
      <mass value=" .248"/>
      <origin xyz=" .0969 -.00117  .00000886"/>
      <inertia ixx=" .000216" ixy="-.000000209" ixz=" .00000000991" iyy=" .000151" iyz="-.00000000377" izz=" .000163"/>
    </inertial>
  </link>
  <!-- joints -->
  <joint name="J1" type="revolute">
    <origin rpy="0 0 0" xyz=" 0  0  .161"/>
    <parent link="base_link"/>
    <child link="J1_link"/>
    <axis xyz=" 0  0  1"/>
    <limit effort="200" lower="-3.490658503988659" upper="3.490658503988659" velocity="2.2689280275926285"/>
  </joint>
  <joint name="J2" type="revolute">
    <origin rpy="0 0 0" xyz=" 0  0  0"/>
    <parent link="J1_link"/>
    <child link="J2_link"/>
    <axis xyz=" 0  1  0"/>
    <limit effort="200" lower="-3.141575200297273" upper="3.141575200297273" velocity="2.2689280275926285"/>
  </joint>
  <joint name="J3" type="revolute">
    <origin rpy="0 0 0" xyz=" 0  0  .28"/>
    <parent link="J2_link"/>
    <child link="J3_link"/>
    <axis xyz=" 0 -1  0"/>
    <limit effort="100" lower="-1.0943214410004447" upper="4.235914094590238" velocity="3.141592653589793"/>
  </joint>
  <joint name="J4" type="revolute">
    <origin rpy="0 0 0" xyz=" 0  0  0"/>
    <parent link="J3_link"/>
    <child link="J4_link"/>
    <axis xyz="-1  0  0"/>
    <limit effort="80" lower="-3.3161255787892263" upper="3.3161255787892263" velocity="3.9269908169872414"/>
  </joint>
  <joint name="J5" type="revolute">
    <origin rpy="0 0 0" xyz=" .28  0  0"/>
    <parent link="J4_link"/>
    <child link="J5_link"/>
    <axis xyz=" 0 -1  0"/>
    <limit effort="60" lower="-3.141575200297273" upper="3.141575200297273" velocity="6.283185307179586"/>
  </joint>
  <joint name="J6" type="revolute">
    <origin rpy="0 0 0" xyz=" 0 -.111  0"/>
    <parent link="J5_link"/>
    <child link="J6_link"/>
    <axis xyz="-1  0  0"/>
    <limit effort="50" lower="-3.9269908169872414" upper="3.9269908169872414" velocity="6.283185307179586"/>
  </joint>
  <!-- world coords -->
  <link name="wbase"/>
  <joint name="base_link-wbase" type="fixed">
    <origin rpy="0 0 0" xyz=" 0  0  .161"/>
    <parent link="base_link"/>
    <child link="wbase"/>
  </joint>
  <!-- flange coords -->
  <link name="flange"/>
  <joint name="J6-flange" type="fixed">
    <origin rpy="0 0 0" xyz=" .123  0  0"/>
    <parent link="J6_link"/>
    <child link="flange"/>
  </joint>
  <!-- FANUC flange coords -->
  <link name="fanuc_flange"/>
  <joint name="flange-fanuc_flange" type="fixed">
    <origin rpy="3.141592653589793 -1.5707963267948966 0.0" xyz="0 0 0"/>
    <parent link="flange"/>
    <child link="fanuc_flange"/>
  </joint>
  <!-- Attach to parent -->
  <joint name="base_joint" type="fixed">
    <origin rpy="0 0 0" xyz="0 0 0"/>
    <parent link="world"/>
    <child link="base_link"/>
  </joint>
  <!-- Attach child -->
  <joint name="child_joint" type="fixed">
    <origin rpy="0 0 0" xyz="0 0 0"/>
    <parent link="flange"/>
    <child link="ee_link"/>
  </joint>
</robot>

