<?xml version="1.0" ?>
<!-- =================================================================================== -->
<!-- |    This document was autogenerated by xacro from /ws/fanuc_m10_description/robot/m10_16-11d.urdf.xacro | -->
<!-- |    EDITING THIS FILE BY HAND IS NOT RECOMMENDED                                 | -->
<!-- =================================================================================== -->
<robot name="m10_16-11d">
  <link name="world"/>
  <link name="ee_link"/>
  <!-- links -->
  <link name="base_link">
    <visual>
      <origin rpy="0 0 0" xyz="0 0 0"/>
      <geometry>
        <mesh filename="package://fanuc_m10_description/meshes/m10_16-11d/visual/base.dae"/>
      </geometry>
    </visual>
    <collision>
      <origin rpy="0 0 0" xyz="0 0 0"/>
      <geometry>
        <mesh filename="package://fanuc_m10_description/meshes/m10_16-11d/collision/base.stl"/>
      </geometry>
    </collision>
    <inertial>
      <mass value=" 53.5"/>
      <origin xyz=" .00757 -.0212  .138"/>
      <inertia ixx=" .883" ixy=" .0362" ixz="-.0311" iyy=" .882" iyz=" .0588" izz=" 1.06"/>
    </inertial>
  </link>
  <link name="J1_link">
    <visual>
      <origin rpy="0 0 0" xyz="0 0 0"/>
      <geometry>
        <mesh filename="package://fanuc_m10_description/meshes/m10_16-11d/visual/j1.dae"/>
      </geometry>
    </visual>
    <collision>
      <origin rpy="0 0 0" xyz="0 0 0"/>
      <geometry>
        <mesh filename="package://fanuc_m10_description/meshes/m10_16-11d/collision/j1.stl"/>
      </geometry>
    </collision>
    <inertial>
      <mass value=" 28"/>
      <origin xyz=" .0385 -.0176 -.0359"/>
      <inertia ixx=" .318" ixy="-.0118" ixz="-.0175" iyy=" .27" iyz="-.01" izz=" .374"/>
    </inertial>
  </link>
  <link name="J2_link">
    <visual>
      <origin rpy="0 0 0" xyz="0 0 0"/>
      <geometry>
        <mesh filename="package://fanuc_m10_description/meshes/m10_16-11d/visual/j2.dae"/>
      </geometry>
    </visual>
    <collision>
      <origin rpy="0 0 0" xyz="0 0 0"/>
      <geometry>
        <mesh filename="package://fanuc_m10_description/meshes/m10_16-11d/collision/j2.stl"/>
      </geometry>
    </collision>
    <inertial>
      <mass value=" 19"/>
      <origin xyz="-.0162 -.147  .207"/>
      <inertia ixx=" .459" ixy="-.0117" ixz=" .00396" iyy=" .465" iyz="-.0123" izz=" .0765"/>
    </inertial>
  </link>
  <link name="J3_link">
    <visual>
      <origin rpy="0 0 0" xyz="0 0 0"/>
      <geometry>
        <mesh filename="package://fanuc_m10_description/meshes/m10_16-11d/visual/j3.dae"/>
      </geometry>
    </visual>
    <collision>
      <origin rpy="0 0 0" xyz="0 0 0"/>
      <geometry>
        <mesh filename="package://fanuc_m10_description/meshes/m10_16-11d/collision/j3.stl"/>
      </geometry>
    </collision>
    <inertial>
      <mass value=" 26.3"/>
      <origin xyz=" .0444  .0135  .102"/>
      <inertia ixx=" .419" ixy="-.00361" ixz="-.0164" iyy=" .27" iyz="-.0339" izz=" .279"/>
    </inertial>
  </link>
  <link name="J4_link">
    <visual>
      <origin rpy="0 0 0" xyz="0 0 0"/>
      <geometry>
        <mesh filename="package://fanuc_m10_description/meshes/m10_16-11d/visual/j4.dae"/>
      </geometry>
    </visual>
    <collision>
      <origin rpy="0 0 0" xyz="0 0 0"/>
      <geometry>
        <mesh filename="package://fanuc_m10_description/meshes/m10_16-11d/collision/j4.stl"/>
      </geometry>
    </collision>
    <inertial>
      <mass value=" 15.5"/>
      <origin xyz=" .337 -.0526 -.00577"/>
      <inertia ixx=" .0593" ixy=" .0261" ixz="-.00633" iyy=" .289" iyz="-.000398" izz=" .292"/>
    </inertial>
  </link>
  <link name="J5_link">
    <visual>
      <origin rpy="0 0 0" xyz="0 0 0"/>
      <geometry>
        <mesh filename="package://fanuc_m10_description/meshes/m10_16-11d/visual/j5.dae"/>
      </geometry>
    </visual>
    <collision>
      <origin rpy="0 0 0" xyz="0 0 0"/>
      <geometry>
        <mesh filename="package://fanuc_m10_description/meshes/m10_16-11d/collision/j5.stl"/>
      </geometry>
    </collision>
    <inertial>
      <mass value=" 2.02"/>
      <origin xyz=" .0276 -.0121  .000000522"/>
      <inertia ixx=" .00402" ixy="-.000801" ixz=" .0000000345" iyy=" .00471" iyz=" .00000000339" izz=" .00418"/>
    </inertial>
  </link>
  <link name="J6_link">
    <visual>
      <origin rpy="0 0 0" xyz="0 0 0"/>
      <geometry>
        <mesh filename="package://fanuc_m10_description/meshes/m10_16-11d/visual/j6.dae"/>
      </geometry>
    </visual>
    <collision>
      <origin rpy="0 0 0" xyz="0 0 0"/>
      <geometry>
        <mesh filename="package://fanuc_m10_description/meshes/m10_16-11d/collision/j6.stl"/>
      </geometry>
    </collision>
    <inertial>
      <mass value=" .569"/>
      <origin xyz=" .0581 -.000000509  .000000147"/>
      <inertia ixx=" .000596" ixy="-.00000000716" ixz=" .00000000194" iyy=" .000441" iyz=" .0000000231" izz=" .000441"/>
    </inertial>
  </link>
  <!-- joints -->
  <joint name="J1" type="revolute">
    <origin rpy="0 0 0" xyz=" 0  0  .45"/>
    <parent link="base_link"/>
    <child link="J1_link"/>
    <axis xyz=" 0  0  1"/>
    <limit effort="2000" lower="-3.2288591161895095" upper="3.2288591161895095" velocity="5.061454830783556"/>
  </joint>
  <joint name="J2" type="revolute">
    <origin rpy="0 0 0" xyz=" .075  0  0"/>
    <parent link="J1_link"/>
    <child link="J2_link"/>
    <axis xyz=" 0  1  0"/>
    <limit effort="3000" lower="-1.5707963267948966" upper="2.530727415391778" velocity="4.71238898038469"/>
  </joint>
  <joint name="J3" type="revolute">
    <origin rpy="0 0 0" xyz=" 0  0  .44"/>
    <parent link="J2_link"/>
    <child link="J3_link"/>
    <axis xyz=" 0 -1  0"/>
    <limit effort="1000" lower="-1.5707963267948966" upper="3.3335788713091694" velocity="4.71238898038469"/>
  </joint>
  <joint name="J4" type="revolute">
    <origin rpy="0 0 0" xyz=" 0  0  .195"/>
    <parent link="J3_link"/>
    <child link="J4_link"/>
    <axis xyz="-1  0  0"/>
    <limit effort="100" lower="-3.3161255787892263" upper="3.3161255787892263" velocity="7.504915783575617"/>
  </joint>
  <joint name="J5" type="revolute">
    <origin rpy="0 0 0" xyz=" .555  0  0"/>
    <parent link="J4_link"/>
    <child link="J5_link"/>
    <axis xyz=" 0 -1  0"/>
    <limit effort="100" lower="-3.141575200297273" upper="3.141575200297273" velocity="7.853981633974483"/>
  </joint>
  <joint name="J6" type="revolute">
    <origin rpy="0 0 0" xyz=" 0  0  0"/>
    <parent link="J5_link"/>
    <child link="J6_link"/>
    <axis xyz="-1  0  0"/>
    <limit effort="70" lower="-7.853981633974483" upper="7.853981633974483" velocity="12.740903539558605"/>
  </joint>
  <!-- world coords -->
  <link name="wbase"/>
  <joint name="base_link-wbase" type="fixed">
    <origin rpy="0 0 0" xyz=" 0  0  .45"/>
    <parent link="base_link"/>
    <child link="wbase"/>
  </joint>
  <!-- flange coords -->
  <link name="flange"/>
  <joint name="J6-flange" type="fixed">
    <origin rpy="0 0 0" xyz=" .09  0  0"/>
    <parent link="J6_link"/>
    <child link="flange"/>
  </joint>
  <!-- FANUC flange coords -->
  <link name="fanuc_flange"/>
  <joint name="flange-fanuc_flange" type="fixed">
    <origin rpy="3.141592653589793 -1.5707963267948966 0.0" xyz="0 0 0"/>
    <parent link="flange"/>
    <child link="fanuc_flange"/>
  </joint>
  <!-- Attach to parent -->
  <joint name="base_joint" type="fixed">
    <origin rpy="0 0 0" xyz="0 0 0"/>
    <parent link="world"/>
    <child link="base_link"/>
  </joint>
  <!-- Attach child -->
  <joint name="child_joint" type="fixed">
    <origin rpy="0 0 0" xyz="0 0 0"/>
    <parent link="flange"/>
    <child link="ee_link"/>
  </joint>
</robot>

