<?xml version="1.0" ?>
<!-- =================================================================================== -->
<!-- |    This document was autogenerated by xacro from /ws/fanuc_lrmate_description/robot/lrmate35-14a.urdf.xacro | -->
<!-- |    EDITING THIS FILE BY HAND IS NOT RECOMMENDED                                 | -->
<!-- =================================================================================== -->
<robot name="lrmate35-14a">
  <link name="world"/>
  <link name="ee_link"/>
  <!-- links -->
  <link name="base_link">
    <visual>
      <origin rpy="0 0 0" xyz="0 0 0"/>
      <geometry>
        <mesh filename="package://fanuc_lrmate_description/meshes/lrmate35-14a/visual/base.dae"/>
      </geometry>
    </visual>
    <collision>
      <origin rpy="0 0 0" xyz="0 0 0"/>
      <geometry>
        <mesh filename="package://fanuc_lrmate_description/meshes/lrmate35-14a/collision/base.stl"/>
      </geometry>
    </collision>
    <inertial>
      <mass value=" 36"/>
      <origin xyz="-.0269 -.0000215  .157"/>
      <inertia ixx=" .616" ixy="-.00604" ixz="-.0058" iyy=" .753" iyz="-.00063" izz=" .738"/>
    </inertial>
  </link>
  <link name="J1_link">
    <visual>
      <origin rpy="0 0 0" xyz="0 0 0"/>
      <geometry>
        <mesh filename="package://fanuc_lrmate_description/meshes/lrmate35-14a/visual/j1.dae"/>
      </geometry>
    </visual>
    <collision>
      <origin rpy="0 0 0" xyz="0 0 0"/>
      <geometry>
        <mesh filename="package://fanuc_lrmate_description/meshes/lrmate35-14a/collision/j1.stl"/>
      </geometry>
    </collision>
    <inertial>
      <mass value=" 57.9"/>
      <origin xyz=" .0372  .00108 -.101"/>
      <inertia ixx=" 2.05" ixy="-.00376" ixz="-.165" iyy=" 1.27" iyz="-.00429" izz=" 1.69"/>
    </inertial>
  </link>
  <link name="J2_link">
    <visual>
      <origin rpy="0 0 0" xyz="0 0 0"/>
      <geometry>
        <mesh filename="package://fanuc_lrmate_description/meshes/lrmate35-14a/visual/j2.dae"/>
      </geometry>
    </visual>
    <collision>
      <origin rpy="0 0 0" xyz="0 0 0"/>
      <geometry>
        <mesh filename="package://fanuc_lrmate_description/meshes/lrmate35-14a/collision/j2.stl"/>
      </geometry>
    </collision>
    <inertial>
      <mass value=" 78.1"/>
      <origin xyz="-.00113 -.000658  .324"/>
      <inertia ixx=" 5.64" ixy="-.00094" ixz=" .000886" iyy=" 5.06" iyz=" .00373" izz=" 1.43"/>
    </inertial>
  </link>
  <link name="J3_link">
    <visual>
      <origin rpy="0 0 0" xyz="0 0 0"/>
      <geometry>
        <mesh filename="package://fanuc_lrmate_description/meshes/lrmate35-14a/visual/j3.dae"/>
      </geometry>
    </visual>
    <collision>
      <origin rpy="0 0 0" xyz="0 0 0"/>
      <geometry>
        <mesh filename="package://fanuc_lrmate_description/meshes/lrmate35-14a/collision/j3.stl"/>
      </geometry>
    </collision>
    <inertial>
      <mass value=" 19"/>
      <origin xyz=" .0221 -.00161  .0386"/>
      <inertia ixx=" .233" ixy="-.00579" ixz="-.0249" iyy=" .258" iyz="-.00229" izz=" .227"/>
    </inertial>
  </link>
  <link name="J4_link">
    <visual>
      <origin rpy="0 0 0" xyz="0 0 0"/>
      <geometry>
        <mesh filename="package://fanuc_lrmate_description/meshes/lrmate35-14a/visual/j4.dae"/>
      </geometry>
    </visual>
    <collision>
      <origin rpy="0 0 0" xyz="0 0 0"/>
      <geometry>
        <mesh filename="package://fanuc_lrmate_description/meshes/lrmate35-14a/collision/j4.stl"/>
      </geometry>
    </collision>
    <inertial>
      <mass value=" 12.8"/>
      <origin xyz=" .456  .00534 -.00000319"/>
      <inertia ixx=" .0516" ixy=" .00205" ixz="-.00000144" iyy=" .385" iyz=" .00000375" izz=" .4"/>
    </inertial>
  </link>
  <link name="J5_link">
    <visual>
      <origin rpy="0 0 0" xyz="0 0 0"/>
      <geometry>
        <mesh filename="package://fanuc_lrmate_description/meshes/lrmate35-14a/visual/j5.dae"/>
      </geometry>
    </visual>
    <collision>
      <origin rpy="0 0 0" xyz="0 0 0"/>
      <geometry>
        <mesh filename="package://fanuc_lrmate_description/meshes/lrmate35-14a/collision/j5.stl"/>
      </geometry>
    </collision>
    <inertial>
      <mass value=" 1.24"/>
      <origin xyz=" .0173  .00272  .0000418"/>
      <inertia ixx=" .00201" ixy=" .0000313" ixz=" .000000159" iyy=" .00296" iyz="-.000000564" izz=" .00287"/>
    </inertial>
  </link>
  <link name="J6_link">
    <visual>
      <origin rpy="0 0 0" xyz="0 0 0"/>
      <geometry>
        <mesh filename="package://fanuc_lrmate_description/meshes/lrmate35-14a/visual/j6.dae"/>
      </geometry>
    </visual>
    <collision>
      <origin rpy="0 0 0" xyz="0 0 0"/>
      <geometry>
        <mesh filename="package://fanuc_lrmate_description/meshes/lrmate35-14a/collision/j6.stl"/>
      </geometry>
    </collision>
    <inertial>
      <mass value=" .0265"/>
      <origin xyz=" .0936 -3.11E-18  2.17E-17"/>
      <inertia ixx=" .0000107" ixy=" 1.93E-20" ixz=" 1.06E-19" iyy=" .00000563" iyz="-4.38E-21" izz=" .00000563"/>
    </inertial>
  </link>
  <!-- joints -->
  <joint name="J1" type="revolute">
    <origin rpy="0 0 0" xyz=" 0  0  .65"/>
    <parent link="base_link"/>
    <child link="J1_link"/>
    <axis xyz=" 0  0  1"/>
    <limit effort="4000" lower="-3.141592653589793" upper="3.141592653589793" velocity="3.5779249665883754"/>
  </joint>
  <joint name="J2" type="revolute">
    <origin rpy="0 0 0" xyz=" .075  0  0"/>
    <parent link="J1_link"/>
    <child link="J2_link"/>
    <axis xyz=" 0  1  0"/>
    <limit effort="7000" lower="-1.7453292519943295" upper="2.443460952792061" velocity="3.5779249665883754"/>
  </joint>
  <joint name="J3" type="revolute">
    <origin rpy="0 0 0" xyz=" 0  0  .637"/>
    <parent link="J2_link"/>
    <child link="J3_link"/>
    <axis xyz=" 0 -1  0"/>
    <limit effort="2000" lower="-1.4224433403753787" upper="3.839724354387525" velocity="4.537856055185257"/>
  </joint>
  <joint name="J4" type="revolute">
    <origin rpy="0 0 0" xyz=" 0  0  .12"/>
    <parent link="J3_link"/>
    <child link="J4_link"/>
    <axis xyz="-1  0  0"/>
    <limit effort="500" lower="-3.490658503988659" upper="3.490658503988659" velocity="7.243116395776467"/>
  </joint>
  <joint name="J5" type="revolute">
    <origin rpy="0 0 0" xyz=" .723  0  0"/>
    <parent link="J4_link"/>
    <child link="J5_link"/>
    <axis xyz=" 0 -1  0"/>
    <limit effort="300" lower="-2.2689280275926285" upper="2.2689280275926285" velocity="7.243116395776467"/>
  </joint>
  <joint name="J6" type="revolute">
    <origin rpy="0 0 0" xyz=" 0  0  0"/>
    <parent link="J5_link"/>
    <child link="J6_link"/>
    <axis xyz="-1  0  0"/>
    <limit effort="200" lower="-4.71238898038469" upper="4.71238898038469" velocity="15.3588974175501"/>
  </joint>
  <!-- world coords -->
  <link name="wbase"/>
  <joint name="base_link-wbase" type="fixed">
    <origin rpy="0 0 0" xyz=" 0  0  .65"/>
    <parent link="base_link"/>
    <child link="wbase"/>
  </joint>
  <!-- flange coords -->
  <link name="flange"/>
  <joint name="J6-flange" type="fixed">
    <origin rpy="0 0 0" xyz=" .1  0  0"/>
    <parent link="J6_link"/>
    <child link="flange"/>
  </joint>
  <!-- FANUC flange coords -->
  <link name="fanuc_flange"/>
  <joint name="flange-fanuc_flange" type="fixed">
    <origin rpy="3.141592653589793 -1.5707963267948966 0.0" xyz="0 0 0"/>
    <parent link="flange"/>
    <child link="fanuc_flange"/>
  </joint>
  <!-- Attach to parent -->
  <joint name="base_joint" type="fixed">
    <origin rpy="0 0 0" xyz="0 0 0"/>
    <parent link="world"/>
    <child link="base_link"/>
  </joint>
  <!-- Attach child -->
  <joint name="child_joint" type="fixed">
    <origin rpy="0 0 0" xyz="0 0 0"/>
    <parent link="flange"/>
    <child link="ee_link"/>
  </joint>
</robot>

