<?xml version="1.0" ?>
<!-- =================================================================================== -->
<!-- |    This document was autogenerated by xacro from /repos/fanuc_description/fanuc_crx_description/robot/crx30ia.urdf.xacro | -->
<!-- |    EDITING THIS FILE BY HAND IS NOT RECOMMENDED                                 | -->
<!-- =================================================================================== -->
<robot name="crx30ia">
  <link name="world"/>
  <link name="ee_link"/>
  <!-- links -->
  <link name="base_link">
    <visual>
      <origin rpy="0 0 0" xyz="0 0 0"/>
      <geometry>
        <mesh filename="package://fanuc_crx_description/meshes/crx30ia/visual/base.dae"/>
      </geometry>
    </visual>
    <collision>
      <origin rpy="0 0 0" xyz="0 0 0"/>
      <geometry>
        <mesh filename="package://fanuc_crx_description/meshes/crx30ia/collision/base.stl" scale="0.001 0.001 0.001"/>
      </geometry>
    </collision>
    <inertial>
      <mass value="21.685"/>
      <origin xyz="-0.00536 0.00024 0.09678"/>
      <inertia ixx="0.12527923" ixy="0.000291545" ixz="0.003029499" iyy="0.138144056" iyz="-0.000163996" izz="0.181495336"/>
    </inertial>
  </link>
  <link name="J1_link">
    <visual>
      <origin rpy="0 0 0" xyz="0 0 -0.37"/>
      <geometry>
        <mesh filename="package://fanuc_crx_description/meshes/crx30ia/visual/j1.dae"/>
      </geometry>
    </visual>
    <collision>
      <origin rpy="0 0 0" xyz="0 0 0"/>
      <geometry>
        <mesh filename="package://fanuc_crx_description/meshes/crx30ia/collision/j1.stl" scale="0.001 0.001 0.001"/>
      </geometry>
    </collision>
    <inertial>
      <mass value="41.083"/>
      <origin xyz="0.00035 -0.06889 -0.05678"/>
      <inertia ixx="0.82048807" ixy="-0.017541919" ixz="0.007165887" iyy="0.517715904" iyz="-0.164727565" izz="0.604395877"/>
    </inertial>
  </link>
  <link name="J2_link">
    <visual>
      <origin rpy="0 0 0" xyz="-0.0 0 -0.37"/>
      <geometry>
        <mesh filename="package://fanuc_crx_description/meshes/crx30ia/visual/j2.dae"/>
      </geometry>
    </visual>
    <collision>
      <origin rpy="0 0 0" xyz="0 0 0"/>
      <geometry>
        <mesh filename="package://fanuc_crx_description/meshes/crx30ia/collision/j2.stl" scale="0.001 0.001 0.001"/>
      </geometry>
    </collision>
    <inertial>
      <mass value="41.783"/>
      <origin xyz="-0.00009 -0.27645 0.42608"/>
      <inertia ixx="7.230469225" ixy="-1.50504E-05" ixz="-0.001548667" iyy="7.188756572" iyz="0.346298742" izz="0.310511653"/>
    </inertial>
  </link>
  <link name="J3_link">
    <visual>
      <origin rpy="0 0 0" xyz="-0.0 0 -1.3199999999999998"/>
      <geometry>
        <mesh filename="package://fanuc_crx_description/meshes/crx30ia/visual/j3.dae"/>
      </geometry>
    </visual>
    <collision>
      <origin rpy="0 0 0" xyz="0 0 0"/>
      <geometry>
        <mesh filename="package://fanuc_crx_description/meshes/crx30ia/collision/j3.stl" scale="0.001 0.001 0.001"/>
      </geometry>
    </collision>
    <inertial>
      <mass value="11.493"/>
      <origin xyz="0.04858 -0.05541 -0.00002"/>
      <inertia ixx="0.07644438" ixy="0.032033116" ixz="-0.000109013" iyy="0.088680582" iyz="0.00008535" izz="0.113440904"/>
    </inertial>
  </link>
  <link name="J4_link">
    <visual>
      <origin rpy="0 0 0" xyz="-0.0 0 -1.3199999999999998"/>
      <geometry>
        <mesh filename="package://fanuc_crx_description/meshes/crx30ia/visual/j4.dae"/>
      </geometry>
    </visual>
    <collision>
      <origin rpy="0 0 0" xyz="0 0 0"/>
      <geometry>
        <mesh filename="package://fanuc_crx_description/meshes/crx30ia/collision/j4.stl" scale="0.001 0.001 0.001"/>
      </geometry>
    </collision>
    <inertial>
      <mass value="10.453"/>
      <origin xyz="0.47486 -0.01068 0.00284"/>
      <inertia ixx="0.033221786" ixy="-0.031400677" ixz="-0.006788255" iyy="0.585886882" iyz="0.000138711" izz="0.591926466"/>
    </inertial>
  </link>
  <link name="J5_link">
    <visual>
      <origin rpy="0 0 0" xyz="-0.75 0 -1.3199999999999998"/>
      <geometry>
        <mesh filename="package://fanuc_crx_description/meshes/crx30ia/visual/j5.dae"/>
      </geometry>
    </visual>
    <collision>
      <origin rpy="0 0 0" xyz="0 -0.185 0"/>
      <geometry>
        <mesh filename="package://fanuc_crx_description/meshes/crx30ia/collision/j5.stl" scale="0.001 0.001 0.001"/>
      </geometry>
    </collision>
    <inertial>
      <mass value="4.247"/>
      <origin xyz="0.02013 -0.1566 0.00022"/>
      <inertia ixx="0.014928224" ixy="-0.002745126" ixz="-6.53103E-05" iyy="0.013565914" iyz="-8.66351E-05" izz="0.020297868"/>
    </inertial>
  </link>
  <link name="J6_link">
    <visual>
      <origin rpy="0 0 0" xyz="-0.75 0.185 -1.3199999999999998"/>
      <geometry>
        <mesh filename="package://fanuc_crx_description/meshes/crx30ia/visual/j6.dae"/>
      </geometry>
    </visual>
    <collision>
      <origin rpy="0 0 0" xyz="0.18 0 0"/>
      <geometry>
        <mesh filename="package://fanuc_crx_description/meshes/crx30ia/collision/j6.stl" scale="0.001 0.001 0.001"/>
      </geometry>
    </collision>
    <inertial>
      <mass value="2.075"/>
      <origin xyz="0.13104 0.00101 -0.00108"/>
      <inertia ixx="0.003415927" ixy="0.000027248" ixz="-3.22498E-05" iyy="0.003012322" iyz="-5.72683E-05" izz="0.003057703"/>
    </inertial>
  </link>
  <!-- joints -->
  <joint name="J1" type="revolute">
    <origin rpy="0 0 0" xyz="0 0 0.37"/>
    <parent link="base_link"/>
    <child link="J1_link"/>
    <axis xyz="0 0 1"/>
    <limit effort="1500" lower="-3.139847324337799" upper="3.139847324337799" velocity="1.3962634015954636"/>
  </joint>
  <joint name="J2" type="revolute">
    <origin rpy="0 0 0" xyz="0.0 0 0"/>
    <parent link="J1_link"/>
    <child link="J2_link"/>
    <axis xyz="0 1 0"/>
    <limit effort="1500" lower="-3.139847324337799" upper="3.139847324337799" velocity="1.3962634015954636"/>
  </joint>
  <joint name="J3" type="revolute">
    <origin rpy="0 0 0" xyz="0 0 0.95"/>
    <parent link="J2_link"/>
    <child link="J3_link"/>
    <axis xyz="0 -1 0"/>
    <limit effort="700" lower="-4.71238898038469" upper="4.71238898038469" velocity="2.0943951023931953"/>
  </joint>
  <joint name="J4" type="revolute">
    <origin rpy="0 0 0" xyz="0 0 0.0"/>
    <parent link="J3_link"/>
    <child link="J4_link"/>
    <axis xyz="-1 0 0"/>
    <limit effort="150" lower="-3.3161255787892263" upper="3.3161255787892263" velocity="3.141592653589793"/>
  </joint>
  <joint name="J5" type="revolute">
    <origin rpy="0 0 0" xyz="0.75 0 0"/>
    <parent link="J4_link"/>
    <child link="J5_link"/>
    <axis xyz="0 -1 0"/>
    <limit effort="150" lower="-3.139847324337799" upper="3.139847324337799" velocity="3.141592653589793"/>
  </joint>
  <joint name="J6" type="revolute">
    <origin rpy="0 0 0" xyz="0 -0.185 0"/>
    <parent link="J5_link"/>
    <child link="J6_link"/>
    <axis xyz="-1 0 0"/>
    <limit effort="120" lower="-3.9269908169872414" upper="3.9269908169872414" velocity="3.141592653589793"/>
  </joint>
  <!-- fanuc world coords -->
  <link name="wbase"/>
  <joint name="base_link-wbase" type="fixed">
    <origin rpy="0 0 0" xyz="0 0 0.37"/>
    <parent link="base_link"/>
    <child link="wbase"/>
  </joint>
  <!-- flange coords -->
  <link name="flange"/>
  <joint name="J6-flange" type="fixed">
    <origin rpy="0 0 0" xyz="0.18 0 0"/>
    <parent link="J6_link"/>
    <child link="flange"/>
  </joint>
  <!-- FANUC flange coords -->
  <link name="fanuc_flange"/>
  <joint name="flange-fanuc_flange" type="fixed">
    <origin rpy="3.141592653589793 -1.5707963267948966 0.0" xyz="0 0 0"/>
    <parent link="flange"/>
    <child link="fanuc_flange"/>
  </joint>
  <!-- Attach to parent -->
  <joint name="base_joint" type="fixed">
    <origin rpy="0 0 0" xyz="0 0 .75"/>
    <parent link="world"/>
    <child link="base_link"/>
  </joint>
  <!-- Attach child -->
  <joint name="child_joint" type="fixed">
    <origin rpy="0 0 0" xyz="0 0 0"/>
    <parent link="flange"/>
    <child link="ee_link"/>
  </joint>
</robot>

