<?xml version="1.0" ?>
<!-- =================================================================================== -->
<!-- |    This document was autogenerated by xacro from /ws/fanuc_r2000_description/robot/r2000ic_165f.urdf.xacro | -->
<!-- |    EDITING THIS FILE BY HAND IS NOT RECOMMENDED                                 | -->
<!-- =================================================================================== -->
<robot name="r2000ic_165f">
  <link name="world"/>
  <link name="ee_link"/>
  <!-- links -->
  <link name="base_link">
    <visual>
      <origin rpy="0 0 0" xyz="0 0 0"/>
      <geometry>
        <mesh filename="package://fanuc_r2000_description/meshes/r2000ic_165f/visual/base.dae"/>
      </geometry>
    </visual>
    <collision>
      <origin rpy="0 0 0" xyz="0 0 0"/>
      <geometry>
        <mesh filename="package://fanuc_r2000_description/meshes/r2000ic_165f/collision/base.stl"/>
      </geometry>
    </collision>
    <inertial>
      <mass value=" 201"/>
      <origin xyz="-.104 -.00417  .135"/>
      <inertia ixx=" 6.34" ixy=" .076" ixz="-.138" iyy=" 12.3" iyz=" .00678" izz=" 15.7"/>
    </inertial>
  </link>
  <link name="J1_link">
    <visual>
      <origin rpy="0 0 0" xyz="0 0 0"/>
      <geometry>
        <mesh filename="package://fanuc_r2000_description/meshes/r2000ic_165f/visual/j1.dae"/>
      </geometry>
    </visual>
    <collision>
      <origin rpy="0 0 0" xyz="0 0 0"/>
      <geometry>
        <mesh filename="package://fanuc_r2000_description/meshes/r2000ic_165f/collision/j1.stl"/>
      </geometry>
    </collision>
    <inertial>
      <mass value=" 381"/>
      <origin xyz=" .0206  .0683 -.123"/>
      <inertia ixx=" 19.7" ixy=" 3.79" ixz="-1.49" iyy=" 27.5" iyz="-.516" izz=" 32.1"/>
    </inertial>
  </link>
  <link name="J2_link">
    <visual>
      <origin rpy="0 0 0" xyz="0 0 0"/>
      <geometry>
        <mesh filename="package://fanuc_r2000_description/meshes/r2000ic_165f/visual/j2.dae"/>
      </geometry>
    </visual>
    <collision>
      <origin rpy="0 0 0" xyz="0 0 0"/>
      <geometry>
        <mesh filename="package://fanuc_r2000_description/meshes/r2000ic_165f/collision/j2.stl"/>
      </geometry>
    </collision>
    <inertial>
      <mass value=" 211"/>
      <origin xyz="-.00183  .229  .441"/>
      <inertia ixx=" 27.6" ixy=" .107" ixz="-.763" iyy=" 28.4" iyz="-2.1" izz=" 4.04"/>
    </inertial>
  </link>
  <link name="J3_link">
    <visual>
      <origin rpy="0 0 0" xyz="0 0 0"/>
      <geometry>
        <mesh filename="package://fanuc_r2000_description/meshes/r2000ic_165f/visual/j3.dae"/>
      </geometry>
    </visual>
    <collision>
      <origin rpy="0 0 0" xyz="0 0 0"/>
      <geometry>
        <mesh filename="package://fanuc_r2000_description/meshes/r2000ic_165f/collision/j3.stl"/>
      </geometry>
    </collision>
    <inertial>
      <mass value=" 267"/>
      <origin xyz=" .324  .055  .127"/>
      <inertia ixx=" 8.35" ixy=" 1.22" ixz="-3.34" iyy=" 26" iyz=" .436" izz=" 26.4"/>
    </inertial>
  </link>
  <link name="J4_link">
    <visual>
      <origin rpy="0 0 0" xyz="0 0 0"/>
      <geometry>
        <mesh filename="package://fanuc_r2000_description/meshes/r2000ic_165f/visual/j4.dae"/>
      </geometry>
    </visual>
    <collision>
      <origin rpy="0 0 0" xyz="0 0 0"/>
      <geometry>
        <mesh filename="package://fanuc_r2000_description/meshes/r2000ic_165f/collision/j4.stl"/>
      </geometry>
    </collision>
    <inertial>
      <mass value=" 10.5"/>
      <origin xyz=" 1.18 -.00867 -.00000000998"/>
      <inertia ixx=" .0412" ixy=" .00554" ixz="-.00000000792" iyy=" .0947" iyz="-.000000000631" izz=" .0925"/>
    </inertial>
  </link>
  <link name="J5_link">
    <visual>
      <origin rpy="0 0 0" xyz="0 0 0"/>
      <geometry>
        <mesh filename="package://fanuc_r2000_description/meshes/r2000ic_165f/visual/j5.dae"/>
      </geometry>
    </visual>
    <collision>
      <origin rpy="0 0 0" xyz="0 0 0"/>
      <geometry>
        <mesh filename="package://fanuc_r2000_description/meshes/r2000ic_165f/collision/j5.stl"/>
      </geometry>
    </collision>
    <inertial>
      <mass value=" 19.1"/>
      <origin xyz=" .0485 -.0214  .00000000178"/>
      <inertia ixx=" .142" ixy="-.0218" ixz=" .000000000614" iyy=" .169" iyz=" .00000000896" izz=" .209"/>
    </inertial>
  </link>
  <link name="J6_link">
    <visual>
      <origin rpy="0 0 0" xyz="0 0 0"/>
      <geometry>
        <mesh filename="package://fanuc_r2000_description/meshes/r2000ic_165f/visual/j6.dae"/>
      </geometry>
    </visual>
    <collision>
      <origin rpy="0 0 0" xyz="0 0 0"/>
      <geometry>
        <mesh filename="package://fanuc_r2000_description/meshes/r2000ic_165f/collision/j6.stl"/>
      </geometry>
    </collision>
    <inertial>
      <mass value=" .982"/>
      <origin xyz=" .198  .000000000699  .0000957"/>
      <inertia ixx=" .00275" ixy="-.00000000000492" ixz="-.000000701" iyy=" .00148" iyz=" .0000000000636" izz=" .00148"/>
    </inertial>
  </link>
  <!-- joints -->
  <joint name="J1" type="revolute">
    <origin rpy="0 0 0" xyz=" 0  0  .67"/>
    <parent link="base_link"/>
    <child link="J1_link"/>
    <axis xyz=" 0  0  1"/>
    <limit effort="10000" lower="-3.2288591161895095" upper="3.2288591161895095" velocity="2.2689280275926285"/>
  </joint>
  <joint name="J2" type="revolute">
    <origin rpy="0 0 0" xyz=" .312  0  0"/>
    <parent link="J1_link"/>
    <child link="J2_link"/>
    <axis xyz=" 0  1  0"/>
    <limit effort="20000" lower="-1.0471975511965976" upper="1.3264502315156905" velocity="2.007128639793479"/>
  </joint>
  <joint name="J3" type="revolute">
    <origin rpy="0 0 0" xyz=" 0  0  1.075"/>
    <parent link="J2_link"/>
    <child link="J3_link"/>
    <axis xyz=" 0 -1  0"/>
    <limit effort="20000" lower="-1.3788101090755203" upper="3.141592653589793" velocity="2.181661564992912"/>
  </joint>
  <joint name="J4" type="revolute">
    <origin rpy="0 0 0" xyz=" 0  0  .225"/>
    <parent link="J3_link"/>
    <child link="J4_link"/>
    <axis xyz="-1  0  0"/>
    <limit effort="4000" lower="-6.283185307179586" upper="6.283185307179586" velocity="3.141592653589793"/>
  </joint>
  <joint name="J5" type="revolute">
    <origin rpy="0 0 0" xyz=" 1.28  0  0"/>
    <parent link="J4_link"/>
    <child link="J5_link"/>
    <axis xyz=" 0 -1  0"/>
    <limit effort="4000" lower="-2.181661564992912" upper="2.181661564992912" velocity="3.141592653589793"/>
  </joint>
  <joint name="J6" type="revolute">
    <origin rpy="0 0 0" xyz=" 0  0  0"/>
    <parent link="J5_link"/>
    <child link="J6_link"/>
    <axis xyz="-1  0  0"/>
    <limit effort="3000" lower="-6.283185307179586" upper="6.283185307179586" velocity="4.537856055185257"/>
  </joint>
  <!-- world coords -->
  <link name="wbase"/>
  <joint name="base_link-wbase" type="fixed">
    <origin rpy="0 0 0" xyz=" 0  0  .67"/>
    <parent link="base_link"/>
    <child link="wbase"/>
  </joint>
  <!-- flange coords -->
  <link name="flange"/>
  <joint name="J6-flange" type="fixed">
    <origin rpy="0 0 0" xyz=" .215  0  0"/>
    <parent link="J6_link"/>
    <child link="flange"/>
  </joint>
  <!-- FANUC flange coords -->
  <link name="fanuc_flange"/>
  <joint name="flange-fanuc_flange" type="fixed">
    <origin rpy="3.141592653589793 -1.5707963267948966 0.0" xyz="0 0 0"/>
    <parent link="flange"/>
    <child link="fanuc_flange"/>
  </joint>
  <!-- Attach to parent -->
  <joint name="base_joint" type="fixed">
    <origin rpy="0 0 0" xyz="0 0 0"/>
    <parent link="world"/>
    <child link="base_link"/>
  </joint>
  <!-- Attach child -->
  <joint name="child_joint" type="fixed">
    <origin rpy="0 0 0" xyz="0 0 0"/>
    <parent link="flange"/>
    <child link="ee_link"/>
  </joint>
</robot>

