<?xml version="1.0" ?>
<!-- =================================================================================== -->
<!-- |    This document was autogenerated by xacro from /repos/fanuc_description/fanuc_lrmate_description/robot/lrmate200id7we.urdf.xacro | -->
<!-- |    EDITING THIS FILE BY HAND IS NOT RECOMMENDED                                 | -->
<!-- =================================================================================== -->
<robot name="lrmate200id7we">
  <link name="world"/>
  <link name="ee_link"/>
  <!-- links -->
  <link name="base_link">
    <visual>
      <origin rpy="0 0 0" xyz="0 0 0"/>
      <geometry>
        <mesh filename="package://fanuc_lrmate_description/meshes/lrmate200id7we/visual/base.dae"/>
      </geometry>
    </visual>
    <collision>
      <origin rpy="0 0 0" xyz="0 0 0"/>
      <geometry>
        <mesh filename="package://fanuc_lrmate_description/meshes/lrmate200id7we/collision/base.stl"/>
      </geometry>
    </collision>
    <inertial>
      <mass value=" 5.89"/>
      <origin xyz="-.019 -.000897  .0796"/>
      <inertia ixx=" .0275" ixy="-.000994" ixz=" .000302" iyy=" .0361" iyz="-.00012" izz=" .0379"/>
    </inertial>
  </link>
  <link name="J1_link">
    <visual>
      <origin rpy="0 0 0" xyz="0 0 0"/>
      <geometry>
        <mesh filename="package://fanuc_lrmate_description/meshes/lrmate200id7we/visual/j1.dae"/>
      </geometry>
    </visual>
    <collision>
      <origin rpy="0 0 0" xyz="0 0 0"/>
      <geometry>
        <mesh filename="package://fanuc_lrmate_description/meshes/lrmate200id7we/collision/j1.stl"/>
      </geometry>
    </collision>
    <inertial>
      <mass value=" 6.03"/>
      <origin xyz=" .0287  .000102 -.0547"/>
      <inertia ixx=" .0447" ixy=" .0000255" ixz="-.00591" iyy=" .0325" iyz=" .00013" izz=" .0345"/>
    </inertial>
  </link>
  <link name="J2_link">
    <visual>
      <origin rpy="0 0 0" xyz="0 0 0"/>
      <geometry>
        <mesh filename="package://fanuc_lrmate_description/meshes/lrmate200id7we/visual/j2.dae"/>
      </geometry>
    </visual>
    <collision>
      <origin rpy="0 0 0" xyz="0 0 0"/>
      <geometry>
        <mesh filename="package://fanuc_lrmate_description/meshes/lrmate200id7we/collision/j2.stl"/>
      </geometry>
    </collision>
    <inertial>
      <mass value=" 9.69"/>
      <origin xyz="-.00271 -.000976  .159"/>
      <inertia ixx=" .17" ixy=" .0000359" ixz=" .000165" iyy=" .146" iyz="-.00116" izz=" .0459"/>
    </inertial>
  </link>
  <link name="J3_link">
    <visual>
      <origin rpy="0 0 0" xyz="0 0 0"/>
      <geometry>
        <mesh filename="package://fanuc_lrmate_description/meshes/lrmate200id7we/visual/j3.dae"/>
      </geometry>
    </visual>
    <collision>
      <origin rpy="0 0 0" xyz="0 0 0"/>
      <geometry>
        <mesh filename="package://fanuc_lrmate_description/meshes/lrmate200id7we/collision/j3.stl"/>
      </geometry>
    </collision>
    <inertial>
      <mass value=" 2.31"/>
      <origin xyz=" .00887 -.0000626  .0171"/>
      <inertia ixx=" .00626" ixy="-.0000492" ixz="-.000666" iyy=" .00713" iyz="-.0000493" izz=" .00717"/>
    </inertial>
  </link>
  <link name="J4_link">
    <visual>
      <origin rpy="0 0 0" xyz="0 0 0"/>
      <geometry>
        <mesh filename="package://fanuc_lrmate_description/meshes/lrmate200id7we/visual/j4.dae"/>
      </geometry>
    </visual>
    <collision>
      <origin rpy="0 0 0" xyz="0 0 0"/>
      <geometry>
        <mesh filename="package://fanuc_lrmate_description/meshes/lrmate200id7we/collision/j4.stl"/>
      </geometry>
    </collision>
    <inertial>
      <mass value=" 2.59"/>
      <origin xyz=" .223  .00356  .00215"/>
      <inertia ixx=" .00423" ixy=" .000000279" ixz=" .0000776" iyy=" .0183" iyz="-.0000101" izz=" .0183"/>
    </inertial>
  </link>
  <link name="J5_link">
    <visual>
      <origin rpy="0 0 0" xyz="0 0 0"/>
      <geometry>
        <mesh filename="package://fanuc_lrmate_description/meshes/lrmate200id7we/visual/j5.dae"/>
      </geometry>
    </visual>
    <collision>
      <origin rpy="0 0 0" xyz="0 0 0"/>
      <geometry>
        <mesh filename="package://fanuc_lrmate_description/meshes/lrmate200id7we/collision/j5.stl"/>
      </geometry>
    </collision>
    <inertial>
      <mass value=" .477"/>
      <origin xyz=" .0177  .0025 -.00000419"/>
      <inertia ixx=" .000363" ixy=" .00002" ixz="-.0000000224" iyy=" .000644" iyz="-.0000000184" izz=" .000603"/>
    </inertial>
  </link>
  <link name="J6_link">
    <visual>
      <origin rpy="0 0 0" xyz="0 0 0"/>
      <geometry>
        <mesh filename="package://fanuc_lrmate_description/meshes/lrmate200id7we/visual/j6.dae"/>
      </geometry>
    </visual>
    <collision>
      <origin rpy="0 0 0" xyz="0 0 0"/>
      <geometry>
        <mesh filename="package://fanuc_lrmate_description/meshes/lrmate200id7we/collision/j6.stl"/>
      </geometry>
    </collision>
    <inertial>
      <mass value=" .0144"/>
      <origin xyz=" .074  2.26E-18  3.35E-18"/>
      <inertia ixx=" .00000295" ixy=" 5.39E-21" ixz=" 2.91E-21" iyy=" .00000164" iyz="-1.17E-22" izz=" .00000164"/>
    </inertial>
  </link>
  <!-- joints -->
  <joint name="J1" type="revolute">
    <origin rpy="0 0 0" xyz=" 0  0  .33"/>
    <parent link="base_link"/>
    <child link="J1_link"/>
    <axis xyz=" 0  0  1"/>
    <limit effort="500" lower="-3.141592653589793" upper="3.141592653589793" velocity="7.853981633974483"/>
  </joint>
  <joint name="J2" type="revolute">
    <origin rpy="0 0 0" xyz=" .05  0  0"/>
    <parent link="J1_link"/>
    <child link="J2_link"/>
    <axis xyz=" 0  1  0"/>
    <limit effort="500" lower="-1.7453292519943295" upper="2.530727415391778" velocity="6.632251157578453"/>
  </joint>
  <joint name="J3" type="revolute">
    <origin rpy="0 0 0" xyz=" 0  0  .33"/>
    <parent link="J2_link"/>
    <child link="J3_link"/>
    <axis xyz=" 0 -1  0"/>
    <limit effort="300" lower="-1.2217304763960306" upper="3.5779249665883754" velocity="7.155849933176751"/>
  </joint>
  <joint name="J4" type="revolute">
    <origin rpy="0 0 0" xyz=" 0  0  .035"/>
    <parent link="J3_link"/>
    <child link="J4_link"/>
    <axis xyz="-1  0  0"/>
    <limit effort="70" lower="-3.3161255787892263" upper="3.3161255787892263" velocity="9.599310885968812"/>
  </joint>
  <joint name="J5" type="revolute">
    <origin rpy="0 0 0" xyz=" .335  0  0"/>
    <parent link="J4_link"/>
    <child link="J5_link"/>
    <axis xyz=" 0 -1  0"/>
    <limit effort="40" lower="-2.181661564992912" upper="2.181661564992912" velocity="9.512044423369096"/>
  </joint>
  <joint name="J6" type="revolute">
    <origin rpy="0 0 0" xyz=" 0  0  0"/>
    <parent link="J5_link"/>
    <child link="J6_link"/>
    <axis xyz="-1  0  0"/>
    <limit effort="20" lower="-6.283185307179586" upper="6.283185307179586" velocity="17.453292519943297"/>
  </joint>
  <!-- world coords -->
  <link name="wbase"/>
  <joint name="base_link-wbase" type="fixed">
    <origin rpy="0 0 0" xyz=" 0  0  .33"/>
    <parent link="base_link"/>
    <child link="wbase"/>
  </joint>
  <!-- flange coords -->
  <link name="flange"/>
  <joint name="J6-flange" type="fixed">
    <origin rpy="0 0 0" xyz=" .08  0  0"/>
    <parent link="J6_link"/>
    <child link="flange"/>
  </joint>
  <!-- FANUC flange coords -->
  <link name="fanuc_flange"/>
  <joint name="flange-fanuc_flange" type="fixed">
    <origin rpy="3.141592653589793 -1.5707963267948966 0.0" xyz="0 0 0"/>
    <parent link="flange"/>
    <child link="fanuc_flange"/>
  </joint>
  <!-- Attach to parent -->
  <joint name="base_joint" type="fixed">
    <origin rpy="0 0 0" xyz="0 0 0"/>
    <parent link="world"/>
    <child link="base_link"/>
  </joint>
  <!-- Attach child -->
  <joint name="child_joint" type="fixed">
    <origin rpy="0 0 0" xyz="0 0 0"/>
    <parent link="flange"/>
    <child link="ee_link"/>
  </joint>
</robot>

