<?xml version="1.0" ?>
<!-- =================================================================================== -->
<!-- |    This document was autogenerated by xacro from /repos/fanuc_description/fanuc_r2000_description/robot/r2000ic_100p.urdf.xacro | -->
<!-- |    EDITING THIS FILE BY HAND IS NOT RECOMMENDED                                 | -->
<!-- =================================================================================== -->
<robot name="r2000ic_100p">
  <link name="world"/>
  <link name="ee_link"/>
  <!-- links -->
  <link name="base_link">
    <visual>
      <origin rpy="0 0 0" xyz="0 0 0"/>
      <geometry>
        <mesh filename="package://fanuc_r2000_description/meshes/r2000ic_100p/visual/base.dae"/>
      </geometry>
    </visual>
    <collision>
      <origin rpy="0 0 0" xyz="0 0 0"/>
      <geometry>
        <mesh filename="package://fanuc_r2000_description/meshes/r2000ic_100p/collision/base.stl"/>
      </geometry>
    </collision>
    <inertial>
      <mass value=" 199"/>
      <origin xyz="-.137 -.00182  .126"/>
      <inertia ixx=" 6.58" ixy=" .0315" ixz="-.107" iyy=" 14.3" iyz=" .00822" izz=" 18.6"/>
    </inertial>
  </link>
  <link name="J1_link">
    <visual>
      <origin rpy="0 0 0" xyz="0 0 0"/>
      <geometry>
        <mesh filename="package://fanuc_r2000_description/meshes/r2000ic_100p/visual/j1.dae"/>
      </geometry>
    </visual>
    <collision>
      <origin rpy="0 0 0" xyz="0 0 0"/>
      <geometry>
        <mesh filename="package://fanuc_r2000_description/meshes/r2000ic_100p/collision/j1.stl"/>
      </geometry>
    </collision>
    <inertial>
      <mass value=" 683"/>
      <origin xyz=" .197  .138 -.00888"/>
      <inertia ixx=" 49.3" ixy=" 6.38" ixz="-2.96" iyy=" 85.7" iyz="-4.33" izz=" 102"/>
    </inertial>
  </link>
  <link name="J2_link">
    <visual>
      <origin rpy="0 0 0" xyz="0 0 0"/>
      <geometry>
        <mesh filename="package://fanuc_r2000_description/meshes/r2000ic_100p/visual/j2.dae"/>
      </geometry>
    </visual>
    <collision>
      <origin rpy="0 0 0" xyz="0 0 0"/>
      <geometry>
        <mesh filename="package://fanuc_r2000_description/meshes/r2000ic_100p/collision/j2.stl"/>
      </geometry>
    </collision>
    <inertial>
      <mass value=" 219"/>
      <origin xyz=" .434  .246  .00114"/>
      <inertia ixx=" 4.55" ixy="-1.47" ixz=" .693" iyy=" 28.1" iyz="-.197" izz=" 27.7"/>
    </inertial>
  </link>
  <link name="J3_link">
    <visual>
      <origin rpy="0 0 0" xyz="0 0 0"/>
      <geometry>
        <mesh filename="package://fanuc_r2000_description/meshes/r2000ic_100p/visual/j3.dae"/>
      </geometry>
    </visual>
    <collision>
      <origin rpy="0 0 0" xyz="0 0 0"/>
      <geometry>
        <mesh filename="package://fanuc_r2000_description/meshes/r2000ic_100p/collision/j3.stl"/>
      </geometry>
    </collision>
    <inertial>
      <mass value=" 339"/>
      <origin xyz=" .131  .0531 -.479"/>
      <inertia ixx=" 61.4" ixy=" .584" ixz=" 5.47" iyy=" 60.8" iyz="-2.19" izz=" 10.4"/>
    </inertial>
  </link>
  <link name="J4_link">
    <visual>
      <origin rpy="0 0 0" xyz="0 0 0"/>
      <geometry>
        <mesh filename="package://fanuc_r2000_description/meshes/r2000ic_100p/visual/j4.dae"/>
      </geometry>
    </visual>
    <collision>
      <origin rpy="0 0 0" xyz="0 0 0"/>
      <geometry>
        <mesh filename="package://fanuc_r2000_description/meshes/r2000ic_100p/collision/j4.stl"/>
      </geometry>
    </collision>
    <inertial>
      <mass value=" 9.79"/>
      <origin xyz="-.0000000108 -.00867 -1.63"/>
      <inertia ixx=" .0859" ixy="-.000000000102" ixz=" .00000000756" iyy=" .088" iyz="-.00514" izz=" .0383"/>
    </inertial>
  </link>
  <link name="J5_link">
    <visual>
      <origin rpy="0 0 0" xyz="0 0 0"/>
      <geometry>
        <mesh filename="package://fanuc_r2000_description/meshes/r2000ic_100p/visual/j5.dae"/>
      </geometry>
    </visual>
    <collision>
      <origin rpy="0 0 0" xyz="0 0 0"/>
      <geometry>
        <mesh filename="package://fanuc_r2000_description/meshes/r2000ic_100p/collision/j5.stl"/>
      </geometry>
    </collision>
    <inertial>
      <mass value=" 19.8"/>
      <origin xyz="-.0000000343 -.0201 -.0606"/>
      <inertia ixx=" .234" ixy=" .0000000636" ixz="-.0000000507" iyy=" .197" iyz=" .0235" izz=" .15"/>
    </inertial>
  </link>
  <link name="J6_link">
    <visual>
      <origin rpy="0 0 0" xyz="0 0 0"/>
      <geometry>
        <mesh filename="package://fanuc_r2000_description/meshes/r2000ic_100p/visual/j6.dae"/>
      </geometry>
    </visual>
    <collision>
      <origin rpy="0 0 0" xyz="0 0 0"/>
      <geometry>
        <mesh filename="package://fanuc_r2000_description/meshes/r2000ic_100p/collision/j6.stl"/>
      </geometry>
    </collision>
    <inertial>
      <mass value=" 1.1"/>
      <origin xyz=" .000102 -.0000000235 -.224"/>
      <inertia ixx=" .0022" ixy="-.0000000242" ixz=" .000000153" iyy=" .00219" iyz=" .000000000266" izz=" .00421"/>
    </inertial>
  </link>
  <!-- joints -->
  <joint name="J1" type="revolute">
    <origin rpy="0 0 0" xyz=" 0  0  .6"/>
    <parent link="base_link"/>
    <child link="J1_link"/>
    <axis xyz=" 0  0  1"/>
    <limit effort="20000" lower="-3.2288591161895095" upper="3.2288591161895095" velocity="2.0943951023931953"/>
  </joint>
  <joint name="J2" type="revolute">
    <origin rpy="0 0 0" xyz=" .72  0  0"/>
    <parent link="J1_link"/>
    <child link="J2_link"/>
    <axis xyz=" 0  1  0"/>
    <limit effort="20000" lower="-2.0943951023931953" upper="1.3962634015954636" velocity="1.7453292519943295"/>
  </joint>
  <joint name="J3" type="revolute">
    <origin rpy="0 0 0" xyz=" 1.075  0  0"/>
    <parent link="J2_link"/>
    <child link="J3_link"/>
    <axis xyz=" 0 -1  0"/>
    <limit effort="20000" lower="-1.3788101090755203" upper="3.141592653589793" velocity="2.007128639793479"/>
  </joint>
  <joint name="J4" type="revolute">
    <origin rpy="0 0 0" xyz=" .225  0  0"/>
    <parent link="J3_link"/>
    <child link="J4_link"/>
    <axis xyz=" 0  0  1"/>
    <limit effort="5000" lower="-6.283185307179586" upper="6.283185307179586" velocity="2.443460952792061"/>
  </joint>
  <joint name="J5" type="revolute">
    <origin rpy="0 0 0" xyz=" 0  0 -1.73"/>
    <parent link="J4_link"/>
    <child link="J5_link"/>
    <axis xyz=" 0 -1  0"/>
    <limit effort="5000" lower="-2.181661564992912" upper="2.181661564992912" velocity="2.443460952792061"/>
  </joint>
  <joint name="J6" type="revolute">
    <origin rpy="0 0 0" xyz=" 0  0  0"/>
    <parent link="J5_link"/>
    <child link="J6_link"/>
    <axis xyz=" 0  0  1"/>
    <limit effort="3000" lower="-6.283185307179586" upper="6.283185307179586" velocity="3.6651914291880923"/>
  </joint>
  <!-- world coords -->
  <link name="wbase"/>
  <joint name="base_link-wbase" type="fixed">
    <origin rpy="0 0 0" xyz=" 0  0  .6"/>
    <parent link="base_link"/>
    <child link="wbase"/>
  </joint>
  <!-- flange coords -->
  <link name="flange"/>
  <joint name="J6-flange" type="fixed">
    <origin rpy="0 0 0" xyz=" 0  0 -.24"/>
    <parent link="J6_link"/>
    <child link="flange"/>
  </joint>
  <!-- FANUC flange coords -->
  <link name="fanuc_flange"/>
  <joint name="flange-fanuc_flange" type="fixed">
    <origin rpy="3.141592653589793 0.0 0.0" xyz="0 0 0"/>
    <parent link="flange"/>
    <child link="fanuc_flange"/>
  </joint>
  <!-- Attach to parent -->
  <joint name="base_joint" type="fixed">
    <origin rpy="0 0 0" xyz="0 0 0"/>
    <parent link="world"/>
    <child link="base_link"/>
  </joint>
  <!-- Attach child -->
  <joint name="child_joint" type="fixed">
    <origin rpy="0 0 0" xyz="0 0 0"/>
    <parent link="flange"/>
    <child link="ee_link"/>
  </joint>
</robot>

