<?xml version="1.0" ?>
<!-- =================================================================================== -->
<!-- |    This document was autogenerated by xacro from /repos/fanuc_description/fanuc_lrmate_description/robot/lrmate10-11a.urdf.xacro | -->
<!-- |    EDITING THIS FILE BY HAND IS NOT RECOMMENDED                                 | -->
<!-- =================================================================================== -->
<robot name="lrmate10-11a">
  <link name="world"/>
  <link name="ee_link"/>
  <!-- links -->
  <link name="base_link">
    <visual>
      <origin rpy="0 0 0" xyz="0 0 0"/>
      <geometry>
        <mesh filename="package://fanuc_lrmate_description/meshes/lrmate10-11a/visual/base.dae"/>
      </geometry>
    </visual>
    <collision>
      <origin rpy="0 0 0" xyz="0 0 0"/>
      <geometry>
        <mesh filename="package://fanuc_lrmate_description/meshes/lrmate10-11a/collision/base.stl"/>
      </geometry>
    </collision>
    <inertial>
      <mass value=" 8.31"/>
      <origin xyz="-.0229  .0000229  .0978"/>
      <inertia ixx=" .0534" ixy="-.0000114" ixz="-.00191" iyy=" .0716" iyz=" .000000707" izz=" .0713"/>
    </inertial>
  </link>
  <link name="J1_link">
    <visual>
      <origin rpy="0 0 0" xyz="0 0 0"/>
      <geometry>
        <mesh filename="package://fanuc_lrmate_description/meshes/lrmate10-11a/visual/j1.dae"/>
      </geometry>
    </visual>
    <collision>
      <origin rpy="0 0 0" xyz="0 0 0"/>
      <geometry>
        <mesh filename="package://fanuc_lrmate_description/meshes/lrmate10-11a/collision/j1.stl"/>
      </geometry>
    </collision>
    <inertial>
      <mass value=" 11.1"/>
      <origin xyz=" .0144  .000328 -.0617"/>
      <inertia ixx=" .131" ixy=" .000236" ixz="-.00678" iyy=" .0941" iyz=" .0000713" izz=" .0986"/>
    </inertial>
  </link>
  <link name="J2_link">
    <visual>
      <origin rpy="0 0 0" xyz="0 0 0"/>
      <geometry>
        <mesh filename="package://fanuc_lrmate_description/meshes/lrmate10-11a/visual/j2.dae"/>
      </geometry>
    </visual>
    <collision>
      <origin rpy="0 0 0" xyz="0 0 0"/>
      <geometry>
        <mesh filename="package://fanuc_lrmate_description/meshes/lrmate10-11a/collision/j2.stl"/>
      </geometry>
    </collision>
    <inertial>
      <mass value=" 19.6"/>
      <origin xyz="-.000213  .000368  .265"/>
      <inertia ixx=" .824" ixy=" .0000957" ixz=" .000158" iyy=" .776" iyz=" .000447" izz=" .122"/>
    </inertial>
  </link>
  <link name="J3_link">
    <visual>
      <origin rpy="0 0 0" xyz="0 0 0"/>
      <geometry>
        <mesh filename="package://fanuc_lrmate_description/meshes/lrmate10-11a/visual/j3.dae"/>
      </geometry>
    </visual>
    <collision>
      <origin rpy="0 0 0" xyz="0 0 0"/>
      <geometry>
        <mesh filename="package://fanuc_lrmate_description/meshes/lrmate10-11a/collision/j3.stl"/>
      </geometry>
    </collision>
    <inertial>
      <mass value=" 2.5"/>
      <origin xyz=" .00103  .00127  .00775"/>
      <inertia ixx=" .00715" ixy="-.0000906" ixz="-.000983" iyy=" .00978" iyz=" .000000123" izz=" .00942"/>
    </inertial>
  </link>
  <link name="J4_link">
    <visual>
      <origin rpy="0 0 0" xyz="0 0 0"/>
      <geometry>
        <mesh filename="package://fanuc_lrmate_description/meshes/lrmate10-11a/visual/j4.dae"/>
      </geometry>
    </visual>
    <collision>
      <origin rpy="0 0 0" xyz="0 0 0"/>
      <geometry>
        <mesh filename="package://fanuc_lrmate_description/meshes/lrmate10-11a/collision/j4.stl"/>
      </geometry>
    </collision>
    <inertial>
      <mass value=" 4.09"/>
      <origin xyz=" .332 -.0000617  .000894"/>
      <inertia ixx=" .00759" ixy="-.00000848" ixz=" .000045" iyy=" .0669" iyz=" .00000872" izz=" .0685"/>
    </inertial>
  </link>
  <link name="J5_link">
    <visual>
      <origin rpy="0 0 0" xyz="0 0 0"/>
      <geometry>
        <mesh filename="package://fanuc_lrmate_description/meshes/lrmate10-11a/visual/j5.dae"/>
      </geometry>
    </visual>
    <collision>
      <origin rpy="0 0 0" xyz="0 0 0"/>
      <geometry>
        <mesh filename="package://fanuc_lrmate_description/meshes/lrmate10-11a/collision/j5.stl"/>
      </geometry>
    </collision>
    <inertial>
      <mass value=" .4"/>
      <origin xyz=" .0184  .00109 -.00000438"/>
      <inertia ixx=" .000291" ixy=" .00000831" ixz="-.0000000209" iyy=" .000539" iyz="-.0000000136" izz=" .000495"/>
    </inertial>
  </link>
  <link name="J6_link">
    <visual>
      <origin rpy="0 0 0" xyz="0 0 0"/>
      <geometry>
        <mesh filename="package://fanuc_lrmate_description/meshes/lrmate10-11a/visual/j6.dae"/>
      </geometry>
    </visual>
    <collision>
      <origin rpy="0 0 0" xyz="0 0 0"/>
      <geometry>
        <mesh filename="package://fanuc_lrmate_description/meshes/lrmate10-11a/collision/j6.stl"/>
      </geometry>
    </collision>
    <inertial>
      <mass value=" .0126"/>
      <origin xyz=" .074  3.35E-18 -4.88E-19"/>
      <inertia ixx=" .00000258" ixy=" 6.66E-21" ixz="-3.99E-22" iyy=" .00000144" iyz="-9.86E-23" izz=" .00000144"/>
    </inertial>
  </link>
  <!-- joints -->
  <joint name="J1" type="revolute">
    <origin rpy="0 0 0" xyz=" 0  0  .4"/>
    <parent link="base_link"/>
    <child link="J1_link"/>
    <axis xyz=" 0  0  1"/>
    <limit effort="800" lower="-3.2288591161895095" upper="3.2288591161895095" velocity="5.235987755982989"/>
  </joint>
  <joint name="J2" type="revolute">
    <origin rpy="0 0 0" xyz=" .025  0  0"/>
    <parent link="J1_link"/>
    <child link="J2_link"/>
    <axis xyz=" 0  1  0"/>
    <limit effort="900" lower="-1.7453292519943295" upper="2.356194490192345" velocity="4.014257279586958"/>
  </joint>
  <joint name="J3" type="revolute">
    <origin rpy="0 0 0" xyz=" 0  0  .56"/>
    <parent link="J2_link"/>
    <child link="J3_link"/>
    <axis xyz=" 0 -1  0"/>
    <limit effort="300" lower="-1.2217304763960306" upper="3.6651914291880923" velocity="5.934119456780721"/>
  </joint>
  <joint name="J4" type="revolute">
    <origin rpy="0 0 0" xyz=" 0  0  .035"/>
    <parent link="J3_link"/>
    <child link="J4_link"/>
    <axis xyz="-1  0  0"/>
    <limit effort="70" lower="-3.3161255787892263" upper="3.3161255787892263" velocity="8.726646259971648"/>
  </joint>
  <joint name="J5" type="revolute">
    <origin rpy="0 0 0" xyz=" .515  0  0"/>
    <parent link="J4_link"/>
    <child link="J5_link"/>
    <axis xyz=" 0 -1  0"/>
    <limit effort="60" lower="-2.181661564992912" upper="2.181661564992912" velocity="6.981317007977318"/>
  </joint>
  <joint name="J6" type="revolute">
    <origin rpy="0 0 0" xyz=" 0  0  0"/>
    <parent link="J5_link"/>
    <child link="J6_link"/>
    <axis xyz="-1  0  0"/>
    <limit effort="30" lower="-6.283185307179586" upper="6.283185307179586" velocity="13.962634015954636"/>
  </joint>
  <!-- world coords -->
  <link name="wbase"/>
  <joint name="base_link-wbase" type="fixed">
    <origin rpy="0 0 0" xyz=" 0  0  .4"/>
    <parent link="base_link"/>
    <child link="wbase"/>
  </joint>
  <!-- flange coords -->
  <link name="flange"/>
  <joint name="J6-flange" type="fixed">
    <origin rpy="0 0 0" xyz=" .08  0  0"/>
    <parent link="J6_link"/>
    <child link="flange"/>
  </joint>
  <!-- FANUC flange coords -->
  <link name="fanuc_flange"/>
  <joint name="flange-fanuc_flange" type="fixed">
    <origin rpy="3.141592653589793 -1.5707963267948966 0.0" xyz="0 0 0"/>
    <parent link="flange"/>
    <child link="fanuc_flange"/>
  </joint>
  <!-- Attach to parent -->
  <joint name="base_joint" type="fixed">
    <origin rpy="0 0 0" xyz="0 0 0"/>
    <parent link="world"/>
    <child link="base_link"/>
  </joint>
  <!-- Attach child -->
  <joint name="child_joint" type="fixed">
    <origin rpy="0 0 0" xyz="0 0 0"/>
    <parent link="flange"/>
    <child link="ee_link"/>
  </joint>
</robot>

