<?xml version="1.0" ?>
<!-- =================================================================================== -->
<!-- |    This document was autogenerated by xacro from /repos/fanuc_description/fanuc_crx_description/robot/crx20ia_l.urdf.xacro | -->
<!-- |    EDITING THIS FILE BY HAND IS NOT RECOMMENDED                                 | -->
<!-- =================================================================================== -->
<robot name="crx20ia_l">
  <link name="world"/>
  <link name="ee_link"/>
  <!-- links -->
  <link name="base_link">
    <visual>
      <origin rpy="0 0 0" xyz="0 0 0"/>
      <geometry>
        <mesh filename="package://fanuc_crx_description/meshes/crx20ia_l/visual/base.dae"/>
      </geometry>
    </visual>
    <collision>
      <origin rpy="0 0 0" xyz="0 0 0"/>
      <geometry>
        <mesh filename="package://fanuc_crx_description/meshes/crx20ia_l/collision/base.stl" scale="0.001 0.001 0.001"/>
      </geometry>
    </collision>
    <inertial>
      <mass value="4.517"/>
      <origin xyz="-0.01099 0.00068 0.06387"/>
      <inertia ixx="0.012030117" ixy="-0.000225344" ixz="0.001122373" iyy="0.016142165" iyz="-0.000086473" izz="0.019880412"/>
    </inertial>
  </link>
  <link name="J1_link">
    <visual>
      <origin rpy="0 0 0" xyz="0 0 -0.245"/>
      <geometry>
        <mesh filename="package://fanuc_crx_description/meshes/crx20ia_l/visual/j1.dae"/>
      </geometry>
    </visual>
    <collision>
      <origin rpy="0 0 0" xyz="0 0 -0.11729999999999999"/>
      <geometry>
        <mesh filename="package://fanuc_crx_description/meshes/crx20ia_l/collision/j1.stl" scale="0.001 0.001 0.001"/>
      </geometry>
    </collision>
    <inertial>
      <mass value="10.673"/>
      <origin xyz="-0.00058 -0.04577 -0.03713"/>
      <inertia ixx="0.107483279" ixy="-0.003187604" ixz="0.001474912" iyy="0.066223333" iyz="-0.019080999" izz="0.07617368"/>
    </inertial>
  </link>
  <link name="J2_link">
    <visual>
      <origin rpy="0 0 0" xyz="-0.0 0 -0.245"/>
      <geometry>
        <mesh filename="package://fanuc_crx_description/meshes/crx20ia_l/visual/j2.dae"/>
      </geometry>
    </visual>
    <collision>
      <origin rpy="0 0 0" xyz="-0.0 0 0.0"/>
      <geometry>
        <mesh filename="package://fanuc_crx_description/meshes/crx20ia_l/collision/j2.stl" scale="0.001 0.001 0.001"/>
      </geometry>
    </collision>
    <inertial>
      <mass value="11.472"/>
      <origin xyz="-0.00005 -0.18506 0.33295"/>
      <inertia ixx="1.254548468" ixy="-0.000000339" ixz="-0.000116455" iyy="1.22471305" iyz="0.072788114" izz="0.062673661"/>
    </inertial>
  </link>
  <link name="J3_link">
    <visual>
      <origin rpy="0 0 0" xyz="-0.0 0 -0.955"/>
      <geometry>
        <mesh filename="package://fanuc_crx_description/meshes/crx20ia_l/visual/j3.dae"/>
      </geometry>
    </visual>
    <collision>
      <origin rpy="0 0 0" xyz="-0.0 0 0.0"/>
      <geometry>
        <mesh filename="package://fanuc_crx_description/meshes/crx20ia_l/collision/j3.stl" scale="0.001 0.001 0.001"/>
      </geometry>
    </collision>
    <inertial>
      <mass value="4.468"/>
      <origin xyz="0.04132 -0.00946 0.00009"/>
      <inertia ixx="0.009210179" ixy="0.001838899" ixz="-0.000014099" iyy="0.022283077" iyz="0.000009944" izz="0.0209147"/>
    </inertial>
  </link>
  <link name="J4_link">
    <visual>
      <origin rpy="0 0 0" xyz="-0.0 0 -0.955"/>
      <geometry>
        <mesh filename="package://fanuc_crx_description/meshes/crx20ia_l/visual/j4.dae"/>
      </geometry>
    </visual>
    <collision>
      <origin rpy="0 0 0" xyz="0.54 0 0.0"/>
      <geometry>
        <mesh filename="package://fanuc_crx_description/meshes/crx20ia_l/collision/j4.stl" scale="0.001 0.001 0.001"/>
      </geometry>
    </collision>
    <inertial>
      <mass value="4.305"/>
      <origin xyz="0.35657 -0.00147 -0.00012"/>
      <inertia ixx="0.005363404" ixy="-0.004474368" ixz="0.000038682" iyy="0.094418096" iyz="0.000001467" izz="0.095218701"/>
    </inertial>
  </link>
  <link name="J5_link">
    <visual>
      <origin rpy="0 0 0" xyz="-0.54 0 -0.955"/>
      <geometry>
        <mesh filename="package://fanuc_crx_description/meshes/crx20ia_l/visual/j5.dae"/>
      </geometry>
    </visual>
    <collision>
      <origin rpy="0 0 0" xyz="0.0 -0.15 0.0"/>
      <geometry>
        <mesh filename="package://fanuc_crx_description/meshes/crx20ia_l/collision/j5.stl" scale="0.001 0.001 0.001"/>
      </geometry>
    </collision>
    <inertial>
      <mass value="2.509"/>
      <origin xyz="0.0225 -0.11714 0.0013"/>
      <inertia ixx="0.006138756" ixy="-0.001800644" ixz="-0.000021155" iyy="0.004453218" iyz="-0.000288577" izz="0.00771992"/>
    </inertial>
  </link>
  <link name="J6_link">
    <visual>
      <origin rpy="0 0 0" xyz="-0.54 0.15 -0.955"/>
      <geometry>
        <mesh filename="package://fanuc_crx_description/meshes/crx20ia_l/visual/j6.dae"/>
      </geometry>
    </visual>
    <collision>
      <origin rpy="0 0 0" xyz="0.15999999999999992 0.0 0.0"/>
      <geometry>
        <mesh filename="package://fanuc_crx_description/meshes/crx20ia_l/collision/j6.stl" scale="0.001 0.001 0.001"/>
      </geometry>
    </collision>
    <inertial>
      <mass value="1.305"/>
      <origin xyz="0.11455 0.00041 0.0001"/>
      <inertia ixx="0.001477627" ixy="0.000009863" ixz="0.000000933" iyy="0.001399425" iyz="0.000000404" izz="0.001451937"/>
    </inertial>
  </link>
  <!-- joints -->
  <joint name="J1" type="revolute">
    <origin rpy="0 0 0" xyz="0 0 0.245"/>
    <parent link="base_link"/>
    <child link="J1_link"/>
    <axis xyz="0 0 1"/>
    <limit effort="750" lower="-3.139847324337799" upper="3.139847324337799" velocity="1.3962634015954636"/>
  </joint>
  <joint name="J2" type="revolute">
    <origin rpy="0 0 0" xyz="0.0 0 0"/>
    <parent link="J1_link"/>
    <child link="J2_link"/>
    <axis xyz="0 1 0"/>
    <limit effort="750" lower="-3.139847324337799" upper="3.139847324337799" velocity="1.3962634015954636"/>
  </joint>
  <joint name="J3" type="revolute">
    <origin rpy="0 0 0" xyz="0 0 0.71"/>
    <parent link="J2_link"/>
    <child link="J3_link"/>
    <axis xyz="0 -1 0"/>
    <limit effort="350" lower="-4.71238898038469" upper="4.71238898038469" velocity="2.0943951023931953"/>
  </joint>
  <joint name="J4" type="revolute">
    <origin rpy="0 0 0" xyz="0 0 0.0"/>
    <parent link="J3_link"/>
    <child link="J4_link"/>
    <axis xyz="-1 0 0"/>
    <limit effort="150" lower="-3.3161255787892263" upper="3.3161255787892263" velocity="1.9634954084936207"/>
  </joint>
  <joint name="J5" type="revolute">
    <origin rpy="0 0 0" xyz="0.54 0 0"/>
    <parent link="J4_link"/>
    <child link="J5_link"/>
    <axis xyz="0 -1 0"/>
    <limit effort="110" lower="-3.139847324337799" upper="3.139847324337799" velocity="1.5707963267948966"/>
  </joint>
  <joint name="J6" type="revolute">
    <origin rpy="0 0 0" xyz="0 -0.15 0"/>
    <parent link="J5_link"/>
    <child link="J6_link"/>
    <axis xyz="-1 0 0"/>
    <limit effort="110" lower="-3.9269908169872414" upper="3.9269908169872414" velocity="1.9634954084936207"/>
  </joint>
  <!-- world coords -->
  <link name="wbase"/>
  <joint name="base_link-wbase" type="fixed">
    <origin rpy="0 0 0" xyz="0 0 0.245"/>
    <parent link="base_link"/>
    <child link="wbase"/>
  </joint>
  <!-- flange coords -->
  <link name="flange"/>
  <joint name="J6-flange" type="fixed">
    <origin rpy="0 0 0" xyz="0.16 0 0"/>
    <parent link="J6_link"/>
    <child link="flange"/>
  </joint>
  <!-- FANUC flange coords -->
  <link name="fanuc_flange"/>
  <joint name="flange-fanuc_flange" type="fixed">
    <origin rpy="3.141592653589793 -1.5707963267948966 0.0" xyz="0 0 0"/>
    <parent link="flange"/>
    <child link="fanuc_flange"/>
  </joint>
  <!-- Attach to parent -->
  <joint name="base_joint" type="fixed">
    <origin rpy="0 0 0" xyz="0 0 .75"/>
    <parent link="world"/>
    <child link="base_link"/>
  </joint>
  <!-- Attach child -->
  <joint name="child_joint" type="fixed">
    <origin rpy="0 0 0" xyz="0 0 0"/>
    <parent link="flange"/>
    <child link="ee_link"/>
  </joint>
</robot>

