<?xml version="1.0" ?>
<!-- =================================================================================== -->
<!-- |    This document was autogenerated by xacro from /ws/fanuc_m710_description/robot/m710ic_50e.urdf.xacro | -->
<!-- |    EDITING THIS FILE BY HAND IS NOT RECOMMENDED                                 | -->
<!-- =================================================================================== -->
<robot name="m710ic_50e">
  <link name="world"/>
  <link name="ee_link"/>
  <!-- links -->
  <link name="base_link">
    <visual>
      <origin rpy="0 0 0" xyz="0 0 0"/>
      <geometry>
        <mesh filename="package://fanuc_m710_description/meshes/m710ic_50e/visual/base.dae"/>
      </geometry>
    </visual>
    <collision>
      <origin rpy="0 0 0" xyz="0 0 0"/>
      <geometry>
        <mesh filename="package://fanuc_m710_description/meshes/m710ic_50e/collision/base.stl"/>
      </geometry>
    </collision>
    <inertial>
      <mass value=" 131"/>
      <origin xyz="-.0493 -.000226  .119"/>
      <inertia ixx=" 3.47" ixy=" .00926" ixz=" .0525" iyy=" 3.55" iyz="-.00431" izz=" 5.65"/>
    </inertial>
  </link>
  <link name="J1_link">
    <visual>
      <origin rpy="0 0 0" xyz="0 0 0"/>
      <geometry>
        <mesh filename="package://fanuc_m710_description/meshes/m710ic_50e/visual/j1.dae"/>
      </geometry>
    </visual>
    <collision>
      <origin rpy="0 0 0" xyz="0 0 0"/>
      <geometry>
        <mesh filename="package://fanuc_m710_description/meshes/m710ic_50e/collision/j1.stl"/>
      </geometry>
    </collision>
    <inertial>
      <mass value=" 202"/>
      <origin xyz=" .0515 -.00696 -.105"/>
      <inertia ixx=" 7.56" ixy="-.336" ixz="-.511" iyy=" 6.45" iyz=" .22" izz=" 8.09"/>
    </inertial>
  </link>
  <link name="J2_link">
    <visual>
      <origin rpy="0 0 0" xyz="0 0 0"/>
      <geometry>
        <mesh filename="package://fanuc_m710_description/meshes/m710ic_50e/visual/j2.dae"/>
      </geometry>
    </visual>
    <collision>
      <origin rpy="0 0 0" xyz="0 0 0"/>
      <geometry>
        <mesh filename="package://fanuc_m710_description/meshes/m710ic_50e/collision/j2.stl"/>
      </geometry>
    </collision>
    <inertial>
      <mass value=" 91.5"/>
      <origin xyz=" .00284  .154  .344"/>
      <inertia ixx=" 7.91" ixy=" .023" ixz=" .00161" iyy=" 8.18" iyz="-.306" izz=" .76"/>
    </inertial>
  </link>
  <link name="J3_link">
    <visual>
      <origin rpy="0 0 0" xyz="0 0 0"/>
      <geometry>
        <mesh filename="package://fanuc_m710_description/meshes/m710ic_50e/visual/j3.dae"/>
      </geometry>
    </visual>
    <collision>
      <origin rpy="0 0 0" xyz="0 0 0"/>
      <geometry>
        <mesh filename="package://fanuc_m710_description/meshes/m710ic_50e/collision/j3.stl"/>
      </geometry>
    </collision>
    <inertial>
      <mass value=" 95.9"/>
      <origin xyz=" .0214 -.0311  .087"/>
      <inertia ixx=" 1.85" ixy="-.184" ixz="-.246" iyy=" 2.42" iyz="-.0984" izz=" 2.18"/>
    </inertial>
  </link>
  <link name="J4_link">
    <visual>
      <origin rpy="0 0 0" xyz="0 0 0"/>
      <geometry>
        <mesh filename="package://fanuc_m710_description/meshes/m710ic_50e/visual/j4.dae"/>
      </geometry>
    </visual>
    <collision>
      <origin rpy="0 0 0" xyz="0 0 0"/>
      <geometry>
        <mesh filename="package://fanuc_m710_description/meshes/m710ic_50e/collision/j4.stl"/>
      </geometry>
    </collision>
    <inertial>
      <mass value=" 34.4"/>
      <origin xyz=" .683 -.00000164  .0276"/>
      <inertia ixx=" .137" ixy="-.0000000153" ixz="-.128" iyy=" 1.76" iyz=" .00000748" izz=" 1.73"/>
    </inertial>
  </link>
  <link name="J5_link">
    <visual>
      <origin rpy="0 0 0" xyz="0 0 0"/>
      <geometry>
        <mesh filename="package://fanuc_m710_description/meshes/m710ic_50e/visual/j5.dae"/>
      </geometry>
    </visual>
    <collision>
      <origin rpy="0 0 0" xyz="0 0 0"/>
      <geometry>
        <mesh filename="package://fanuc_m710_description/meshes/m710ic_50e/collision/j5.stl"/>
      </geometry>
    </collision>
    <inertial>
      <mass value=" 4.76"/>
      <origin xyz=" .0608 -.000319  .156"/>
      <inertia ixx=" .00983" ixy="-.0000229" ixz="-.00129" iyy=" .0192" iyz="-.0000244" izz=" .0205"/>
    </inertial>
  </link>
  <link name="J6_link">
    <visual>
      <origin rpy="0 0 0" xyz="0 0 0"/>
      <geometry>
        <mesh filename="package://fanuc_m710_description/meshes/m710ic_50e/visual/j6.dae"/>
      </geometry>
    </visual>
    <collision>
      <origin rpy="0 0 0" xyz="0 0 0"/>
      <geometry>
        <mesh filename="package://fanuc_m710_description/meshes/m710ic_50e/collision/j6.stl"/>
      </geometry>
    </collision>
    <inertial>
      <mass value=" .37"/>
      <origin xyz=" .162  .00000000106 -4.91E-18"/>
      <inertia ixx=" .000702" ixy=" .0000000000017" ixz="-2.01E-19" iyy=" .000359" iyz="-2.84E-20" izz=" .000359"/>
    </inertial>
  </link>
  <!-- joints -->
  <joint name="J1" type="revolute">
    <origin rpy="0 0 0" xyz=" 0  0  .565"/>
    <parent link="base_link"/>
    <child link="J1_link"/>
    <axis xyz=" 0  0  1"/>
    <limit effort="5000" lower="-3.141592653589793" upper="3.141592653589793" velocity="3.0543261909900767"/>
  </joint>
  <joint name="J2" type="revolute">
    <origin rpy="0 0 0" xyz=" .15  0  0"/>
    <parent link="J1_link"/>
    <child link="J2_link"/>
    <axis xyz=" 0  1  0"/>
    <limit effort="7000" lower="-1.5707963267948966" upper="2.356194490192345" velocity="3.0543261909900767"/>
  </joint>
  <joint name="J3" type="revolute">
    <origin rpy="0 0 0" xyz=" 0  0  .87"/>
    <parent link="J2_link"/>
    <child link="J3_link"/>
    <axis xyz=" 0 -1  0"/>
    <limit effort="6000" lower="-1.4049900478554354" upper="3.5779249665883754" velocity="3.0543261909900767"/>
  </joint>
  <joint name="J4" type="revolute">
    <origin rpy="0 0 0" xyz=" 0  0  .17"/>
    <parent link="J3_link"/>
    <child link="J4_link"/>
    <axis xyz="-1  0  0"/>
    <limit effort="800" lower="-6.283185307179586" upper="6.283185307179586" velocity="4.363323129985824"/>
  </joint>
  <joint name="J5" type="revolute">
    <origin rpy="0 0 0" xyz=" 1.016  0  0"/>
    <parent link="J4_link"/>
    <child link="J5_link"/>
    <axis xyz=" 0  0  1"/>
    <limit effort="700" lower="-3.3161255787892263" upper="3.3161255787892263" velocity="4.1887902047863905"/>
  </joint>
  <joint name="J6" type="revolute">
    <origin rpy="0 0 0" xyz=" 0  0  .16"/>
    <parent link="J5_link"/>
    <child link="J6_link"/>
    <axis xyz="-1  0  0"/>
    <limit effort="400" lower="-6.283185307179586" upper="6.283185307179586" velocity="5.934119456780721"/>
  </joint>
  <!-- world coords -->
  <link name="wbase"/>
  <joint name="base_link-wbase" type="fixed">
    <origin rpy="0 0 0" xyz=" 0  0  .565"/>
    <parent link="base_link"/>
    <child link="wbase"/>
  </joint>
  <!-- flange coords -->
  <link name="flange"/>
  <joint name="J6-flange" type="fixed">
    <origin rpy="0 0 0" xyz=" .17  0  0"/>
    <parent link="J6_link"/>
    <child link="flange"/>
  </joint>
  <!-- FANUC flange coords -->
  <link name="fanuc_flange"/>
  <joint name="flange-fanuc_flange" type="fixed">
    <origin rpy="3.141592653589793 -1.5707963267948966 0.0" xyz="0 0 0"/>
    <parent link="flange"/>
    <child link="fanuc_flange"/>
  </joint>
  <!-- Attach to parent -->
  <joint name="base_joint" type="fixed">
    <origin rpy="0 0 0" xyz="0 0 0"/>
    <parent link="world"/>
    <child link="base_link"/>
  </joint>
  <!-- Attach child -->
  <joint name="child_joint" type="fixed">
    <origin rpy="0 0 0" xyz="0 0 0"/>
    <parent link="flange"/>
    <child link="ee_link"/>
  </joint>
</robot>

