<?xml version='1.0' encoding='utf-8'?>
<robot name="er4ia">
  <link name="world" />
  <link name="ee_link" />
  
  <link name="base_link">
    <visual>
      <origin rpy="0 0 0" xyz="0 0 0" />
      <geometry>
        <mesh filename="meshes/base.dae" />
      </geometry>
    </visual>
    <collision>
      <origin rpy="0 0 0" xyz="0 0 0" />
      <geometry>
        <mesh filename="meshes/base.stl" />
      </geometry>
    </collision>
    <inertial>
      <mass value=" 5.15" />
      <origin xyz="-.0281 .00396 .0799" />
      <inertia ixx=" .0219" ixy="-.00106" ixz="-.000067" iyy=" .0301" iyz=" .0000847" izz=" .0295" />
    </inertial>
  </link>
  <link name="J1_link">
    <visual>
      <origin rpy="0 0 0" xyz="0 0 0" />
      <geometry>
        <mesh filename="meshes/j1.dae" />
      </geometry>
    </visual>
    <collision>
      <origin rpy="0 0 0" xyz="0 0 0" />
      <geometry>
        <mesh filename="meshes/j1.stl" />
      </geometry>
    </collision>
    <inertial>
      <mass value=" 4.17" />
      <origin xyz=".00151 .000041 -.0578" />
      <inertia ixx=" .0252" ixy="-.00000663" ixz=" .000264" iyy=" .019" iyz=" .0000011" izz=" .0162" />
    </inertial>
  </link>
  <link name="J2_link">
    <visual>
      <origin rpy="0 0 0" xyz="0 0 0" />
      <geometry>
        <mesh filename="meshes/j2.dae" />
      </geometry>
    </visual>
    <collision>
      <origin rpy="0 0 0" xyz="0 0 0" />
      <geometry>
        <mesh filename="meshes/j2.stl" />
      </geometry>
    </collision>
    <inertial>
      <mass value=" 6.67" />
      <origin xyz="-.00721 -.000956 .13" />
      <inertia ixx=" .0769" ixy=" .0000572" ixz="-.000476" iyy=" .0672" iyz="-.000635" izz=" .0252" />
    </inertial>
  </link>
  <link name="J3_link">
    <visual>
      <origin rpy="0 0 0" xyz="0 0 0" />
      <geometry>
        <mesh filename="meshes/j3.dae" />
      </geometry>
    </visual>
    <collision>
      <origin rpy="0 0 0" xyz="0 0 0" />
      <geometry>
        <mesh filename="meshes/j3.stl" />
      </geometry>
    </collision>
    <inertial>
      <mass value=" 1.66" />
      <origin xyz="-.00781 -.00446 -.00000291" />
      <inertia ixx=" .00369" ixy=" .000000468" ixz="-.000423" iyy=" .00425" iyz="-.0000116" izz=" .00414" />
    </inertial>
  </link>
  <link name="J4_link">
    <visual>
      <origin rpy="0 0 0" xyz="0 0 0" />
      <geometry>
        <mesh filename="meshes/j4.dae" />
      </geometry>
    </visual>
    <collision>
      <origin rpy="0 0 0" xyz="0 0 0" />
      <geometry>
        <mesh filename="meshes/j4.stl" />
      </geometry>
    </collision>
    <inertial>
      <mass value=" 1.95" />
      <origin xyz=".187 .00165 .00184" />
      <inertia ixx=" .00266" ixy=" .00000358" ixz=" .0000703" iyy=" .0115" iyz="-.0000074" izz=" .0116" />
    </inertial>
  </link>
  <link name="J5_link">
    <visual>
      <origin rpy="0 0 0" xyz="0 0 0" />
      <geometry>
        <mesh filename="meshes/j5.dae" />
      </geometry>
    </visual>
    <collision>
      <origin rpy="0 0 0" xyz="0 0 0" />
      <geometry>
        <mesh filename="meshes/j5.stl" />
      </geometry>
    </collision>
    <inertial>
      <mass value=" .39" />
      <origin xyz=".0172 .000903 -.00000423" />
      <inertia ixx=" .000268" ixy=" .00000599" ixz="-.0000000104" iyy=" .000453" iyz="-.0000000172" izz=" .000425" />
    </inertial>
  </link>
  <link name="J6_link">
    <visual>
      <origin rpy="0 0 0" xyz="0 0 0" />
      <geometry>
        <mesh filename="meshes/j6.dae" />
      </geometry>
    </visual>
    <collision>
      <origin rpy="0 0 0" xyz="0 0 0" />
      <geometry>
        <mesh filename="meshes/j6.stl" />
      </geometry>
    </collision>
    <inertial>
      <mass value=" .0138" />
      <origin xyz=".069 5.91E-19 -2.85E-19" />
      <inertia ixx=" .00000274" ixy="-3.46E-21" ixz="-6.2E-23" iyy=" .00000153" iyz="-1.38E-23" izz=" .00000153" />
    </inertial>
  </link>
  
  <joint name="J1" type="revolute">
    <origin rpy="0 0 0" xyz="0 0 .33" />
    <parent link="base_link" />
    <child link="J1_link" />
    <axis xyz="0 0 1" />
    <limit effort="400" lower="-2.9670597283903604" upper="2.9670597283903604" velocity="8.028514559173916" />
  </joint>
  <joint name="J2" type="revolute">
    <origin rpy="0 0 0" xyz="0 0 0" />
    <parent link="J1_link" />
    <child link="J2_link" />
    <axis xyz="0 1 0" />
    <limit effort="300" lower="-1.9198621771937625" upper="2.0943951023931953" velocity="6.283185307179586" />
  </joint>
  <joint name="J3" type="revolute">
    <origin rpy="0 0 0" xyz="0 0 .26" />
    <parent link="J2_link" />
    <child link="J3_link" />
    <axis xyz="0 -1 0" />
    <limit effort="200" lower="-1.2042771838760873" upper="3.5779249665883754" velocity="9.075712110370514" />
  </joint>
  <joint name="J4" type="revolute">
    <origin rpy="0 0 0" xyz="0 0 .02" />
    <parent link="J3_link" />
    <child link="J4_link" />
    <axis xyz="-1 0 0" />
    <limit effort="50" lower="-3.3161255787892263" upper="3.3161255787892263" velocity="9.773843811168245" />
  </joint>
  <joint name="J5" type="revolute">
    <origin rpy="0 0 0" xyz=".29 0 0" />
    <parent link="J4_link" />
    <child link="J5_link" />
    <axis xyz="0 -1 0" />
    <limit effort="30" lower="-2.0943951023931953" upper="2.0943951023931953" velocity="9.773843811168245" />
  </joint>
  <joint name="J6" type="revolute">
    <origin rpy="0 0 0" xyz="0 0 0" />
    <parent link="J5_link" />
    <child link="J6_link" />
    <axis xyz="-1 0 0" />
    <limit effort="20" lower="-6.283185307179586" upper="6.283185307179586" velocity="15.707963267948966" />
  </joint>
  
  <link name="wbase" />
  <joint name="base_link-wbase" type="fixed">
    <origin rpy="0 0 0" xyz="0 0 .33" />
    <parent link="base_link" />
    <child link="wbase" />
  </joint>
  
  <link name="flange" />
  <joint name="J6-flange" type="fixed">
    <origin rpy="0 0 0" xyz=".07 0 0" />
    <parent link="J6_link" />
    <child link="flange" />
  </joint>
  
  <link name="fanuc_flange" />
  <joint name="flange-fanuc_flange" type="fixed">
    <origin rpy="3.141592653589793 -1.5707963267948966 0.0" xyz="0 0 0" />
    <parent link="flange" />
    <child link="fanuc_flange" />
  </joint>
  
  <joint name="base_joint" type="fixed">
    <origin rpy="0 0 0" xyz="0 0 0" />
    <parent link="world" />
    <child link="base_link" />
  </joint>
  
  <joint name="child_joint" type="fixed">
    <origin rpy="0 0 0" xyz="0 0 0" />
    <parent link="flange" />
    <child link="ee_link" />
  </joint>
</robot>