<?xml version='1.0' encoding='utf-8'?>
<robot name="talos">
  
  
  
  
  
  
  
  
  
  
  
  
  
  
  
  
  
  
  
  
  
  <link name="torso_2_link">
    <inertial>
      <origin rpy="0.00000 0.00000 0.00000" xyz="-0.04551 -0.00053 0.16386" />
      <mass value="17.55011" />
      <inertia ixx="0.37376900000" ixy="0.00063900000" ixz="0.01219600000" iyy="0.24790200000" iyz="0.00000700000" izz="0.28140400000" />
    </inertial>
    <visual>
      <origin rpy="0 0 0" xyz="0 0 0" />
      <geometry>
        <mesh filename="meshes/torso_2.STL" scale="1 1 1" />
      </geometry>
      <material name="LightGrey" />
    </visual>
    <collision>
      <origin rpy="0 0 0" xyz="0 0 0" />
      <geometry>
        <mesh filename="meshes/torso_2_collision.STL" scale="1 1 1" />
      </geometry>
    </collision>
  </link>
  
  
  
  <link name="torso_1_link">
    <inertial>
      <origin rpy="0.00000 0.00000 0.00000" xyz="0.00013 -0.00001 -0.01306" />
      <mass value="3.02433" />
      <inertia ixx="0.00759400000" ixy="0.00000100000" ixz="-0.00004800000" iyy="0.00429200000" iyz="-0.00000100000" izz="0.00749700000" />
    </inertial>
    <visual>
      <origin rpy="0 0 0" xyz="0 0 0" />
      <geometry>
        <mesh filename="meshes/torso_1.STL" scale="1 1 1" />
      </geometry>
      <material name="LightGrey" />
    </visual>
    <collision>
      <origin rpy="0 0 0" xyz="0 0 0" />
      <geometry>
        <mesh filename="meshes/torso_1.STL" scale="1 1 1" />
      </geometry>
    </collision>
  </link>
  <joint name="torso_1_joint" type="revolute">
    <parent link="base_link" />
    <child link="torso_1_link" />
    <origin rpy="0.0 0.0 0.0" xyz="0.0 0.0 0.0722" />
    <axis xyz="0 0 1" />
    <limit effort="78.0" lower="-1.308996939" upper="1.308996939" velocity="5.4" />
    <dynamics damping="1.0" friction="1.0" />
    
  </joint>
  
  
  
  <link name="base_link">
    <inertial>
      <origin rpy="0.00000 0.00000 0.00000" xyz="-0.08222 0.00838 -0.07261" />
      <mass value="13.53810" />
      <inertia ixx="0.06989000000" ixy="-0.00011700000" ixz="0.00023000000" iyy="0.03998200000" iyz="-0.00132500000" izz="0.08234500000" />
    </inertial>
    <visual>
      <origin rpy="0 0 0" xyz="0 0 0" />
      <geometry>
        <mesh filename="meshes/base_link.STL" scale="1 1 1" />
      </geometry>
      <material name="LightGrey" />
    </visual>
    <collision>
      <origin rpy="0 0 0" xyz="0 0 0" />
      <geometry>
        <mesh filename="meshes/base_link_collision.STL" scale="1 1 1" />
      </geometry>
    </collision>
  </link>
  <joint name="torso_2_joint" type="revolute">
    <parent link="torso_1_link" />
    <child link="torso_2_link" />
    <origin rpy="0.0 0.0 0.0" xyz="0.0 0.0 0.0" />
    <axis xyz="0 1 0" />
    <limit effort="78.0" lower="-0.261799387799" upper="0.785398163397" velocity="5.4" />
    <dynamics damping="1.0" friction="1.0" />
    
  </joint>
  <link name="imu_link">
    <inertial>
      <mass value="0.01" />
      <origin xyz="0 0 0" />
      <inertia ixx="0.000001" ixy="0" ixz="0" iyy="0.000001" iyz="0" izz="0.000001" />
    </inertial>
    <visual>
      <origin rpy="0 0 0" xyz="0 0 0" />
      <geometry>
        <box size="0.01 0.01 0.01" />
      </geometry>
    </visual>
  </link>
  <joint name="imu_joint" type="fixed">
    <origin rpy="3.14159265359 0 1.57079632679" xyz="0.04925 0 0.078" />
    <parent link="torso_2_link" />
    <child link="imu_link" />
  </joint>
  
  
  
  
  
  
  <transmission name="talos_torso_trans">
    <type>transmission_interface/DifferentialTransmission</type>
    <actuator name="torso_1_motor">
      <role>actuator1</role>
      <mechanicalReduction>1.0</mechanicalReduction>
    </actuator>
    <actuator name="torso_2_motor">
      <role>actuator2</role>
      <mechanicalReduction>1.0</mechanicalReduction>
    </actuator>
    <joint name="torso_1_joint">
      <role>joint1</role>
      <offset>0.0</offset>
      <mechanicalReduction>1.0</mechanicalReduction>
      <hardwareInterface>hardware_interface/PositionJointInterface</hardwareInterface>
      <hardwareInterface>hardware_interface/EffortJointInterface</hardwareInterface>
    </joint>
    <joint name="torso_2_joint">
      <role>joint2</role>
      <offset>0.0</offset>
      <mechanicalReduction>1.0</mechanicalReduction>
      <hardwareInterface>hardware_interface/PositionJointInterface</hardwareInterface>
      <hardwareInterface>hardware_interface/EffortJointInterface</hardwareInterface>
    </joint>
  </transmission>
  <link name="head_1_link">
    <inertial>
      <origin rpy="0.00000 0.00000 0.00000" xyz="0.00120 0.00145 0.02165" />
      <mass value="0.65988" />
      <inertia ixx="0.00122100000" ixy="-0.00000400000" ixz="0.00007000000" iyy="0.00092400000" iyz="-0.00004100000" izz="0.00103300000" />
    </inertial>
    <visual>
      <origin rpy="0 0 0" xyz="0 0 0" />
      <geometry>
        <mesh filename="meshes/head_1.stl" scale="1 1 1" />
      </geometry>
      <material name="DarkGrey" />
    </visual>
    <collision>
      <origin rpy="0 0 0" xyz="0 0 0" />
      <geometry>
        <mesh filename="meshes/head_1_collision.stl" scale="1 1 1" />
      </geometry>
    </collision>
  </link>
  <joint name="head_1_joint" type="revolute">
    <parent link="torso_2_link" />
    <child link="head_1_link" />
    <origin rpy="0.0 0.0 0.0" xyz="0.00000 0.00000 0.31600" />
    <axis xyz="0 1 0" />
    <limit effort="8.0" lower="-0.261799387799" upper="0.785398163397" velocity="1.0" />
    <dynamics damping="0.5" friction="1.0" />
    
  </joint>
  
  
  
  <link name="head_2_link">
    <inertial>
      <origin rpy="0.00000 0.00000 0.00000" xyz="-0.01036 -0.00037 0.13778" />
      <mass value="1.40353" />
      <inertia ixx="0.00722500000" ixy="-0.00002500000" ixz="0.00032900000" iyy="0.00687300000" iyz="0.00004400000" izz="0.00437300000" />
    </inertial>
    <visual>
      <origin rpy="0 0 0" xyz="0 0 0" />
      <geometry>
        <mesh filename="meshes/head_2.stl" scale="1 1 1" />
      </geometry>
      <material name="LightGrey" />
    </visual>
    <collision>
      <origin rpy="0 0 0" xyz="0 0 0" />
      <geometry>
        <mesh filename="meshes/head_2_collision.stl" scale="1 1 1" />
      </geometry>
    </collision>
  </link>
  <joint name="head_2_joint" type="revolute">
    <parent link="head_1_link" />
    <child link="head_2_link" />
    <origin rpy="0.0 0.0 0.0" xyz="0.00000 0.00000 0.00000" />
    <axis xyz="0 0 1" />
    <limit effort="4.0" lower="-1.308996939" upper="1.308996939" velocity="1.0" />
    <dynamics damping="0.5" friction="1.0" />
    
  </joint>
  
  
  
  
  <joint name="rgbd_joint" type="fixed">
    <origin rpy="0 0 0" xyz="0.066 0.0 0.1982" />
    <axis xyz="0 0 1" />
    
    <parent link="head_2_link" />
    <child link="rgbd_link" />
  </joint>
  <link name="rgbd_link">
    <inertial>
      <mass value="0.01" />
      <origin rpy="0 0 0" xyz="0 0 0" />
      
      <inertia ixx="0.000030" ixy="0.0" ixz="0.0" iyy="0.000030" iyz="0.0" izz="0.000002" />
    </inertial>
    <visual>
      <origin rpy="0 0 0" xyz="0 0 0" />
      <geometry>
        <mesh filename="meshes/orbbec.STL" />
      </geometry>
      <material name="DarkGrey">
        <color rgba="0.5 0.5 0.5 1" />
      </material>
    </visual>
    <collision>
      <origin rpy="0 0 0" xyz="-0.01 0.0025 0" />
      <geometry>
        <box size="0.04 0.185 0.03" />
      </geometry>
    </collision>
  </link>
  <joint name="rgbd_optical_joint" type="fixed">
    <origin rpy="-1.57079632679 0 -1.57079632679" xyz="0 0 0" />
    <parent link="rgbd_link" />
    <child link="rgbd_optical_frame" />
  </joint>
  <link name="rgbd_optical_frame">
    <inertial>
      <mass value="0.01" />
      <origin rpy="0 0 0" xyz="0 0 0" />
      <inertia ixx="0.0" ixy="0.0" ixz="0.0" iyy="0.0" iyz="0.0" izz="0.0" />
    </inertial>
  </link>
  
  <joint name="rgbd_depth_joint" type="fixed">
    <origin rpy="0 0 0" xyz="0.0 0.03751 0.0" />
    <parent link="rgbd_link" />
    <child link="rgbd_depth_frame" />
  </joint>
  <link name="rgbd_depth_frame" />
  <joint name="rgbd_depth_optical_joint" type="fixed">
    <origin rpy="-1.57079632679 0.0 -1.57079632679" xyz="0 0 0" />
    <parent link="rgbd_depth_frame" />
    <child link="rgbd_depth_optical_frame" />
  </joint>
  <link name="rgbd_depth_optical_frame" />
  
  <joint name="rgbd_rgb_joint" type="fixed">
    <origin rpy="0 0 0" xyz="0.0 0.01251 0.0" />
    <parent link="rgbd_link" />
    <child link="rgbd_rgb_frame" />
  </joint>
  <link name="rgbd_rgb_frame" />
  <joint name="rgbd_rgb_optical_joint" type="fixed">
    <origin rpy="-1.57079632679 0.0 -1.57079632679" xyz="0 0 0" />
    <parent link="rgbd_rgb_frame" />
    <child link="rgbd_rgb_optical_frame" />
  </joint>
  <link name="rgbd_rgb_optical_frame" />
  
  
  <transmission name="talos_trans">
    <type>transmission_interface/HalfDifferentialTransmission</type>
    <actuator name="head_1_motor">
      <role>actuator1</role>
      <mechanicalReduction>1.0</mechanicalReduction>
    </actuator>
    <actuator name="head_2_motor">
      <role>actuator2</role>
      <mechanicalReduction>1.0</mechanicalReduction>
    </actuator>
    <joint name="head_1_joint">
      <role>joint1</role>
      <offset>0.0</offset>
      <mechanicalReduction>1.0</mechanicalReduction>
      <hardwareInterface>hardware_interface/PositionJointInterface</hardwareInterface>
      <hardwareInterface>hardware_interface/EffortJointInterface</hardwareInterface>
    </joint>
    <joint name="head_2_joint">
      <role>joint2</role>
      <offset>0.0</offset>
      <mechanicalReduction>2.0</mechanicalReduction>
      <hardwareInterface>hardware_interface/PositionJointInterface</hardwareInterface>
      <hardwareInterface>hardware_interface/EffortJointInterface</hardwareInterface>
    </joint>
  </transmission>
  
  
  
  <link name="arm_left_1_link">
    
    <inertial>
      <origin rpy="0.00000 0.00000 0.00000" xyz="-0.01346 0.0913 0.04812" />
      
      <mass value="1.42896" />
      <inertia ixx="0.00555100000" ixy="-0.00073100000" ixz="0.00000800000" iyy="0.00167300000" iyz="-0.00006000000" izz="0.00582200000" />
    </inertial>
    <visual>
      <origin rpy="0 0 0" xyz="0 0 0" />
      <geometry>
        <mesh filename="meshes/arm_1.STL" scale="1 1 1" />
      </geometry>
      <material name="DarkGrey" />
    </visual>
    <collision>
      <origin rpy="0 0 0" xyz="0 0 0" />
      <geometry>
        <mesh filename="meshes/arm_1_collision.STL" scale="1 1 1" />
      </geometry>
    </collision>
  </link>
  <joint name="arm_left_1_joint" type="revolute">
    <parent link="torso_2_link" />
    <child link="arm_left_1_link" />
    <origin rpy="0.0 0.0 0.0" xyz="0.00000 0.1575 0.23200" />
    <axis xyz="0 0 1" />
    <limit effort="44.64" lower="-1.57079632679" upper="0.523598775598" velocity="2.7" />
    <dynamics damping="1.0" friction="1.0" />
    
  </joint>
  <link name="arm_left_2_link">
    <inertial>
      <origin rpy="0.00000 0.00000 0.00000" xyz="0.02607 0.00049 -0.05209" />
      
      <mass value="1.67729" />
      <inertia ixx="0.00708700000" ixy="-0.00001400000" ixz="0.00214200000" iyy="0.00793600000" iyz="0.00003000000" izz="0.00378800000" />
    </inertial>
    <visual>
      <origin rpy="0 0 0" xyz="0 0 0" />
      <geometry>
        <mesh filename="meshes/arm_2.STL" scale="1 1 1" />
      </geometry>
      <material name="DarkGrey" />
    </visual>
    <collision>
      <origin rpy="0 0 0" xyz="0 0 0" />
      <geometry>
        <mesh filename="meshes/arm_2_collision.STL" scale="1 1 1" />
      </geometry>
    </collision>
  </link>
  <joint name="arm_left_2_joint" type="revolute">
    <parent link="arm_left_1_link" />
    <child link="arm_left_2_link" />
    <origin rpy="0.0 0.0 0.0" xyz="0.00493 0.1365 0.04673" />
    <axis xyz="1 0 0" />
    <limit effort="22.32" lower="0.0" upper="2.87979326579" velocity="3.66" />
    <dynamics damping="1.0" friction="1.0" />
    
  </joint>
  <link name="arm_left_3_link">
    <inertial>
      <origin rpy="0.00000 0.00000 0.00000" xyz="0.00841 0.01428 -0.22291" />
      
      <mass value="1.47029" />
      <inertia ixx="0.00433200000" ixy="0.00015300000" ixz="-0.00049600000" iyy="0.00434000000" iyz="-0.00060900000" izz="0.00254300000" />
    </inertial>
    <visual>
      <origin rpy="0 0 0" xyz="0 0 0" />
      <geometry>
        <mesh filename="meshes/arm_3.STL" scale="1 1 1" />
      </geometry>
      <material name="DarkGrey" />
    </visual>
    <collision>
      <origin rpy="0 0 0" xyz="0 0 0" />
      <geometry>
        <mesh filename="meshes/arm_3_collision.STL" scale="1 1 1" />
      </geometry>
    </collision>
  </link>
  <joint name="arm_left_3_joint" type="revolute">
    <parent link="arm_left_2_link" />
    <child link="arm_left_3_link" />
    <origin rpy="0.0 0.0 0.0" xyz="0.00000 0.00000 0.00000" />
    <axis xyz="0 0 1" />
    <limit effort="17.86" lower="-2.44346095279" upper="2.44346095279" velocity="4.58" />
    <dynamics damping="1.0" friction="1.0" />
    
  </joint>
  
  
  
  <link name="arm_left_4_link">
    <inertial>
      <origin rpy="0.00000 0.00000 0.00000" xyz="-0.00655 -0.02107 -0.02612" />
      
      <mass value="1.10216" />
      <inertia ixx="0.00221700000" ixy="-0.00010100000" ixz="0.00028800000" iyy="0.00241800000" iyz="-0.00039300000" izz="0.00111500000" />
    </inertial>
    <visual>
      <origin rpy="0 0 0" xyz="0 0 0" />
      <geometry>
        <mesh filename="meshes/arm_4.STL" scale="1 1 1" />
      </geometry>
      <material name="DarkGrey" />
    </visual>
    <collision>
      <origin rpy="0 0 0" xyz="0 0 0" />
      <geometry>
        <mesh filename="meshes/arm_4_collision.STL" scale="1 1 1" />
      </geometry>
    </collision>
  </link>
  <joint name="arm_left_4_joint" type="revolute">
    <parent link="arm_left_3_link" />
    <child link="arm_left_4_link" />
    <origin rpy="0.0 0.0 0.0" xyz="0.02000 0.00000 -0.27300" />
    <axis xyz="0 1 0" />
    <limit effort="17.86" lower="-2.35619449019" upper="0.0" velocity="4.58" />
    <dynamics damping="1.0" friction="1.0" />
    
  </joint>
  
  
  
  
  
  
  
  
  
  
  
  
  
  
  <link name="arm_left_5_link">
    <inertial>
      <origin rpy="0.00000 0.00000 0.00000" xyz="-0.00006 0.00326 0.07963" />
      
      <mass value="1.77792" />
      <inertia ixx="0.00349500000" ixy="-0.00001300000" ixz="-0.00001000000" iyy="0.00436800000" iyz="0.00009700000" izz="0.00228300000" />
    </inertial>
    <visual>
      <origin rpy="0 0 0" xyz="0 0 0" />
      <geometry>
        <mesh filename="meshes/arm_5.STL" scale="1 1 1" />
      </geometry>
      <material name="LightGrey" />
    </visual>
    <collision>
      <origin rpy="0 0 0" xyz="0 0 0" />
      <geometry>
        <mesh filename="meshes/arm_5_collision.STL" scale="1 1 1" />
      </geometry>
    </collision>
  </link>
  <joint name="arm_left_5_joint" type="revolute">
    <parent link="arm_left_4_link" />
    <child link="arm_left_5_link" />
    <origin rpy="0.0 0.0 0.0" xyz="-0.02000 0.00000 -0.26430" />
    <axis xyz="0 0 1" />
    <limit effort="3" lower="-2.53072741539" upper="2.53072741539" velocity="1.95" />
    <dynamics damping="1.0" friction="1.0" />
    
  </joint>
  <link name="arm_left_6_link">
    <inertial>
      <origin rpy="0.00000 0.00000 0.00000" xyz="0.00002 -0.00197 -0.00059" />
      
      <mass value="0.30931" />
      <inertia ixx="0.00010700000" ixy="0.00000000000" ixz="0.00000000000" iyy="0.00014100000" iyz="-0.00000000000" izz="0.00015400000" />
    </inertial>
    <visual>
      <origin rpy="0 0 0" xyz="0 0 0" />
      <geometry>
        <mesh filename="meshes/arm_6.STL" scale="1 1 1" />
      </geometry>
      <material name="LightGrey" />
    </visual>
    <collision>
      <origin rpy="0 0 0" xyz="0 0 0" />
      <geometry>
        <mesh filename="meshes/arm_6_collision.STL" scale="1 1 1" />
      </geometry>
    </collision>
  </link>
  <joint name="arm_left_6_joint" type="revolute">
    <parent link="arm_left_5_link" />
    <child link="arm_left_6_link" />
    <origin rpy="0.0 0.0 0.0" xyz="0.00000 0.00000 0.00000" />
    <axis xyz="1 0 0" />
    <limit effort="6.6" lower="-1.3962634016" upper="1.3962634016" velocity="1.76" />
    <dynamics damping="1.0" friction="1.0" />
    
  </joint>
  <link name="arm_left_7_link">
    
    <inertial>
      <origin rpy="0.00000 0.00000 0.00000" xyz="0.007525 0.001378 -0.024630" />
      <mass value="0.308441" />
      <inertia ixx="0.000309" ixy="0.000002" ixz="-0.000002" iyy="0.000219" iyz="0.000012" izz="0.000176" />
    </inertial>
    <visual>
      <origin rpy="0 0 0" xyz="0 0 0" />
      <geometry>
        <mesh filename="meshes/arm_7.STL" scale="1 1 1" />
      </geometry>
      <material name="DarkGrey" />
    </visual>
    <collision>
      <origin rpy="0 0 0" xyz="0 0 0" />
      <geometry>
        <mesh filename="meshes/arm_7_collision.STL" scale="1 1 1" />
      </geometry>
    </collision>
  </link>
  <joint name="arm_left_7_joint" type="revolute">
    <parent link="arm_left_6_link" />
    <child link="arm_left_7_link" />
    <origin rpy="0.0 0.0 0.0" xyz="0.0 0.0 0.0" />
    <axis xyz="0 1 0" />
    <limit effort="6.6" lower="-0.698131700798" upper="0.698131700798" velocity="1.76" />
    <dynamics damping="1.0" friction="1.0" />
    
  </joint>
  
  
  
  
  
  
  
  <transmission name="arm_left_5_trans">
    <type>transmission_interface/SimpleTransmission</type>
    <actuator name="arm_left_5_motor">
      <mechanicalReduction>1.0</mechanicalReduction>
    </actuator>
    <joint name="arm_left_5_joint">
      <hardwareInterface>hardware_interface/PositionJointInterface</hardwareInterface>
      <hardwareInterface>hardware_interface/EffortJointInterface</hardwareInterface>
    </joint>
  </transmission>
  <transmission name="wrist_left_trans">
    <type>transmission_interface/DifferentialTransmission</type>
    <actuator name="arm_left_6_motor">
      <role>actuator1</role>
      <mechanicalReduction>-1.0</mechanicalReduction>
    </actuator>
    <actuator name="arm_left_7_motor">
      <role>actuator2</role>
      <mechanicalReduction>1.0</mechanicalReduction>
    </actuator>
    <joint name="arm_left_6_joint">
      <role>joint1</role>
      <offset>0.0</offset>
      <mechanicalReduction>-1.0</mechanicalReduction>
      <hardwareInterface>hardware_interface/PositionJointInterface</hardwareInterface>
      <hardwareInterface>hardware_interface/EffortJointInterface</hardwareInterface>
    </joint>
    <joint name="arm_left_7_joint">
      <role>joint2</role>
      <offset>0.0</offset>
      <mechanicalReduction>-1.0</mechanicalReduction>
      <hardwareInterface>hardware_interface/PositionJointInterface</hardwareInterface>
      <hardwareInterface>hardware_interface/EffortJointInterface</hardwareInterface>
    </joint>
  </transmission>
  
  <transmission name="arm_left_1_trans">
    <type>transmission_interface/SimpleTransmission</type>
    <actuator name="arm_left_1_motor">
      <mechanicalReduction>1.0</mechanicalReduction>
    </actuator>
    <joint name="arm_left_1_joint">
      <hardwareInterface>hardware_interface/PositionJointInterface</hardwareInterface>
      <hardwareInterface>hardware_interface/EffortJointInterface</hardwareInterface>
    </joint>
  </transmission>
  <transmission name="arm_left_2_trans">
    <type>transmission_interface/SimpleTransmission</type>
    <actuator name="arm_left_2_motor">
      <mechanicalReduction>1.0</mechanicalReduction>
    </actuator>
    <joint name="arm_left_2_joint">
      <hardwareInterface>hardware_interface/PositionJointInterface</hardwareInterface>
      <hardwareInterface>hardware_interface/EffortJointInterface</hardwareInterface>
    </joint>
  </transmission>
  <transmission name="arm_left_3_trans">
    <type>transmission_interface/SimpleTransmission</type>
    <actuator name="arm_left_3_motor">
      <mechanicalReduction>1.0</mechanicalReduction>
    </actuator>
    <joint name="arm_left_3_joint">
      <hardwareInterface>hardware_interface/PositionJointInterface</hardwareInterface>
      <hardwareInterface>hardware_interface/EffortJointInterface</hardwareInterface>
    </joint>
  </transmission>
  <transmission name="arm_left_4_trans">
    <type>transmission_interface/SimpleTransmission</type>
    <actuator name="arm_left_4_motor">
      <mechanicalReduction>1.0</mechanicalReduction>
    </actuator>
    <joint name="arm_left_4_joint">
      <hardwareInterface>hardware_interface/PositionJointInterface</hardwareInterface>
      <hardwareInterface>hardware_interface/EffortJointInterface</hardwareInterface>
    </joint>
  </transmission>
  
  
  
  <link name="arm_right_1_link">
    
    <inertial>
      <origin rpy="0.00000 0.00000 0.00000" xyz="-0.01346 -0.0913 0.04812" />
      
      <mass value="1.42896" />
      <inertia ixx="0.00555100000" ixy="-0.00073100000" ixz="0.00000800000" iyy="0.00167300000" iyz="-0.00006000000" izz="0.00582200000" />
    </inertial>
    <visual>
      <origin rpy="0 0 0" xyz="0 0 0" />
      <geometry>
        <mesh filename="meshes/arm_1.STL" scale="1 -1 1" />
      </geometry>
      <material name="DarkGrey" />
    </visual>
    <collision>
      <origin rpy="0 0 0" xyz="0 0 0" />
      <geometry>
        <mesh filename="meshes/arm_1_collision.STL" scale="1 -1 1" />
      </geometry>
    </collision>
  </link>
  <joint name="arm_right_1_joint" type="revolute">
    <parent link="torso_2_link" />
    <child link="arm_right_1_link" />
    <origin rpy="0.0 0.0 0.0" xyz="0.00000 -0.1575 0.23200" />
    <axis xyz="0 0 1" />
    <limit effort="44.64" lower="-0.523598775598" upper="1.57079632679" velocity="2.7" />
    <dynamics damping="1.0" friction="1.0" />
    
  </joint>
  <link name="arm_right_2_link">
    <inertial>
      <origin rpy="0.00000 0.00000 0.00000" xyz="0.02607 0.00049 -0.05209" />
      
      <mass value="1.67729" />
      <inertia ixx="0.00708700000" ixy="-0.00001400000" ixz="0.00214200000" iyy="0.00793600000" iyz="0.00003000000" izz="0.00378800000" />
    </inertial>
    <visual>
      <origin rpy="0 0 0" xyz="0 0 0" />
      <geometry>
        <mesh filename="meshes/arm_2.STL" scale="1 -1 1" />
      </geometry>
      <material name="DarkGrey" />
    </visual>
    <collision>
      <origin rpy="0 0 0" xyz="0 0 0" />
      <geometry>
        <mesh filename="meshes/arm_2_collision.STL" scale="1 -1 1" />
      </geometry>
    </collision>
  </link>
  <joint name="arm_right_2_joint" type="revolute">
    <parent link="arm_right_1_link" />
    <child link="arm_right_2_link" />
    <origin rpy="0.0 0.0 0.0" xyz="0.00493 -0.1365 0.04673" />
    <axis xyz="1 0 0" />
    <limit effort="22.32" lower="-2.87979326579" upper="0.0" velocity="3.66" />
    <dynamics damping="1.0" friction="1.0" />
    
  </joint>
  <link name="arm_right_3_link">
    <inertial>
      <origin rpy="0.00000 0.00000 0.00000" xyz="0.00841 0.01428 -0.22291" />
      
      <mass value="1.47029" />
      <inertia ixx="0.00433200000" ixy="0.00015300000" ixz="-0.00049600000" iyy="0.00434000000" iyz="-0.00060900000" izz="0.00254300000" />
    </inertial>
    <visual>
      <origin rpy="0 0 0" xyz="0 0 0" />
      <geometry>
        <mesh filename="meshes/arm_3.STL" scale="1 -1 1" />
      </geometry>
      <material name="DarkGrey" />
    </visual>
    <collision>
      <origin rpy="0 0 0" xyz="0 0 0" />
      <geometry>
        <mesh filename="meshes/arm_3_collision.STL" scale="1 -1 1" />
      </geometry>
    </collision>
  </link>
  <joint name="arm_right_3_joint" type="revolute">
    <parent link="arm_right_2_link" />
    <child link="arm_right_3_link" />
    <origin rpy="0.0 0.0 0.0" xyz="0.00000 0.00000 0.00000" />
    <axis xyz="0 0 1" />
    <limit effort="17.86" lower="-2.44346095279" upper="2.44346095279" velocity="4.58" />
    <dynamics damping="1.0" friction="1.0" />
    
  </joint>
  
  
  
  <link name="arm_right_4_link">
    <inertial>
      <origin rpy="0.00000 0.00000 0.00000" xyz="-0.00655 -0.02107 -0.02612" />
      
      <mass value="1.10216" />
      <inertia ixx="0.00221700000" ixy="-0.00010100000" ixz="0.00028800000" iyy="0.00241800000" iyz="-0.00039300000" izz="0.00111500000" />
    </inertial>
    <visual>
      <origin rpy="0 0 0" xyz="0 0 0" />
      <geometry>
        <mesh filename="meshes/arm_4.STL" scale="1 -1 1" />
      </geometry>
      <material name="DarkGrey" />
    </visual>
    <collision>
      <origin rpy="0 0 0" xyz="0 0 0" />
      <geometry>
        <mesh filename="meshes/arm_4_collision.STL" scale="1 -1 1" />
      </geometry>
    </collision>
  </link>
  <joint name="arm_right_4_joint" type="revolute">
    <parent link="arm_right_3_link" />
    <child link="arm_right_4_link" />
    <origin rpy="0.0 0.0 0.0" xyz="0.02000 0.00000 -0.27300" />
    <axis xyz="0 1 0" />
    <limit effort="17.86" lower="-2.35619449019" upper="0.0" velocity="4.58" />
    <dynamics damping="1.0" friction="1.0" />
    
  </joint>
  
  
  
  
  
  
  
  
  
  
  
  
  
  
  <link name="arm_right_5_link">
    <inertial>
      <origin rpy="0.00000 0.00000 0.00000" xyz="-0.00006 0.00326 0.07963" />
      
      <mass value="1.77792" />
      <inertia ixx="0.00349500000" ixy="-0.00001300000" ixz="-0.00001000000" iyy="0.00436800000" iyz="0.00009700000" izz="0.00228300000" />
    </inertial>
    <visual>
      <origin rpy="0 0 0" xyz="0 0 0" />
      <geometry>
        <mesh filename="meshes/arm_5.STL" scale="1 -1 1" />
      </geometry>
      <material name="LightGrey" />
    </visual>
    <collision>
      <origin rpy="0 0 0" xyz="0 0 0" />
      <geometry>
        <mesh filename="meshes/arm_5_collision.STL" scale="1 -1 1" />
      </geometry>
    </collision>
  </link>
  <joint name="arm_right_5_joint" type="revolute">
    <parent link="arm_right_4_link" />
    <child link="arm_right_5_link" />
    <origin rpy="0.0 0.0 0.0" xyz="-0.02000 0.00000 -0.26430" />
    <axis xyz="0 0 1" />
    <limit effort="3" lower="-2.53072741539" upper="2.53072741539" velocity="1.95" />
    <dynamics damping="1.0" friction="1.0" />
    
  </joint>
  <link name="arm_right_6_link">
    <inertial>
      <origin rpy="0.00000 0.00000 0.00000" xyz="0.00002 -0.00197 -0.00059" />
      
      <mass value="0.30931" />
      <inertia ixx="0.00010700000" ixy="0.00000000000" ixz="0.00000000000" iyy="0.00014100000" iyz="-0.00000000000" izz="0.00015400000" />
    </inertial>
    <visual>
      <origin rpy="0 0 0" xyz="0 0 0" />
      <geometry>
        <mesh filename="meshes/arm_6.STL" scale="1 -1 1" />
      </geometry>
      <material name="LightGrey" />
    </visual>
    <collision>
      <origin rpy="0 0 0" xyz="0 0 0" />
      <geometry>
        <mesh filename="meshes/arm_6_collision.STL" scale="1 -1 1" />
      </geometry>
    </collision>
  </link>
  <joint name="arm_right_6_joint" type="revolute">
    <parent link="arm_right_5_link" />
    <child link="arm_right_6_link" />
    <origin rpy="0.0 0.0 0.0" xyz="0.00000 0.00000 0.00000" />
    <axis xyz="1 0 0" />
    <limit effort="6.6" lower="-1.3962634016" upper="1.3962634016" velocity="1.76" />
    <dynamics damping="1.0" friction="1.0" />
    
  </joint>
  <link name="arm_right_7_link">
    
    <inertial>
      <origin rpy="0.00000 0.00000 0.00000" xyz="0.007525 0.001378 -0.024630" />
      <mass value="0.308441" />
      <inertia ixx="0.000309" ixy="0.000002" ixz="-0.000002" iyy="0.000219" iyz="0.000012" izz="0.000176" />
    </inertial>
    <visual>
      <origin rpy="0 0 0" xyz="0 0 0" />
      <geometry>
        <mesh filename="meshes/arm_7.STL" scale="1 -1 1" />
      </geometry>
      <material name="DarkGrey" />
    </visual>
    <collision>
      <origin rpy="0 0 0" xyz="0 0 0" />
      <geometry>
        <mesh filename="meshes/arm_7_collision.STL" scale="1 -1 1" />
      </geometry>
    </collision>
  </link>
  <joint name="arm_right_7_joint" type="revolute">
    <parent link="arm_right_6_link" />
    <child link="arm_right_7_link" />
    <origin rpy="0.0 0.0 0.0" xyz="0.0 0.0 0.0" />
    <axis xyz="0 1 0" />
    <limit effort="6.6" lower="-0.698131700798" upper="0.698131700798" velocity="1.76" />
    <dynamics damping="1.0" friction="1.0" />
    
  </joint>
  
  
  
  
  
  
  
  <transmission name="arm_right_5_trans">
    <type>transmission_interface/SimpleTransmission</type>
    <actuator name="arm_right_5_motor">
      <mechanicalReduction>1.0</mechanicalReduction>
    </actuator>
    <joint name="arm_right_5_joint">
      <hardwareInterface>hardware_interface/PositionJointInterface</hardwareInterface>
      <hardwareInterface>hardware_interface/EffortJointInterface</hardwareInterface>
    </joint>
  </transmission>
  <transmission name="wrist_right_trans">
    <type>transmission_interface/DifferentialTransmission</type>
    <actuator name="arm_right_6_motor">
      <role>actuator1</role>
      <mechanicalReduction>-1.0</mechanicalReduction>
    </actuator>
    <actuator name="arm_right_7_motor">
      <role>actuator2</role>
      <mechanicalReduction>1.0</mechanicalReduction>
    </actuator>
    <joint name="arm_right_6_joint">
      <role>joint1</role>
      <offset>0.0</offset>
      <mechanicalReduction>-1.0</mechanicalReduction>
      <hardwareInterface>hardware_interface/PositionJointInterface</hardwareInterface>
      <hardwareInterface>hardware_interface/EffortJointInterface</hardwareInterface>
    </joint>
    <joint name="arm_right_7_joint">
      <role>joint2</role>
      <offset>0.0</offset>
      <mechanicalReduction>1.0</mechanicalReduction>
      <hardwareInterface>hardware_interface/PositionJointInterface</hardwareInterface>
      <hardwareInterface>hardware_interface/EffortJointInterface</hardwareInterface>
    </joint>
  </transmission>
  
  <transmission name="arm_right_1_trans">
    <type>transmission_interface/SimpleTransmission</type>
    <actuator name="arm_right_1_motor">
      <mechanicalReduction>1.0</mechanicalReduction>
    </actuator>
    <joint name="arm_right_1_joint">
      <hardwareInterface>hardware_interface/PositionJointInterface</hardwareInterface>
      <hardwareInterface>hardware_interface/EffortJointInterface</hardwareInterface>
    </joint>
  </transmission>
  <transmission name="arm_right_2_trans">
    <type>transmission_interface/SimpleTransmission</type>
    <actuator name="arm_right_2_motor">
      <mechanicalReduction>1.0</mechanicalReduction>
    </actuator>
    <joint name="arm_right_2_joint">
      <hardwareInterface>hardware_interface/PositionJointInterface</hardwareInterface>
      <hardwareInterface>hardware_interface/EffortJointInterface</hardwareInterface>
    </joint>
  </transmission>
  <transmission name="arm_right_3_trans">
    <type>transmission_interface/SimpleTransmission</type>
    <actuator name="arm_right_3_motor">
      <mechanicalReduction>1.0</mechanicalReduction>
    </actuator>
    <joint name="arm_right_3_joint">
      <hardwareInterface>hardware_interface/PositionJointInterface</hardwareInterface>
      <hardwareInterface>hardware_interface/EffortJointInterface</hardwareInterface>
    </joint>
  </transmission>
  <transmission name="arm_right_4_trans">
    <type>transmission_interface/SimpleTransmission</type>
    <actuator name="arm_right_4_motor">
      <mechanicalReduction>1.0</mechanicalReduction>
    </actuator>
    <joint name="arm_right_4_joint">
      <hardwareInterface>hardware_interface/PositionJointInterface</hardwareInterface>
      <hardwareInterface>hardware_interface/EffortJointInterface</hardwareInterface>
    </joint>
  </transmission>
  
  
  
  <link name="wrist_right_ft_link">
    <inertial>
      <mass value="0.1" />
      <inertia ixx="0.0" ixy="0.0" ixz="0.0" iyy="0.0" iyz="0.0" izz="0.0" />
    </inertial>
    <visual>
      <origin rpy="0 0 0" xyz="0 0 0" />
      <geometry>
        <cylinder length="0.0157" radius="0.0225" />
      </geometry>
      <material name="LightGrey" />
    </visual>
    <collision>
      <origin rpy="0 0 0" xyz="0 0 0" />
      <geometry>
        <cylinder length="0.0157" radius="0.0225" />
      </geometry>
    </collision>
  </link>
  <joint name="wrist_right_ft_joint" type="fixed">
    <parent link="arm_right_7_link" />
    <child link="wrist_right_ft_link" />
    <origin rpy="0.0 0 -1.57079632679" xyz="0 0 -0.051" />
  </joint>
  
  
  
  <link name="wrist_right_ft_tool_link">
    <inertial>
      <mass value="0.1" />
      <inertia ixx="0.0" ixy="0.0" ixz="0.0" iyy="0.0" iyz="0.0" izz="0.0" />
    </inertial>
    <visual>
      <origin rpy="0 0.0 0" xyz="0.0 0 0" />
      <geometry>
        <cylinder length="0.00975" radius="0.025" />
      </geometry>
      <material name="FlatBlack" />
    </visual>
    <collision>
      <origin rpy="0 0.0 0" xyz="0.0 0 0" />
      <geometry>
        <cylinder length="0.00975" radius="0.025" />
      </geometry>
    </collision>
  </link>
  <joint name="wrist_right_tool_joint" type="fixed">
    <parent link="wrist_right_ft_link" />
    <child link="wrist_right_ft_tool_link" />
    <origin rpy="0 0 -1.57079632679" xyz="0 0 -0.012725" />
  </joint>
  
  
  
  <link name="wrist_left_ft_link">
    <inertial>
      <mass value="0.1" />
      <inertia ixx="0.0" ixy="0.0" ixz="0.0" iyy="0.0" iyz="0.0" izz="0.0" />
    </inertial>
    <visual>
      <origin rpy="0 0 0" xyz="0 0 0" />
      <geometry>
        <cylinder length="0.0157" radius="0.0225" />
      </geometry>
      <material name="LightGrey" />
    </visual>
    <collision>
      <origin rpy="0 0 0" xyz="0 0 0" />
      <geometry>
        <cylinder length="0.0157" radius="0.0225" />
      </geometry>
    </collision>
  </link>
  <joint name="wrist_left_ft_joint" type="fixed">
    <parent link="arm_left_7_link" />
    <child link="wrist_left_ft_link" />
    <origin rpy="0.0 0 -4.71238898038" xyz="0 0 -0.051" />
  </joint>
  
  
  
  <link name="wrist_left_ft_tool_link">
    <inertial>
      <mass value="0.1" />
      <inertia ixx="0.0" ixy="0.0" ixz="0.0" iyy="0.0" iyz="0.0" izz="0.0" />
    </inertial>
    <visual>
      <origin rpy="0 0.0 0" xyz="0.0 0 0" />
      <geometry>
        <cylinder length="0.00975" radius="0.025" />
      </geometry>
      <material name="FlatBlack" />
    </visual>
    <collision>
      <origin rpy="0 0.0 0" xyz="0.0 0 0" />
      <geometry>
        <cylinder length="0.00975" radius="0.025" />
      </geometry>
    </collision>
  </link>
  <joint name="wrist_left_tool_joint" type="fixed">
    <parent link="wrist_left_ft_link" />
    <child link="wrist_left_ft_tool_link" />
    <origin rpy="0 0 4.71238898038" xyz="0 0 -0.012725" />
  </joint>
  <link name="gripper_left_base_link">
    <inertial>
      <origin rpy="0.00000 0.00000 0.00000" xyz="-0.00534 0.00362 -0.02357" />
      <mass value="0.61585" />
      <inertia ixx="0.00047200000" ixy="-0.00000800000" ixz="0.00003500000" iyy="0.00052100000" iyz="0.00000000000" izz="0.00069000000" />
    </inertial>
    <visual>
      <origin rpy="0 0 0" xyz="0 0 0" />
      <geometry>
        <mesh filename="meshes/gripper_base_link.STL" scale="1 1 1" />
      </geometry>
      <material name="DarkGrey" />
    </visual>
    <collision>
      <origin rpy="0 0 0" xyz="0 0 0" />
      <geometry>
        <mesh filename="meshes/gripper_base_link_collision.STL" scale="1 1 1" />
      </geometry>
    </collision>
  </link>
  <joint name="gripper_left_base_link_joint" type="fixed">
    <parent link="wrist_left_ft_tool_link" />
    <child link="gripper_left_base_link" />
    <origin rpy="0.0 0.0 0.0" xyz="0.00000 0.00000 -0.02875" />
    <axis xyz="0 0 0" />
  </joint>
  <link name="gripper_left_motor_double_link">
    <inertial>
      <origin rpy="0.00000 0.00000 0.00000" xyz="0.02270 0.01781 -0.00977" />
      <mass value="0.16889" />
      
      <inertia ixx="0.001159" ixy="-0.00007000000" ixz="0.00003800000" iyy="0.001221" iyz="-0.00005300000" izz="0.001268" />
    </inertial>
    <visual>
      <origin rpy="0 0 0" xyz="0 0 0" />
      <geometry>
        <mesh filename="meshes/gripper_motor_double.STL" scale="1 1 1" />
      </geometry>
      <material name="Orange" />
    </visual>
    <collision>
      <origin rpy="0 0 0" xyz="0 0 0" />
      <geometry>
        <mesh filename="meshes/gripper_motor_double_collision.STL" scale="1 1 1" />
      </geometry>
    </collision>
  </link>
  <joint name="gripper_left_joint" type="revolute">
    <parent link="gripper_left_base_link" />
    <child link="gripper_left_motor_double_link" />
    <origin rpy="0.0 0.0 0.0" xyz="0.0 0.02025 -0.03" />
    <axis xyz="1 0 0" />
    <limit effort="1.0" lower="-1.0471975512" upper="0.0" velocity="1.0" />
    <dynamics damping="1.0" friction="1.0" />
  </joint>
  <link name="gripper_left_inner_double_link">
    <inertial>
      <origin rpy="0.00000 0.00000 0.00000" xyz="-0.00056 0.03358 -0.01741" />
      <mass value="0.11922" />
      <inertia ixx="0.00009100000" ixy="0.00000100000" ixz="-0.00000100000" iyy="0.00015600000" iyz="-0.00003200000" izz="0.00012600000" />
    </inertial>
    <visual>
      <origin rpy="0 0 0" xyz="0 0 0" />
      <geometry>
        <mesh filename="meshes/inner_double.STL" scale="1 1 1" />
      </geometry>
      <material name="Orange" />
    </visual>
    <collision>
      <origin rpy="0 0 0" xyz="0 0 0" />
      <geometry>
        <mesh filename="meshes/inner_double_collision.STL" scale="1 1 1" />
      </geometry>
    </collision>
  </link>
  <joint name="gripper_left_inner_double_joint" type="revolute">
    <parent link="gripper_left_base_link" />
    <child link="gripper_left_inner_double_link" />
    <origin rpy="0.0 0.0 0.0" xyz="0.00000 0.00525 -0.05598" />
    <axis xyz="1 0 0" />
    <limit effort="100.0" lower="-1.0471975512" upper="0.0" velocity="1.0" />
    <mimic joint="gripper_left_joint" multiplier="1.0" offset="0.0" />
  </joint>
  <link name="gripper_left_fingertip_1_link">
    <inertial>
      <origin rpy="0.00000 0.00000 0.00000" xyz="0.00000 0.00460 -0.00254" />
      <mass value="0.02630" />
      <inertia ixx="0.00000800000" ixy="0.00000000000" ixz="0.00000000000" iyy="0.00000900000" iyz="0.00000100000" izz="0.00000200000" />
    </inertial>
    <visual>
      <origin rpy="0 0 0" xyz="0 0 0" />
      <geometry>
        <mesh filename="meshes/fingertip.STL" scale="1 1 1" />
      </geometry>
      <material name="DarkGrey" />
    </visual>
    <collision>
      <origin rpy="0 0 0" xyz="0 0 0" />
      <geometry>
        <mesh filename="meshes/fingertip_collision.STL" scale="1 1 1" />
      </geometry>
    </collision>
  </link>
  <joint name="gripper_left_fingertip_1_joint" type="revolute">
    <parent link="gripper_left_inner_double_link" />
    <child link="gripper_left_fingertip_1_link" />
    <origin rpy="0.0 0.0 0.0" xyz="0.03200 0.04589 -0.06553" />
    <axis xyz="1 0 0" />
    <limit effort="100.0" lower="0.0" upper="1.0471975512" velocity="1.0" />
    <mimic joint="gripper_left_joint" multiplier="-1.0" offset="0.0" />
  </joint>
  <link name="gripper_left_fingertip_2_link">
    <inertial>
      <origin rpy="0.00000 0.00000 0.00000" xyz="0.00000 0.00460 -0.00254" />
      <mass value="0.02630" />
      <inertia ixx="0.00000800000" ixy="0.00000000000" ixz="0.00000000000" iyy="0.00000900000" iyz="0.00000100000" izz="0.00000200000" />
    </inertial>
    <visual>
      <origin rpy="0 0 0" xyz="0 0 0" />
      <geometry>
        <mesh filename="meshes/fingertip.STL" scale="1 1 1" />
      </geometry>
      <material name="DarkGrey" />
    </visual>
    <collision>
      <origin rpy="0 0 0" xyz="0 0 0" />
      <geometry>
        <mesh filename="meshes/fingertip_collision.STL" scale="1 1 1" />
      </geometry>
    </collision>
  </link>
  <joint name="gripper_left_fingertip_2_joint" type="revolute">
    <parent link="gripper_left_inner_double_link" />
    <child link="gripper_left_fingertip_2_link" />
    <origin rpy="0.0 0.0 0.0" xyz="-0.03200 0.04589 -0.06553" />
    <axis xyz="1 0 0" />
    <limit effort="100.0" lower="0.0" upper="1.0471975512" velocity="1.0" />
    <mimic joint="gripper_left_joint" multiplier="-1.0" offset="0.0" />
  </joint>
  <link name="gripper_left_motor_single_link">
    <inertial>
      <origin rpy="0.00000 0.00000 0.00000" xyz="0.02589 -0.01284 -0.00640" />
      <mass value="0.14765" />
      <inertia ixx="0.00011500000" ixy="0.00005200000" ixz="0.00002500000" iyy="0.00015300000" iyz="0.00003400000" izz="0.00019000000" />
    </inertial>
    <visual>
      <origin rpy="0 0 0" xyz="0 0 0" />
      <geometry>
        <mesh filename="meshes/gripper_motor_single.STL" scale="1 1 1" />
      </geometry>
      <material name="Orange" />
    </visual>
    <collision>
      <origin rpy="0 0 0" xyz="0 0 0" />
      <geometry>
        <mesh filename="meshes/gripper_motor_single_collision.STL" scale="1 1 1" />
      </geometry>
    </collision>
  </link>
  <joint name="gripper_left_motor_single_joint" type="revolute">
    <parent link="gripper_left_base_link" />
    <child link="gripper_left_motor_single_link" />
    <origin rpy="0.0 0.0 0.0" xyz="0.00000 -0.02025 -0.03000" />
    <axis xyz="1 0 0" />
    <limit effort="100.0" lower="0.0" upper="1.0471975512" velocity="1.0" />
    <mimic joint="gripper_left_joint" multiplier="-1.0" offset="0.0" />
  </joint>
  <link name="gripper_left_inner_single_link">
    <inertial>
      <origin rpy="0.00000 0.00000 0.00000" xyz="0.00000 -0.03253 -0.01883" />
      <mass value="0.05356" />
      <inertia ixx="0.00004700000" ixy="-0.00000000000" ixz="-0.00000000000" iyy="0.00003500000" iyz="0.00001700000" izz="0.00002400000" />
    </inertial>
    <visual>
      <origin rpy="0 0 0" xyz="0 0 0" />
      <geometry>
        <mesh filename="meshes/inner_single.STL" scale="1 1 1" />
      </geometry>
      <material name="Orange" />
    </visual>
    <collision>
      <origin rpy="0 0 0" xyz="0 0 0" />
      <geometry>
        <mesh filename="meshes/inner_single_collision.STL" scale="1 1 1" />
      </geometry>
    </collision>
  </link>
  <joint name="gripper_left_inner_single_joint" type="revolute">
    <parent link="gripper_left_base_link" />
    <child link="gripper_left_inner_single_link" />
    <origin rpy="0.0 0.0 0.0" xyz="0.00000 -0.00525 -0.05598" />
    <axis xyz="1 0 0" />
    <limit effort="100.0" lower="0.0" upper="1.0471975512" velocity="1.0" />
    <mimic joint="gripper_left_joint" multiplier="-1.0" offset="0.0" />
  </joint>
  <link name="gripper_left_fingertip_3_link">
    <inertial>
      <origin rpy="0.00000 0.00000 0.00000" xyz="0.00000 0.00460 -0.00254" />
      <mass value="0.02630" />
      <inertia ixx="0.00000800000" ixy="0.00000000000" ixz="0.00000000000" iyy="0.00000900000" iyz="0.00000100000" izz="0.00000200000" />
    </inertial>
    <visual>
      <origin rpy="0 0 0" xyz="0 0 0" />
      <geometry>
        <mesh filename="meshes/fingertip.STL" scale="1 1 1" />
      </geometry>
      <material name="DarkGrey" />
    </visual>
    <collision>
      <origin rpy="0 0 0" xyz="0 0 0" />
      <geometry>
        <mesh filename="meshes/fingertip_collision.STL" scale="1 1 1" />
      </geometry>
    </collision>
  </link>
  <joint name="gripper_left_fingertip_3_joint" type="revolute">
    <parent link="gripper_left_inner_single_link" />
    <child link="gripper_left_fingertip_3_link" />
    <origin rpy="0.0 0.0 3.14159265359" xyz="0.00000 -0.04589 -0.06553" />
    <axis xyz="1 0 0" />
    <limit effort="100.0" lower="0.0" upper="1.0471975512" velocity="1.0" />
    <mimic joint="gripper_left_joint" multiplier="-1.0" offset="0.0" />
  </joint>
  
  
  
  
  
  
  
  
  
  
  
  
  
  
  
  
  
  
  <transmission name="gripper_left_trans">
    <type>transmission_interface/SimpleTransmission</type>
    <actuator name="gripper_left_motor">
      <mechanicalReduction>1.0</mechanicalReduction>
    </actuator>
    <joint name="gripper_left_joint">
      <hardwareInterface>hardware_interface/PositionJointInterface</hardwareInterface>
    </joint>
  </transmission>
  
  
  <link name="gripper_right_base_link">
    <inertial>
      <origin rpy="0.00000 0.00000 0.00000" xyz="-0.00534 0.00362 -0.02357" />
      <mass value="0.61585" />
      <inertia ixx="0.00047200000" ixy="-0.00000800000" ixz="0.00003500000" iyy="0.00052100000" iyz="0.00000000000" izz="0.00069000000" />
    </inertial>
    <visual>
      <origin rpy="0 0 0" xyz="0 0 0" />
      <geometry>
        <mesh filename="meshes/gripper_base_link.STL" scale="1 1 1" />
      </geometry>
      <material name="DarkGrey" />
    </visual>
    <collision>
      <origin rpy="0 0 0" xyz="0 0 0" />
      <geometry>
        <mesh filename="meshes/gripper_base_link_collision.STL" scale="1 1 1" />
      </geometry>
    </collision>
  </link>
  <joint name="gripper_right_base_link_joint" type="fixed">
    <parent link="wrist_right_ft_tool_link" />
    <child link="gripper_right_base_link" />
    <origin rpy="0.0 0.0 0.0" xyz="0.00000 0.00000 -0.02875" />
    <axis xyz="0 0 0" />
  </joint>
  <link name="gripper_right_motor_double_link">
    <inertial>
      <origin rpy="0.00000 0.00000 0.00000" xyz="0.02270 0.01781 -0.00977" />
      <mass value="0.16889" />
      
      <inertia ixx="0.001159" ixy="-0.00007000000" ixz="0.00003800000" iyy="0.001221" iyz="-0.00005300000" izz="0.001268" />
    </inertial>
    <visual>
      <origin rpy="0 0 0" xyz="0 0 0" />
      <geometry>
        <mesh filename="meshes/gripper_motor_double.STL" scale="1 1 1" />
      </geometry>
      <material name="Orange" />
    </visual>
    <collision>
      <origin rpy="0 0 0" xyz="0 0 0" />
      <geometry>
        <mesh filename="meshes/gripper_motor_double_collision.STL" scale="1 1 1" />
      </geometry>
    </collision>
  </link>
  <joint name="gripper_right_joint" type="revolute">
    <parent link="gripper_right_base_link" />
    <child link="gripper_right_motor_double_link" />
    <origin rpy="0.0 0.0 0.0" xyz="0.0 0.02025 -0.03" />
    <axis xyz="1 0 0" />
    <limit effort="1.0" lower="-1.0471975512" upper="0.0" velocity="1.0" />
    <dynamics damping="1.0" friction="1.0" />
  </joint>
  <link name="gripper_right_inner_double_link">
    <inertial>
      <origin rpy="0.00000 0.00000 0.00000" xyz="-0.00056 0.03358 -0.01741" />
      <mass value="0.11922" />
      <inertia ixx="0.00009100000" ixy="0.00000100000" ixz="-0.00000100000" iyy="0.00015600000" iyz="-0.00003200000" izz="0.00012600000" />
    </inertial>
    <visual>
      <origin rpy="0 0 0" xyz="0 0 0" />
      <geometry>
        <mesh filename="meshes/inner_double.STL" scale="1 1 1" />
      </geometry>
      <material name="Orange" />
    </visual>
    <collision>
      <origin rpy="0 0 0" xyz="0 0 0" />
      <geometry>
        <mesh filename="meshes/inner_double_collision.STL" scale="1 1 1" />
      </geometry>
    </collision>
  </link>
  <joint name="gripper_right_inner_double_joint" type="revolute">
    <parent link="gripper_right_base_link" />
    <child link="gripper_right_inner_double_link" />
    <origin rpy="0.0 0.0 0.0" xyz="0.00000 0.00525 -0.05598" />
    <axis xyz="1 0 0" />
    <limit effort="100.0" lower="-1.0471975512" upper="0.0" velocity="1.0" />
    <mimic joint="gripper_right_joint" multiplier="1.0" offset="0.0" />
  </joint>
  <link name="gripper_right_fingertip_1_link">
    <inertial>
      <origin rpy="0.00000 0.00000 0.00000" xyz="0.00000 0.00460 -0.00254" />
      <mass value="0.02630" />
      <inertia ixx="0.00000800000" ixy="0.00000000000" ixz="0.00000000000" iyy="0.00000900000" iyz="0.00000100000" izz="0.00000200000" />
    </inertial>
    <visual>
      <origin rpy="0 0 0" xyz="0 0 0" />
      <geometry>
        <mesh filename="meshes/fingertip.STL" scale="1 1 1" />
      </geometry>
      <material name="DarkGrey" />
    </visual>
    <collision>
      <origin rpy="0 0 0" xyz="0 0 0" />
      <geometry>
        <mesh filename="meshes/fingertip_collision.STL" scale="1 1 1" />
      </geometry>
    </collision>
  </link>
  <joint name="gripper_right_fingertip_1_joint" type="revolute">
    <parent link="gripper_right_inner_double_link" />
    <child link="gripper_right_fingertip_1_link" />
    <origin rpy="0.0 0.0 0.0" xyz="0.03200 0.04589 -0.06553" />
    <axis xyz="1 0 0" />
    <limit effort="100.0" lower="0.0" upper="1.0471975512" velocity="1.0" />
    <mimic joint="gripper_right_joint" multiplier="-1.0" offset="0.0" />
  </joint>
  <link name="gripper_right_fingertip_2_link">
    <inertial>
      <origin rpy="0.00000 0.00000 0.00000" xyz="0.00000 0.00460 -0.00254" />
      <mass value="0.02630" />
      <inertia ixx="0.00000800000" ixy="0.00000000000" ixz="0.00000000000" iyy="0.00000900000" iyz="0.00000100000" izz="0.00000200000" />
    </inertial>
    <visual>
      <origin rpy="0 0 0" xyz="0 0 0" />
      <geometry>
        <mesh filename="meshes/fingertip.STL" scale="1 1 1" />
      </geometry>
      <material name="DarkGrey" />
    </visual>
    <collision>
      <origin rpy="0 0 0" xyz="0 0 0" />
      <geometry>
        <mesh filename="meshes/fingertip_collision.STL" scale="1 1 1" />
      </geometry>
    </collision>
  </link>
  <joint name="gripper_right_fingertip_2_joint" type="revolute">
    <parent link="gripper_right_inner_double_link" />
    <child link="gripper_right_fingertip_2_link" />
    <origin rpy="0.0 0.0 0.0" xyz="-0.03200 0.04589 -0.06553" />
    <axis xyz="1 0 0" />
    <limit effort="100.0" lower="0.0" upper="1.0471975512" velocity="1.0" />
    <mimic joint="gripper_right_joint" multiplier="-1.0" offset="0.0" />
  </joint>
  <link name="gripper_right_motor_single_link">
    <inertial>
      <origin rpy="0.00000 0.00000 0.00000" xyz="0.02589 -0.01284 -0.00640" />
      <mass value="0.14765" />
      <inertia ixx="0.00011500000" ixy="0.00005200000" ixz="0.00002500000" iyy="0.00015300000" iyz="0.00003400000" izz="0.00019000000" />
    </inertial>
    <visual>
      <origin rpy="0 0 0" xyz="0 0 0" />
      <geometry>
        <mesh filename="meshes/gripper_motor_single.STL" scale="1 1 1" />
      </geometry>
      <material name="Orange" />
    </visual>
    <collision>
      <origin rpy="0 0 0" xyz="0 0 0" />
      <geometry>
        <mesh filename="meshes/gripper_motor_single_collision.STL" scale="1 1 1" />
      </geometry>
    </collision>
  </link>
  <joint name="gripper_right_motor_single_joint" type="revolute">
    <parent link="gripper_right_base_link" />
    <child link="gripper_right_motor_single_link" />
    <origin rpy="0.0 0.0 0.0" xyz="0.00000 -0.02025 -0.03000" />
    <axis xyz="1 0 0" />
    <limit effort="100.0" lower="0.0" upper="1.0471975512" velocity="1.0" />
    <mimic joint="gripper_right_joint" multiplier="-1.0" offset="0.0" />
  </joint>
  <link name="gripper_right_inner_single_link">
    <inertial>
      <origin rpy="0.00000 0.00000 0.00000" xyz="0.00000 -0.03253 -0.01883" />
      <mass value="0.05356" />
      <inertia ixx="0.00004700000" ixy="-0.00000000000" ixz="-0.00000000000" iyy="0.00003500000" iyz="0.00001700000" izz="0.00002400000" />
    </inertial>
    <visual>
      <origin rpy="0 0 0" xyz="0 0 0" />
      <geometry>
        <mesh filename="meshes/inner_single.STL" scale="1 1 1" />
      </geometry>
      <material name="Orange" />
    </visual>
    <collision>
      <origin rpy="0 0 0" xyz="0 0 0" />
      <geometry>
        <mesh filename="meshes/inner_single_collision.STL" scale="1 1 1" />
      </geometry>
    </collision>
  </link>
  <joint name="gripper_right_inner_single_joint" type="revolute">
    <parent link="gripper_right_base_link" />
    <child link="gripper_right_inner_single_link" />
    <origin rpy="0.0 0.0 0.0" xyz="0.00000 -0.00525 -0.05598" />
    <axis xyz="1 0 0" />
    <limit effort="100.0" lower="0.0" upper="1.0471975512" velocity="1.0" />
    <mimic joint="gripper_right_joint" multiplier="-1.0" offset="0.0" />
  </joint>
  <link name="gripper_right_fingertip_3_link">
    <inertial>
      <origin rpy="0.00000 0.00000 0.00000" xyz="0.00000 0.00460 -0.00254" />
      <mass value="0.02630" />
      <inertia ixx="0.00000800000" ixy="0.00000000000" ixz="0.00000000000" iyy="0.00000900000" iyz="0.00000100000" izz="0.00000200000" />
    </inertial>
    <visual>
      <origin rpy="0 0 0" xyz="0 0 0" />
      <geometry>
        <mesh filename="meshes/fingertip.STL" scale="1 1 1" />
      </geometry>
      <material name="DarkGrey" />
    </visual>
    <collision>
      <origin rpy="0 0 0" xyz="0 0 0" />
      <geometry>
        <mesh filename="meshes/fingertip_collision.STL" scale="1 1 1" />
      </geometry>
    </collision>
  </link>
  <joint name="gripper_right_fingertip_3_joint" type="revolute">
    <parent link="gripper_right_inner_single_link" />
    <child link="gripper_right_fingertip_3_link" />
    <origin rpy="0.0 0.0 3.14159265359" xyz="0.00000 -0.04589 -0.06553" />
    <axis xyz="1 0 0" />
    <limit effort="100.0" lower="0.0" upper="1.0471975512" velocity="1.0" />
    <mimic joint="gripper_right_joint" multiplier="-1.0" offset="0.0" />
  </joint>
  
  
  
  
  
  
  
  
  
  
  
  
  
  
  
  
  
  
  <transmission name="gripper_right_trans">
    <type>transmission_interface/SimpleTransmission</type>
    <actuator name="gripper_right_motor">
      <mechanicalReduction>1.0</mechanicalReduction>
    </actuator>
    <joint name="gripper_right_joint">
      <hardwareInterface>hardware_interface/PositionJointInterface</hardwareInterface>
    </joint>
  </transmission>
  
  
  
  <link name="leg_left_1_link">
    <inertial>
      <origin rpy="0.00000 0.00000 0.00000" xyz="0.02320 -0.00009 0.04949" />
      <mass value="1.88569" />
      <inertia ixx="0.00384800000" ixy="0.00003200000" ixz="-0.00082600000" iyy="0.00599400000" iyz="0.00007800000" izz="0.00322200000" />
    </inertial>
    <visual>
      <origin rpy="0 0 0" xyz="0 0 0" />
      <geometry>
        <mesh filename="meshes/hip_z_lo_res.stl" scale="1 1 1" />
      </geometry>
      <material name="DarkGrey" />
    </visual>
    <collision>
      <origin rpy="0 0 0" xyz="0 0 0" />
      <geometry>
        <mesh filename="meshes/hip_z_collision.stl" scale="1 1 1" />
      </geometry>
    </collision>
  </link>
  <joint name="leg_left_1_joint" type="revolute">
    <parent link="base_link" />
    <child link="leg_left_1_link" />
    <origin rpy="0.0 0.0 0.0" xyz="-0.02 0.085 -0.27105" />
    <axis xyz="0 0 1" />
    <limit effort="100" lower="-0.349065850399" upper="1.57079632679" velocity="3.87" />
    <dynamics damping="0.0" friction="0.0" />
  </joint>
  
  <link name="leg_left_2_link">
    <inertial>
      <origin rpy="0.00000 0.00000 0.00000" xyz="0.01583 -0.00021 0.00619" />
      <mass value="2.37607" />
      <inertia ixx="0.00342100000" ixy="-0.00011300000" ixz="-0.00022500000" iyy="0.00402400000" iyz="-0.00003100000" izz="0.00416400000" />
    </inertial>
    <visual>
      <origin rpy="0 0 0" xyz="0 0 0.0" />
      <geometry>
        <mesh filename="meshes/hip_x_lo_res.stl" scale="1 1 1" />
      </geometry>
      <material name="DarkGrey" />
    </visual>
    <collision>
      <origin rpy="0 0 0" xyz="0 0 0.0" />
      <geometry>
        <mesh filename="meshes/hip_x_collision.stl" scale="1 1 1" />
      </geometry>
    </collision>
  </link>
  <joint name="leg_left_2_joint" type="revolute">
    <parent link="leg_left_1_link" />
    <child link="leg_left_2_link" />
    <origin rpy="0.0 0.0 0.0" xyz="0.00000 0.00000 0.00000" />
    <axis xyz="1 0 0" />
    <limit effort="160" lower="-0.5236" upper="0.5236" velocity="5.8" />
    <dynamics damping="0.0" friction="0.0" />
  </joint>
  
  <link name="leg_left_3_link">
    <inertial>
      <origin rpy="0.00000 0.00000 0.00000" xyz="0.00658 0.06563 -0.17278" />
      <mass value="6.82734" />
      <inertia ixx="0.12390600000" ixy="-0.000412" ixz="-0.00205900000" iyy="0.10844700000" iyz="0.016725" izz="0.02781200000" />
    </inertial>
    <visual>
      <origin rpy="0 0 0" xyz="0 0 0" />
      <geometry>
        <mesh filename="meshes/hip_y_lo_res.stl" scale="1 1 1" />
      </geometry>
      <material name="DarkGrey" />
    </visual>
    <collision>
      <origin rpy="0 0 0" xyz="0 0 0" />
      <geometry>
        <mesh filename="meshes/hip_y_collision.stl" scale="1 1 1" />
      </geometry>
    </collision>
  </link>
  <joint name="leg_left_3_joint" type="revolute">
    <parent link="leg_left_2_link" />
    <child link="leg_left_3_link" />
    <origin rpy="0.0 0.0 0.0" xyz="0.00000 0.00000 0.00000" />
    <axis xyz="0 1 0" />
    <limit effort="160" lower="-2.095" upper="0.7" velocity="5.8" />
    <dynamics damping="0.0" friction="0.0" />
  </joint>
  
  <link name="leg_left_4_link">
    <inertial>
      <origin rpy="0.00000 0.00000 0.00000" xyz="0.01520 0.02331 -0.12063" />
      <mass value="3.63668" />
      <inertia ixx="0.03531500000" ixy="2.9e-05" ixz="-0.00016600000" iyy="0.02933600000" iyz="-0.001305" izz="0.01174000000" />
    </inertial>
    <visual>
      <origin rpy="0 0 0" xyz="0 0 0" />
      <geometry>
        <mesh filename="meshes/knee_lo_res.stl" scale="1 1 1" />
      </geometry>
      <material name="DarkGrey" />
    </visual>
    <collision>
      <origin rpy="0 0 0" xyz="0 0 0" />
      <geometry>
        <mesh filename="meshes/knee_collision.stl" scale="1 1 1" />
      </geometry>
    </collision>
  </link>
  <joint name="leg_left_4_joint" type="revolute">
    <parent link="leg_left_3_link" />
    <child link="leg_left_4_link" />
    <origin rpy="0.0 0.0 0.0" xyz="0.00000 0.00000 -0.38000" />
    <axis xyz="0 1 0" />
    <limit effort="300" lower="0" upper="2.618" velocity="7" />
    <dynamics damping="0.0" friction="0.0" />
  </joint>
  
  <link name="leg_left_5_link">
    <inertial>
      <origin rpy="0.00000 0.00000 0.00000" xyz="-0.01106 0.04708 0.05271" />
      <mass value="1.24433" />
      <inertia ixx="0.01148700000" ixy="-0.000686" ixz="-0.00052600000" iyy="0.00952600000" iyz="0.002633" izz="0.00390800000" />
    </inertial>
    <visual>
      <origin rpy="0 0 0" xyz="0 0 0.0" />
      <geometry>
        <mesh filename="meshes/ankle_Y_lo_res.stl" scale="1 1 1" />
      </geometry>
      <material name="Grey" />
    </visual>
    <collision>
      <origin rpy="0 0 0" xyz="0 0 0.0" />
      <geometry>
        <mesh filename="meshes/ankle_Y_collision.stl" scale="1 1 1" />
      </geometry>
    </collision>
  </link>
  <joint name="leg_left_5_joint" type="revolute">
    <parent link="leg_left_4_link" />
    <child link="leg_left_5_link" />
    <origin rpy="0.0 0.0 0.0" xyz="0.00000 0.00000 -0.32500" />
    <axis xyz="0 1 0" />
    <limit effort="160" lower="-1.309" upper="0.768" velocity="5.8" />
    <dynamics damping="0.0" friction="0.0" />
  </joint>
  
  <link name="leg_left_6_link">
    <inertial>
      <origin rpy="0.00000 0.00000 0.00000" xyz="-0.02087 -0.00019 -0.06059" />
      <mass value="1.59457" />
      <inertia ixx="0.00383800000" ixy="0.00001600000" ixz="-0.00104100000" iyy="0.00657200000" iyz="-0.00001700000" izz="0.00504400000" />
    </inertial>
    <visual>
      <origin rpy="0 0 0" xyz="0 0 0" />
      <geometry>
        <mesh filename="meshes/ankle_X_lo_res.stl" scale="1 1 1" />
      </geometry>
      <material name="Grey" />
    </visual>
    
    <collision>
      <origin rpy="0 0 0" xyz="0 0 -0.1" />
      <geometry>
        <box size="0.21 0.13 0.02" />
      </geometry>
    </collision>
  </link>
  <joint name="leg_left_6_joint" type="revolute">
    <parent link="leg_left_5_link" />
    <child link="leg_left_6_link" />
    <origin rpy="0.0 0.0 0.0" xyz="0.00000 0.00000 0.00000" />
    <axis xyz="1 0 0" />
    <limit effort="100" lower="-0.5236" upper="0.5236" velocity="4.8" />
    <dynamics damping="0.0" friction="0.0" />
  </joint>
  
  <link name="left_sole_link">
    <inertial>
      <origin rpy="0 0 0" xyz="0.0 0.0 0.0" />
      <mass value="0.01" />
      <inertia ixx="0.0001" ixy="0.0" ixz="0.0" iyy="0.0001" iyz="0.0" izz="0.0001" />
    </inertial>
  </link>
  <joint name="leg_left_sole_fix_joint" type="fixed">
    <parent link="leg_left_6_link" />
    <child link="left_sole_link" />
    <origin rpy="0 0 0" xyz="0.00 0.00 -0.107" />
    <axis xyz="1 0 0" />
    <dynamics damping="0.0" friction="0.0" />
  </joint>
  <transmission name="leg_left_1_trans">
    <type>transmission_interface/SimpleTransmission</type>
    <actuator name="leg_left_1_motor">
      <mechanicalReduction>1.0</mechanicalReduction>
    </actuator>
    <joint name="leg_left_1_joint">
      <hardwareInterface>hardware_interface/PositionJointInterface</hardwareInterface>
      <hardwareInterface>hardware_interface/EffortJointInterface</hardwareInterface>
    </joint>
  </transmission>
  <transmission name="leg_left_2_trans">
    <type>transmission_interface/SimpleTransmission</type>
    <actuator name="leg_left_2_motor">
      <mechanicalReduction>1.0</mechanicalReduction>
    </actuator>
    <joint name="leg_left_2_joint">
      <hardwareInterface>hardware_interface/PositionJointInterface</hardwareInterface>
      <hardwareInterface>hardware_interface/EffortJointInterface</hardwareInterface>
    </joint>
  </transmission>
  <transmission name="leg_left_3_trans">
    <type>transmission_interface/SimpleTransmission</type>
    <actuator name="leg_left_3_motor">
      <mechanicalReduction>1.0</mechanicalReduction>
    </actuator>
    <joint name="leg_left_3_joint">
      <hardwareInterface>hardware_interface/PositionJointInterface</hardwareInterface>
      <hardwareInterface>hardware_interface/EffortJointInterface</hardwareInterface>
    </joint>
  </transmission>
  <transmission name="leg_left_4_trans">
    <type>transmission_interface/SimpleTransmission</type>
    <actuator name="leg_left_4_motor">
      <mechanicalReduction>1.0</mechanicalReduction>
    </actuator>
    <joint name="leg_left_4_joint">
      <hardwareInterface>hardware_interface/PositionJointInterface</hardwareInterface>
      <hardwareInterface>hardware_interface/EffortJointInterface</hardwareInterface>
    </joint>
  </transmission>
  <transmission name="leg_left_5_trans">
    <type>transmission_interface/SimpleTransmission</type>
    <actuator name="leg_left_5_motor">
      <mechanicalReduction>1.0</mechanicalReduction>
    </actuator>
    <joint name="leg_left_5_joint">
      <hardwareInterface>hardware_interface/PositionJointInterface</hardwareInterface>
      <hardwareInterface>hardware_interface/EffortJointInterface</hardwareInterface>
    </joint>
  </transmission>
  <transmission name="leg_left_6_trans">
    <type>transmission_interface/SimpleTransmission</type>
    <actuator name="leg_left_6_motor">
      <mechanicalReduction>1.0</mechanicalReduction>
    </actuator>
    <joint name="leg_left_6_joint">
      <hardwareInterface>hardware_interface/PositionJointInterface</hardwareInterface>
      <hardwareInterface>hardware_interface/EffortJointInterface</hardwareInterface>
    </joint>
  </transmission>
  
  
  
  
  
  
  
  
  
  
  
  
  
  
  
  
  
  
  
  
  <link name="leg_right_1_link">
    <inertial>
      <origin rpy="0.00000 0.00000 0.00000" xyz="0.02320 -0.00009 0.04949" />
      <mass value="1.88569" />
      <inertia ixx="0.00384800000" ixy="0.00003200000" ixz="-0.00082600000" iyy="0.00599400000" iyz="0.00007800000" izz="0.00322200000" />
    </inertial>
    <visual>
      <origin rpy="0 0 0" xyz="0 0 0" />
      <geometry>
        <mesh filename="meshes/hip_z_lo_res.stl" scale="1 -1 1" />
      </geometry>
      <material name="DarkGrey" />
    </visual>
    <collision>
      <origin rpy="0 0 0" xyz="0 0 0" />
      <geometry>
        <mesh filename="meshes/hip_z_collision.stl" scale="1 -1 1" />
      </geometry>
    </collision>
  </link>
  <joint name="leg_right_1_joint" type="revolute">
    <parent link="base_link" />
    <child link="leg_right_1_link" />
    <origin rpy="0.0 0.0 0.0" xyz="-0.02 -0.085 -0.27105" />
    <axis xyz="0 0 1" />
    <limit effort="100" lower="-1.57079632679" upper="0.349065850399" velocity="3.87" />
    <dynamics damping="0.0" friction="0.0" />
  </joint>
  
  <link name="leg_right_2_link">
    <inertial>
      <origin rpy="0.00000 0.00000 0.00000" xyz="0.01583 -0.00021 0.00619" />
      <mass value="2.37607" />
      <inertia ixx="0.00342100000" ixy="-0.00011300000" ixz="-0.00022500000" iyy="0.00402400000" iyz="-0.00003100000" izz="0.00416400000" />
    </inertial>
    <visual>
      <origin rpy="0 0 0" xyz="0 0 0.0" />
      <geometry>
        <mesh filename="meshes/hip_x_lo_res.stl" scale="1 -1 1" />
      </geometry>
      <material name="DarkGrey" />
    </visual>
    <collision>
      <origin rpy="0 0 0" xyz="0 0 0.0" />
      <geometry>
        <mesh filename="meshes/hip_x_collision.stl" scale="1 -1 1" />
      </geometry>
    </collision>
  </link>
  <joint name="leg_right_2_joint" type="revolute">
    <parent link="leg_right_1_link" />
    <child link="leg_right_2_link" />
    <origin rpy="0.0 0.0 0.0" xyz="0.00000 0.00000 0.00000" />
    <axis xyz="1 0 0" />
    <limit effort="160" lower="-0.5236" upper="0.5236" velocity="5.8" />
    <dynamics damping="0.0" friction="0.0" />
  </joint>
  
  <link name="leg_right_3_link">
    <inertial>
      <origin rpy="0.00000 0.00000 0.00000" xyz="0.00658 -0.06563 -0.17278" />
      <mass value="6.82734" />
      <inertia ixx="0.12390600000" ixy="0.000412" ixz="-0.00205900000" iyy="0.10844700000" iyz="-0.016725" izz="0.02781200000" />
    </inertial>
    <visual>
      <origin rpy="0 0 0" xyz="0 0 0" />
      <geometry>
        <mesh filename="meshes/hip_y_lo_res.stl" scale="1 -1 1" />
      </geometry>
      <material name="DarkGrey" />
    </visual>
    <collision>
      <origin rpy="0 0 0" xyz="0 0 0" />
      <geometry>
        <mesh filename="meshes/hip_y_collision.stl" scale="1 -1 1" />
      </geometry>
    </collision>
  </link>
  <joint name="leg_right_3_joint" type="revolute">
    <parent link="leg_right_2_link" />
    <child link="leg_right_3_link" />
    <origin rpy="0.0 0.0 0.0" xyz="0.00000 0.00000 0.00000" />
    <axis xyz="0 1 0" />
    <limit effort="160" lower="-2.095" upper="0.7" velocity="5.8" />
    <dynamics damping="0.0" friction="0.0" />
  </joint>
  
  <link name="leg_right_4_link">
    <inertial>
      <origin rpy="0.00000 0.00000 0.00000" xyz="0.01520 -0.02331 -0.12063" />
      <mass value="3.63668" />
      <inertia ixx="0.03531500000" ixy="-2.9e-05" ixz="-0.00016600000" iyy="0.02933600000" iyz="0.001305" izz="0.01174000000" />
    </inertial>
    <visual>
      <origin rpy="0 0 0" xyz="0 0 0" />
      <geometry>
        <mesh filename="meshes/knee_lo_res.stl" scale="1 -1 1" />
      </geometry>
      <material name="DarkGrey" />
    </visual>
    <collision>
      <origin rpy="0 0 0" xyz="0 0 0" />
      <geometry>
        <mesh filename="meshes/knee_collision.stl" scale="1 -1 1" />
      </geometry>
    </collision>
  </link>
  <joint name="leg_right_4_joint" type="revolute">
    <parent link="leg_right_3_link" />
    <child link="leg_right_4_link" />
    <origin rpy="0.0 0.0 0.0" xyz="0.00000 0.00000 -0.38000" />
    <axis xyz="0 1 0" />
    <limit effort="300" lower="0" upper="2.618" velocity="7" />
    <dynamics damping="0.0" friction="0.0" />
  </joint>
  
  <link name="leg_right_5_link">
    <inertial>
      <origin rpy="0.00000 0.00000 0.00000" xyz="-0.01106 -0.04708 0.05271" />
      <mass value="1.24433" />
      <inertia ixx="0.01148700000" ixy="0.000686" ixz="-0.00052600000" iyy="0.00952600000" iyz="-0.002633" izz="0.00390800000" />
    </inertial>
    <visual>
      <origin rpy="0 0 0" xyz="0 0 0.0" />
      <geometry>
        <mesh filename="meshes/ankle_Y_lo_res.stl" scale="1 -1 1" />
      </geometry>
      <material name="Grey" />
    </visual>
    <collision>
      <origin rpy="0 0 0" xyz="0 0 0.0" />
      <geometry>
        <mesh filename="meshes/ankle_Y_collision.stl" scale="1 -1 1" />
      </geometry>
    </collision>
  </link>
  <joint name="leg_right_5_joint" type="revolute">
    <parent link="leg_right_4_link" />
    <child link="leg_right_5_link" />
    <origin rpy="0.0 0.0 0.0" xyz="0.00000 0.00000 -0.32500" />
    <axis xyz="0 1 0" />
    <limit effort="160" lower="-1.309" upper="0.768" velocity="5.8" />
    <dynamics damping="0.0" friction="0.0" />
  </joint>
  
  <link name="leg_right_6_link">
    <inertial>
      <origin rpy="0.00000 0.00000 0.00000" xyz="-0.02087 -0.00019 -0.06059" />
      <mass value="1.59457" />
      <inertia ixx="0.00383800000" ixy="0.00001600000" ixz="-0.00104100000" iyy="0.00657200000" iyz="-0.00001700000" izz="0.00504400000" />
    </inertial>
    <visual>
      <origin rpy="0 0 0" xyz="0 0 0" />
      <geometry>
        <mesh filename="meshes/ankle_X_lo_res.stl" scale="1 -1 1" />
      </geometry>
      <material name="Grey" />
    </visual>
    
    <collision>
      <origin rpy="0 0 0" xyz="0 0 -0.1" />
      <geometry>
        <box size="0.21 0.13 0.02" />
      </geometry>
    </collision>
  </link>
  <joint name="leg_right_6_joint" type="revolute">
    <parent link="leg_right_5_link" />
    <child link="leg_right_6_link" />
    <origin rpy="0.0 0.0 0.0" xyz="0.00000 0.00000 0.00000" />
    <axis xyz="1 0 0" />
    <limit effort="100" lower="-0.5236" upper="0.5236" velocity="4.8" />
    <dynamics damping="0.0" friction="0.0" />
  </joint>
  
  <link name="right_sole_link">
    <inertial>
      <origin rpy="0 0 0" xyz="0.0 0.0 0.0" />
      <mass value="0.01" />
      <inertia ixx="0.0001" ixy="0.0" ixz="0.0" iyy="0.0001" iyz="0.0" izz="0.0001" />
    </inertial>
  </link>
  <joint name="leg_right_sole_fix_joint" type="fixed">
    <parent link="leg_right_6_link" />
    <child link="right_sole_link" />
    <origin rpy="0 0 0" xyz="0.00 0.00 -0.107" />
    <axis xyz="1 0 0" />
    <dynamics damping="0.0" friction="0.0" />
  </joint>
  <transmission name="leg_right_1_trans">
    <type>transmission_interface/SimpleTransmission</type>
    <actuator name="leg_right_1_motor">
      <mechanicalReduction>1.0</mechanicalReduction>
    </actuator>
    <joint name="leg_right_1_joint">
      <hardwareInterface>hardware_interface/PositionJointInterface</hardwareInterface>
      <hardwareInterface>hardware_interface/EffortJointInterface</hardwareInterface>
    </joint>
  </transmission>
  <transmission name="leg_right_2_trans">
    <type>transmission_interface/SimpleTransmission</type>
    <actuator name="leg_right_2_motor">
      <mechanicalReduction>1.0</mechanicalReduction>
    </actuator>
    <joint name="leg_right_2_joint">
      <hardwareInterface>hardware_interface/PositionJointInterface</hardwareInterface>
      <hardwareInterface>hardware_interface/EffortJointInterface</hardwareInterface>
    </joint>
  </transmission>
  <transmission name="leg_right_3_trans">
    <type>transmission_interface/SimpleTransmission</type>
    <actuator name="leg_right_3_motor">
      <mechanicalReduction>1.0</mechanicalReduction>
    </actuator>
    <joint name="leg_right_3_joint">
      <hardwareInterface>hardware_interface/PositionJointInterface</hardwareInterface>
      <hardwareInterface>hardware_interface/EffortJointInterface</hardwareInterface>
    </joint>
  </transmission>
  <transmission name="leg_right_4_trans">
    <type>transmission_interface/SimpleTransmission</type>
    <actuator name="leg_right_4_motor">
      <mechanicalReduction>1.0</mechanicalReduction>
    </actuator>
    <joint name="leg_right_4_joint">
      <hardwareInterface>hardware_interface/PositionJointInterface</hardwareInterface>
      <hardwareInterface>hardware_interface/EffortJointInterface</hardwareInterface>
    </joint>
  </transmission>
  <transmission name="leg_right_5_trans">
    <type>transmission_interface/SimpleTransmission</type>
    <actuator name="leg_right_5_motor">
      <mechanicalReduction>1.0</mechanicalReduction>
    </actuator>
    <joint name="leg_right_5_joint">
      <hardwareInterface>hardware_interface/PositionJointInterface</hardwareInterface>
      <hardwareInterface>hardware_interface/EffortJointInterface</hardwareInterface>
    </joint>
  </transmission>
  <transmission name="leg_right_6_trans">
    <type>transmission_interface/SimpleTransmission</type>
    <actuator name="leg_right_6_motor">
      <mechanicalReduction>1.0</mechanicalReduction>
    </actuator>
    <joint name="leg_right_6_joint">
      <hardwareInterface>hardware_interface/PositionJointInterface</hardwareInterface>
      <hardwareInterface>hardware_interface/EffortJointInterface</hardwareInterface>
    </joint>
  </transmission>
  
  
  
  
  
  
  
  
  
  
  
  
  
  
  
  
  
  
  
  
  
  
  
  
  
  
  
  <material name="Blue">
    <color rgba="0.0 0.0 0.8 1.0" />
  </material>
  <material name="Green">
    <color rgba="0.0 0.8 0.0 1.0" />
  </material>
  <material name="Grey">
    <color rgba="0.7 0.7 0.7 1.0" />
  </material>
  <material name="LightGrey">
    <color rgba="0.9 0.9 0.9 1.0" />
  </material>
  <material name="DarkGrey">
    <color rgba="0.2 0.2 0.2 1.0" />
  </material>
  <material name="Red">
    <color rgba="0.8 0.0 0.0 1.0" />
  </material>
  <material name="White">
    <color rgba="1.0 1.0 1.0 1.0" />
  </material>
  <material name="Orange">
    <color rgba="1.0 0.5 0.0 1.0" />
  </material>
</robot>