<?xml version='1.0' encoding='utf-8'?>
<robot name="fingeredu">
  
  
  <material name="fingeredu_material">
    <color rgba="0.6 0.6 0.6 1.0" />
  </material>
  <link name="base_link">
    <inertial>
      <origin rpy="0 0 0" xyz="0 0 0" />
      <mass value="1" />
      <inertia ixx="4.16666666667e-06" ixy="0" ixz="0" iyy="4.16666666667e-06" iyz="0" izz="4.16666666667e-06" />
    </inertial>
  </link>
  
  <link name="finger_base_link">
    <visual>
      <origin rpy="0 0 0" xyz="-0.17995 0 0" />
      <geometry>
        <mesh filename="meshes/base_back.stl" scale="1 1 1" />
      </geometry>
      <material name="fingeredu_material" />
    </visual>
    <collision>
      <origin rpy="0 0 0" xyz="-0.17995 0 0" />
      <geometry>
        <mesh filename="meshes/base_back.stl" scale="1 1 1" />
      </geometry>
    </collision>
    <visual>
      <origin rpy="0 0 0" xyz="0.0255 0 0" />
      <geometry>
        <mesh filename="meshes/base_front.stl" scale="1 1 1" />
      </geometry>
      <material name="fingeredu_material" />
    </visual>
    <collision>
      <origin rpy="0 0 0" xyz="0.0255 0 0" />
      <geometry>
        <mesh filename="meshes/base_front.stl" scale="1 1 1" />
      </geometry>
    </collision>
    <visual>
      <origin rpy="0 0 0" xyz="0.0255 0.02 0.08" />
      <geometry>
        <mesh filename="meshes/base_side_left.stl" scale="1 1 1" />
      </geometry>
      <material name="fingeredu_material" />
    </visual>
    <collision>
      <origin rpy="0 0 0" xyz="0.0255 0.02 0.08" />
      <geometry>
        <mesh filename="meshes/base_side_left.stl" scale="1 1 1" />
      </geometry>
    </collision>
    
    <visual>
      <origin rpy="0 0 0" xyz="0.0255 0 0.08" />
      <geometry>
        <mesh filename="meshes/base_top.stl" scale="1 1 1" />
      </geometry>
      <material name="fingeredu_material" />
    </visual>
    <collision>
      <origin rpy="0 0 0" xyz="0.0255 0 0.08" />
      <geometry>
        <mesh filename="meshes/base_top.stl" scale="1 1 1" />
      </geometry>
    </collision>
    <inertial>
      <origin rpy="0 0 0" xyz="-0.1 0 0.4" />
      <mass value="1" />
      <inertia ixx="0.0608333333333" ixy="0" ixz="0" iyy="0.0566666666667" iyz="0" izz="0.0108333333333" />
    </inertial>
  </link>
  
  
  <link name="finger_upper_link">
    <visual>
      <origin rpy="0 0 0" xyz="0.0195 0 0" />
      <geometry>
        <mesh filename="meshes/upper_link.stl" scale="1 1 1" />
      </geometry>
      <material name="fingeredu_material" />
    </visual>
    <collision>
      <origin rpy="0 0 0" xyz="0.0195 0 0" />
      <geometry>
        <mesh filename="meshes/upper_link.stl" scale="1 1 1" />
      </geometry>
    </collision>
    <inertial>
      
      
      <origin rpy="0 0 0" xyz="-0.079 0 0" />
      <mass value="0.14854" />
      <inertia ixx="0.00003" ixy="0.00005" ixz="0.00000" iyy="0.00041" iyz="0.00000" izz="0.00041" />
    </inertial>
  </link>
  <link name="finger_middle_link">
    <visual>
      <origin rpy="0 0 0" xyz="0 0 0" />
      <geometry>
        <mesh filename="meshes/middle_link.stl" scale="1 1 1" />
      </geometry>
      <material name="fingeredu_material" />
    </visual>
    <collision>
      <origin rpy="0 0 0" xyz="0 0 0" />
      <geometry>
        <mesh filename="meshes/middle_link.stl" scale="1 1 1" />
      </geometry>
    </collision>
    <inertial>
      <origin rpy="0 0 0" xyz="0 -0.019 -0.079" />
      <mass value="0.14854" />
      <inertia ixx="0.00041" ixy="0.00000" ixz="0.00000" iyy="0.00041" iyz="0.00005" izz="0.00003" />
    </inertial>
  </link>
  <link name="finger_lower_link">
    <visual>
      <origin rpy="0 0 0" xyz="0 0 0" />
      <geometry>
        <mesh filename="meshes/lower_link.stl" scale="1 1 1" />
      </geometry>
      <material name="fingeredu_material" />
    </visual>
    <collision>
      <origin rpy="0 0 0" xyz="0 0 0" />
      <geometry>
        <mesh filename="meshes/lower_link.stl" scale="1 1 1" />
      </geometry>
    </collision>
    
    <inertial>
      <origin rpy="0 0 0" xyz="0 -0.009 -0.089" />
      <mass value="0.03070" />
      <inertia ixx="0.00012" ixy="0.00000" ixz="0.00000" iyy="0.00012" iyz="0.00000" izz="0.00000" />
    </inertial>
  </link>
  
  <link name="finger_tip_link">
    <inertial>
      <origin rpy="0 0 0" xyz="0 0 0" />
      <mass value="0.01" />
      <inertia ixx="1.66666666667e-07" ixy="0" ixz="0" iyy="1.66666666667e-07" iyz="0" izz="1.66666666667e-07" />
    </inertial>
  </link>
  <joint name="finger_lower_to_tip_joint" type="fixed">
    <parent link="finger_lower_link" />
    <child link="finger_tip_link" />
    <origin xyz="0 -0.008 -0.16" />
  </joint>
  
  <joint name="finger_base_to_upper_joint" type="revolute">
    <parent link="finger_base_link" />
    <child link="finger_upper_link" />
    <limit effort="1000" lower="-1.57079632679" upper="1.57079632679" velocity="1000" />
    <axis xyz="-1 0 0" />
    <origin rpy="0 0 0" xyz="0 0 0" />
  </joint>
  <joint name="finger_upper_to_middle_joint" type="revolute">
    <parent link="finger_upper_link" />
    <child link="finger_middle_link" />
    <limit effort="1000" lower="-1.57079632679" upper="1.57079632679" velocity="1000" />
    <axis xyz="0 1 0" />
    <origin rpy="0 0 0" xyz="0 -0.014 0" />
  </joint>
  <joint name="finger_middle_to_lower_joint" type="revolute">
    <parent link="finger_middle_link" />
    <child link="finger_lower_link" />
    <limit effort="1000" lower="-3.14159265359" upper="3.14159265359" velocity="1000" />
    <axis xyz="0 1 0" />
    <origin rpy="0 0 0" xyz="0 -0.03745 -0.16" />
  </joint>
  
  <joint name="base_to_finger" type="fixed">
    <parent link="base_link" />
    <child link="finger_base_link" />
    <origin xyz="0 0 0.283" />
  </joint>
</robot>