<?xml version='1.0' encoding='utf-8'?>
<robot name="r1000ia_130f">
  <link name="world" />
  <link name="ee_link" />
  
  <link name="base_link">
    <visual>
      <origin rpy="0 0 0" xyz="0 0 0" />
      <geometry>
        <mesh filename="meshes/base.dae" />
      </geometry>
    </visual>
    <collision>
      <origin rpy="0 0 0" xyz="0 0 0" />
      <geometry>
        <mesh filename="meshes/base.stl" />
      </geometry>
    </collision>
    <inertial>
      <mass value=" 141" />
      <origin xyz="-.146 .00115 .117" />
      <inertia ixx=" 2.76" ixy=" .0638" ixz="-.158" iyy=" 6.88" iyz=" .0137" izz=" 8.33" />
    </inertial>
  </link>
  <link name="J1_link">
    <visual>
      <origin rpy="0 0 0" xyz="0 0 0" />
      <geometry>
        <mesh filename="meshes/j1.dae" />
      </geometry>
    </visual>
    <collision>
      <origin rpy="0 0 0" xyz="0 0 0" />
      <geometry>
        <mesh filename="meshes/j1.stl" />
      </geometry>
    </collision>
    <inertial>
      <mass value=" 196" />
      <origin xyz=".14 -.0172 -.0368" />
      <inertia ixx=" 5.69" ixy=" .046" ixz="-.247" iyy=" 7.72" iyz=" .484" izz=" 8.51" />
    </inertial>
  </link>
  <link name="J2_link">
    <visual>
      <origin rpy="0 0 0" xyz="0 0 0" />
      <geometry>
        <mesh filename="meshes/j2.dae" />
      </geometry>
    </visual>
    <collision>
      <origin rpy="0 0 0" xyz="0 0 0" />
      <geometry>
        <mesh filename="meshes/j2.stl" />
      </geometry>
    </collision>
    <inertial>
      <mass value=" 110" />
      <origin xyz=".00598 .148 .394" />
      <inertia ixx=" 10.3" ixy="-.00252" ixz=" .00625" iyy=" 10.7" iyz="-.167" izz=" 1.03" />
    </inertial>
  </link>
  <link name="J3_link">
    <visual>
      <origin rpy="0 0 0" xyz="0 0 0" />
      <geometry>
        <mesh filename="meshes/j3.dae" />
      </geometry>
    </visual>
    <collision>
      <origin rpy="0 0 0" xyz="0 0 0" />
      <geometry>
        <mesh filename="meshes/j3.stl" />
      </geometry>
    </collision>
    <inertial>
      <mass value=" 205" />
      <origin xyz=".238 .0114 .137" />
      <inertia ixx=" 5.21" ixy="-.0632" ixz="-1.89" iyy=" 13.3" iyz="-.196" izz=" 12.4" />
    </inertial>
  </link>
  <link name="J4_link">
    <visual>
      <origin rpy="0 0 0" xyz="0 0 0" />
      <geometry>
        <mesh filename="meshes/j4.dae" />
      </geometry>
    </visual>
    <collision>
      <origin rpy="0 0 0" xyz="0 0 0" />
      <geometry>
        <mesh filename="meshes/j4.stl" />
      </geometry>
    </collision>
    <inertial>
      <mass value=" 7.84" />
      <origin xyz=".929 -.00482 1.99E-16" />
      <inertia ixx=" .0229" ixy=" .00214" ixz=" 2.97E-15" iyy=" .0503" iyz=" .00000000000454" izz=" .0478" />
    </inertial>
  </link>
  <link name="J5_link">
    <visual>
      <origin rpy="0 0 0" xyz="0 0 0" />
      <geometry>
        <mesh filename="meshes/j5.dae" />
      </geometry>
    </visual>
    <collision>
      <origin rpy="0 0 0" xyz="0 0 0" />
      <geometry>
        <mesh filename="meshes/j5.stl" />
      </geometry>
    </collision>
    <inertial>
      <mass value=" 15.3" />
      <origin xyz=".0473 -.0132 -.00000000107" />
      <inertia ixx=" .0851" ixy="-.0118" ixz="-.000000000371" iyy=" .105" iyz="-.000000000953" izz=" .127" />
    </inertial>
  </link>
  <link name="J6_link">
    <visual>
      <origin rpy="0 0 0" xyz="0 0 0" />
      <geometry>
        <mesh filename="meshes/j6.dae" />
      </geometry>
    </visual>
    <collision>
      <origin rpy="0 0 0" xyz="0 0 0" />
      <geometry>
        <mesh filename="meshes/j6.stl" />
      </geometry>
    </collision>
    <inertial>
      <mass value=" .423" />
      <origin xyz=".181 .00000000234 .000171" />
      <inertia ixx=" .000843" ixy="-.00000000000497" ixz="-.00000046" iyy=" .000431" iyz=" .000000000056" izz=" .000435" />
    </inertial>
  </link>
  
  <joint name="J1" type="revolute">
    <origin rpy="0 0 0" xyz="0 0 .45" />
    <parent link="base_link" />
    <child link="J1_link" />
    <axis xyz="0 0 1" />
    <limit effort="9000" lower="-3.141592653589793" upper="3.141592653589793" velocity="2.2689280275926285" />
  </joint>
  <joint name="J2" type="revolute">
    <origin rpy="0 0 0" xyz=".32 0 0" />
    <parent link="J1_link" />
    <child link="J2_link" />
    <axis xyz="0 1 0" />
    <limit effort="30000" lower="-1.5707963267948966" upper="2.705260340591211" velocity="1.9198621771937625" />
  </joint>
  <joint name="J3" type="revolute">
    <origin rpy="0 0 0" xyz="0 0 .87" />
    <parent link="J2_link" />
    <child link="J3_link" />
    <axis xyz="0 -1 0" />
    <limit effort="8000" lower="-1.4311699866353502" upper="2.443460952792061" velocity="2.0943951023931953" />
  </joint>
  <joint name="J4" type="revolute">
    <origin rpy="0 0 0" xyz="0 0 .225" />
    <parent link="J3_link" />
    <child link="J4_link" />
    <axis xyz="-1 0 0" />
    <limit effort="3000" lower="-6.283185307179586" upper="6.283185307179586" velocity="2.9670597283903604" />
  </joint>
  <joint name="J5" type="revolute">
    <origin rpy="0 0 0" xyz="1.015 0 0" />
    <parent link="J4_link" />
    <child link="J5_link" />
    <axis xyz="0 -1 0" />
    <limit effort="3000" lower="-2.181661564992912" upper="2.181661564992912" velocity="2.9670597283903604" />
  </joint>
  <joint name="J6" type="revolute">
    <origin rpy="0 0 0" xyz="0 0 0" />
    <parent link="J5_link" />
    <child link="J6_link" />
    <axis xyz="-1 0 0" />
    <limit effort="2000" lower="-6.283185307179586" upper="6.283185307179586" velocity="4.363323129985824" />
  </joint>
  
  <link name="wbase" />
  <joint name="base_link-wbase" type="fixed">
    <origin rpy="0 0 0" xyz="0 0 .45" />
    <parent link="base_link" />
    <child link="wbase" />
  </joint>
  
  <link name="flange" />
  <joint name="J6-flange" type="fixed">
    <origin rpy="0 0 0" xyz=".19 0 0" />
    <parent link="J6_link" />
    <child link="flange" />
  </joint>
  
  <link name="fanuc_flange" />
  <joint name="flange-fanuc_flange" type="fixed">
    <origin rpy="3.141592653589793 -1.5707963267948966 0.0" xyz="0 0 0" />
    <parent link="flange" />
    <child link="fanuc_flange" />
  </joint>
  
  <joint name="base_joint" type="fixed">
    <origin rpy="0 0 0" xyz="0 0 0" />
    <parent link="world" />
    <child link="base_link" />
  </joint>
  
  <joint name="child_joint" type="fixed">
    <origin rpy="0 0 0" xyz="0 0 0" />
    <parent link="flange" />
    <child link="ee_link" />
  </joint>
</robot>