<?xml version='1.0' encoding='utf-8'?>
<robot name="lrmate200id7l">
  <link name="world" />
  <link name="ee_link" />
  
  <link name="base_link">
    <visual>
      <origin rpy="0 0 0" xyz="0 0 0" />
      <geometry>
        <mesh filename="meshes/base.dae" />
      </geometry>
    </visual>
    <collision>
      <origin rpy="0 0 0" xyz="0 0 0" />
      <geometry>
        <mesh filename="meshes/base.stl" />
      </geometry>
    </collision>
    <inertial>
      <mass value=" 5.09" />
      <origin xyz="-.0146 -.000342 .0796" />
      <inertia ixx=" .0241" ixy="-.000552" ixz=" .000285" iyy=" .0294" iyz="-.000117" izz=" .0309" />
    </inertial>
  </link>
  <link name="J1_link">
    <visual>
      <origin rpy="0 0 0" xyz="0 0 0" />
      <geometry>
        <mesh filename="meshes/j1.dae" />
      </geometry>
    </visual>
    <collision>
      <origin rpy="0 0 0" xyz="0 0 0" />
      <geometry>
        <mesh filename="meshes/j1.stl" />
      </geometry>
    </collision>
    <inertial>
      <mass value=" 5.41" />
      <origin xyz=".0287 .000102 -.0547" />
      <inertia ixx=" .0401" ixy=" .0000229" ixz="-.0053" iyy=" .0291" iyz=" .000117" izz=" .031" />
    </inertial>
  </link>
  <link name="J2_link">
    <visual>
      <origin rpy="0 0 0" xyz="0 0 0" />
      <geometry>
        <mesh filename="meshes/j2.dae" />
      </geometry>
    </visual>
    <collision>
      <origin rpy="0 0 0" xyz="0 0 0" />
      <geometry>
        <mesh filename="meshes/j2.stl" />
      </geometry>
    </collision>
    <inertial>
      <mass value=" 10.9" />
      <origin xyz="-.00311 -.00124 .217" />
      <inertia ixx=" .28" ixy=" .0000324" ixz=" .000718" iyy=" .255" iyz="-.00195" izz=" .0511" />
    </inertial>
  </link>
  <link name="J3_link">
    <visual>
      <origin rpy="0 0 0" xyz="0 0 0" />
      <geometry>
        <mesh filename="meshes/j3.dae" />
      </geometry>
    </visual>
    <collision>
      <origin rpy="0 0 0" xyz="0 0 0" />
      <geometry>
        <mesh filename="meshes/j3.stl" />
      </geometry>
    </collision>
    <inertial>
      <mass value=" 2.07" />
      <origin xyz=".00887 -.0000626 .0171" />
      <inertia ixx=" .00562" ixy="-.0000442" ixz="-.000598" iyy=" .0064" iyz="-.0000443" izz=" .00643" />
    </inertial>
  </link>
  <link name="J4_link">
    <visual>
      <origin rpy="0 0 0" xyz="0 0 0" />
      <geometry>
        <mesh filename="meshes/j4.dae" />
      </geometry>
    </visual>
    <collision>
      <origin rpy="0 0 0" xyz="0 0 0" />
      <geometry>
        <mesh filename="meshes/j4.stl" />
      </geometry>
    </collision>
    <inertial>
      <mass value=" 3.07" />
      <origin xyz=".266 .00354 .00226" />
      <inertia ixx=" .00511" ixy="-.00000922" ixz=" .0000312" iyy=" .0347" iyz="-.0000096" izz=" .0346" />
    </inertial>
  </link>
  <link name="J5_link">
    <visual>
      <origin rpy="0 0 0" xyz="0 0 0" />
      <geometry>
        <mesh filename="meshes/j5.dae" />
      </geometry>
    </visual>
    <collision>
      <origin rpy="0 0 0" xyz="0 0 0" />
      <geometry>
        <mesh filename="meshes/j5.stl" />
      </geometry>
    </collision>
    <inertial>
      <mass value=" .428" />
      <origin xyz=".0177 .0025 -.00000419" />
      <inertia ixx=" .000326" ixy=" .0000179" ixz="-.0000000201" iyy=" .000578" iyz="-.0000000165" izz=" .000542" />
    </inertial>
  </link>
  <link name="J6_link">
    <visual>
      <origin rpy="0 0 0" xyz="0 0 0" />
      <geometry>
        <mesh filename="meshes/j6.dae" />
      </geometry>
    </visual>
    <collision>
      <origin rpy="0 0 0" xyz="0 0 0" />
      <geometry>
        <mesh filename="meshes/j6.stl" />
      </geometry>
    </collision>
    <inertial>
      <mass value=" .0129" />
      <origin xyz=".074 3.35E-18 -4.88E-19" />
      <inertia ixx=" .00000264" ixy=" 6.82E-21" ixz="-4.09E-22" iyy=" .00000148" iyz="-1.01E-22" izz=" .00000148" />
    </inertial>
  </link>
  
  <joint name="J1" type="revolute">
    <origin rpy="0 0 0" xyz="0 0 .33" />
    <parent link="base_link" />
    <child link="J1_link" />
    <axis xyz="0 0 1" />
    <limit effort="600" lower="-3.141592653589793" upper="3.141592653589793" velocity="6.457718232379019" />
  </joint>
  <joint name="J2" type="revolute">
    <origin rpy="0 0 0" xyz=".05 0 0" />
    <parent link="J1_link" />
    <child link="J2_link" />
    <axis xyz="0 1 0" />
    <limit effort="600" lower="-1.7453292519943295" upper="2.530727415391778" velocity="5.410520681182422" />
  </joint>
  <joint name="J3" type="revolute">
    <origin rpy="0 0 0" xyz="0 0 .44" />
    <parent link="J2_link" />
    <child link="J3_link" />
    <axis xyz="0 -1 0" />
    <limit effort="300" lower="-1.2217304763960306" upper="3.717551306747922" velocity="7.155849933176751" />
  </joint>
  <joint name="J4" type="revolute">
    <origin rpy="0 0 0" xyz="0 0 .035" />
    <parent link="J3_link" />
    <child link="J4_link" />
    <axis xyz="-1 0 0" />
    <limit effort="70" lower="-3.3161255787892263" upper="3.3161255787892263" velocity="9.599310885968812" />
  </joint>
  <joint name="J5" type="revolute">
    <origin rpy="0 0 0" xyz=".42 0 0" />
    <parent link="J4_link" />
    <child link="J5_link" />
    <axis xyz="0 -1 0" />
    <limit effort="40" lower="-2.181661564992912" upper="2.181661564992912" velocity="9.512044423369096" />
  </joint>
  <joint name="J6" type="revolute">
    <origin rpy="0 0 0" xyz="0 0 0" />
    <parent link="J5_link" />
    <child link="J6_link" />
    <axis xyz="-1 0 0" />
    <limit effort="20" lower="-6.283185307179586" upper="6.283185307179586" velocity="17.453292519943297" />
  </joint>
  
  <link name="wbase" />
  <joint name="base_link-wbase" type="fixed">
    <origin rpy="0 0 0" xyz="0 0 .33" />
    <parent link="base_link" />
    <child link="wbase" />
  </joint>
  
  <link name="flange" />
  <joint name="J6-flange" type="fixed">
    <origin rpy="0 0 0" xyz=".08 0 0" />
    <parent link="J6_link" />
    <child link="flange" />
  </joint>
  
  <link name="fanuc_flange" />
  <joint name="flange-fanuc_flange" type="fixed">
    <origin rpy="3.141592653589793 -1.5707963267948966 0.0" xyz="0 0 0" />
    <parent link="flange" />
    <child link="fanuc_flange" />
  </joint>
  
  <joint name="base_joint" type="fixed">
    <origin rpy="0 0 0" xyz="0 0 0" />
    <parent link="world" />
    <child link="base_link" />
  </joint>
  
  <joint name="child_joint" type="fixed">
    <origin rpy="0 0 0" xyz="0 0 0" />
    <parent link="flange" />
    <child link="ee_link" />
  </joint>
</robot>