<?xml version='1.0' encoding='utf-8'?>
<robot name="m710ic_20m">
  <link name="world" />
  <link name="ee_link" />
  
  <link name="base_link">
    <visual>
      <origin rpy="0 0 0" xyz="0 0 0" />
      <geometry>
        <mesh filename="meshes/base.dae" />
      </geometry>
    </visual>
    <collision>
      <origin rpy="0 0 0" xyz="0 0 0" />
      <geometry>
        <mesh filename="meshes/base.stl" />
      </geometry>
    </collision>
    <inertial>
      <mass value=" 123" />
      <origin xyz="-.0576 -.0009 .119" />
      <inertia ixx=" 3.25" ixy="-.0141" ixz=" .038" iyy=" 3.53" iyz="-.00627" izz=" 5.51" />
    </inertial>
  </link>
  <link name="J1_link">
    <visual>
      <origin rpy="0 0 0" xyz="0 0 0" />
      <geometry>
        <mesh filename="meshes/j1.dae" />
      </geometry>
    </visual>
    <collision>
      <origin rpy="0 0 0" xyz="0 0 0" />
      <geometry>
        <mesh filename="meshes/j1.stl" />
      </geometry>
    </collision>
    <inertial>
      <mass value=" 185" />
      <origin xyz=".0512 -.00715 -.104" />
      <inertia ixx=" 6.88" ixy="-.304" ixz="-.478" iyy=" 5.86" iyz=" .197" izz=" 7.38" />
    </inertial>
  </link>
  <link name="J2_link">
    <visual>
      <origin rpy="0 0 0" xyz="0 0 0" />
      <geometry>
        <mesh filename="meshes/j2.dae" />
      </geometry>
    </visual>
    <collision>
      <origin rpy="0 0 0" xyz="0 0 0" />
      <geometry>
        <mesh filename="meshes/j2.stl" />
      </geometry>
    </collision>
    <inertial>
      <mass value=" 97.7" />
      <origin xyz=".0018 .145 .39" />
      <inertia ixx=" 9.2" ixy=" .0165" ixz=" .0123" iyy=" 9.5" iyz="-.0735" izz=" .863" />
    </inertial>
  </link>
  <link name="J3_link">
    <visual>
      <origin rpy="0 0 0" xyz="0 0 0" />
      <geometry>
        <mesh filename="meshes/j3.dae" />
      </geometry>
    </visual>
    <collision>
      <origin rpy="0 0 0" xyz="0 0 0" />
      <geometry>
        <mesh filename="meshes/j3.stl" />
      </geometry>
    </collision>
    <inertial>
      <mass value=" 80.2" />
      <origin xyz=".077 -.0376 .118" />
      <inertia ixx=" 1.5" ixy="-.119" ixz="-.196" iyy=" 1.91" iyz=" .0305" izz=" 1.66" />
    </inertial>
  </link>
  <link name="J4_link">
    <visual>
      <origin rpy="0 0 0" xyz="0 0 0" />
      <geometry>
        <mesh filename="meshes/j4.dae" />
      </geometry>
    </visual>
    <collision>
      <origin rpy="0 0 0" xyz="0 0 0" />
      <geometry>
        <mesh filename="meshes/j4.stl" />
      </geometry>
    </collision>
    <inertial>
      <mass value=" 41.3" />
      <origin xyz=".978 -.00621 .00000000224" />
      <inertia ixx=" .128" ixy=" .0536" ixz="-.00000000102" iyy=" 5.3" iyz=" .00000000678" izz=" 5.32" />
    </inertial>
  </link>
  <link name="J5_link">
    <visual>
      <origin rpy="0 0 0" xyz="0 0 0" />
      <geometry>
        <mesh filename="meshes/j5.dae" />
      </geometry>
    </visual>
    <collision>
      <origin rpy="0 0 0" xyz="0 0 0" />
      <geometry>
        <mesh filename="meshes/j5.stl" />
      </geometry>
    </collision>
    <inertial>
      <mass value=" 2.86" />
      <origin xyz="-.00371 .00471 -.00439" />
      <inertia ixx=" .00413" ixy=" .0000825" ixz="-.0000955" iyy=" .00951" iyz="-.0000088" izz=" .00942" />
    </inertial>
  </link>
  <link name="J6_link">
    <visual>
      <origin rpy="0 0 0" xyz="0 0 0" />
      <geometry>
        <mesh filename="meshes/j6.dae" />
      </geometry>
    </visual>
    <collision>
      <origin rpy="0 0 0" xyz="0 0 0" />
      <geometry>
        <mesh filename="meshes/j6.stl" />
      </geometry>
    </collision>
    <inertial>
      <mass value=" .038" />
      <origin xyz=".0955 -7.91E-18 1.33E-17" />
      <inertia ixx=" .0000153" ixy="-1.98E-20" ixz=" 1.92E-19" iyy=" .00000788" iyz=" 8.45E-21" izz=" .00000788" />
    </inertial>
  </link>
  
  <joint name="J1" type="revolute">
    <origin rpy="0 0 0" xyz="0 0 .565" />
    <parent link="base_link" />
    <child link="J1_link" />
    <axis xyz="0 0 1" />
    <limit effort="5000" lower="-3.141592653589793" upper="3.141592653589793" velocity="3.0543261909900767" />
  </joint>
  <joint name="J2" type="revolute">
    <origin rpy="0 0 0" xyz=".15 0 0" />
    <parent link="J1_link" />
    <child link="J2_link" />
    <axis xyz="0 1 0" />
    <limit effort="6000" lower="-1.5707963267948966" upper="2.356194490192345" velocity="3.0543261909900767" />
  </joint>
  <joint name="J3" type="revolute">
    <origin rpy="0 0 0" xyz="0 0 .87" />
    <parent link="J2_link" />
    <child link="J3_link" />
    <axis xyz="0 -1 0" />
    <limit effort="4000" lower="-1.4049900478554354" upper="3.5779249665883754" velocity="3.141592653589793" />
  </joint>
  <joint name="J4" type="revolute">
    <origin rpy="0 0 0" xyz="0 0 .19" />
    <parent link="J3_link" />
    <child link="J4_link" />
    <axis xyz="-1 0 0" />
    <limit effort="200" lower="-3.490658503988659" upper="3.490658503988659" velocity="6.1086523819801535" />
  </joint>
  <joint name="J5" type="revolute">
    <origin rpy="0 0 0" xyz="1.55 0 0" />
    <parent link="J4_link" />
    <child link="J5_link" />
    <axis xyz="0 -1 0" />
    <limit effort="200" lower="-2.443460952792061" upper="2.443460952792061" velocity="6.283185307179586" />
  </joint>
  <joint name="J6" type="revolute">
    <origin rpy="0 0 0" xyz="0 0 0" />
    <parent link="J5_link" />
    <child link="J6_link" />
    <axis xyz="-1 0 0" />
    <limit effort="100" lower="-7.853981633974483" upper="7.853981633974483" velocity="10.471975511965978" />
  </joint>
  
  <link name="wbase" />
  <joint name="base_link-wbase" type="fixed">
    <origin rpy="0 0 0" xyz="0 0 .565" />
    <parent link="base_link" />
    <child link="wbase" />
  </joint>
  
  <link name="flange" />
  <joint name="J6-flange" type="fixed">
    <origin rpy="0 0 0" xyz=".1 0 0" />
    <parent link="J6_link" />
    <child link="flange" />
  </joint>
  
  <link name="fanuc_flange" />
  <joint name="flange-fanuc_flange" type="fixed">
    <origin rpy="3.141592653589793 -1.5707963267948966 0.0" xyz="0 0 0" />
    <parent link="flange" />
    <child link="fanuc_flange" />
  </joint>
  
  <joint name="base_joint" type="fixed">
    <origin rpy="0 0 0" xyz="0 0 0" />
    <parent link="world" />
    <child link="base_link" />
  </joint>
  
  <joint name="child_joint" type="fixed">
    <origin rpy="0 0 0" xyz="0 0 0" />
    <parent link="flange" />
    <child link="ee_link" />
  </joint>
</robot>