<?xml version='1.0' encoding='utf-8'?>
<robot name="r2000ic_210we">
  <link name="world" />
  <link name="ee_link" />
  
  <link name="base_link">
    <visual>
      <origin rpy="0 0 0" xyz="0 0 0" />
      <geometry>
        <mesh filename="meshes/base.dae" />
      </geometry>
    </visual>
    <collision>
      <origin rpy="0 0 0" xyz="0 0 0" />
      <geometry>
        <mesh filename="meshes/base.stl" />
      </geometry>
    </collision>
    <inertial>
      <mass value=" 154" />
      <origin xyz="-.15 .00307 .11" />
      <inertia ixx=" 4.51" ixy=" .123" ixz=" .382" iyy=" 11.1" iyz=" .00898" izz=" 14.3" />
    </inertial>
  </link>
  <link name="J1_link">
    <visual>
      <origin rpy="0 0 0" xyz="0 0 0" />
      <geometry>
        <mesh filename="meshes/j1.dae" />
      </geometry>
    </visual>
    <collision>
      <origin rpy="0 0 0" xyz="0 0 0" />
      <geometry>
        <mesh filename="meshes/j1.stl" />
      </geometry>
    </collision>
    <inertial>
      <mass value=" 428" />
      <origin xyz=".13 -.0023 -.134" />
      <inertia ixx=" 25.5" ixy=" 1.04" ixz="-5.45" iyy=" 37.5" iyz=" .755" izz=" 43.8" />
    </inertial>
  </link>
  <link name="J2_link">
    <visual>
      <origin rpy="0 0 0" xyz="0 0 0" />
      <geometry>
        <mesh filename="meshes/j2.dae" />
      </geometry>
    </visual>
    <collision>
      <origin rpy="0 0 0" xyz="0 0 0" />
      <geometry>
        <mesh filename="meshes/j2.stl" />
      </geometry>
    </collision>
    <inertial>
      <mass value=" 230" />
      <origin xyz=".00513 .255 .47" />
      <inertia ixx=" 33.7" ixy=" .198" ixz=" .229" iyy=" 34.1" iyz="-1.89" izz=" 4.97" />
    </inertial>
  </link>
  <link name="J3_link">
    <visual>
      <origin rpy="0 0 0" xyz="0 0 0" />
      <geometry>
        <mesh filename="meshes/j3.dae" />
      </geometry>
    </visual>
    <collision>
      <origin rpy="0 0 0" xyz="0 0 0" />
      <geometry>
        <mesh filename="meshes/j3.stl" />
      </geometry>
    </collision>
    <inertial>
      <mass value=" 341" />
      <origin xyz=".3 .0356 .14" />
      <inertia ixx=" 15.8" ixy=" .967" ixz="-3.88" iyy=" 33" iyz="-.222" izz=" 35.6" />
    </inertial>
  </link>
  <link name="J4_link">
    <visual>
      <origin rpy="0 0 0" xyz="0 0 0" />
      <geometry>
        <mesh filename="meshes/j4.dae" />
      </geometry>
    </visual>
    <collision>
      <origin rpy="0 0 0" xyz="0 0 0" />
      <geometry>
        <mesh filename="meshes/j4.stl" />
      </geometry>
    </collision>
    <inertial>
      <mass value=" 9.11" />
      <origin xyz="1.18 -.00873 -.00000000235" />
      <inertia ixx=" .0355" ixy=" .00475" ixz="-.0000000015" iyy=" .0812" iyz=" .00000000242" izz=" .0792" />
    </inertial>
  </link>
  <link name="J5_link">
    <visual>
      <origin rpy="0 0 0" xyz="0 0 0" />
      <geometry>
        <mesh filename="meshes/j5.dae" />
      </geometry>
    </visual>
    <collision>
      <origin rpy="0 0 0" xyz="0 0 0" />
      <geometry>
        <mesh filename="meshes/j5.stl" />
      </geometry>
    </collision>
    <inertial>
      <mass value=" 16.7" />
      <origin xyz=".0489 -.0214 .00000000105" />
      <inertia ixx=" .125" ixy="-.019" ixz=" .00000000188" iyy=" .148" iyz=" .00000000757" izz=" .183" />
    </inertial>
  </link>
  <link name="J6_link">
    <visual>
      <origin rpy="0 0 0" xyz="0 0 0" />
      <geometry>
        <mesh filename="meshes/j6.dae" />
      </geometry>
    </visual>
    <collision>
      <origin rpy="0 0 0" xyz="0 0 0" />
      <geometry>
        <mesh filename="meshes/j6.stl" />
      </geometry>
    </collision>
    <inertial>
      <mass value=" .621" />
      <origin xyz=".216 .00000000124 .000178" />
      <inertia ixx=" .00198" ixy=" 8.53E-19" ixz="-2.25E-19" iyy=" .00101" iyz=" .0000000000316" izz=" .00102" />
    </inertial>
  </link>
  
  <joint name="J1" type="revolute">
    <origin rpy="0 0 0" xyz="0 0 .67" />
    <parent link="base_link" />
    <child link="J1_link" />
    <axis xyz="0 0 1" />
    <limit effort="10000" lower="-2.8797932657906435" upper="2.8797932657906435" velocity="1.6580627893946132" />
  </joint>
  <joint name="J2" type="revolute">
    <origin rpy="0 0 0" xyz=".43 0 0" />
    <parent link="J1_link" />
    <child link="J2_link" />
    <axis xyz="0 1 0" />
    <limit effort="30000" lower="-1.1344640137963142" upper="1.3264502315156905" velocity="1.4835298641951802" />
  </joint>
  <joint name="J3" type="revolute">
    <origin rpy="0 0 0" xyz="0 0 1.075" />
    <parent link="J2_link" />
    <child link="J3_link" />
    <axis xyz="0 -1 0" />
    <limit effort="20000" lower="-1.3788101090755203" upper="2.6179938779914944" velocity="1.6580627893946132" />
  </joint>
  <joint name="J4" type="revolute">
    <origin rpy="0 0 0" xyz="0 0 .225" />
    <parent link="J3_link" />
    <child link="J4_link" />
    <axis xyz="-1 0 0" />
    <limit effort="5000" lower="-6.283185307179586" upper="6.283185307179586" velocity="2.0943951023931953" />
  </joint>
  <joint name="J5" type="revolute">
    <origin rpy="0 0 0" xyz="1.28 0 0" />
    <parent link="J4_link" />
    <child link="J5_link" />
    <axis xyz="0 -1 0" />
    <limit effort="5000" lower="-2.181661564992912" upper="2.181661564992912" velocity="2.0943951023931953" />
  </joint>
  <joint name="J6" type="revolute">
    <origin rpy="0 0 0" xyz="0 0 0" />
    <parent link="J5_link" />
    <child link="J6_link" />
    <axis xyz="-1 0 0" />
    <limit effort="3000" lower="-6.283185307179586" upper="6.283185307179586" velocity="3.3161255787892263" />
  </joint>
  
  <link name="wbase" />
  <joint name="base_link-wbase" type="fixed">
    <origin rpy="0 0 0" xyz="0 0 .67" />
    <parent link="base_link" />
    <child link="wbase" />
  </joint>
  
  <link name="flange" />
  <joint name="J6-flange" type="fixed">
    <origin rpy="0 0 0" xyz=".227 0 0" />
    <parent link="J6_link" />
    <child link="flange" />
  </joint>
  
  <link name="fanuc_flange" />
  <joint name="flange-fanuc_flange" type="fixed">
    <origin rpy="3.141592653589793 -1.5707963267948966 0.0" xyz="0 0 0" />
    <parent link="flange" />
    <child link="fanuc_flange" />
  </joint>
  
  <joint name="base_joint" type="fixed">
    <origin rpy="0 0 0" xyz="0 0 0" />
    <parent link="world" />
    <child link="base_link" />
  </joint>
  
  <joint name="child_joint" type="fixed">
    <origin rpy="0 0 0" xyz="0 0 0" />
    <parent link="flange" />
    <child link="ee_link" />
  </joint>
</robot>