<?xml version='1.0' encoding='utf-8'?>
<robot name="r1000ia_100f">
  <link name="world" />
  <link name="ee_link" />
  
  <link name="base_link">
    <visual>
      <origin rpy="0 0 0" xyz="0 0 0" />
      <geometry>
        <mesh filename="meshes/base.dae" />
      </geometry>
    </visual>
    <collision>
      <origin rpy="0 0 0" xyz="0 0 0" />
      <geometry>
        <mesh filename="meshes/base.stl" />
      </geometry>
    </collision>
    <inertial>
      <mass value=" 137" />
      <origin xyz="-.129 .0048 .117" />
      <inertia ixx=" 2.71" ixy=" .241" ixz="-.158" iyy=" 6.08" iyz=" .015" izz=" 7.49" />
    </inertial>
  </link>
  <link name="J1_link">
    <visual>
      <origin rpy="0 0 0" xyz="0 0 0" />
      <geometry>
        <mesh filename="meshes/j1.dae" />
      </geometry>
    </visual>
    <collision>
      <origin rpy="0 0 0" xyz="0 0 0" />
      <geometry>
        <mesh filename="meshes/j1.stl" />
      </geometry>
    </collision>
    <inertial>
      <mass value=" 185" />
      <origin xyz=".133 -.00239 -.0395" />
      <inertia ixx=" 4.93" ixy="-.262" ixz="-.216" iyy=" 7.33" iyz=" .424" izz=" 7.6" />
    </inertial>
  </link>
  <link name="J2_link">
    <visual>
      <origin rpy="0 0 0" xyz="0 0 0" />
      <geometry>
        <mesh filename="meshes/j2.dae" />
      </geometry>
    </visual>
    <collision>
      <origin rpy="0 0 0" xyz="0 0 0" />
      <geometry>
        <mesh filename="meshes/j2.stl" />
      </geometry>
    </collision>
    <inertial>
      <mass value=" 111" />
      <origin xyz=".00598 .148 .394" />
      <inertia ixx=" 10.5" ixy="-.00257" ixz=" .00636" iyy=" 10.9" iyz="-.17" izz=" 1.04" />
    </inertial>
  </link>
  <link name="J3_link">
    <visual>
      <origin rpy="0 0 0" xyz="0 0 0" />
      <geometry>
        <mesh filename="meshes/j3.dae" />
      </geometry>
    </visual>
    <collision>
      <origin rpy="0 0 0" xyz="0 0 0" />
      <geometry>
        <mesh filename="meshes/j3.stl" />
      </geometry>
    </collision>
    <inertial>
      <mass value=" 208" />
      <origin xyz=".238 .011 .139" />
      <inertia ixx=" 5.25" ixy="-.0585" ixz="-1.92" iyy=" 13.4" iyz="-.209" izz=" 12.6" />
    </inertial>
  </link>
  <link name="J4_link">
    <visual>
      <origin rpy="0 0 0" xyz="0 0 0" />
      <geometry>
        <mesh filename="meshes/j4.dae" />
      </geometry>
    </visual>
    <collision>
      <origin rpy="0 0 0" xyz="0 0 0" />
      <geometry>
        <mesh filename="meshes/j4.stl" />
      </geometry>
    </collision>
    <inertial>
      <mass value=" 7.97" />
      <origin xyz=".929 -.00482 1.99E-16" />
      <inertia ixx=" .0233" ixy=" .00217" ixz=" 3.02E-15" iyy=" .0512" iyz=" .00000000000462" izz=" .0487" />
    </inertial>
  </link>
  <link name="J5_link">
    <visual>
      <origin rpy="0 0 0" xyz="0 0 0" />
      <geometry>
        <mesh filename="meshes/j5.dae" />
      </geometry>
    </visual>
    <collision>
      <origin rpy="0 0 0" xyz="0 0 0" />
      <geometry>
        <mesh filename="meshes/j5.stl" />
      </geometry>
    </collision>
    <inertial>
      <mass value=" 15.5" />
      <origin xyz=".0473 -.0132 -.00000000107" />
      <inertia ixx=" .0866" ixy="-.012" ixz="-.000000000378" iyy=" .107" iyz="-.00000000097" izz=" .13" />
    </inertial>
  </link>
  <link name="J6_link">
    <visual>
      <origin rpy="0 0 0" xyz="0 0 0" />
      <geometry>
        <mesh filename="meshes/j6.dae" />
      </geometry>
    </visual>
    <collision>
      <origin rpy="0 0 0" xyz="0 0 0" />
      <geometry>
        <mesh filename="meshes/j6.stl" />
      </geometry>
    </collision>
    <inertial>
      <mass value=" .431" />
      <origin xyz=".181 .000127 .000171" />
      <inertia ixx=" .000858" ixy="-.00000000000219" ixz="-.000000468" iyy=" .000438" iyz=" .0000000000661" izz=" .000443" />
    </inertial>
  </link>
  
  <joint name="J1" type="revolute">
    <origin rpy="0 0 0" xyz="0 0 .45" />
    <parent link="base_link" />
    <child link="J1_link" />
    <axis xyz="0 0 1" />
    <limit effort="9000" lower="-3.141592653589793" upper="3.141592653589793" velocity="2.2689280275926285" />
  </joint>
  <joint name="J2" type="revolute">
    <origin rpy="0 0 0" xyz=".32 0 0" />
    <parent link="J1_link" />
    <child link="J2_link" />
    <axis xyz="0 1 0" />
    <limit effort="20000" lower="-1.5707963267948966" upper="2.705260340591211" velocity="1.9198621771937625" />
  </joint>
  <joint name="J3" type="revolute">
    <origin rpy="0 0 0" xyz="0 0 .87" />
    <parent link="J2_link" />
    <child link="J3_link" />
    <axis xyz="0 -1 0" />
    <limit effort="8000" lower="-1.4311699866353502" upper="2.443460952792061" velocity="2.0943951023931953" />
  </joint>
  <joint name="J4" type="revolute">
    <origin rpy="0 0 0" xyz="0 0 .225" />
    <parent link="J3_link" />
    <child link="J4_link" />
    <axis xyz="-1 0 0" />
    <limit effort="3000" lower="-6.283185307179586" upper="6.283185307179586" velocity="2.9670597283903604" />
  </joint>
  <joint name="J5" type="revolute">
    <origin rpy="0 0 0" xyz="1.015 0 0" />
    <parent link="J4_link" />
    <child link="J5_link" />
    <axis xyz="0 -1 0" />
    <limit effort="3000" lower="-2.181661564992912" upper="2.181661564992912" velocity="2.9670597283903604" />
  </joint>
  <joint name="J6" type="revolute">
    <origin rpy="0 0 0" xyz="0 0 0" />
    <parent link="J5_link" />
    <child link="J6_link" />
    <axis xyz="-1 0 0" />
    <limit effort="2000" lower="-6.283185307179586" upper="6.283185307179586" velocity="4.363323129985824" />
  </joint>
  
  <link name="wbase" />
  <joint name="base_link-wbase" type="fixed">
    <origin rpy="0 0 0" xyz="0 0 .45" />
    <parent link="base_link" />
    <child link="wbase" />
  </joint>
  
  <link name="flange" />
  <joint name="J6-flange" type="fixed">
    <origin rpy="0 0 0" xyz=".19 0 0" />
    <parent link="J6_link" />
    <child link="flange" />
  </joint>
  
  <link name="fanuc_flange" />
  <joint name="flange-fanuc_flange" type="fixed">
    <origin rpy="3.141592653589793 -1.5707963267948966 0.0" xyz="0 0 0" />
    <parent link="flange" />
    <child link="fanuc_flange" />
  </joint>
  
  <joint name="base_joint" type="fixed">
    <origin rpy="0 0 0" xyz="0 0 0" />
    <parent link="world" />
    <child link="base_link" />
  </joint>
  
  <joint name="child_joint" type="fixed">
    <origin rpy="0 0 0" xyz="0 0 0" />
    <parent link="flange" />
    <child link="ee_link" />
  </joint>
</robot>