<?xml version='1.0' encoding='utf-8'?>
<robot name="m710id_50m">
  <link name="world" />
  <link name="ee_link" />
  
  <link name="base_link">
    <visual>
      <origin rpy="0 0 0" xyz="0 0 0" />
      <geometry>
        <mesh filename="meshes/base.dae" />
      </geometry>
    </visual>
    <collision>
      <origin rpy="0 0 0" xyz="0 0 0" />
      <geometry>
        <mesh filename="meshes/base.stl" />
      </geometry>
    </collision>
    <inertial>
      <mass value=" 109" />
      <origin xyz="-.0562 -.000509 .109" />
      <inertia ixx=" 2.8" ixy="-.0329" ixz=" .025" iyy=" 3" iyz=" .00163" izz=" 4.87" />
    </inertial>
  </link>
  <link name="J1_link">
    <visual>
      <origin rpy="0 0 0" xyz="0 0 0" />
      <geometry>
        <mesh filename="meshes/j1.dae" />
      </geometry>
    </visual>
    <collision>
      <origin rpy="0 0 0" xyz="0 0 0" />
      <geometry>
        <mesh filename="meshes/j1.stl" />
      </geometry>
    </collision>
    <inertial>
      <mass value=" 180" />
      <origin xyz=".0361 -.00381 -.0873" />
      <inertia ixx=" 6.87" ixy=" .225" ixz="-.615" iyy=" 5.55" iyz=" .424" izz=" 7.07" />
    </inertial>
  </link>
  <link name="J2_link">
    <visual>
      <origin rpy="0 0 0" xyz="0 0 0" />
      <geometry>
        <mesh filename="meshes/j2.dae" />
      </geometry>
    </visual>
    <collision>
      <origin rpy="0 0 0" xyz="0 0 0" />
      <geometry>
        <mesh filename="meshes/j2.stl" />
      </geometry>
    </collision>
    <inertial>
      <mass value=" 167" />
      <origin xyz="-.035 .173 .519" />
      <inertia ixx=" 24.1" ixy=" .149" ixz=" .00551" iyy=" 25.3" iyz="-1.58" izz=" 2.46" />
    </inertial>
  </link>
  <link name="J3_link">
    <visual>
      <origin rpy="0 0 0" xyz="0 0 0" />
      <geometry>
        <mesh filename="meshes/j3.dae" />
      </geometry>
    </visual>
    <collision>
      <origin rpy="0 0 0" xyz="0 0 0" />
      <geometry>
        <mesh filename="meshes/j3.stl" />
      </geometry>
    </collision>
    <inertial>
      <mass value=" 89.4" />
      <origin xyz=".0255 -.005 .0679" />
      <inertia ixx=" 1.9" ixy="-.0775" ixz="-.311" iyy=" 2.41" iyz="-.06" izz=" 1.92" />
    </inertial>
  </link>
  <link name="J4_link">
    <visual>
      <origin rpy="0 0 0" xyz="0 0 0" />
      <geometry>
        <mesh filename="meshes/j4.dae" />
      </geometry>
    </visual>
    <collision>
      <origin rpy="0 0 0" xyz="0 0 0" />
      <geometry>
        <mesh filename="meshes/j4.stl" />
      </geometry>
    </collision>
    <inertial>
      <mass value=" 44.2" />
      <origin xyz=".722 -.00464 .0000825" />
      <inertia ixx=" .181" ixy=" .0138" ixz=" .0000199" iyy=" 3.93" iyz="-.000138" izz=" 3.93" />
    </inertial>
  </link>
  <link name="J5_link">
    <visual>
      <origin rpy="0 0 0" xyz="0 0 0" />
      <geometry>
        <mesh filename="meshes/j5.dae" />
      </geometry>
    </visual>
    <collision>
      <origin rpy="0 0 0" xyz="0 0 0" />
      <geometry>
        <mesh filename="meshes/j5.stl" />
      </geometry>
    </collision>
    <inertial>
      <mass value=" 9.67" />
      <origin xyz=".0325 -.0138 .000000624" />
      <inertia ixx=" .0432" ixy="-.00522" ixz="-.000000315" iyy=" .0487" iyz="-.0000000877" izz=" .0633" />
    </inertial>
  </link>
  <link name="J6_link">
    <visual>
      <origin rpy="0 0 0" xyz="0 0 0" />
      <geometry>
        <mesh filename="meshes/j6.dae" />
      </geometry>
    </visual>
    <collision>
      <origin rpy="0 0 0" xyz="0 0 0" />
      <geometry>
        <mesh filename="meshes/j6.stl" />
      </geometry>
    </collision>
    <inertial>
      <mass value=" .415" />
      <origin xyz=".165 4.54E-18 2.83E-18" />
      <inertia ixx=" .000809" ixy=" 1.32E-19" ixz=" 3E-19" iyy=" .000417" iyz=" .0000000000746" izz=" .000417" />
    </inertial>
  </link>
  
  <joint name="J1" type="revolute">
    <origin rpy="0 0 0" xyz="0 0 .565" />
    <parent link="base_link" />
    <child link="J1_link" />
    <axis xyz="0 0 1" />
    <limit effort="8000" lower="-3.2288591161895095" upper="3.2288591161895095" velocity="3.141592653589793" />
  </joint>
  <joint name="J2" type="revolute">
    <origin rpy="0 0 0" xyz=".15 0 0" />
    <parent link="J1_link" />
    <child link="J2_link" />
    <axis xyz="0 1 0" />
    <limit effort="10000" lower="-1.3089969389957472" upper="2.6179938779914944" velocity="3.141592653589793" />
  </joint>
  <joint name="J3" type="revolute">
    <origin rpy="0 0 0" xyz="0 0 1.15" />
    <parent link="J2_link" />
    <child link="J3_link" />
    <axis xyz="0 -1 0" />
    <limit effort="5000" lower="-1.4049900478554354" upper="3.5779249665883754" velocity="3.141592653589793" />
  </joint>
  <joint name="J4" type="revolute">
    <origin rpy="0 0 0" xyz="0 0 .17" />
    <parent link="J3_link" />
    <child link="J4_link" />
    <axis xyz="-1 0 0" />
    <limit effort="2000" lower="-6.981317007977318" upper="6.981317007977318" velocity="4.537856055185257" />
  </joint>
  <joint name="J5" type="revolute">
    <origin rpy="0 0 0" xyz="1.295 0 0" />
    <parent link="J4_link" />
    <child link="J5_link" />
    <axis xyz="0 -1 0" />
    <limit effort="1000" lower="-2.181661564992912" upper="2.181661564992912" velocity="4.537856055185257" />
  </joint>
  <joint name="J6" type="revolute">
    <origin rpy="0 0 0" xyz="0 0 0" />
    <parent link="J5_link" />
    <child link="J6_link" />
    <axis xyz="-1 0 0" />
    <limit effort="900" lower="-6.981317007977318" upper="6.981317007977318" velocity="6.457718232379019" />
  </joint>
  
  <link name="wbase" />
  <joint name="base_link-wbase" type="fixed">
    <origin rpy="0 0 0" xyz="0 0 .565" />
    <parent link="base_link" />
    <child link="wbase" />
  </joint>
  
  <link name="flange" />
  <joint name="J6-flange" type="fixed">
    <origin rpy="0 0 0" xyz=".175 0 0" />
    <parent link="J6_link" />
    <child link="flange" />
  </joint>
  
  <link name="fanuc_flange" />
  <joint name="flange-fanuc_flange" type="fixed">
    <origin rpy="3.141592653589793 -1.5707963267948966 0.0" xyz="0 0 0" />
    <parent link="flange" />
    <child link="fanuc_flange" />
  </joint>
  
  <joint name="base_joint" type="fixed">
    <origin rpy="0 0 0" xyz="0 0 0" />
    <parent link="world" />
    <child link="base_link" />
  </joint>
  
  <joint name="child_joint" type="fixed">
    <origin rpy="0 0 0" xyz="0 0 0" />
    <parent link="flange" />
    <child link="ee_link" />
  </joint>
</robot>