<?xml version='1.0' encoding='utf-8'?>
<robot name="pr2">
  <link name="base_link">
    <inertial>
      <mass value="116.0" />
      <origin xyz="-0.061 0.0 0.1465" />
      <inertia ixx="5.652232699207" ixy="-0.009719934438" ixz="1.293988226423" iyy="5.669473158652" iyz="-0.007379583694" izz="3.683196351726" />
    </inertial>
    <visual>
      <origin rpy="0 0 0" xyz="0 0 0" />
      <geometry>
        <mesh filename="meshes/base_L.stl" />
      </geometry>
    </visual>
    <collision>
      <origin rpy="0 0 0" xyz="0 0 0" />
      <geometry>
        <mesh filename="meshes/base_L.stl" />
      </geometry>
    </collision>
  </link>
  <link name="base_footprint">
    <inertial>
      <mass value="1.0" />
      <origin xyz="0 0 0" />
      <inertia ixx="0.01" ixy="0.0" ixz="0.0" iyy="0.01" iyz="0.0" izz="0.01" />
    </inertial>
    <visual>
      <origin rpy="0 0 0" xyz="0 0 0" />
      <geometry>
        <box size="0.01 0.01 0.01" />
      </geometry>
    </visual>
    <collision>
      <origin rpy="0 0 0" xyz="0 0 0.071" />
      <geometry>
        <box size="0.001 0.001 0.001" />
      </geometry>
    </collision>
  </link>
  <joint name="base_footprint_joint" type="fixed">
    <origin rpy="0 0 0" xyz="0 0 0.051" />
    <child link="base_link" />
    <parent link="base_footprint" />
  </joint>
  
  <link name="base_bellow_link">
    <inertial>
      <mass value="1.0" />
      <origin xyz="0 0 0" />
      <inertia ixx="0.01" ixy="0.0" ixz="0.0" iyy="0.01" iyz="0.0" izz="0.01" />
    </inertial>
    <visual>
      <origin rpy="0 0 0" xyz="0 0 0" />
      <geometry>
        <box size="0.05 0.37 0.3" />
      </geometry>
    </visual>
    <collision>
      <origin rpy="0 0 0" xyz="0 0 0" />
      <geometry>
        <box size="0.05 0.37 0.3" />
      </geometry>
    </collision>
  </link>
  <joint name="base_bellow_joint" type="fixed">
    <origin rpy="0 0 0" xyz="-0.29 0 0.8" />
    <parent link="base_link" />
    <child link="base_bellow_link" />
  </joint>
  
  <joint name="fl_caster_rotation_joint" type="revolute">
    <axis xyz="0 0 1" />
    <limit effort="6.5" velocity="10" lower="-3.141592653589793" upper="3.141592653589793" />
    
    <safety_controller k_velocity="10" />
    <calibration rising="-0.785398163397" />
    <dynamics damping="1.0" friction="0.0" />
    <origin rpy="0 0 0" xyz="0.2246 0.2246 0.0282" />
    <parent link="base_link" />
    <child link="fl_caster_rotation_link" />
  </joint>
  <link name="fl_caster_rotation_link">
    <inertial>
      <mass value="3.473082" />
      <origin xyz="0 0 0.07" />
      <inertia ixx="0.012411765597" ixy="-0.000711733678" ixz="0.00050272983" iyy="0.015218160428" iyz="-0.000004273467" izz="0.011763977943" />
    </inertial>
    <visual>
      <origin rpy="0 0 0" xyz="0 0 0" />
      <geometry>
        <mesh filename="meshes/caster.stl" />
      </geometry>
    </visual>
    <collision>
      <origin rpy="0 0 0" xyz="0 0 0" />
      <geometry>
        <mesh filename="meshes/caster_L.stl" />
      </geometry>
    </collision>
  </link>
  <transmission name="fl_caster_rotation_trans" type="pr2_mechanism_model/SimpleTransmission">
    <actuator name="fl_caster_rotation_motor" />
    <joint name="fl_caster_rotation_joint" />
    <mechanicalReduction>-79.2380952381</mechanicalReduction>
  </transmission>
  <joint name="fl_caster_l_wheel_joint" type="revolute">
    <axis xyz="0 1 0" />
    <limit effort="7" velocity="15" lower="-3.141592653589793" upper="3.141592653589793" />
    
    <safety_controller k_velocity="10" />
    <dynamics damping="1.0" friction="0.0" />
    <origin rpy="0 0 0" xyz="0 0.049 0" />
    <parent link="fl_caster_rotation_link" />
    <child link="fl_caster_l_wheel_link" />
  </joint>
  <link name="fl_caster_l_wheel_link">
    <inertial>
      <mass value="0.44036" />
      <origin xyz="0 0 0" />
      <inertia ixx="0.012411765597" ixy="-0.000711733678" ixz="0.00050272983" iyy="0.015218160428" iyz="-0.000004273467" izz="0.011763977943" />
    </inertial>
    <visual>
      <origin rpy="0 0 0" xyz="0 0 0" />
      <geometry>
        <mesh filename="meshes/caster.stl" />
      </geometry>
    </visual>
    <collision>
      <origin rpy="1.57079632679 0 0" xyz="0 0 0" />
      
      <geometry>
        <cylinder length="0.034" radius="0.074792" />
      </geometry>
    </collision>
  </link>
  <transmission name="fl_caster_l_wheel_trans" type="pr2_mechanism_model/SimpleTransmission">
    <actuator name="fl_caster_l_wheel_motor" />
    <joint name="fl_caster_l_wheel_joint" />
    <mechanicalReduction>79.2380952381</mechanicalReduction>
  </transmission>
  <joint name="fl_caster_r_wheel_joint" type="revolute">
    <axis xyz="0 1 0" />
    <limit effort="7" velocity="15" lower="-3.141592653589793" upper="3.141592653589793" />
    
    <safety_controller k_velocity="10" />
    <dynamics damping="1.0" friction="0.0" />
    <origin rpy="0 0 0" xyz="0 -0.049 0" />
    <parent link="fl_caster_rotation_link" />
    <child link="fl_caster_r_wheel_link" />
  </joint>
  <link name="fl_caster_r_wheel_link">
    <inertial>
      <mass value="0.44036" />
      <origin xyz="0 0 0" />
      <inertia ixx="0.012411765597" ixy="-0.000711733678" ixz="0.00050272983" iyy="0.015218160428" iyz="-0.000004273467" izz="0.011763977943" />
    </inertial>
    <visual>
      <origin rpy="0 0 0" xyz="0 0 0" />
      <geometry>
        <mesh filename="meshes/caster.stl" />
      </geometry>
    </visual>
    <collision>
      <origin rpy="1.57079632679 0 0" xyz="0 0 0" />
      
      <geometry>
        <cylinder length="0.034" radius="0.074792" />
      </geometry>
    </collision>
  </link>
  <transmission name="fl_caster_r_wheel_trans" type="pr2_mechanism_model/SimpleTransmission">
    <actuator name="fl_caster_r_wheel_motor" />
    <joint name="fl_caster_r_wheel_joint" />
    <mechanicalReduction>-79.2380952381</mechanicalReduction>
  </transmission>
  <joint name="fr_caster_rotation_joint" type="revolute">
    <axis xyz="0 0 1" />
    <limit effort="6.5" velocity="10" lower="-3.141592653589793" upper="3.141592653589793" />
    
    <safety_controller k_velocity="10" />
    <calibration rising="-0.785398163397" />
    <dynamics damping="1.0" friction="0.0" />
    <origin rpy="0 0 0" xyz="0.2246 -0.2246 0.0282" />
    <parent link="base_link" />
    <child link="fr_caster_rotation_link" />
  </joint>
  <link name="fr_caster_rotation_link">
    <inertial>
      <mass value="3.473082" />
      <origin xyz="0 0 0.07" />
      <inertia ixx="0.012411765597" ixy="-0.000711733678" ixz="0.00050272983" iyy="0.015218160428" iyz="-0.000004273467" izz="0.011763977943" />
    </inertial>
    <visual>
      <origin rpy="0 0 0" xyz="0 0 0" />
      <geometry>
        <mesh filename="meshes/caster.stl" />
      </geometry>
    </visual>
    <collision>
      <origin rpy="0 0 0" xyz="0 0 0" />
      <geometry>
        <mesh filename="meshes/caster_L.stl" />
      </geometry>
    </collision>
  </link>
  <transmission name="fr_caster_rotation_trans" type="pr2_mechanism_model/SimpleTransmission">
    <actuator name="fr_caster_rotation_motor" />
    <joint name="fr_caster_rotation_joint" />
    <mechanicalReduction>-79.2380952381</mechanicalReduction>
  </transmission>
  <joint name="fr_caster_l_wheel_joint" type="revolute">
    <axis xyz="0 1 0" />
    <limit effort="7" velocity="15" lower="-3.141592653589793" upper="3.141592653589793" />
    
    <safety_controller k_velocity="10" />
    <dynamics damping="1.0" friction="0.0" />
    <origin rpy="0 0 0" xyz="0 0.049 0" />
    <parent link="fr_caster_rotation_link" />
    <child link="fr_caster_l_wheel_link" />
  </joint>
  <link name="fr_caster_l_wheel_link">
    <inertial>
      <mass value="0.44036" />
      <origin xyz="0 0 0" />
      <inertia ixx="0.012411765597" ixy="-0.000711733678" ixz="0.00050272983" iyy="0.015218160428" iyz="-0.000004273467" izz="0.011763977943" />
    </inertial>
    <visual>
      <origin rpy="0 0 0" xyz="0 0 0" />
      <geometry>
        <mesh filename="meshes/caster.stl" />
      </geometry>
    </visual>
    <collision>
      <origin rpy="1.57079632679 0 0" xyz="0 0 0" />
      
      <geometry>
        <cylinder length="0.034" radius="0.074792" />
      </geometry>
    </collision>
  </link>
  <transmission name="fr_caster_l_wheel_trans" type="pr2_mechanism_model/SimpleTransmission">
    <actuator name="fr_caster_l_wheel_motor" />
    <joint name="fr_caster_l_wheel_joint" />
    <mechanicalReduction>79.2380952381</mechanicalReduction>
  </transmission>
  <joint name="fr_caster_r_wheel_joint" type="revolute">
    <axis xyz="0 1 0" />
    <limit effort="7" velocity="15" lower="-3.141592653589793" upper="3.141592653589793" />
    
    <safety_controller k_velocity="10" />
    <dynamics damping="1.0" friction="0.0" />
    <origin rpy="0 0 0" xyz="0 -0.049 0" />
    <parent link="fr_caster_rotation_link" />
    <child link="fr_caster_r_wheel_link" />
  </joint>
  <link name="fr_caster_r_wheel_link">
    <inertial>
      <mass value="0.44036" />
      <origin xyz="0 0 0" />
      <inertia ixx="0.012411765597" ixy="-0.000711733678" ixz="0.00050272983" iyy="0.015218160428" iyz="-0.000004273467" izz="0.011763977943" />
    </inertial>
    <visual>
      <origin rpy="0 0 0" xyz="0 0 0" />
      <geometry>
        <mesh filename="meshes/caster.stl" />
      </geometry>
    </visual>
    <collision>
      <origin rpy="1.57079632679 0 0" xyz="0 0 0" />
      
      <geometry>
        <cylinder length="0.034" radius="0.074792" />
      </geometry>
    </collision>
  </link>
  <transmission name="fr_caster_r_wheel_trans" type="pr2_mechanism_model/SimpleTransmission">
    <actuator name="fr_caster_r_wheel_motor" />
    <joint name="fr_caster_r_wheel_joint" />
    <mechanicalReduction>-79.2380952381</mechanicalReduction>
  </transmission>
  <joint name="bl_caster_rotation_joint" type="revolute">
    <axis xyz="0 0 1" />
    <limit effort="6.5" velocity="10" lower="-3.141592653589793" upper="3.141592653589793" />
    
    <safety_controller k_velocity="10" />
    <calibration rising="2.35619449019" />
    <dynamics damping="1.0" friction="0.0" />
    <origin rpy="0 0 0" xyz="-0.2246 0.2246 0.0282" />
    <parent link="base_link" />
    <child link="bl_caster_rotation_link" />
  </joint>
  <link name="bl_caster_rotation_link">
    <inertial>
      <mass value="3.473082" />
      <origin xyz="0 0 0.07" />
      <inertia ixx="0.012411765597" ixy="-0.000711733678" ixz="0.00050272983" iyy="0.015218160428" iyz="-0.000004273467" izz="0.011763977943" />
    </inertial>
    <visual>
      <origin rpy="0 0 0" xyz="0 0 0" />
      <geometry>
        <mesh filename="meshes/caster.stl" />
      </geometry>
    </visual>
    <collision>
      <origin rpy="0 0 0" xyz="0 0 0" />
      <geometry>
        <mesh filename="meshes/caster_L.stl" />
      </geometry>
    </collision>
  </link>
  <transmission name="bl_caster_rotation_trans" type="pr2_mechanism_model/SimpleTransmission">
    <actuator name="bl_caster_rotation_motor" />
    <joint name="bl_caster_rotation_joint" />
    <mechanicalReduction>-79.2380952381</mechanicalReduction>
  </transmission>
  <joint name="bl_caster_l_wheel_joint" type="revolute">
    <axis xyz="0 1 0" />
    <limit effort="7" velocity="15" lower="-3.141592653589793" upper="3.141592653589793" />
    
    <safety_controller k_velocity="10" />
    <dynamics damping="1.0" friction="0.0" />
    <origin rpy="0 0 0" xyz="0 0.049 0" />
    <parent link="bl_caster_rotation_link" />
    <child link="bl_caster_l_wheel_link" />
  </joint>
  <link name="bl_caster_l_wheel_link">
    <inertial>
      <mass value="0.44036" />
      <origin xyz="0 0 0" />
      <inertia ixx="0.012411765597" ixy="-0.000711733678" ixz="0.00050272983" iyy="0.015218160428" iyz="-0.000004273467" izz="0.011763977943" />
    </inertial>
    <visual>
      <origin rpy="0 0 0" xyz="0 0 0" />
      <geometry>
        <mesh filename="meshes/caster.stl" />
      </geometry>
    </visual>
    <collision>
      <origin rpy="1.57079632679 0 0" xyz="0 0 0" />
      
      <geometry>
        <cylinder length="0.034" radius="0.074792" />
      </geometry>
    </collision>
  </link>
  
  <transmission name="bl_caster_l_wheel_trans" type="pr2_mechanism_model/SimpleTransmission">
    <actuator name="bl_caster_l_wheel_motor" />
    <joint name="bl_caster_l_wheel_joint" />
    <mechanicalReduction>79.2380952381</mechanicalReduction>
  </transmission>
  <joint name="bl_caster_r_wheel_joint" type="revolute">
    <axis xyz="0 1 0" />
    <limit effort="7" velocity="15" lower="-3.141592653589793" upper="3.141592653589793" />
    
    <safety_controller k_velocity="10" />
    <dynamics damping="1.0" friction="0.0" />
    <origin rpy="0 0 0" xyz="0 -0.049 0" />
    <parent link="bl_caster_rotation_link" />
    <child link="bl_caster_r_wheel_link" />
  </joint>
  <link name="bl_caster_r_wheel_link">
    <inertial>
      <mass value="0.44036" />
      <origin xyz="0 0 0" />
      <inertia ixx="0.012411765597" ixy="-0.000711733678" ixz="0.00050272983" iyy="0.015218160428" iyz="-0.000004273467" izz="0.011763977943" />
    </inertial>
    <visual>
      <origin rpy="0 0 0" xyz="0 0 0" />
      <geometry>
        <mesh filename="meshes/caster.stl" />
      </geometry>
    </visual>
    <collision>
      <origin rpy="1.57079632679 0 0" xyz="0 0 0" />
      
      <geometry>
        <cylinder length="0.034" radius="0.074792" />
      </geometry>
    </collision>
  </link>
  
  <transmission name="bl_caster_r_wheel_trans" type="pr2_mechanism_model/SimpleTransmission">
    <actuator name="bl_caster_r_wheel_motor" />
    <joint name="bl_caster_r_wheel_joint" />
    <mechanicalReduction>-79.2380952381</mechanicalReduction>
  </transmission>
  
  <joint name="br_caster_rotation_joint" type="revolute">
    <axis xyz="0 0 1" />
    <limit effort="6.5" velocity="10" lower="-3.141592653589793" upper="3.141592653589793" />
    
    <safety_controller k_velocity="10" />
    <calibration rising="2.35619449019" />
    <dynamics damping="1.0" friction="0.0" />
    <origin rpy="0 0 0" xyz="-0.2246 -0.2246 0.0282" />
    <parent link="base_link" />
    <child link="br_caster_rotation_link" />
  </joint>
  <link name="br_caster_rotation_link">
    <inertial>
      <mass value="3.473082" />
      <origin xyz="0 0 0.07" />
      <inertia ixx="0.012411765597" ixy="-0.000711733678" ixz="0.00050272983" iyy="0.015218160428" iyz="-0.000004273467" izz="0.011763977943" />
    </inertial>
    <visual>
      <origin rpy="0 0 0" xyz="0 0 0" />
      <geometry>
        <mesh filename="meshes/caster.stl" />
      </geometry>
    </visual>
    <collision>
      <origin rpy="0 0 0" xyz="0 0 0" />
      <geometry>
        <mesh filename="meshes/caster_L.stl" />
      </geometry>
    </collision>
  </link>
  <transmission name="br_caster_rotation_trans" type="pr2_mechanism_model/SimpleTransmission">
    <actuator name="br_caster_rotation_motor" />
    <joint name="br_caster_rotation_joint" />
    <mechanicalReduction>-79.2380952381</mechanicalReduction>
  </transmission>
  <joint name="br_caster_l_wheel_joint" type="revolute">
    <axis xyz="0 1 0" />
    <limit effort="7" velocity="15" lower="-3.141592653589793" upper="3.141592653589793" />
    
    <safety_controller k_velocity="10" />
    <dynamics damping="1.0" friction="0.0" />
    <origin rpy="0 0 0" xyz="0 0.049 0" />
    <parent link="br_caster_rotation_link" />
    <child link="br_caster_l_wheel_link" />
  </joint>
  <link name="br_caster_l_wheel_link">
    <inertial>
      <mass value="0.44036" />
      <origin xyz="0 0 0" />
      <inertia ixx="0.012411765597" ixy="-0.000711733678" ixz="0.00050272983" iyy="0.015218160428" iyz="-0.000004273467" izz="0.011763977943" />
    </inertial>
    <visual>
      <origin rpy="0 0 0" xyz="0 0 0" />
      <geometry>
        <mesh filename="meshes/caster.stl" />
      </geometry>
    </visual>
    <collision>
      <origin rpy="1.57079632679 0 0" xyz="0 0 0" />
      
      <geometry>
        <cylinder length="0.034" radius="0.074792" />
      </geometry>
    </collision>
  </link>
  
  <transmission name="br_caster_l_wheel_trans" type="pr2_mechanism_model/SimpleTransmission">
    <actuator name="br_caster_l_wheel_motor" />
    <joint name="br_caster_l_wheel_joint" />
    <mechanicalReduction>79.2380952381</mechanicalReduction>
  </transmission>
  <joint name="br_caster_r_wheel_joint" type="revolute">
    <axis xyz="0 1 0" />
    <limit effort="7" velocity="15" lower="-3.141592653589793" upper="3.141592653589793" />
    
    <safety_controller k_velocity="10" />
    <dynamics damping="1.0" friction="0.0" />
    <origin rpy="0 0 0" xyz="0 -0.049 0" />
    <parent link="br_caster_rotation_link" />
    <child link="br_caster_r_wheel_link" />
  </joint>
  <link name="br_caster_r_wheel_link">
    <inertial>
      <mass value="0.44036" />
      <origin xyz="0 0 0" />
      <inertia ixx="0.012411765597" ixy="-0.000711733678" ixz="0.00050272983" iyy="0.015218160428" iyz="-0.000004273467" izz="0.011763977943" />
    </inertial>
    <visual>
      <origin rpy="0 0 0" xyz="0 0 0" />
      <geometry>
        <mesh filename="meshes/caster.stl" />
      </geometry>
    </visual>
    <collision>
      <origin rpy="1.57079632679 0 0" xyz="0 0 0" />
      
      <geometry>
        <cylinder length="0.034" radius="0.074792" />
      </geometry>
    </collision>
  </link>
  
  <transmission name="br_caster_r_wheel_trans" type="pr2_mechanism_model/SimpleTransmission">
    <actuator name="br_caster_r_wheel_motor" />
    <joint name="br_caster_r_wheel_joint" />
    <mechanicalReduction>-79.2380952381</mechanicalReduction>
  </transmission>
  
  <joint name="torso_lift_joint" type="prismatic">
    <axis xyz="0 0 1" />
    <limit effort="10000" lower="0.0" upper="0.33" velocity="0.013" />
    
    <safety_controller k_position="100" k_velocity="2000000" soft_lower_limit="0.0115" soft_upper_limit="0.325" />
    <calibration falling="0.00475" />
    <dynamics damping="20000.0" />
    <origin rpy="0 0 0" xyz="-0.05 0 0.739675" />
    <parent link="base_link" />
    <child link="torso_lift_link" />
  </joint>
  <link name="torso_lift_link">
    <inertial>
      <mass value="36.248046" />
      <origin xyz="-0.1 0 -0.0885" />
      <inertia ixx="2.771653750257" ixy="0.004284522609" ixz="-0.160418504506" iyy="2.510019507959" iyz="0.029664468704" izz="0.526432355569" />
    </inertial>
    <visual>
      <origin rpy="0 0 0" xyz="0 0 0" />
      <geometry>
        <mesh filename="meshes/torso_lift_L.stl" />
      </geometry>
    </visual>
    <collision name="torso_lift_collision">
      <origin rpy="0 0 0" xyz="0 0 0" />
      <geometry>
        <mesh filename="meshes/torso_lift_L.stl" />
      </geometry>
    </collision>
  </link>
  
  
  
  
  <transmission name="torso_lift_trans" type="pr2_mechanism_model/SimpleTransmission">
    <actuator name="torso_lift_motor" />
    <joint name="torso_lift_joint" />
    <mechanicalReduction>-47641.53</mechanicalReduction>
    <simulated_actuated_joint name="torso_lift_motor_screw_joint" simulated_reduction="3141.6" />
  </transmission>
  
  
  <joint name="head_pan_joint" type="revolute">
    <axis xyz="0 0 1" />
    <limit effort="2.645" lower="-3.007" upper="3.007" velocity="6" />
    
    <safety_controller k_position="100" k_velocity="1.5" soft_lower_limit="-2.857" soft_upper_limit="2.857" />
    <calibration rising="0.0" />
    <dynamics damping="0.5" />
    <origin rpy="0.0 0.0 0.0" xyz="-0.01707 0.0 0.38145" />
    <parent link="torso_lift_link" />
    <child link="head_pan_link" />
  </joint>
  <link name="head_pan_link">
    <inertial>
      <mass value="6.339" />
      
      <origin rpy="0 0 0" xyz="0.010907 0.031693 0.090507" />
      <inertia ixx="0.032497592" ixy="0.00063604088" ixz="0.0025851534" iyy="0.046545627" iyz="-0.0024534295" izz="0.057652724" />
    </inertial>
    <visual>
      <origin rpy="0 0 0" xyz="0 0 0.0" />
      <geometry>
        <mesh filename="meshes/head_pan_L.stl" />
      </geometry>
    </visual>
    <collision>
      <geometry>
        <mesh filename="meshes/head_pan_L.stl" />
      </geometry>
    </collision>
  </link>
  <transmission name="head_pan_trans" type="pr2_mechanism_model/SimpleTransmission">
    <actuator name="head_pan_motor" />
    <joint name="head_pan_joint" />
    <mechanicalReduction>6.0</mechanicalReduction>
  </transmission>
  <joint name="head_tilt_joint" type="revolute">
    <axis xyz="0 1 0" />
    <limit effort="18" lower="-0.471238" upper="1.39626" velocity="5" />
    
    <safety_controller k_position="100" k_velocity="3.0" soft_lower_limit="-0.3712" soft_upper_limit="1.29626" />
    <calibration falling="0.0" />
    <dynamics damping="10.0" />
    <origin rpy="0 0 0" xyz="0.068 0 0" />
    <parent link="head_pan_link" />
    <child link="head_tilt_link" />
  </joint>
  <link name="head_tilt_link">
    <inertial>
      <mass value="4.479" />
      
      <origin rpy="0 0 0" xyz="0.001716 -0.019556 0.055002" />
      <inertia ixx="0.024223222" ixy="0.00062063507" ixz="-0.000096909696" iyy="0.054723086" iyz="0.00279702400" izz="0.067306377" />
    </inertial>
    <visual>
      <origin rpy="0.0 0.0 0.0" xyz="0 0 0" />
      <geometry>
        <mesh filename="meshes/head_tilt_L.stl" />
      </geometry>
    </visual>
    <collision>
      <origin rpy="0.0 0.0 0.0" xyz="0 0 0" />
      <geometry>
        <mesh filename="meshes/head_tilt_L.stl" />
      </geometry>
    </collision>
  </link>
  <transmission name="head_tilt_trans" type="pr2_mechanism_model/SimpleTransmission">
    <actuator name="head_tilt_motor" />
    <joint name="head_tilt_joint" />
    <mechanicalReduction>6.0</mechanicalReduction>
  </transmission>
  
  <joint name="head_plate_frame_joint" type="fixed">
    <origin rpy="0 0 0" xyz="0.0232 0 0.0645" />
    <parent link="head_tilt_link" />
    <child link="head_plate_frame" />
  </joint>
  <link name="head_plate_frame">
    <inertial>
      <mass value="0.01" />
      <origin rpy="0 0 0" xyz="0 0 0" />
      <inertia ixx="0.001" ixy="0.0" ixz="0.0" iyy="0.001" iyz="0.0" izz="0.001" />
    </inertial>
    <visual>
      <origin rpy="0 0 0" xyz="0 0 0" />
      <geometry>
        <box size="0.01 0.01 0.01" />
      </geometry>
    </visual>
    <collision>
      <origin rpy="0 0 0" xyz="0 0 0" />
      <geometry>
        <box size="0.01 0.01 0.01" />
      </geometry>
    </collision>
  </link>
  
  
  
  
  
  
  
  
  
  
  
  
  
  
  
  
  
  <joint name="laser_tilt_mount_joint" type="revolute">
    <axis xyz="0 1 0" />
    <limit effort="0.65" lower="-0.7854" upper="1.48353" velocity="10.0" />
    
    <safety_controller k_position="100" k_velocity="0.05" soft_lower_limit="-0.7354" soft_upper_limit="1.43353" />
    <calibration falling="0.0" />
    <dynamics damping="0.008" />
    <origin rpy="0 0 0" xyz="0.09893 0 0.227" />
    <parent link="torso_lift_link" />
    <child link="laser_tilt_mount_link" />
  </joint>
  <link name="laser_tilt_mount_link">
    <inertial>
      <mass value="0.591" />
      <origin rpy="0 0 0" xyz="-0.001136 0.00167 -0.00713" />
      <inertia ixx="0.001195273" ixy="0.000023087" ixz="0.000037467" iyy="0.001083956" iyz="0.000034906" izz="0.000795014" />
    </inertial>
    <visual>
      <origin rpy="0 0 0" xyz="0 0 0" />
      <geometry>
        <mesh filename="meshes/tilting_hokuyo_L.stl" />
      </geometry>
    </visual>
    <collision>
      <origin rpy="0 0 0" xyz="0 0 0" />
      <geometry>
        <mesh filename="meshes/tilting_hokuyo_L.stl" />
      </geometry>
    </collision>
  </link>
  
  
  <transmission name="laser_tilt_mount_trans" type="pr2_mechanism_model/SimpleTransmission">
    <actuator name="laser_tilt_mount_motor" />
    <joint name="laser_tilt_mount_joint" />
    <mechanicalReduction>-6.05</mechanicalReduction>
  </transmission>
  
  <joint name="r_shoulder_pan_joint" type="revolute">
    <axis xyz="0 0 1" />
    <origin rpy="0 0 0" xyz="0.0 -0.188 0.0" />
    
    <parent link="torso_lift_link" />
    <child link="r_shoulder_pan_link" />
    <limit effort="30" lower="-2.2853981634" upper="0.714601836603" velocity="2.088" />
    
    <dynamics damping="10.0" />
    <safety_controller k_position="100" k_velocity="10" soft_lower_limit="-2.1353981634" soft_upper_limit="0.564601836603" />
    
    <calibration rising="-0.785398163397" />
  </joint>
  <link name="r_shoulder_pan_link">
    <inertial>
      <mass value="25.799322" />
      <origin rpy="0 0 0" xyz="-0.001201 0.024513 -0.098231" />
      <inertia ixx="0.866179142480" ixy="-0.06086507933" ixz="-0.12118061183" iyy="0.87421714893" iyz="-0.05886609911" izz="0.27353821674" />
    </inertial>
    <visual>
      <origin rpy="0 0 0" xyz="0 0 0" />
      <geometry>
        <mesh filename="meshes/shoulder_pan.dae" />
      </geometry>
    </visual>
    <collision>
      <origin rpy="0 0 0" xyz="0.0 0 0.0" />
      <geometry>
        <mesh filename="meshes/shoulder_pan.stl" />
      </geometry>
    </collision>
  </link>
  
  <joint name="r_shoulder_lift_joint" type="revolute">
    <axis xyz="0 1 0" />
    
    <limit effort="30" lower="-0.5236" upper="1.3963" velocity="2.082" />
    
    <safety_controller k_position="100" k_velocity="10" soft_lower_limit="-0.3536" soft_upper_limit="1.2963" />
    <calibration falling="0.0" />
    <dynamics damping="10.0" />
    <origin rpy="0 0 0" xyz="0.1 0 0" />
    <parent link="r_shoulder_pan_link" />
    <child link="r_shoulder_lift_link" />
  </joint>
  <link name="r_shoulder_lift_link">
    <inertial>
      <mass value="2.74988" />
      <origin rpy="0 0 0" xyz="0.02195 -0.02664 -0.03127" />
      <inertia ixx="0.02105584615" ixy="0.00496704022" ixz="-0.00194808955" iyy="0.02127223737" iyz="0.00110425490" izz="0.01975753814" />
    </inertial>
    <visual>
      <origin rpy="0 0 0" xyz="0 0 0" />
      <geometry>
        <mesh filename="meshes/shoulder_lift.dae" />
      </geometry>
    </visual>
    <collision>
      <origin rpy="0 0 0" xyz="0 0 0" />
      <geometry>
        <mesh filename="meshes/shoulder_lift.stl" />
      </geometry>
    </collision>
  </link>
  <joint name="r_upper_arm_roll_joint" type="revolute">
    <axis xyz="1 0 0" />
    <origin rpy="0 0 0" xyz="0 0 0" />
    <parent link="r_shoulder_lift_link" />
    <child link="r_upper_arm_roll_link" />
    <limit effort="30" lower="-3.9" upper="0.8" velocity="3.27" />
    
    <safety_controller k_position="100" k_velocity="2" soft_lower_limit="-3.75" soft_upper_limit="0.65" />
    <calibration rising="-1.57079632679" />
    <dynamics damping="0.1" />
  </joint>
  <link name="r_upper_arm_roll_link">
    <inertial>
      
      <mass value="0.1" />
      <origin rpy="0 0 0" xyz="0.0 0 0" />
      <inertia ixx="0.01" ixy="0.00" ixz="0.00" iyy="0.01" iyz="0.00" izz="0.01" />
    </inertial>
    <visual>
      
      <origin rpy="0 0 0" xyz="0 0 0" />
      <geometry>
        <mesh filename="meshes/upper_arm_roll.stl" />
      </geometry>
    </visual>
    <collision>
      <origin rpy="0 0 0" xyz="0 0 0" />
      <geometry>
        <mesh filename="meshes/upper_arm_roll_L.stl" />
      </geometry>
    </collision>
  </link>
  
  
  <transmission name="r_shoulder_pan_trans" type="pr2_mechanism_model/SimpleTransmission">
    <joint name="r_shoulder_pan_joint" />
    <actuator name="r_shoulder_pan_motor" />
    <mechanicalReduction>63.1552452977</mechanicalReduction>
    <compensator k_belt="4000.0" kd_motor="15.0" lambda_combined="0.0" lambda_joint="40.0" lambda_motor="40.0" mass_motor="0.05" />
  </transmission>
  
  <transmission name="r_shoulder_lift_trans" type="pr2_mechanism_model/SimpleTransmission">
    <joint name="r_shoulder_lift_joint" />
    <actuator name="r_shoulder_lift_motor" />
    <mechanicalReduction>61.8948225713</mechanicalReduction>
    <compensator k_belt="4000.0" kd_motor="10.0" lambda_combined="0.0" lambda_joint="60.0" lambda_motor="60.0" mass_motor="0.05" />
  </transmission>
  <joint name="r_upper_arm_joint" type="fixed">
    <origin rpy="0 0 0" xyz="0 0 0" />
    <parent link="r_upper_arm_roll_link" />
    <child link="r_upper_arm_link" />
  </joint>
  <link name="r_upper_arm_link">
    <inertial>
      
      <mass value="6.01769" />
      <origin xyz="0.21398 -0.01621 -0.0002" />
      <inertia ixx="0.01537748957" ixy="0.00375711247" ixz="-0.00070852914" iyy="0.0747367044" iyz="-0.0001793645" izz="0.07608763307" />
    </inertial>
    <visual>
      <origin rpy="0 0 0" xyz="0 0 0" />
      <geometry>
        <mesh filename="meshes/upper_arm.dae" />
      </geometry>
    </visual>
    <collision>
      <origin rpy="0 0 0" xyz="0 0 0" />
      <geometry>
        <mesh filename="meshes/upper_arm.stl" />
      </geometry>
    </collision>
  </link>
  
  
  
  
  <joint name="r_forearm_roll_joint" type="revolute">
    <axis xyz="1 0 0" />
    <limit effort="30" velocity="3.6" lower="-3.141592653589793" upper="3.141592653589793" />
    
    <safety_controller k_velocity="1" />
    <calibration rising="0.0" />
    <dynamics damping="0.1" />
    <origin rpy="0 0 0" xyz="0 0 0" />
    <parent link="r_elbow_flex_link" />
    <child link="r_forearm_roll_link" />
  </joint>
  
  <link name="r_forearm_roll_link">
    <inertial>
      
      <mass value="0.1" />
      <origin xyz="0 0 0" />
      <inertia ixx="0.01" ixy="0.00" ixz="0.00" iyy="0.01" iyz="0.00" izz="0.01" />
    </inertial>
    <visual>
      <origin rpy="0 0 0" xyz="0 0 0" />
      <geometry>
        <mesh filename="meshes/forearm_roll.stl" />
      </geometry>
    </visual>
    
    <collision>
      <origin rpy="0 0 0" xyz="0 0 0" />
      <geometry>
        <mesh filename="meshes/forearm_roll_L.stl" />
      </geometry>
    </collision>
  </link>
  
  <transmission name="r_forearm_roll_trans" type="pr2_mechanism_model/SimpleTransmission">
    <actuator name="r_forearm_roll_motor" />
    <joint name="r_forearm_roll_joint" />
    <mechanicalReduction>-90.5142857143</mechanicalReduction>
  </transmission>
  
  <joint name="r_elbow_flex_joint" type="revolute">
    <axis xyz="0 1 0" />
    
    <limit effort="30" lower="-2.3213" upper="0.00" velocity="3.3" />
    
    <safety_controller k_position="100" k_velocity="3" soft_lower_limit="-2.1213" soft_upper_limit="-0.15" />
    <calibration falling="-1.1606" />
    <dynamics damping="1.0" />
    <origin rpy="0 0 0" xyz="0.4 0 0" />
    <parent link="r_upper_arm_link" />
    <child link="r_elbow_flex_link" />
  </joint>
  <link name="r_elbow_flex_link">
    <inertial>
      <mass value="1.90327" />
      <origin xyz="0.01014 0.00032 -0.01211" />
      <inertia ixx="0.00346541989" ixy="0.00004066825" ixz="0.00043171614" iyy="0.00441606455" iyz="-0.00003968914" izz="0.00359156824" />
    </inertial>
    <visual>
      <origin rpy="0 0 0" xyz="0 0 0" />
      <geometry>
        <mesh filename="meshes/elbow_flex.dae" />
      </geometry>
    </visual>
    <collision>
      <origin rpy="0 0 0" xyz="0 0 0" />
      <geometry>
        <mesh filename="meshes/elbow_flex.stl" />
      </geometry>
    </collision>
  </link>
  
  
  
  <transmission name="r_elbow_flex_trans" type="pr2_mechanism_model/SimpleTransmission">
    <actuator name="r_elbow_flex_motor" />
    <joint name="r_elbow_flex_joint" />
    <mechanicalReduction>-36.167452007</mechanicalReduction>
  </transmission>
  <joint name="r_forearm_joint" type="fixed">
    <origin rpy="0 0 0" xyz="0 0 0" />
    
    <parent link="r_forearm_roll_link" />
    <child link="r_forearm_link" />
  </joint>
  <link name="r_forearm_link">
    <inertial>
      <mass value="2.57968" />
      <origin xyz="0.18791 -0.00017 -0.00912" />
      <inertia ixx="0.00364857222" ixy="0.00005215877" ixz="0.00071534842" iyy="0.01507736897" iyz="-0.00001310770" izz="0.01659310749" />
    </inertial>
    <visual>
      <origin rpy="0 0 0" xyz="0 0 0" />
      <geometry>
        <mesh filename="meshes/forearm.dae" />
      </geometry>
    </visual>
    <collision>
      <origin rpy="0 0 0" xyz="0 0 0" />
      <geometry>
        <mesh filename="meshes/forearm.stl" />
      </geometry>
    </collision>
  </link>
  
  <joint name="r_wrist_flex_joint" type="revolute">
    <axis xyz="0 1 0" />
    <limit effort="10" lower="-2.18" upper="0.0" velocity="3.078" />
    
    <safety_controller k_position="20" k_velocity="4" soft_lower_limit="-2.0" soft_upper_limit="-0.1" />
    <dynamics damping="0.1" />
    <calibration falling="-0.5410521" />
    <origin rpy="0 0 0" xyz="0.321 0 0" />
    <parent link="r_forearm_link" />
    <child link="r_wrist_flex_link" />
  </joint>
  <link name="r_wrist_flex_link">
    <inertial>
      <mass value="0.61402" />
      <origin xyz="-0.00157 0.0 -0.00075" />
      <inertia ixx="0.00065165722" ixy="0.00000028864" ixz="0.00000303477" iyy="0.00019824443" iyz="-0.00000022645" izz="0.00064450498" />
    </inertial>
    <visual>
      <origin rpy="0 0 0" xyz="0 0 0" />
      <geometry>
        <mesh filename="meshes/wrist_flex.dae" />
      </geometry>
    </visual>
    <collision>
      <origin rpy="0 0 0" xyz="0 0 0" />
      <geometry>
        <mesh filename="meshes/wrist_flex.stl" />
      </geometry>
    </collision>
  </link>
  
  <joint name="r_wrist_roll_joint" type="revolute">
    <axis xyz="1 0 0" />
    <limit effort="10" velocity="3.6" lower="-3.141592653589793" upper="3.141592653589793" />
    
    <safety_controller k_velocity="2" />
    <dynamics damping="0.1" />
    <calibration rising="-1.57079632679" />
    <origin rpy="0 0 0" xyz="0 0 0" />
    <parent link="r_wrist_flex_link" />
    <child link="r_wrist_roll_link" />
  </joint>
  <link name="r_wrist_roll_link">
    <inertial>
      
      <mass value="0.1" />
      <origin xyz="0 0 0" />
      <inertia ixx="0.01" ixy="0" ixz="0" iyy="0.01" iyz="0" izz="0.01" />
    </inertial>
    <visual>
      <origin rpy="0 0 0" xyz="0 0 0" />
      <geometry>
        <mesh filename="meshes/wrist_roll.stl" />
      </geometry>
    </visual>
    <collision>
      <origin rpy="0 0 0" xyz="0 0 0" />
      <geometry>
        <mesh filename="meshes/wrist_roll_L.stl" />
      </geometry>
    </collision>
  </link>
  
  
  <transmission name="r_wrist_trans" type="pr2_mechanism_model/WristTransmission">
    <rightActuator mechanicalReduction="60.1714285714" name="r_wrist_r_motor" />
    <leftActuator mechanicalReduction="60.1714285714" name="r_wrist_l_motor" />
    <flexJoint mechanicalReduction="-1.0" name="r_wrist_flex_joint" />
    <rollJoint mechanicalReduction="1.0" name="r_wrist_roll_joint" />
  </transmission>
  <joint name="r_gripper_palm_joint" type="fixed">
    <origin rpy="0 0 0" xyz="0 0 0" />
    <parent link="r_wrist_roll_link" />
    <child link="r_gripper_palm_link" />
  </joint>
  <link name="r_gripper_palm_link">
    <inertial>
      <mass value="0.58007" />
      <origin rpy="0 0 0" xyz="0.06623 0.00053 -0.00119" />
      <inertia ixx="0.00035223921" ixy="-0.00001580476" ixz="-0.00000091750" iyy="0.00067741312" iyz="-0.00000059554" izz="0.00086563316" />
    </inertial>
    <visual>
      <origin rpy="0 0 0" xyz="0 0 0" />
      <geometry>
        <mesh filename="meshes/gripper_palm.dae" />
      </geometry>
    </visual>
    <collision>
      <origin rpy="0 0 0" xyz="0 0 0" />
      <geometry>
        <mesh filename="meshes/gripper_palm.stl" />
      </geometry>
    </collision>
  </link>
  
  <joint name="r_gripper_motor_accelerometer_joint" type="fixed">
    <origin rpy="0 0 0" xyz="0 0 0" />
    <parent link="r_gripper_palm_link" />
    <child link="r_gripper_motor_accelerometer_link" />
  </joint>
  <link name="r_gripper_motor_accelerometer_link">
    <inertial>
      <mass value="0.001" />
      <origin rpy="0 0 0" xyz="0 0 0" />
      <inertia ixx="0.001" ixy="0.0" ixz="0.0" iyy="0.001" iyz="0.0" izz="0.001" />
    </inertial>
    <visual>
      <origin rpy="0 0 0" xyz="0 0 0" />
      <geometry>
        <box size="0.001 0.001 0.001" />
      </geometry>
    </visual>
    <collision>
      <origin rpy="0 0 0" xyz="0 0 0" />
      <geometry>
        <box size="0.001 0.001 0.001" />
      </geometry>
    </collision>
  </link>
  
  
  
  <joint name="r_gripper_l_finger_joint" type="revolute">
    <axis xyz="0 0 1" />
    
    <limit effort="1000.0" lower="0.0" upper="0.548" velocity="0.5" />
    <dynamics damping="0.02" />
    <origin rpy="0 0 0" xyz="0.07691 0.01 0" />
    <parent link="r_gripper_palm_link" />
    <child link="r_gripper_l_finger_link" />
  </joint>
  <link name="r_gripper_l_finger_link">
    <inertial>
      <mass value="0.17126" />
      <origin rpy="0 0 0" xyz="0.03598 0.01730 -0.00164" />
      <inertia ixx="0.00007756198" ixy="0.00000149095" ixz="-0.00000983385" iyy="0.00019708305" iyz="-0.00000306125" izz="0.00018105446" />
    </inertial>
    <visual>
      <origin rpy="0 0 0" xyz="0 0 0" />
      <geometry>
        <mesh filename="meshes/l_finger.dae" />
      </geometry>
    </visual>
    <collision>
      <origin rpy="0 0 0" xyz="0 0 0" />
      <geometry>
        <mesh filename="meshes/l_finger.stl" />
      </geometry>
    </collision>
  </link>
  
  <joint name="r_gripper_r_finger_joint" type="revolute">
    <axis xyz="0 0 -1" />
    <origin rpy="0 0 0" xyz="0.07691 -0.01 0" />
    
    <limit effort="1000.0" lower="0.0" upper="0.548" velocity="0.5" />
    <dynamics damping="0.02" />
    <mimic joint="r_gripper_l_finger_joint" multiplier="1" offset="0" />
    <parent link="r_gripper_palm_link" />
    <child link="r_gripper_r_finger_link" />
  </joint>
  <link name="r_gripper_r_finger_link">
    <inertial>
      <mass value="0.17389" />
      <origin rpy="0 0 0" xyz="0.03576 -0.01736 -0.00095" />
      <inertia ixx="0.00007738410" ixy="-0.00000209309" ixz="-0.00000836228" iyy="0.00019847383" iyz="0.00000246110" izz="0.00018106988" />
    </inertial>
    <visual>
      <origin rpy="3.14159265359 0 0" xyz="0 0 0" />
      <geometry>
        <mesh filename="meshes/l_finger.dae" />
      </geometry>
    </visual>
    <collision>
      <origin rpy="3.14159265359 0 0" xyz="0 0 0" />
      <geometry>
        <mesh filename="meshes/l_finger.stl" />
      </geometry>
    </collision>
  </link>
  
  <joint name="r_gripper_l_finger_tip_joint" type="revolute">
    <axis xyz="0 0 -1" />
    <origin rpy="0 0 0" xyz="0.09137 0.00495 0" />
    
    <limit effort="1000.0" lower="0.0" upper="0.548" velocity="0.5" />
    <dynamics damping="0.001" />
    <mimic joint="r_gripper_l_finger_joint" multiplier="1" offset="0" />
    <parent link="r_gripper_l_finger_link" />
    <child link="r_gripper_l_finger_tip_link" />
  </joint>
  <link name="r_gripper_l_finger_tip_link">
    <inertial>
      <mass value="0.04419" />
      <origin rpy="0 0 0" xyz="0.00423 0.00284 0.0" />
      <inertia ixx="0.00000837047" ixy="0.00000583632" ixz="0.0" iyy="0.00000987067" iyz="0.0" izz="0.00001541768" />
    </inertial>
    <visual>
      <origin rpy="0 0 0" xyz="0 0 0" />
      <geometry>
        <mesh filename="meshes/l_finger_tip.dae" />
      </geometry>
    </visual>
    <collision>
      <origin rpy="0 0 0" xyz="0 0 0" />
      <geometry>
        <mesh filename="meshes/l_finger_tip.stl" />
      </geometry>
    </collision>
  </link>
  
  <joint name="r_gripper_r_finger_tip_joint" type="revolute">
    <axis xyz="0 0 1" />
    <origin rpy="0 0 0" xyz="0.09137 -0.00495 0" />
    
    <limit effort="1000.0" lower="0.0" upper="0.548" velocity="0.5" />
    <dynamics damping="0.001" />
    <mimic joint="r_gripper_l_finger_joint" multiplier="1" offset="0" />
    <parent link="r_gripper_r_finger_link" />
    <child link="r_gripper_r_finger_tip_link" />
  </joint>
  <link name="r_gripper_r_finger_tip_link">
    <inertial>
      <mass value="0.04419" />
      <origin rpy="0 0 0" xyz="0.00423 -0.00284 0.0" />
      <inertia ixx="0.00000837047" ixy="-0.00000583632" ixz="0.0" iyy="0.00000987067" iyz="0.0" izz="0.00001541768" />
    </inertial>
    <visual>
      <origin rpy="3.14159265359 0 0" xyz="0 0 0" />
      <geometry>
        <mesh filename="meshes/l_finger_tip.dae" />
      </geometry>
    </visual>
    <collision>
      <origin rpy="3.14159265359 0 0" xyz="0 0 0" />
      <geometry>
        <mesh filename="meshes/l_finger_tip.stl" />
      </geometry>
    </collision>
  </link>
  
  
  
  
  
  
  
  
  
  
  
  
  
  
  
  
  
  
  
  
  
  
  
  <transmission name="r_gripper_trans" type="pr2_mechanism_model/PR2GripperTransmission">
    <actuator name="r_gripper_motor" />
    <gap_joint L0="0.0375528" a="0.0683698" b="0.0433849" gear_ratio="40.095" h="0.0" mechanical_reduction="1.0" name="r_gripper_joint" phi0="0.518518122146" r="0.0915" screw_reduction="0.004" t0="-0.0001914" theta0="0.0628824676201" />
    
    <use_simulated_gripper_joint />
    
    <passive_joint name="r_gripper_l_finger_joint" />
    <passive_joint name="r_gripper_r_finger_joint" />
    <passive_joint name="r_gripper_r_finger_tip_joint" />
    <passive_joint name="r_gripper_l_finger_tip_joint" />
    
    <simulated_actuated_joint name="r_gripper_motor_screw_joint" passive_actuated_joint="r_gripper_motor_slider_joint" simulated_reduction="3141.6" />
  </transmission>
  
  <joint name="l_shoulder_pan_joint" type="revolute">
    <axis xyz="0 0 1" />
    <origin rpy="0 0 0" xyz="0.0 0.188 0.0" />
    
    <parent link="torso_lift_link" />
    <child link="l_shoulder_pan_link" />
    <limit effort="30" lower="-0.714601836603" upper="2.2853981634" velocity="2.088" />
    
    <dynamics damping="10.0" />
    <safety_controller k_position="100" k_velocity="10" soft_lower_limit="-0.564601836603" soft_upper_limit="2.1353981634" />
    
    <calibration rising="0.785398163397" />
  </joint>
  <link name="l_shoulder_pan_link">
    <inertial>
      <mass value="25.799322" />
      <origin rpy="0 0 0" xyz="-0.001201 0.024513 -0.098231" />
      <inertia ixx="0.866179142480" ixy="-0.06086507933" ixz="-0.12118061183" iyy="0.87421714893" iyz="-0.05886609911" izz="0.27353821674" />
    </inertial>
    <visual>
      <origin rpy="0 0 0" xyz="0 0 0" />
      <geometry>
        <mesh filename="meshes/shoulder_pan.dae" />
      </geometry>
    </visual>
    <collision>
      <origin rpy="0 0 0" xyz="0.0 0 0.0" />
      <geometry>
        <mesh filename="meshes/shoulder_pan.stl" />
      </geometry>
    </collision>
  </link>
  
  <joint name="l_shoulder_lift_joint" type="revolute">
    <axis xyz="0 1 0" />
    
    <limit effort="30" lower="-0.5236" upper="1.3963" velocity="2.082" />
    
    <safety_controller k_position="100" k_velocity="10" soft_lower_limit="-0.3536" soft_upper_limit="1.2963" />
    <calibration falling="0.0" />
    <dynamics damping="10.0" />
    <origin rpy="0 0 0" xyz="0.1 0 0" />
    <parent link="l_shoulder_pan_link" />
    <child link="l_shoulder_lift_link" />
  </joint>
  <link name="l_shoulder_lift_link">
    <inertial>
      <mass value="2.74988" />
      <origin rpy="0 0 0" xyz="0.02195 -0.02664 -0.03127" />
      <inertia ixx="0.02105584615" ixy="0.00496704022" ixz="-0.00194808955" iyy="0.02127223737" iyz="0.00110425490" izz="0.01975753814" />
    </inertial>
    <visual>
      <origin rpy="0 0 0" xyz="0 0 0" />
      <geometry>
        <mesh filename="meshes/shoulder_lift.dae" />
      </geometry>
    </visual>
    <collision>
      <origin rpy="0 0 0" xyz="0 0 0" />
      <geometry>
        <mesh filename="meshes/shoulder_lift.stl" />
      </geometry>
    </collision>
  </link>
  <joint name="l_upper_arm_roll_joint" type="revolute">
    <axis xyz="1 0 0" />
    <origin rpy="0 0 0" xyz="0 0 0" />
    <parent link="l_shoulder_lift_link" />
    <child link="l_upper_arm_roll_link" />
    <limit effort="30" lower="-0.8" upper="3.9" velocity="3.27" />
    
    <safety_controller k_position="100" k_velocity="2" soft_lower_limit="-0.65" soft_upper_limit="3.75" />
    <calibration rising="1.57079632679" />
    <dynamics damping="0.1" />
  </joint>
  <link name="l_upper_arm_roll_link">
    <inertial>
      
      <mass value="0.1" />
      <origin rpy="0 0 0" xyz="0.0 0 0" />
      <inertia ixx="0.01" ixy="0.00" ixz="0.00" iyy="0.01" iyz="0.00" izz="0.01" />
    </inertial>
    <visual>
      
      <origin rpy="0 0 0" xyz="0 0 0" />
      <geometry>
        <mesh filename="meshes/upper_arm_roll.stl" />
      </geometry>
    </visual>
    <collision>
      <origin rpy="0 0 0" xyz="0 0 0" />
      <geometry>
        <mesh filename="meshes/upper_arm_roll_L.stl" />
      </geometry>
    </collision>
  </link>
  
  
  <transmission name="l_shoulder_pan_trans" type="pr2_mechanism_model/SimpleTransmission">
    <joint name="l_shoulder_pan_joint" />
    <actuator name="l_shoulder_pan_motor" />
    <mechanicalReduction>63.1552452977</mechanicalReduction>
    <compensator k_belt="4000.0" kd_motor="15.0" lambda_combined="0.0" lambda_joint="40.0" lambda_motor="40.0" mass_motor="0.05" />
  </transmission>
  
  <transmission name="l_shoulder_lift_trans" type="pr2_mechanism_model/SimpleTransmission">
    <joint name="l_shoulder_lift_joint" />
    <actuator name="l_shoulder_lift_motor" />
    <mechanicalReduction>61.8948225713</mechanicalReduction>
    <compensator k_belt="4000.0" kd_motor="10.0" lambda_combined="0.0" lambda_joint="60.0" lambda_motor="60.0" mass_motor="0.05" />
  </transmission>
  <joint name="l_upper_arm_joint" type="fixed">
    <origin rpy="0 0 0" xyz="0 0 0" />
    <parent link="l_upper_arm_roll_link" />
    <child link="l_upper_arm_link" />
  </joint>
  <link name="l_upper_arm_link">
    <inertial>
      
      <mass value="6.01769" />
      <origin xyz="0.21405 0.01658 -0.00057" />
      <inertia ixx="0.01530603856" ixy="-0.00339324862" ixz="0.00060765455" iyy="0.07473694455" iyz="-0.00019953729" izz="0.07601594191" />
    </inertial>
    <visual>
      <origin rpy="0 0 0" xyz="0 0 0" />
      <geometry>
        <mesh filename="meshes/upper_arm.dae" />
      </geometry>
    </visual>
    <collision>
      <origin rpy="0 0 0" xyz="0 0 0" />
      <geometry>
        <mesh filename="meshes/upper_arm.stl" />
      </geometry>
    </collision>
  </link>
  
  
  
  
  <joint name="l_forearm_roll_joint" type="revolute">
    <axis xyz="1 0 0" />
    <limit effort="30" velocity="3.6" lower="-3.141592653589793" upper="3.141592653589793" />
    
    <safety_controller k_velocity="1" />
    <calibration rising="0.0" />
    <dynamics damping="0.1" />
    <origin rpy="0 0 0" xyz="0 0 0" />
    <parent link="l_elbow_flex_link" />
    <child link="l_forearm_roll_link" />
  </joint>
  
  <link name="l_forearm_roll_link">
    <inertial>
      
      <mass value="0.1" />
      <origin xyz="0 0 0" />
      <inertia ixx="0.01" ixy="0.00" ixz="0.00" iyy="0.01" iyz="0.00" izz="0.01" />
    </inertial>
    <visual>
      <origin rpy="0 0 0" xyz="0 0 0" />
      <geometry>
        <mesh filename="meshes/forearm_roll.stl" />
      </geometry>
    </visual>
    
    <collision>
      <origin rpy="0 0 0" xyz="0 0 0" />
      <geometry>
        <mesh filename="meshes/forearm_roll_L.stl" />
      </geometry>
    </collision>
  </link>
  
  <transmission name="l_forearm_roll_trans" type="pr2_mechanism_model/SimpleTransmission">
    <actuator name="l_forearm_roll_motor" />
    <joint name="l_forearm_roll_joint" />
    <mechanicalReduction>-90.5142857143</mechanicalReduction>
  </transmission>
  
  <joint name="l_elbow_flex_joint" type="revolute">
    <axis xyz="0 1 0" />
    
    <limit effort="30" lower="-2.3213" upper="0.00" velocity="3.3" />
    
    <safety_controller k_position="100" k_velocity="3" soft_lower_limit="-2.1213" soft_upper_limit="-0.15" />
    <calibration falling="-1.1606" />
    <dynamics damping="1.0" />
    <origin rpy="0 0 0" xyz="0.4 0 0" />
    <parent link="l_upper_arm_link" />
    <child link="l_elbow_flex_link" />
  </joint>
  <link name="l_elbow_flex_link">
    <inertial>
      <mass value="1.90327" />
      <origin xyz="0.01014 0.00032 -0.01211" />
      <inertia ixx="0.00346541989" ixy="0.00004066825" ixz="0.00043171614" iyy="0.00441606455" iyz="-0.00003968914" izz="0.00359156824" />
    </inertial>
    <visual>
      <origin rpy="0 0 0" xyz="0 0 0" />
      <geometry>
        <mesh filename="meshes/elbow_flex.dae" />
      </geometry>
    </visual>
    <collision>
      <origin rpy="0 0 0" xyz="0 0 0" />
      <geometry>
        <mesh filename="meshes/elbow_flex.stl" />
      </geometry>
    </collision>
  </link>
  
  
  
  <transmission name="l_elbow_flex_trans" type="pr2_mechanism_model/SimpleTransmission">
    <actuator name="l_elbow_flex_motor" />
    <joint name="l_elbow_flex_joint" />
    <mechanicalReduction>-36.167452007</mechanicalReduction>
  </transmission>
  <joint name="l_forearm_joint" type="fixed">
    <origin rpy="0 0 0" xyz="0 0 0" />
    
    <parent link="l_forearm_roll_link" />
    <child link="l_forearm_link" />
  </joint>
  <link name="l_forearm_link">
    <inertial>
      <mass value="2.57968" />
      <origin xyz="0.18791 -0.00017 -0.00912" />
      <inertia ixx="0.00364857222" ixy="0.00005215877" ixz="0.00071534842" iyy="0.01507736897" iyz="-0.00001310770" izz="0.01659310749" />
    </inertial>
    <visual>
      <origin rpy="0 0 0" xyz="0 0 0" />
      <geometry>
        <mesh filename="meshes/forearm.dae" />
      </geometry>
    </visual>
    <collision>
      <origin rpy="0 0 0" xyz="0 0 0" />
      <geometry>
        <mesh filename="meshes/forearm.stl" />
      </geometry>
    </collision>
  </link>
  
  <joint name="l_wrist_flex_joint" type="revolute">
    <axis xyz="0 1 0" />
    <limit effort="10" lower="-2.18" upper="0.0" velocity="3.078" />
    
    <safety_controller k_position="20" k_velocity="4" soft_lower_limit="-2.0" soft_upper_limit="-0.1" />
    <dynamics damping="0.1" />
    <calibration falling="-0.5410521" />
    <origin rpy="0 0 0" xyz="0.321 0 0" />
    <parent link="l_forearm_link" />
    <child link="l_wrist_flex_link" />
  </joint>
  <link name="l_wrist_flex_link">
    <inertial>
      <mass value="0.61402" />
      <origin xyz="-0.00157 0.0 -0.00075" />
      <inertia ixx="0.00065165722" ixy="0.00000028864" ixz="0.00000303477" iyy="0.00019824443" iyz="-0.00000022645" izz="0.00064450498" />
    </inertial>
    <visual>
      <origin rpy="0 0 0" xyz="0 0 0" />
      <geometry>
        <mesh filename="meshes/wrist_flex.dae" />
      </geometry>
    </visual>
    <collision>
      <origin rpy="0 0 0" xyz="0 0 0" />
      <geometry>
        <mesh filename="meshes/wrist_flex.stl" />
      </geometry>
    </collision>
  </link>
  
  <joint name="l_wrist_roll_joint" type="revolute">
    <axis xyz="1 0 0" />
    <limit effort="10" velocity="3.6" lower="-3.141592653589793" upper="3.141592653589793" />
    
    <safety_controller k_velocity="2" />
    <dynamics damping="0.1" />
    <calibration rising="-1.57079632679" />
    <origin rpy="0 0 0" xyz="0 0 0" />
    <parent link="l_wrist_flex_link" />
    <child link="l_wrist_roll_link" />
  </joint>
  <link name="l_wrist_roll_link">
    <inertial>
      
      <mass value="0.1" />
      <origin xyz="0 0 0" />
      <inertia ixx="0.01" ixy="0" ixz="0" iyy="0.01" iyz="0" izz="0.01" />
    </inertial>
    <visual>
      <origin rpy="0 0 0" xyz="0 0 0" />
      <geometry>
        <mesh filename="meshes/wrist_roll.stl" />
      </geometry>
    </visual>
    <collision>
      <origin rpy="0 0 0" xyz="0 0 0" />
      <geometry>
        <mesh filename="meshes/wrist_roll_L.stl" />
      </geometry>
    </collision>
  </link>
 
  
  <transmission name="l_wrist_trans" type="pr2_mechanism_model/WristTransmission">
    <rightActuator mechanicalReduction="60.1714285714" name="l_wrist_r_motor" />
    <leftActuator mechanicalReduction="60.1714285714" name="l_wrist_l_motor" />
    <flexJoint mechanicalReduction="-1.0" name="l_wrist_flex_joint" />
    <rollJoint mechanicalReduction="1.0" name="l_wrist_roll_joint" />
  </transmission>
  <joint name="l_gripper_palm_joint" type="fixed">
    <origin rpy="0 0 0" xyz="0 0 0" />
    <parent link="l_wrist_roll_link" />
    <child link="l_gripper_palm_link" />
  </joint>
  <link name="l_gripper_palm_link">
    <inertial>
      <mass value="0.58007" />
      <origin rpy="0 0 0" xyz="0.06623 0.00053 -0.00119" />
      <inertia ixx="0.00035223921" ixy="-0.00001580476" ixz="-0.00000091750" iyy="0.00067741312" iyz="-0.00000059554" izz="0.00086563316" />
    </inertial>
    <visual>
      <origin rpy="0 0 0" xyz="0 0 0" />
      <geometry>
        <mesh filename="meshes/gripper_palm.dae" />
      </geometry>
    </visual>
    <collision>
      <origin rpy="0 0 0" xyz="0 0 0" />
      <geometry>
        <mesh filename="meshes/gripper_palm.stl" />
      </geometry>
    </collision>
  </link>
  
  <joint name="l_gripper_motor_accelerometer_joint" type="fixed">
    <origin rpy="0 0 0" xyz="0 0 0" />
    <parent link="l_gripper_palm_link" />
    <child link="l_gripper_motor_accelerometer_link" />
  </joint>
  <link name="l_gripper_motor_accelerometer_link">
    <inertial>
      <mass value="0.001" />
      <origin rpy="0 0 0" xyz="0 0 0" />
      <inertia ixx="0.001" ixy="0.0" ixz="0.0" iyy="0.001" iyz="0.0" izz="0.001" />
    </inertial>
    <visual>
      <origin rpy="0 0 0" xyz="0 0 0" />
      <geometry>
        <box size="0.001 0.001 0.001" />
      </geometry>
    </visual>
    <collision>
      <origin rpy="0 0 0" xyz="0 0 0" />
      <geometry>
        <box size="0.001 0.001 0.001" />
      </geometry>
    </collision>
  </link>
  
  
  
  
  
  <joint name="l_gripper_l_finger_joint" type="revolute">
    <axis xyz="0 0 1" />
    
    <limit effort="1000.0" lower="0.0" upper="0.548" velocity="0.5" />
    <dynamics damping="0.02" />
    <origin rpy="0 0 0" xyz="0.07691 0.01 0" />
    <parent link="l_gripper_palm_link" />
    <child link="l_gripper_l_finger_link" />
  </joint>
  <link name="l_gripper_l_finger_link">
    <inertial>
      <mass value="0.17126" />
      <origin rpy="0 0 0" xyz="0.03598 0.01730 -0.00164" />
      <inertia ixx="0.00007756198" ixy="0.00000149095" ixz="-0.00000983385" iyy="0.00019708305" iyz="-0.00000306125" izz="0.00018105446" />
    </inertial>
    <visual>
      <origin rpy="0 0 0" xyz="0 0 0" />
      <geometry>
        <mesh filename="meshes/l_finger.dae" />
      </geometry>
    </visual>
    <collision>
      <origin rpy="0 0 0" xyz="0 0 0" />
      <geometry>
        <mesh filename="meshes/l_finger.stl" />
      </geometry>
    </collision>
  </link>
  
  <joint name="l_gripper_r_finger_joint" type="revolute">
    <axis xyz="0 0 -1" />
    <origin rpy="0 0 0" xyz="0.07691 -0.01 0" />
    
    <limit effort="1000.0" lower="0.0" upper="0.548" velocity="0.5" />
    <dynamics damping="0.02" />
    <mimic joint="l_gripper_l_finger_joint" multiplier="1" offset="0" />
    <parent link="l_gripper_palm_link" />
    <child link="l_gripper_r_finger_link" />
  </joint>
  <link name="l_gripper_r_finger_link">
    <inertial>
      <mass value="0.17389" />
      <origin rpy="0 0 0" xyz="0.03576 -0.01736 -0.00095" />
      <inertia ixx="0.00007738410" ixy="-0.00000209309" ixz="-0.00000836228" iyy="0.00019847383" iyz="0.00000246110" izz="0.00018106988" />
    </inertial>
    <visual>
      <origin rpy="3.14159265359 0 0" xyz="0 0 0" />
      <geometry>
        <mesh filename="meshes/l_finger.dae" />
      </geometry>
    </visual>
    <collision>
      <origin rpy="3.14159265359 0 0" xyz="0 0 0" />
      <geometry>
        <mesh filename="meshes/l_finger.stl" />
      </geometry>
    </collision>
  </link>
  
  <joint name="l_gripper_l_finger_tip_joint" type="revolute">
    <axis xyz="0 0 -1" />
    <origin rpy="0 0 0" xyz="0.09137 0.00495 0" />
    
    <limit effort="1000.0" lower="0.0" upper="0.548" velocity="0.5" />
    <dynamics damping="0.001" />
    <mimic joint="l_gripper_l_finger_joint" multiplier="1" offset="0" />
    <parent link="l_gripper_l_finger_link" />
    <child link="l_gripper_l_finger_tip_link" />
  </joint>
  <link name="l_gripper_l_finger_tip_link">
    <inertial>
      <mass value="0.04419" />
      <origin rpy="0 0 0" xyz="0.00423 0.00284 0.0" />
      <inertia ixx="0.00000837047" ixy="0.00000583632" ixz="0.0" iyy="0.00000987067" iyz="0.0" izz="0.00001541768" />
    </inertial>
    <visual>
      <origin rpy="0 0 0" xyz="0 0 0" />
      <geometry>
        <mesh filename="meshes/l_finger_tip.dae" />
      </geometry>
    </visual>
    <collision>
      <origin rpy="0 0 0" xyz="0 0 0" />
      <geometry>
        <mesh filename="meshes/l_finger_tip.stl" />
      </geometry>
    </collision>
  </link>
  
  <joint name="l_gripper_r_finger_tip_joint" type="revolute">
    <axis xyz="0 0 1" />
    <origin rpy="0 0 0" xyz="0.09137 -0.00495 0" />
    
    <limit effort="1000.0" lower="0.0" upper="0.548" velocity="0.5" />
    <dynamics damping="0.001" />
    <mimic joint="l_gripper_l_finger_joint" multiplier="1" offset="0" />
    <parent link="l_gripper_r_finger_link" />
    <child link="l_gripper_r_finger_tip_link" />
  </joint>
  <link name="l_gripper_r_finger_tip_link">
    <inertial>
      <mass value="0.04419" />
      <origin rpy="0 0 0" xyz="0.00423 -0.00284 0.0" />
      <inertia ixx="0.00000837047" ixy="-0.00000583632" ixz="0.0" iyy="0.00000987067" iyz="0.0" izz="0.00001541768" />
    </inertial>
    <visual>
      <origin rpy="3.14159265359 0 0" xyz="0 0 0" />
      <geometry>
        <mesh filename="meshes/l_finger_tip.dae" />
      </geometry>
    </visual>
    <collision>
      <origin rpy="3.14159265359 0 0" xyz="0 0 0" />
      <geometry>
        <mesh filename="meshes/l_finger_tip.stl" />
      </geometry>
    </collision>
  </link>
  
  
  
  
  
  
  
  
  
  
  
  
  
  
  
  
  
  
  
  <transmission name="l_gripper_trans" type="pr2_mechanism_model/PR2GripperTransmission">
    <actuator name="l_gripper_motor" />
    <gap_joint L0="0.0375528" a="0.0683698" b="0.0433849" gear_ratio="40.095" h="0.0" mechanical_reduction="1.0" name="l_gripper_joint" phi0="0.518518122146" r="0.0915" screw_reduction="0.004" t0="-0.0001914" theta0="0.0628824676201" />
    
    <use_simulated_gripper_joint />
    
    <passive_joint name="l_gripper_l_finger_joint" />
    <passive_joint name="l_gripper_r_finger_joint" />
    <passive_joint name="l_gripper_r_finger_tip_joint" />
    <passive_joint name="l_gripper_l_finger_tip_joint" />
    
    <simulated_actuated_joint name="l_gripper_motor_screw_joint" passive_actuated_joint="l_gripper_motor_slider_joint" simulated_reduction="3141.6" />
  </transmission>
  
  
  
  
  
</robot>