<?xml version='1.0' encoding='utf-8'?>
<robot name="abb_irb6650s_125_350">
  
  
  <link name="base_link">
    <visual>
      <origin rpy="0 0 0" xyz="0 0 0" />
      <geometry>
        <mesh filename="meshes/base_link.stl" />
      </geometry>
      <material name="">
        <color rgba="0.7372549 0.3490196 0.1607843 1" />
      </material>
    </visual>
    <collision>
      <geometry>
        <mesh filename="meshes/collision_base_link.stl" />
      </geometry>
      <material name="">
        <color rgba="1 1 0 1" />
      </material>
    </collision>
  </link>
  <link name="link_1">
    <visual>
      <origin rpy="0 0 0" xyz="0 0 0" />
      <geometry>
        <mesh filename="meshes/link_1.stl" />
      </geometry>
      <material name="">
        <color rgba="0.7372549 0.3490196 0.1607843 1" />
      </material>
    </visual>
    <collision>
      <origin rpy="0 0 0" xyz="0 0 0" />
      <geometry>
        <mesh filename="meshes/collision_link_1.stl" />
      </geometry>
      <material name="">
        <color rgba="1 1 0 1" />
      </material>
    </collision>
  </link>
  <link name="link_2">
    <visual>
      <origin rpy="0 0 0" xyz="0 0 0" />
      <geometry>
        <mesh filename="meshes/link_2.stl" />
      </geometry>
      <material name="">
        <color rgba="0.7372549 0.3490196 0.1607843 1" />
      </material>
    </visual>
    <collision>
      <origin rpy="0 0 0" xyz="0 0 0" />
      <geometry>
        <mesh filename="meshes/collision_link_2.stl" />
      </geometry>
      <material name="">
        <color rgba="1 1 0 1" />
      </material>
    </collision>
  </link>
  <link name="link_3">
    <visual>
      <origin rpy="0 0 0" xyz="0 0 0" />
      <geometry>
        <mesh filename="meshes/link_3.stl" />
      </geometry>
      <material name="">
        <color rgba="0.7372549 0.3490196 0.1607843 1" />
      </material>
    </visual>
    <collision>
      <origin rpy="0 0 0" xyz="0 0 0" />
      <geometry>
        <mesh filename="meshes/collision_link_3.stl" />
      </geometry>
      <material name="">
        <color rgba="1 1 0 1" />
      </material>
    </collision>
  </link>
  <link name="link_4">
    <visual>
      <origin rpy="0 0 0" xyz="-0.600 0 0" />
      <geometry>
        <mesh filename="meshes/link_4.stl" />
      </geometry>
      <material name="">
        <color rgba="0.7372549 0.3490196 0.1607843 1" />
      </material>
    </visual>
    <collision>
      <origin rpy="0 0 0" xyz="-0.600 0 0" />
      <geometry>
        <mesh filename="meshes/collision_link_4.stl" />
      </geometry>
      <material name="">
        <color rgba="1 1 0 1" />
      </material>
    </collision>
  </link>
  <link name="link_5">
    <visual>
      <origin rpy="0 0 0" xyz="0 0 0" />
      <geometry>
        <mesh filename="meshes/link_5.stl" />
      </geometry>
      <material name="">
        <color rgba="0.7372549 0.3490196 0.1607843 1" />
      </material>
    </visual>
    <collision>
      <origin rpy="0 0 0" xyz="0 0 0" />
      <geometry>
        <mesh filename="meshes/collision_link_5.stl" />
      </geometry>
      <material name="">
        <color rgba="1 1 0 1" />
      </material>
    </collision>
  </link>
  <link name="link_6">
    <visual>
      <origin rpy="0 0 0" xyz="0 0 0" />
      <geometry>
        <mesh filename="meshes/link_6.stl" />
      </geometry>
      <material name="">
        <color rgba="0.1882353 0.1960784 0.2039216 1" />
      </material>
    </visual>
    <collision>
      <origin rpy="0 0 0" xyz="0 0 0" />
      <geometry>
        <mesh filename="meshes/collision_link_6.stl" />
      </geometry>
      <material name="">
        <color rgba="1 1 0 1" />
      </material>
    </collision>
  </link>
  
  
  <joint name="joint_1" type="revolute">
    <origin rpy="0 0 0" xyz="0 0 0.630" />
    <parent link="base_link" />
    <child link="link_1" />
    <axis xyz="0 0 1" />
    <limit effort="0" lower="-3.141592653589793" upper="3.141592653589793" velocity="1.9198621771937625" />
  </joint>
  <joint name="joint_2" type="revolute">
    <origin rpy="0 0 0" xyz="0.600 0 0" />
    <parent link="link_1" />
    <child link="link_2" />
    <axis xyz="0 1 0" />
    <limit effort="0" lower="-0.6981317007977318" upper="2.792526803190927" velocity="1.5707963267948966" />
  </joint>
  <joint name="joint_3" type="revolute">
    <origin rpy="0 0 0" xyz="0 0 1.280" />
    <parent link="link_2" />
    <child link="link_3" />
    <axis xyz="0 1 0" />
    <limit effort="0" lower="-3.141592653589793" upper="1.2217304763960306" velocity="1.5707963267948966" />
  </joint>
  <joint name="joint_4" type="revolute">
    <origin rpy="0 0 0" xyz="0 0 0.200" />
    <parent link="link_3" />
    <child link="link_4" />
    <axis xyz="1 0 0" />
    <limit effort="0" lower="-5.235987755982989" upper="5.235987755982989" velocity="2.6179938779914944" />
  </joint>
  <joint name="joint_5" type="revolute">
    <origin rpy="0 0 0" xyz="1.592 0 0" />
    <parent link="link_4" />
    <child link="link_5" />
    <axis xyz="0 1 0" />
    <limit effort="0" lower="-2.0943951023931953" upper="2.0943951023931953" velocity="2.0943951023931953" />
  </joint>
  <joint name="joint_6" type="revolute">
    <origin rpy="0 0 0" xyz="0.200 0 0" />
    <parent link="link_5" />
    <child link="link_6" />
    <axis xyz="1 0 0" />
    <limit effort="0" lower="-6.283185307179586" upper="6.283185307179586" velocity="4.101523742186674" />
  </joint>
  
  
  <link name="base" />
  <joint name="base_link-base" type="fixed">
    <origin rpy="0 0 0" xyz="0 0 0" />
    <parent link="base_link" />
    <child link="base" />
  </joint>
  
  <link name="flange" />
  <joint name="joint_6-flange" type="fixed">
    <origin rpy="0 0 0" xyz="0 0 0" />
    <parent link="link_6" />
    <child link="flange" />
  </joint>
  
  <link name="tool0" />
  <joint name="link_6-tool0" type="fixed">
    <origin rpy="0 1.5707963267948966 0" xyz="0 0 0" />
    <parent link="flange" />
    <child link="tool0" />
  </joint>
</robot>