<?xml version='1.0' encoding='utf-8'?>
<robot name="r2000ic_270r">
  <link name="world" />
  <link name="ee_link" />
  
  <link name="base_link">
    <visual>
      <origin rpy="0 0 0" xyz="0 0 0" />
      <geometry>
        <mesh filename="meshes/base.dae" />
      </geometry>
    </visual>
    <collision>
      <origin rpy="0 0 0" xyz="0 0 0" />
      <geometry>
        <mesh filename="meshes/base.stl" />
      </geometry>
    </collision>
    <inertial>
      <mass value=" 223" />
      <origin xyz="-.137 -.00069 .142" />
      <inertia ixx=" 7.65" ixy=" .204" ixz="-.325" iyy=" 16" iyz=" .0159" izz=" 20.2" />
    </inertial>
  </link>
  <link name="J1_link">
    <visual>
      <origin rpy="0 0 0" xyz="0 0 0" />
      <geometry>
        <mesh filename="meshes/j1.dae" />
      </geometry>
    </visual>
    <collision>
      <origin rpy="0 0 0" xyz="0 0 0" />
      <geometry>
        <mesh filename="meshes/j1.stl" />
      </geometry>
    </collision>
    <inertial>
      <mass value=" 725" />
      <origin xyz=".211 .137 -.0178" />
      <inertia ixx=" 53.7" ixy=" 7.01" ixz="-3.09" iyy=" 94" iyz="-5" izz=" 110" />
    </inertial>
  </link>
  <link name="J2_link">
    <visual>
      <origin rpy="0 0 0" xyz="0 0 0" />
      <geometry>
        <mesh filename="meshes/j2.dae" />
      </geometry>
    </visual>
    <collision>
      <origin rpy="0 0 0" xyz="0 0 0" />
      <geometry>
        <mesh filename="meshes/j2.stl" />
      </geometry>
    </collision>
    <inertial>
      <mass value=" 279" />
      <origin xyz=".496 .266 -.00408" />
      <inertia ixx=" 6.6" ixy="-2.38" ixz=" 1.03" iyy=" 41.6" iyz=" .00791" izz=" 41.4" />
    </inertial>
  </link>
  <link name="J3_link">
    <visual>
      <origin rpy="0 0 0" xyz="0 0 0" />
      <geometry>
        <mesh filename="meshes/j3.dae" />
      </geometry>
    </visual>
    <collision>
      <origin rpy="0 0 0" xyz="0 0 0" />
      <geometry>
        <mesh filename="meshes/j3.stl" />
      </geometry>
    </collision>
    <inertial>
      <mass value=" 323" />
      <origin xyz=".154 .0593 -.242" />
      <inertia ixx=" 37.6" ixy="-.0842" ixz=" 2.23" iyy=" 36.7" iyz="-.355" izz=" 11.2" />
    </inertial>
  </link>
  <link name="J4_link">
    <visual>
      <origin rpy="0 0 0" xyz="0 0 0" />
      <geometry>
        <mesh filename="meshes/j4.dae" />
      </geometry>
    </visual>
    <collision>
      <origin rpy="0 0 0" xyz="0 0 0" />
      <geometry>
        <mesh filename="meshes/j4.stl" />
      </geometry>
    </collision>
    <inertial>
      <mass value=" 14.1" />
      <origin xyz=".00000000126 -.00981 -1.16" />
      <inertia ixx=" .158" ixy="-.00000000134" ixz="-.00000000267" iyy=" .164" iyz="-.0099" izz=" .0688" />
    </inertial>
  </link>
  <link name="J5_link">
    <visual>
      <origin rpy="0 0 0" xyz="0 0 0" />
      <geometry>
        <mesh filename="meshes/j5.dae" />
      </geometry>
    </visual>
    <collision>
      <origin rpy="0 0 0" xyz="0 0 0" />
      <geometry>
        <mesh filename="meshes/j5.stl" />
      </geometry>
    </collision>
    <inertial>
      <mass value=" 24.5" />
      <origin xyz="-.0000000483 -.024 -.0522" />
      <inertia ixx=" .33" ixy="-.000000138" ixz="-.000000112" iyy=" .255" iyz=" .0354" izz=" .233" />
    </inertial>
  </link>
  <link name="J6_link">
    <visual>
      <origin rpy="0 0 0" xyz="0 0 0" />
      <geometry>
        <mesh filename="meshes/j6.dae" />
      </geometry>
    </visual>
    <collision>
      <origin rpy="0 0 0" xyz="0 0 0" />
      <geometry>
        <mesh filename="meshes/j6.stl" />
      </geometry>
    </collision>
    <inertial>
      <mass value=" 1.74" />
      <origin xyz=".0000159 .000000423 -.221" />
      <inertia ixx=" .00429" ixy=" .000000428" ixz="-.000000216" iyy=" .00429" iyz=" .00000000489" izz=" .00812" />
    </inertial>
  </link>
  
  <joint name="J1" type="revolute">
    <origin rpy="0 0 0" xyz="0 0 .6" />
    <parent link="base_link" />
    <child link="J1_link" />
    <axis xyz="0 0 1" />
    <limit effort="20000" lower="-3.2288591161895095" upper="3.2288591161895095" velocity="1.8325957145940461" />
  </joint>
  <joint name="J2" type="revolute">
    <origin rpy="0 0 0" xyz=".72 0 0" />
    <parent link="J1_link" />
    <child link="J2_link" />
    <axis xyz="0 1 0" />
    <limit effort="30000" lower="-2.0943951023931953" upper="1.3962634015954636" velocity="1.4835298641951802" />
  </joint>
  <joint name="J3" type="revolute">
    <origin rpy="0 0 0" xyz="1.075 0 0" />
    <parent link="J2_link" />
    <child link="J3_link" />
    <axis xyz="0 -1 0" />
    <limit effort="30000" lower="-1.3788101090755203" upper="3.141592653589793" velocity="1.4835298641951802" />
  </joint>
  <joint name="J4" type="revolute">
    <origin rpy="0 0 0" xyz=".225 0 0" />
    <parent link="J3_link" />
    <child link="J4_link" />
    <axis xyz="0 0 1" />
    <limit effort="6000" lower="-6.283185307179586" upper="6.283185307179586" velocity="2.0943951023931953" />
  </joint>
  <joint name="J5" type="revolute">
    <origin rpy="0 0 0" xyz="0 0 -1.28" />
    <parent link="J4_link" />
    <child link="J5_link" />
    <axis xyz="0 -1 0" />
    <limit effort="6000" lower="-2.181661564992912" upper="2.181661564992912" velocity="2.0943951023931953" />
  </joint>
  <joint name="J6" type="revolute">
    <origin rpy="0 0 0" xyz="0 0 0" />
    <parent link="J5_link" />
    <child link="J6_link" />
    <axis xyz="0 0 1" />
    <limit effort="3000" lower="-6.283185307179586" upper="6.283185307179586" velocity="3.490658503988659" />
  </joint>
  
  <link name="wbase" />
  <joint name="base_link-wbase" type="fixed">
    <origin rpy="0 0 0" xyz="0 0 .6" />
    <parent link="base_link" />
    <child link="wbase" />
  </joint>
  
  <link name="flange" />
  <joint name="J6-flange" type="fixed">
    <origin rpy="0 0 0" xyz="0 0 -.24" />
    <parent link="J6_link" />
    <child link="flange" />
  </joint>
  
  <link name="fanuc_flange" />
  <joint name="flange-fanuc_flange" type="fixed">
    <origin rpy="3.141592653589793 0.0 0.0" xyz="0 0 0" />
    <parent link="flange" />
    <child link="fanuc_flange" />
  </joint>
  
  <joint name="base_joint" type="fixed">
    <origin rpy="0 0 0" xyz="0 0 0" />
    <parent link="world" />
    <child link="base_link" />
  </joint>
  
  <joint name="child_joint" type="fixed">
    <origin rpy="0 0 0" xyz="0 0 0" />
    <parent link="flange" />
    <child link="ee_link" />
  </joint>
</robot>