<?xml version='1.0' encoding='utf-8'?>
<robot name="lrmate10-11afc">
  <link name="world" />
  <link name="ee_link" />
  
  <link name="base_link">
    <visual>
      <origin rpy="0 0 0" xyz="0 0 0" />
      <geometry>
        <mesh filename="meshes/base.dae" />
      </geometry>
    </visual>
    <collision>
      <origin rpy="0 0 0" xyz="0 0 0" />
      <geometry>
        <mesh filename="meshes/base.stl" />
      </geometry>
    </collision>
    <inertial>
      <mass value=" 8.3" />
      <origin xyz="-.0229 .0000229 .0978" />
      <inertia ixx=" .0533" ixy="-.0000114" ixz="-.00191" iyy=" .0715" iyz=" .000000706" izz=" .0712" />
    </inertial>
  </link>
  <link name="J1_link">
    <visual>
      <origin rpy="0 0 0" xyz="0 0 0" />
      <geometry>
        <mesh filename="meshes/j1.dae" />
      </geometry>
    </visual>
    <collision>
      <origin rpy="0 0 0" xyz="0 0 0" />
      <geometry>
        <mesh filename="meshes/j1.stl" />
      </geometry>
    </collision>
    <inertial>
      <mass value=" 11.1" />
      <origin xyz=".0144 .000328 -.0617" />
      <inertia ixx=" .131" ixy=" .000236" ixz="-.00677" iyy=" .094" iyz=" .0000712" izz=" .0985" />
    </inertial>
  </link>
  <link name="J2_link">
    <visual>
      <origin rpy="0 0 0" xyz="0 0 0" />
      <geometry>
        <mesh filename="meshes/j2.dae" />
      </geometry>
    </visual>
    <collision>
      <origin rpy="0 0 0" xyz="0 0 0" />
      <geometry>
        <mesh filename="meshes/j2.stl" />
      </geometry>
    </collision>
    <inertial>
      <mass value=" 19.6" />
      <origin xyz="-.000213 .000368 .265" />
      <inertia ixx=" .823" ixy=" .0000956" ixz=" .000158" iyy=" .775" iyz=" .000446" izz=" .122" />
    </inertial>
  </link>
  <link name="J3_link">
    <visual>
      <origin rpy="0 0 0" xyz="0 0 0" />
      <geometry>
        <mesh filename="meshes/j3.dae" />
      </geometry>
    </visual>
    <collision>
      <origin rpy="0 0 0" xyz="0 0 0" />
      <geometry>
        <mesh filename="meshes/j3.stl" />
      </geometry>
    </collision>
    <inertial>
      <mass value=" 2.49" />
      <origin xyz=".00103 .00127 .00775" />
      <inertia ixx=" .00714" ixy="-.0000904" ixz="-.000982" iyy=" .00977" iyz=" .000000126" izz=" .0094" />
    </inertial>
  </link>
  <link name="J4_link">
    <visual>
      <origin rpy="0 0 0" xyz="0 0 0" />
      <geometry>
        <mesh filename="meshes/j4.dae" />
      </geometry>
    </visual>
    <collision>
      <origin rpy="0 0 0" xyz="0 0 0" />
      <geometry>
        <mesh filename="meshes/j4.stl" />
      </geometry>
    </collision>
    <inertial>
      <mass value=" 4.09" />
      <origin xyz=".332 -.0000617 .000894" />
      <inertia ixx=" .00758" ixy="-.00000847" ixz=" .000045" iyy=" .0668" iyz=" .00000871" izz=" .0684" />
    </inertial>
  </link>
  <link name="J5_link">
    <visual>
      <origin rpy="0 0 0" xyz="0 0 0" />
      <geometry>
        <mesh filename="meshes/j5.dae" />
      </geometry>
    </visual>
    <collision>
      <origin rpy="0 0 0" xyz="0 0 0" />
      <geometry>
        <mesh filename="meshes/j5.stl" />
      </geometry>
    </collision>
    <inertial>
      <mass value=" .452" />
      <origin xyz=".0244 .00105 -.00000729" />
      <inertia ixx=" .000339" ixy=" .00001" ixz="-.0000000249" iyy=" .000705" iyz="-.0000000226" izz=" .000656" />
    </inertial>
  </link>
  <link name="J6_link">
    <visual>
      <origin rpy="0 0 0" xyz="0 0 0" />
      <geometry>
        <mesh filename="meshes/j6.dae" />
      </geometry>
    </visual>
    <collision>
      <origin rpy="0 0 0" xyz="0 0 0" />
      <geometry>
        <mesh filename="meshes/j6.stl" />
      </geometry>
    </collision>
    <inertial>
      <mass value=" .0198" />
      <origin xyz=".0836 -3.24E-19 -1.22E-18" />
      <inertia ixx=" .00000474" ixy=" 1.74E-21" ixz="-4.43E-21" iyy=" .00000279" iyz=" 4.68E-22" izz=" .00000279" />
    </inertial>
  </link>
  
  <joint name="J1" type="revolute">
    <origin rpy="0 0 0" xyz="0 0 .4" />
    <parent link="base_link" />
    <child link="J1_link" />
    <axis xyz="0 0 1" />
    <limit effort="800" lower="-3.2288591161895095" upper="3.2288591161895095" velocity="5.235987755982989" />
  </joint>
  <joint name="J2" type="revolute">
    <origin rpy="0 0 0" xyz=".025 0 0" />
    <parent link="J1_link" />
    <child link="J2_link" />
    <axis xyz="0 1 0" />
    <limit effort="900" lower="-1.7453292519943295" upper="2.356194490192345" velocity="4.014257279586958" />
  </joint>
  <joint name="J3" type="revolute">
    <origin rpy="0 0 0" xyz="0 0 .56" />
    <parent link="J2_link" />
    <child link="J3_link" />
    <axis xyz="0 -1 0" />
    <limit effort="300" lower="-1.2217304763960306" upper="3.6651914291880923" velocity="5.934119456780721" />
  </joint>
  <joint name="J4" type="revolute">
    <origin rpy="0 0 0" xyz="0 0 .035" />
    <parent link="J3_link" />
    <child link="J4_link" />
    <axis xyz="-1 0 0" />
    <limit effort="70" lower="-3.3161255787892263" upper="3.3161255787892263" velocity="8.726646259971648" />
  </joint>
  <joint name="J5" type="revolute">
    <origin rpy="0 0 0" xyz=".515 0 0" />
    <parent link="J4_link" />
    <child link="J5_link" />
    <axis xyz="0 -1 0" />
    <limit effort="60" lower="-2.181661564992912" upper="2.181661564992912" velocity="6.981317007977318" />
  </joint>
  <joint name="J6" type="revolute">
    <origin rpy="0 0 0" xyz="0 0 0" />
    <parent link="J5_link" />
    <child link="J6_link" />
    <axis xyz="-1 0 0" />
    <limit effort="30" lower="-6.283185307179586" upper="6.283185307179586" velocity="13.962634015954636" />
  </joint>
  
  <link name="wbase" />
  <joint name="base_link-wbase" type="fixed">
    <origin rpy="0 0 0" xyz="0 0 .4" />
    <parent link="base_link" />
    <child link="wbase" />
  </joint>
  
  <link name="flange" />
  <joint name="J6-flange" type="fixed">
    <origin rpy="0 0 0" xyz=".092 0 0" />
    <parent link="J6_link" />
    <child link="flange" />
  </joint>
  
  <link name="fanuc_flange" />
  <joint name="flange-fanuc_flange" type="fixed">
    <origin rpy="3.141592653589793 -1.5707963267948966 0.0" xyz="0 0 0" />
    <parent link="flange" />
    <child link="fanuc_flange" />
  </joint>
  
  <joint name="base_joint" type="fixed">
    <origin rpy="0 0 0" xyz="0 0 0" />
    <parent link="world" />
    <child link="base_link" />
  </joint>
  
  <joint name="child_joint" type="fixed">
    <origin rpy="0 0 0" xyz="0 0 0" />
    <parent link="flange" />
    <child link="ee_link" />
  </joint>
</robot>