<?xml version='1.0' encoding='utf-8'?>
<robot name="r2000ic_100ph">
  <link name="world" />
  <link name="ee_link" />
  
  <link name="base_link">
    <visual>
      <origin rpy="0 0 0" xyz="0 0 0" />
      <geometry>
        <mesh filename="meshes/base.dae" />
      </geometry>
    </visual>
    <collision>
      <origin rpy="0 0 0" xyz="0 0 0" />
      <geometry>
        <mesh filename="meshes/base.stl" />
      </geometry>
    </collision>
    <inertial>
      <mass value=" 197" />
      <origin xyz="-.14 -.000499 .126" />
      <inertia ixx=" 6.57" ixy=" .154" ixz="-.115" iyy=" 14.4" iyz=" .0127" izz=" 18.7" />
    </inertial>
  </link>
  <link name="J1_link">
    <visual>
      <origin rpy="0 0 0" xyz="0 0 0" />
      <geometry>
        <mesh filename="meshes/j1.dae" />
      </geometry>
    </visual>
    <collision>
      <origin rpy="0 0 0" xyz="0 0 0" />
      <geometry>
        <mesh filename="meshes/j1.stl" />
      </geometry>
    </collision>
    <inertial>
      <mass value=" 714" />
      <origin xyz=".212 .115 -.00833" />
      <inertia ixx=" 56.6" ixy=" 10.7" ixz="-3.2" iyy=" 90.1" iyz="-4.44" izz=" 113" />
    </inertial>
  </link>
  <link name="J2_link">
    <visual>
      <origin rpy="0 0 0" xyz="0 0 0" />
      <geometry>
        <mesh filename="meshes/j2.dae" />
      </geometry>
    </visual>
    <collision>
      <origin rpy="0 0 0" xyz="0 0 0" />
      <geometry>
        <mesh filename="meshes/j2.stl" />
      </geometry>
    </collision>
    <inertial>
      <mass value=" 216" />
      <origin xyz=".434 .246 .00114" />
      <inertia ixx=" 4.49" ixy="-1.45" ixz=" .685" iyy=" 27.7" iyz="-.194" izz=" 27.4" />
    </inertial>
  </link>
  <link name="J3_link">
    <visual>
      <origin rpy="0 0 0" xyz="0 0 0" />
      <geometry>
        <mesh filename="meshes/j3.dae" />
      </geometry>
    </visual>
    <collision>
      <origin rpy="0 0 0" xyz="0 0 0" />
      <geometry>
        <mesh filename="meshes/j3.stl" />
      </geometry>
    </collision>
    <inertial>
      <mass value=" 338" />
      <origin xyz=".132 .0538 -.476" />
      <inertia ixx=" 61.4" ixy=" .558" ixz=" 5.27" iyy=" 60.7" iyz="-2.28" izz=" 10.4" />
    </inertial>
  </link>
  <link name="J4_link">
    <visual>
      <origin rpy="0 0 0" xyz="0 0 0" />
      <geometry>
        <mesh filename="meshes/j4.dae" />
      </geometry>
    </visual>
    <collision>
      <origin rpy="0 0 0" xyz="0 0 0" />
      <geometry>
        <mesh filename="meshes/j4.stl" />
      </geometry>
    </collision>
    <inertial>
      <mass value=" 9.68" />
      <origin xyz="-.0000000108 -.00867 -1.63" />
      <inertia ixx=" .0849" ixy="-.000000000101" ixz=" .00000000747" iyy=" .087" iyz="-.00509" izz=" .0378" />
    </inertial>
  </link>
  <link name="J5_link">
    <visual>
      <origin rpy="0 0 0" xyz="0 0 0" />
      <geometry>
        <mesh filename="meshes/j5.dae" />
      </geometry>
    </visual>
    <collision>
      <origin rpy="0 0 0" xyz="0 0 0" />
      <geometry>
        <mesh filename="meshes/j5.stl" />
      </geometry>
    </collision>
    <inertial>
      <mass value=" 19.5" />
      <origin xyz="-.0000000343 -.0201 -.0606" />
      <inertia ixx=" .231" ixy=" .0000000629" ixz="-.0000000501" iyy=" .195" iyz=" .0232" izz=" .149" />
    </inertial>
  </link>
  <link name="J6_link">
    <visual>
      <origin rpy="0 0 0" xyz="0 0 0" />
      <geometry>
        <mesh filename="meshes/j6.dae" />
      </geometry>
    </visual>
    <collision>
      <origin rpy="0 0 0" xyz="0 0 0" />
      <geometry>
        <mesh filename="meshes/j6.stl" />
      </geometry>
    </collision>
    <inertial>
      <mass value=" 1.09" />
      <origin xyz=".000102 -.0000000235 -.224" />
      <inertia ixx=" .00217" ixy="-.0000000239" ixz=" .000000151" iyy=" .00216" iyz=" .000000000263" izz=" .00416" />
    </inertial>
  </link>
  
  <joint name="J1" type="revolute">
    <origin rpy="0 0 0" xyz="0 0 .6" />
    <parent link="base_link" />
    <child link="J1_link" />
    <axis xyz="0 0 1" />
    <limit effort="20000" lower="-3.2288591161895095" upper="3.2288591161895095" velocity="2.0943951023931953" />
  </joint>
  <joint name="J2" type="revolute">
    <origin rpy="0 0 0" xyz=".72 0 0" />
    <parent link="J1_link" />
    <child link="J2_link" />
    <axis xyz="0 1 0" />
    <limit effort="30000" lower="-2.0943951023931953" upper="1.3962634015954636" velocity="1.7453292519943295" />
  </joint>
  <joint name="J3" type="revolute">
    <origin rpy="0 0 0" xyz="1.075 0 0" />
    <parent link="J2_link" />
    <child link="J3_link" />
    <axis xyz="0 -1 0" />
    <limit effort="20000" lower="-1.3788101090755203" upper="3.141592653589793" velocity="2.007128639793479" />
  </joint>
  <joint name="J4" type="revolute">
    <origin rpy="0 0 0" xyz=".225 0 0" />
    <parent link="J3_link" />
    <child link="J4_link" />
    <axis xyz="0 0 1" />
    <limit effort="5000" lower="-6.283185307179586" upper="6.283185307179586" velocity="2.443460952792061" />
  </joint>
  <joint name="J5" type="revolute">
    <origin rpy="0 0 0" xyz="0 0 -1.73" />
    <parent link="J4_link" />
    <child link="J5_link" />
    <axis xyz="0 -1 0" />
    <limit effort="5000" lower="-2.181661564992912" upper="2.181661564992912" velocity="2.443460952792061" />
  </joint>
  <joint name="J6" type="revolute">
    <origin rpy="0 0 0" xyz="0 0 0" />
    <parent link="J5_link" />
    <child link="J6_link" />
    <axis xyz="0 0 1" />
    <limit effort="3000" lower="-6.283185307179586" upper="6.283185307179586" velocity="3.6651914291880923" />
  </joint>
  
  <link name="wbase" />
  <joint name="base_link-wbase" type="fixed">
    <origin rpy="0 0 0" xyz="0 0 .6" />
    <parent link="base_link" />
    <child link="wbase" />
  </joint>
  
  <link name="flange" />
  <joint name="J6-flange" type="fixed">
    <origin rpy="0 0 0" xyz="0 0 -.24" />
    <parent link="J6_link" />
    <child link="flange" />
  </joint>
  
  <link name="fanuc_flange" />
  <joint name="flange-fanuc_flange" type="fixed">
    <origin rpy="3.141592653589793 0.0 0.0" xyz="0 0 0" />
    <parent link="flange" />
    <child link="fanuc_flange" />
  </joint>
  
  <joint name="base_joint" type="fixed">
    <origin rpy="0 0 0" xyz="0 0 0" />
    <parent link="world" />
    <child link="base_link" />
  </joint>
  
  <joint name="child_joint" type="fixed">
    <origin rpy="0 0 0" xyz="0 0 0" />
    <parent link="flange" />
    <child link="ee_link" />
  </joint>
</robot>