<?xml version='1.0' encoding='utf-8'?>
<robot name="abb_irb2600_12_185">
  
  
  <link name="base_link">
    <visual>
      <origin rpy="0 0 0" xyz="0 0 0" />
      <geometry>
        <mesh filename="meshes/base_link.stl" />
      </geometry>
      <material name="">
        <color rgba="0.7372549 0.3490196 0.1607843 1" />
      </material>
    </visual>
    <collision>
      <origin rpy="0 0 0" xyz="0 0 0" />
      <geometry>
        <mesh filename="meshes/collision_base_link.stl" />
      </geometry>
    </collision>
  </link>
  <link name="link_1">
    <visual>
      <origin rpy="0 0 0" xyz="0 0 0" />
      <geometry>
        <mesh filename="meshes/link_1.stl" />
      </geometry>
      <material name="">
        <color rgba="0.7372549 0.3490196 0.1607843 1" />
      </material>
    </visual>
    <collision>
      <origin rpy="0 0 0" xyz="0 0 0" />
      <geometry>
        <mesh filename="meshes/collision_link_1.stl" />
      </geometry>
    </collision>
  </link>
  <link name="link_2">
    <visual>
      <origin rpy="0 0 0" xyz="0 0 0" />
      <geometry>
        <mesh filename="meshes/link_2.stl" />
      </geometry>
      <material name="">
        <color rgba="0.7372549 0.3490196 0.1607843 1" />
      </material>
    </visual>
    <collision>
      <origin rpy="0 0 0" xyz="0 0 0" />
      <geometry>
        <mesh filename="meshes/collision_link_2.stl" />
      </geometry>
    </collision>
  </link>
  <link name="link_3">
    <visual>
      <origin rpy="0 0 0" xyz="0 0 0" />
      <geometry>
        <mesh filename="meshes/link_3.stl" />
      </geometry>
      <material name="">
        <color rgba="0.7372549 0.3490196 0.1607843 1" />
      </material>
    </visual>
    <collision>
      <origin rpy="0 0 0" xyz="0 0 0" />
      <geometry>
        <mesh filename="meshes/collision_link_3.stl" />
      </geometry>
    </collision>
  </link>
  <link name="link_4">
    <visual>
      <origin rpy="0 0 0" xyz="0 0 0" />
      <geometry>
        <mesh filename="meshes/link_4.stl" />
      </geometry>
      <material name="">
        <color rgba="0.7372549 0.3490196 0.1607843 1" />
      </material>
    </visual>
    <collision>
      <origin rpy="0 0 0" xyz="0 0 0" />
      <geometry>
        <mesh filename="meshes/collision_link_4.stl" />
      </geometry>
    </collision>
  </link>
  <link name="link_5">
    <visual>
      <origin rpy="0 0 0" xyz="0 0 0" />
      <geometry>
        <mesh filename="meshes/link_5.stl" />
      </geometry>
      <material name="">
        <color rgba="0.7372549 0.3490196 0.1607843 1" />
      </material>
    </visual>
    <collision>
      <origin rpy="0 0 0" xyz="0 0 0" />
      <geometry>
        <mesh filename="meshes/collision_link_5.stl" />
      </geometry>
    </collision>
  </link>
  <link name="link_6">
    <visual>
      <origin rpy="0 0 0" xyz="0 0 0" />
      <geometry>
        <mesh filename="meshes/link_6.stl" />
      </geometry>
      <material name="">
        <color rgba="0.5 0.5 0.5 1" />
      </material>
    </visual>
    <collision>
      <origin rpy="0 0 0" xyz="0 0 0" />
      <geometry>
        <mesh filename="meshes/collision_link_6.stl" />
      </geometry>
    </collision>
  </link>
  
  <joint name="joint_1" type="revolute">
    <origin rpy="0 0 0" xyz="0 0 0.445" />
    <parent link="base_link" />
    <child link="link_1" />
    <axis xyz="0 0 1" />
    <limit effort="0" lower="-3.141592653589793" upper="3.141592653589793" velocity="3.0543261909900767" />
  </joint>
  <joint name="joint_2" type="revolute">
    <origin rpy="0 0 0" xyz="0.15 0 0.0" />
    <parent link="link_1" />
    <child link="link_2" />
    <axis xyz="0 1 0" />
    <limit effort="0" lower="-1.6580627893946132" upper="2.705260340591211" velocity="3.0543261909900767" />
  </joint>
  <joint name="joint_3" type="revolute">
    <origin rpy="0 0 0" xyz="0 0 0.900" />
    <parent link="link_2" />
    <child link="link_3" />
    <axis xyz="0 1 0" />
    <limit effort="0" lower="-3.141592653589793" upper="1.3089969389957472" velocity="3.0543261909900767" />
  </joint>
  <joint name="joint_4" type="revolute">
    <origin rpy="0 0 0" xyz="0 0 0.115" />
    <parent link="link_3" />
    <child link="link_4" />
    <axis xyz="1 0 0" />
    <limit effort="0" lower="-6.981317007977318" upper="6.981317007977318" velocity="6.283185307179586" />
  </joint>
  <joint name="joint_5" type="revolute">
    <origin rpy="0 0 0" xyz="0.795 0 0" />
    <parent link="link_4" />
    <child link="link_5" />
    <axis xyz="0 1 0" />
    <limit effort="0" lower="-2.0943951023931953" upper="2.0943951023931953" velocity="6.283185307179586" />
  </joint>
  <joint name="joint_6" type="revolute">
    <origin rpy="0 0 0" xyz="0.085 0 0" />
    <parent link="link_5" />
    <child link="link_6" />
    <axis xyz="1 0 0" />
    <limit effort="0" lower="-6.981317007977318" upper="6.981317007977318" velocity="8.726646259971648" />
  </joint>
  
  <link name="base" />
  <joint name="base_link-base" type="fixed">
    <origin rpy="0 0 0" xyz="0 0 0" />
    <parent link="base_link" />
    <child link="base" />
  </joint>
  
  <link name="flange" />
  <joint name="joint_6-flange" type="fixed">
    <origin rpy="0 0 0" xyz="0 0 0" />
    <parent link="link_6" />
    <child link="flange" />
  </joint>
  
  <link name="tool0" />
  <joint name="link_6-tool0" type="fixed">
    <origin rpy="0 1.5707963267948966 0" xyz="0 0 0" />
    <parent link="flange" />
    <child link="tool0" />
  </joint>
</robot>